Workbook

Sheet Neu
E1: leak | G1: Na | AH1: K | BI1: KA | CJ1: CaN | DK1: Kcas | EL1: Kcaf | FM1: Napp | GN1: HCN | HO1: K_pp
D2: File | E2: vdg | G2: vdg | J2: A | V2: B | AH2: vdg | AK2: A | AW2: B | BI2: vdg | BL2: A | BX2: B | CJ2: vdg | CM2: A | CY2: B | DK2: vdg | DN2: A | DZ2: B | EL2: vdg | EO2: A | FA2: B | FM2: vdg | FP2: A | GB2: B | GN2: vdg | GQ2: A | HC2: B | HO2: vdg | HR2: A | ID2: B
B3: Name | C3: Template | D3: cm | E3: g | F3: E | G3: g | H3: p | I3: E | J3: An | K3: h | L3: s | M3: p | N3: tmx | O3: tmin | P3: th1 | Q3: ts1 | R3: tp1 | S3: th2 | T3: ts2 | U3: tp2 | V3: Bn | W3: h | X3: s | Y3: p | Z3: tmx | AA3: tmin | AB3: th1 | AC3: ts1 | AD3: tp1 | AE3: th2 | AF3: ts2 | AG3: tp2 | AH3: g | AI3: p | AJ3: E | AK3: An | AL3: h | AM3: s | AN3: p | AO3: tmx | AP3: tmin | AQ3: th1 | AR3: ts1 | AS3: tp1 | AT3: th2 | AU3: ts2 | AV3: tp2 | AW3: Bn | AX3: h | AY3: s | AZ3: p | BA3: tmx | BB3: tmin | BC3: th1 | BD3: ts1 | BE3: tp1 | BF3: th2 | BG3: ts2 | BH3: tp2 | BI3: g | BJ3: p | BK3: E | BL3: An | BM3: h | BN3: s | BO3: p | BP3: tmx | BQ3: tmin | BR3: th1 | BS3: ts1 | BT3: tp1 | BU3: th2 | BV3: ts2 | BW3: tp2 | BX3: Bn | BY3: h | BZ3: s | CA3: p | CB3: tmx | CC3: tmin | CD3: th1 | CE3: ts1 | CF3: tp1 | CG3: th2 | CH3: ts2 | CI3: tp2 | CJ3: g | CK3: p | CL3: E | CM3: An | CN3: h | CO3: s | CP3: p | CQ3: tmx | CR3: tmin | CS3: th1 | CT3: ts1 | CU3: tp1 | CV3: th2 | CW3: ts2 | CX3: tp2 | CY3: Bn | CZ3: h | DA3: s | DB3: p | DC3: tmx | DD3: tmin | DE3: th1 | DF3: ts1 | DG3: tp1 | DH3: th2 | DI3: ts2 | DJ3: tp2 | DK3: g | DL3: p | DM3: E | DN3: An | DO3: h | DP3: s | DQ3: p | DR3: tmx | DS3: tmin | DT3: th1 | DU3: ts1 | DV3: tp1 | DW3: th2 | DX3: ts2 | DY3: tp2 | DZ3: Bn | EA3: h | EB3: s | EC3: p | ED3: tmx | EE3: tmin | EF3: th1 | EG3: ts1 | EH3: tp1 | EI3: th2 | EJ3: ts2 | EK3: tp2 | EL3: g | EM3: p | EN3: E | EO3: An | EP3: h | EQ3: s | ER3: p | ES3: tmx | ET3: tmin | EU3: th1 | EV3: ts1 | EW3: tp1 | EX3: th2 | EY3: ts2 | EZ3: tp2 | FA3: Bn | FB3: h | FC3: s | FD3: p | FE3: tmx | FF3: tmin | FG3: th1 | FH3: ts1 | FI3: tp1 | FJ3: th2 | FK3: ts2 | FL3: tp2 | FM3: g | FN3: p | FO3: E | FP3: An | FQ3: h | FR3: s | FS3: p | FT3: tmx | FU3: tmin | FV3: th1 | FW3: ts1 | FX3: tp1 | FY3: th2 | FZ3: ts2 | GA3: tp2 | GB3: Bn | GC3: h | GD3: s | GE3: p | GF3: tmx | GG3: tmin | GH3: th1 | GI3: ts1 | GJ3: tp1 | GK3: th2 | GL3: ts2 | GM3: tp2 | GN3: g | GO3: p | GP3: E | GQ3: An | GR3: h | GS3: s | GT3: p | GU3: tmx | GV3: tmin | GW3: th1 | GX3: ts1 | GY3: tp1 | GZ3: th2 | HA3: ts2 | HB3: tp2 | HC3: Bn | HD3: h | HE3: s | HF3: p | HG3: tmx | HH3: tmin | HI3: th1 | HJ3: ts1 | HK3: tp1 | HL3: th2 | HM3: ts2 | HN3: tp2 | HO3: g | HP3: p | HQ3: E | HR3: An | HS3: h | HT3: s | HU3: p | HV3: tmx | HW3: tmin | HX3: th1 | HY3: ts1 | HZ3: tp1 | IA3: th2 | IB3: ts2 | IC3: tp2 | ID3: Bn | IE3: h | IF3: s | IG3: p | IH3: tmx | II3: tmin | IJ3: th1 | IK3: ts1 | IL3: tp1 | IM3: th2 | IN3: ts2 | IO3: tp2
A4: =Neu!B4 -> B4 | B4: B4 | D4: 0.007 | E4: 0.1 | F4: -55 | G4: 60 | H4: 3 | I4: 30 | J4: 0 | K4: -28.5 | L4: 8.6 | M4: 1 | N4: 0.0006 | O4: 0.0001 | P4: -40.5 | Q4: 6 | R4: 1 | V4: 0 | W4: -38 | X4: 5 | Y4: 1 | Z4: 0.005 | AA4: 0.0002 | AB4: -37 | AC4: 11.6 | AD4: 1 | AH4: 100 | AI4: 4 | AJ4: -80 | AK4: 0 | AL4: -30 | AM4: 9.8 | AN4: 1 | AO4: 0.025 | AP4: 0.0002 | AQ4: 0 | AR4: 9 | AS4: 1 | BI4: 5 | BJ4: 3 | BK4: -70 | BL4: 0 | BM4: -55 | BN4: 15 | BO4: 1 | BP4: 0.017 | BQ4: 0.001 | BR4: -30 | BS4: 20 | BT4: 1 | BU4: -120 | BV4: 24 | BW4: 1 | BX4: 0 | BY4: -65 | BZ4: 5 | CA4: 1 | CB4: 0.224 | CC4: 0.0001 | CD4: -54.4 | CE4: 30.8 | CF4: 1 | CJ4: 0.16 | CK4: 2 | CL4: 60 | CM4: 0 | CN4: 0.15 | CO4: 5 | CP4: 1 | CQ4: 0.01 | CR4: 5e-05 | CS4: 3 | CT4: 18.4 | CU4: 1 | CV4: -4 | CW4: -4.6 | CX4: 1 | CY4: 0 | CZ4: -15 | DA4: 11 | DB4: 1 | DC4: 0.62 | DD4: 0.00372 | DE4: -18 | DF4: 18 | DG4: 1 | DH4: -20 | DI4: -15 | DJ4: 1 | DK4: 0.8 | DM4: -66.2 | EL4: 0.02 | EM4: 1 | EN4: -65 | EO4: 0 | EP4: 23.5 | EQ4: 10.5 | ER4: 1 | ES4: 0.001
A5: =Neu!B5 -> B8 | B5: B8 | D5: 0.01 | E5: 0.09 | F5: -59 | G5: 25 | H5: 3 | I5: 30 | J5: 0 | K5: -37 | L5: 5 | M5: 1 | N5: 0.006 | O5: 0.001 | P5: -43 | Q5: 4 | R5: 1 | V5: 0 | W5: -43 | X5: 5 | Y5: 1 | Z5: 0.02 | AA5: 0.005 | AB5: -38 | AC5: 10 | AD5: 1 | AH5: 21 | AI5: 4 | AJ5: -70 | AK5: 0 | AL5: -23 | AM5: 9 | AN5: 1 | AO5: 0.04 | AP5: 0.004 | AQ5: -8 | AR5: 10 | AS5: 1
A6: =Neu!B6 -> B20 | B6: B20 | D6: 0.01 | E6: 0.05 | F6: -60 | G6: 28 | H6: 3 | I6: 30 | J6: 0 | K6: -39 | L6: 5 | M6: 1 | N6: 0.006 | O6: 0.001 | P6: -45 | Q6: 4 | R6: 1 | V6: 0 | W6: -45 | X6: 5 | Y6: 1 | Z6: 0.02 | AA6: 0.005 | AB6: -40 | AC6: 10 | AD6: 1 | AH6: 34 | AI6: 4 | AJ6: -70 | AK6: 0 | AL6: -25 | AM6: 9 | AN6: 1 | AO6: 0.03 | AP6: 0.003 | AQ6: -10 | AR6: 10 | AS6: 1 | BI6: 1.25 | BJ6: 2 | BK6: -60 | BL6: 0 | BM6: -60 | BN6: 1 | BO6: 1 | BP6: 0.2 | BQ6: 0.02 | BR6: -56 | BS6: 1 | BT6: 2 | BX6: 0 | BY6: -55 | BZ6: 1 | CA6: 2 | CB6: 0.5
A7: =Neu!B7 -> B30 | B7: B30 | D7: 0.01 | E7: 0.1 | F7: -55 | G7: 25 | H7: 3 | I7: 30 | J7: 0 | K7: -37 | L7: 5 | M7: 1 | N7: 0.006 | O7: 0.001 | P7: -43 | Q7: 4 | R7: 1 | V7: 0 | W7: -43 | X7: 5 | Y7: 1 | Z7: 0.02 | AA7: 0.005 | AB7: -38 | AC7: 10 | AD7: 1 | AH7: 16 | AI7: 4 | AJ7: -70 | AK7: 0 | AL7: -23 | AM7: 9 | AN7: 1 | AO7: 0.04 | AP7: 0.004 | AQ7: -8 | AR7: 10 | AS7: 1
A8: =Neu!B8 -> B31s | B8: B31s | D8: 0.01 | E8: 0.05 | F8: -60
A9: =Neu!B9 -> B31a | B9: B31a | D9: 0.01 | E9: 0.04 | F9: -57 | G9: 25 | H9: 3 | I9: 30 | J9: 0 | K9: -37 | L9: 5 | M9: 1 | N9: 0.006 | O9: 0.001 | P9: -43 | Q9: 4 | R9: 1 | V9: 0 | W9: -43 | X9: 5 | Y9: 1 | Z9: 0.02 | AA9: 0.005 | AB9: -38 | AC9: 10 | AD9: 1 | AH9: 12 | AI9: 4 | AJ9: -70 | AK9: 0 | AL9: -23 | AM9: 9 | AN9: 1 | AO9: 0.04 | AP9: 0.004 | AQ9: -8 | AR9: 10 | AS9: 1
A10: =Neu!B10 -> B34 | B10: B34 | D10: 0.01 | E10: 0.09 | F10: -59 | G10: 25 | H10: 3 | I10: 30 | J10: 0 | K10: -39 | L10: 5 | M10: 1 | N10: 0.006 | O10: 0.001 | P10: -45 | Q10: 4 | R10: 1 | V10: 0 | W10: -45 | X10: 5 | Y10: 1 | Z10: 0.02 | AA10: 0.005 | AB10: -40 | AC10: 10 | AD10: 1 | AH10: 19 | AI10: 4 | AJ10: -70 | AK10: 0 | AL10: -25 | AM10: 9 | AN10: 1 | AO10: 0.04 | AP10: 0.004 | AQ10: -10 | AR10: 10 | AS10: 1 | BI10: 1.25 | BJ10: 2 | BK10: -60 | BL10: 0 | BM10: -60 | BN10: 1 | BO10: 1 | BP10: 0.2 | BQ10: 0.02 | BR10: -56 | BS10: 1 | BT10: 2 | BX10: 0 | BY10: -55 | BZ10: 1 | CA10: 2 | CB10: 0.5
A11: =Neu!B11 -> B35 | B11: B35 | D11: 0.0005 | E11: 0.1 | F11: -60 | G11: 7.5 | H11: 3 | I11: 50 | J11: 0 | K11: -39 | L11: 5 | M11: 1 | N11: 0.003 | O11: 0.0009 | P11: -40 | Q11: 2 | R11: 1 | V11: 0 | W11: -49 | X11: 9 | Y11: 1 | Z11: 0.02 | AA11: 0.0048 | AB11: -36 | AC11: 3.5 | AD11: 1 | AH11: 25 | AI11: 4 | AJ11: -70 | AK11: 0 | AL11: -23.5 | AM11: 9 | AN11: 1 | AO11: 0.034 | AP11: 0.003 | AQ11: -10 | AR11: 10 | AS11: 1 | AW11: 0.15 | AX11: -14.4 | AY11: 1.5 | AZ11: 2 | BA11: 0.4 | BB11: 0.04 | BC11: -21 | BD11: 8 | BE11: 1 | FM11: 0.12 | FN11: 1 | FO11: -28 | FP11: 0 | FQ11: -48 | FR11: 2.5 | FS11: 1 | FT11: 0.2 | GB11: 0 | GC11: -48 | GD11: 0.5 | GE11: 1 | GF11: 9.5
A12: =Neu!B12 -> B40 | B12: B40 | D12: 0.01 | E12: 0.1 | F12: -57 | G12: 25 | H12: 3 | I12: 30 | J12: 0 | K12: -37 | L12: 5 | M12: 1 | N12: 0.006 | O12: 0.001 | P12: -43 | Q12: 4 | R12: 1 | V12: 0 | W12: -43 | X12: 5 | Y12: 1 | Z12: 0.02 | AA12: 0.005 | AB12: -38 | AC12: 10 | AD12: 1 | AH12: 16 | AI12: 4 | AJ12: -70 | AK12: 0 | AL12: -23 | AM12: 9 | AN12: 1 | AO12: 0.04 | AP12: 0.004 | AQ12: -8 | AR12: 10 | AS12: 1
A13: =Neu!B13 -> B51s | B13: B51s | D13: 0.001 | E13: 0.15 | F13: -64 | G13: 3 | H13: 3 | I13: 30 | J13: 0 | K13: -37 | L13: 5 | M13: 1 | N13: 0.006 | O13: 0.001 | P13: -43 | Q13: 4 | R13: 1 | V13: 0 | W13: -43 | X13: 5 | Y13: 1 | Z13: 0.02 | AA13: 0.005 | AB13: -38 | AC13: 10 | AD13: 1 | AH13: 1.8 | AI13: 4 | AJ13: -80 | AK13: 0 | AL13: -23 | AM13: 9 | AN13: 1 | AO13: 0.04 | AP13: 0.004 | AQ13: -8 | AR13: 10 | AS13: 1 | FM13: 0.11 | FN13: 1 | FO13: 30 | FP13: 0 | FQ13: -50 | FR13: 1 | FS13: 1 | FT13: 0.1 | HO13: 0.35 | HP13: 1 | HQ13: -70 | HR13: 0 | HS13: -54 | HT13: 1 | HU13: 1 | HV13: 10
A14: =Neu!B14 -> B51a | B14: B51a | D14: 0.003 | E14: 0.08 | F14: -77 | G14: 40 | H14: 3 | I14: 30 | J14: 0 | K14: -37 | L14: 5 | M14: 1 | N14: 0.006 | O14: 0.001 | P14: -43 | Q14: 4 | R14: 1 | V14: 0 | W14: -43 | X14: 5 | Y14: 1 | Z14: 0.02 | AA14: 0.005 | AB14: -38 | AC14: 10 | AD14: 1 | AH14: 24 | AI14: 4 | AJ14: -70 | AK14: 0 | AL14: -23 | AM14: 9 | AN14: 1 | AO14: 0.04 | AP14: 0.004 | AQ14: -8 | AR14: 10 | AS14: 1
A15: =Neu!B15 -> B52 | B15: B52 | D15: 0.01 | E15: 0.1 | F15: -62 | G15: 25 | H15: 3 | I15: 30 | J15: 0 | K15: -37 | L15: 5 | M15: 1 | N15: 0.006 | O15: 0.001 | P15: -43 | Q15: 4 | R15: 1 | V15: 0 | W15: -43 | X15: 5 | Y15: 1 | Z15: 0.02 | AA15: 0.005 | AB15: -38 | AC15: 10 | AD15: 1 | AH15: 18 | AI15: 4 | AJ15: -70 | AK15: 0 | AL15: -23 | AM15: 9 | AN15: 1 | AO15: 0.04 | AP15: 0.004 | AQ15: -8 | AR15: 10 | AS15: 1 | GN15: 0.1 | GO15: 1 | GP15: 30 | GQ15: 0 | GR15: -61 | GS15: -1 | GT15: 3 | GU15: 15 | GV15: 5 | GW15: -60 | GX15: 5 | GY15: 1
A16: =Neu!B16 -> B63 | B16: B63 | D16: 0.01 | E16: 0.04 | F16: -60 | G16: 25 | H16: 3 | I16: 30 | J16: 0 | K16: -37 | L16: 5 | M16: 1 | N16: 0.006 | O16: 0.001 | P16: -43 | Q16: 4 | R16: 1 | V16: 0 | W16: -43 | X16: 5 | Y16: 1 | Z16: 0.02 | AA16: 0.005 | AB16: -38 | AC16: 10 | AD16: 1 | AH16: 20 | AI16: 4 | AJ16: -70 | AK16: 0 | AL16: -23 | AM16: 9 | AN16: 1 | AO16: 0.04 | AP16: 0.004 | AQ16: -8 | AR16: 10 | AS16: 1
A17: =Neu!B17 -> B64s | B17: B64s | D17: 0.01 | E17: 0.08 | F17: -60 | G17: 2.5 | H17: 3 | I17: 30 | J17: 0 | K17: -37 | L17: 5 | M17: 1 | N17: 0.006 | O17: 0.001 | P17: -43 | Q17: 4 | R17: 1 | V17: 0 | W17: -43 | X17: 5 | Y17: 1 | Z17: 0.02 | AA17: 0.005 | AB17: -38 | AC17: 10 | AD17: 1 | AH17: 1.6 | AI17: 4 | AJ17: -80 | AK17: 0 | AL17: -23 | AM17: 9 | AN17: 1 | AO17: 0.04 | AP17: 0.004 | AQ17: -8 | AR17: 10 | AS17: 1 | FM17: 0.1 | FN17: 1 | FO17: 30 | FP17: 0 | FQ17: -50 | FR17: 1 | FS17: 1 | FT17: 0.1 | HO17: 0.35 | HP17: 1 | HQ17: -70 | HR17: 0 | HS17: -50 | HT17: 1 | HU17: 1 | HV17: 7
A18: =Neu!B18 -> B64a | B18: B64a | D18: 0.01 | E18: 0.1 | F18: -60 | G18: 25 | H18: 3 | I18: 30 | J18: 0 | K18: -37 | L18: 5 | M18: 1 | N18: 0.006 | O18: 0.001 | P18: -43 | Q18: 4 | R18: 1 | V18: 0 | W18: -43 | X18: 5 | Y18: 1 | Z18: 0.02 | AA18: 0.005 | AB18: -38 | AC18: 10 | AD18: 1 | AH18: 28 | AI18: 4 | AJ18: -70 | AK18: 0 | AL18: -23 | AM18: 9 | AN18: 1 | AO18: 0.04 | AP18: 0.004 | AQ18: -8 | AR18: 10 | AS18: 1
A19: =Neu!B19 -> B65 | B19: B65 | D19: 0.01 | E19: 0.08 | F19: -55 | G19: 25 | H19: 3 | I19: 30 | J19: 0 | K19: -37 | L19: 5 | M19: 1 | N19: 0.006 | O19: 0.001 | P19: -43 | Q19: 4 | R19: 1 | V19: 0 | W19: -43 | X19: 5 | Y19: 1 | Z19: 0.02 | AA19: 0.005 | AB19: -38 | AC19: 10 | AD19: 1 | AH19: 19 | AI19: 4 | AJ19: -70 | AK19: 0 | AL19: -23 | AM19: 9 | AN19: 1 | AO19: 0.2 | AP19: 0.004 | AQ19: -8 | AR19: 10 | AS19: 1 | FM19: 0.3 | FN19: 1 | FO19: -40 | FP19: 0 | FQ19: -45 | FR19: 5 | FS19: 3 | FT19: 2 | HO19: 0.01 | HP19: 1 | HQ19: -60 | HR19: 0 | HS19: -40 | HT19: -5 | HU19: 4 | HV19: 1
A20: =Neu!B20 -> CBI2 | B20: CBI2 | D20: 0.01 | E20: 0.1 | F20: -60 | G20: 25 | H20: 3 | I20: 30 | J20: 0 | K20: -37 | L20: 5 | M20: 1 | N20: 0.006 | O20: 0.001 | P20: -43 | Q20: 4 | R20: 1 | V20: 0 | W20: -43 | X20: 5 | Y20: 1 | Z20: 0.02 | AA20: 0.005 | AB20: -38 | AC20: 10 | AD20: 1 | AH20: 20 | AI20: 4 | AJ20: -70 | AK20: 0 | AL20: -23 | AM20: 9 | AN20: 1 | AO20: 0.04 | AP20: 0.004 | AQ20: -8 | AR20: 10 | AS20: 1
A21: =Neu!B21 -> 0
A22: =Neu!B22 -> 0
A23: =Neu!B23 -> 0
A24: =Neu!B24 -> 0
D29: Ion pools | O29: Conductance to ion | Z29: Ion to conductance | BD29: Initial voltage
D30: Name | E30: ion | F30: K1 | G30: K2 | H30: ion | I30: K1 | J30: K2 | K30: ion | L30: K1 | M30: K2 | O30: Name | P30: ch | Q30: ion | R30: ch | S30: ion | T30: ch | U30: ion | V30: ch | W30: ion | Z30: Name | AA30: ion | AB30: ch | AC30: opt1 | AD30: opt2 | AE30: p1 | AF30: p2 | AG30: b | AH30: ion | AI30: ch | AJ30: opt1 | AK30: opt2 | AL30: p1 | AM30: p2 | AN30: b | AO30: ion | AP30: ch | AQ30: opt1 | AR30: opt2 | AS30: p1 | AT30: p2 | AU30: b | AV30: ion | AW30: ch | AX30: opt1 | AY30: opt2 | AZ30: p1 | BA30: p2 | BB30: b | BD30: Name | BE30: mV
D31: =Neu!$B4 -> B4 | E31: Ca | F31: 10 | G31: 9 | O31: =Neu!$B4 -> B4 | P31: CaN | Q31: Ca | Z31: =Neu!$B4 -> B4 | AA31: Ca | AB31: CaN | AC31: 3 | AD31: 2 | AE31: 60 | AG31: 17 | AH31: Ca | AI31: Kcaf | AJ31: 1 | AK31: 1 | AL31: 0.01 | AO31: Ca | AP31: Kcas | AQ31: 1 | AR31: 1 | AS31: 3 | BD31: =Neu!$B4 -> B4 | BE31: -60
D32: =Neu!$B5 -> B8 | O32: =Neu!$B5 -> B8 | Z32: =Neu!$B5 -> B8 | BD32: =Neu!$B5 -> B8 | BE32: -60
D33: =Neu!$B6 -> B20 | E33: Na | F33: 1 | G33: 0.2 | O33: =Neu!$B6 -> B20 | P33: Na | Q33: Na | Z33: =Neu!$B6 -> B20 | BD33: =Neu!$B6 -> B20 | BE33: -60
D34: =Neu!$B7 -> B30 | E34: Na | F34: 1 | G34: 0.2 | O34: =Neu!$B7 -> B30 | P34: Na | Q34: Na | Z34: =Neu!$B7 -> B30 | BD34: =Neu!$B7 -> B30 | BE34: -60
D35: =Neu!$B8 -> B31s | O35: =Neu!$B8 -> B31s | Z35: =Neu!$B8 -> B31s | BD35: =Neu!$B8 -> B31s | BE35: -60
D36: =Neu!$B9 -> B31a | E36: Na | F36: 14 | G36: 0.4 | O36: =Neu!$B9 -> B31a | P36: Na | Q36: Na | Z36: =Neu!$B9 -> B31a | BD36: =Neu!$B9 -> B31a | BE36: -60
D37: =Neu!$B10 -> B34 | E37: Na | F37: 1 | G37: 0.2 | O37: =Neu!$B10 -> B34 | P37: Na | Q37: Na | Z37: =Neu!$B10 -> B34 | BD37: =Neu!$B10 -> B34 | BE37: -60
D38: =Neu!$B11 -> B35 | O38: =Neu!$B11 -> B35 | Z38: =Neu!$B11 -> B35 | BD38: =Neu!$B11 -> B35 | BE38: -60
D39: =Neu!$B12 -> B40 | O39: =Neu!$B12 -> B40 | Z39: =Neu!$B12 -> B40 | BD39: =Neu!$B12 -> B40 | BE39: -60
D40: =Neu!$B13 -> B51s | O40: =Neu!$B13 -> B51s | Z40: =Neu!$B13 -> B51s | BD40: =Neu!$B13 -> B51s | BE40: -60
D41: =Neu!$B14 -> B51a | O41: =Neu!$B14 -> B51a | Z41: =Neu!$B14 -> B51a | BD41: =Neu!$B14 -> B51a | BE41: -60
D42: =Neu!$B15 -> B52 | O42: =Neu!$B15 -> B52 | Z42: =Neu!$B15 -> B52 | BD42: =Neu!$B15 -> B52 | BE42: -60
D43: =Neu!$B16 -> B63 | E43: Na | F43: 14 | G43: 0.4 | O43: =Neu!$B16 -> B63 | P43: Na | Q43: Na | Z43: =Neu!$B16 -> B63 | BD43: =Neu!$B16 -> B63 | BE43: -60
D44: =Neu!$B17 -> B64s | O44: =Neu!$B17 -> B64s | Z44: =Neu!$B17 -> B64s | BD44: =Neu!$B17 -> B64s | BE44: -60
...

Sheet excitability.smu
F1: syntax | L1: example variables | M1: IVDxREG | N1: currrent by conductance and regulation | T1: example synapses
A2: smu | B2: name | C2: excitability | D2: graph | E2: 1 | F2: conductance | G2: variable.conductance.neuron | M2: V | N2: voltage | Q2: Ics | R2: chem syn current | T2: f_exc | U2: fast excitatory
B3: duration | C3: 30 | D3: store | E3: 0 | F3: example | G3: Ivd.Na.N1 | I3: fBR | J3: fBR.ion.ch.neuron | M3: Ivd | N3: current by voltage gated conductance | Q3: Cion | R3: amount of ion | T3: s_exc | U3: slow excitatory
B4: stepsize | C4: 5e-05 | D4: method | E4: 1 | F4: neuron | G4: variable.neuron | I4: synapse | J4: variable.pre.post.type | M4: A | N4: activation of conductance | Q4: Ies | R4: elec syn current | T4: f_inh | U4: fast inhibitory
B5: red indicates simlation longer than graph duration | F5: example | G5: V.N1 | I5: example | J5: Ics.N1.N4.f_exc | M5: B | N5: Inactivation of conductance | Q5: slex | R5: trt current | T5: s_inh | U5: slow inhibitory
A6: graph (ous) | J6: Ies.N1.N4 | M6: sIVD_reg | N6: for total current
B7: time | G7: variable 1 | L7: variable 2 | Q7: variable 3 | V7: variable 4
A8: Size | B8: variable | C8: # ticks | D8: start | E8: stop | F8: color | G8: variable | H8: # ticks | I8: min | J8: max | K8: color | L8: variable | M8: # ticks | N8: min | O8: max | P8: color | Q8: variable | R8: # ticks | S8: min | T8: max | U8: color | V8: variable | W8: # ticks | X8: min | Y8: max | Z8: color
A9: 1 | B9: time | C9: 15 | D9: 0 | E9: 30 | F9: white | G9: V.B4 | H9: 10 | I9: -80 | J9: 20 | K9: red | L9: V.B8 | M9: 10 | N9: -80 | O9: 20 | P9: green | Q9: V.B20 | R9: 10 | S9: -80 | T9: 20 | U9: orange
A10: 1 | B10: time | C10: 15 | D10: 0 | E10: 30 | F10: white | G10: V.B30 | H10: 10 | I10: -80 | J10: 20 | K10: red | L10: V.B31s | M10: 10 | N10: -80 | O10: 20 | P10: green | Q10: V.B31a | R10: 10 | S10: -80 | T10: 20 | U10: orange
A11: 1 | B11: time | C11: 15 | D11: 0 | E11: 30 | F11: white | G11: V.B34 | H11: 10 | I11: -80 | J11: 20 | K11: red | L11: V.B35 | M11: 10 | N11: -80 | O11: 20 | P11: green | Q11: V.B40 | R11: 10 | S11: -80 | T11: 20 | U11: orange
A12: 1 | B12: time | C12: 15 | D12: 0 | E12: 30 | F12: white | G12: V.B51s | H12: 10 | I12: -80 | J12: 20 | K12: red | L12: V.B51a | M12: 10 | N12: -80 | O12: 20 | P12: green | Q12: V.B52 | R12: 10 | S12: -80 | T12: 20 | U12: orange
A13: 1 | B13: time | C13: 15 | D13: 0 | E13: 30 | F13: white | G13: V.B63 | H13: 10 | I13: -80 | J13: 20 | K13: red | L13: V.B64s | M13: 10 | N13: -80 | O13: 20 | P13: green | Q13: V.B64a | R13: 10 | S13: -80 | T13: 20 | U13: orange
A14: 1 | B14: time | C14: 15 | D14: 0 | E14: 30 | F14: white | G14: V.B65 | H14: 10 | I14: -80 | J14: 20 | K14: red | L14: V.CBI2 | M14: 10 | N14: -80 | O14: 20 | P14: green
A25: stimulation (.trt) | L25: output variables
B26: Current injection | G26: Voltage clamp | L26: all | M26: type "all" in first cell to output all graphed variables or type individual channels
B27: neuron | C27: start | D27: stop | E27: magnitude | G27: neuron | H27: start | I27: stop | J27: potential
B28: B4 | C28: 0 | D28: 30 | E28: -2
B29: B8 | C29: 0 | D29: 30 | E29: -2
B30: B20 | C30: 0 | D30: 30 | E30: -2
B31: B30 | C31: 0 | D31: 30 | E31: -2
B32: B31s | C32: 0 | D32: 30 | E32: -2
B33: B34 | C33: 0 | D33: 30 | E33: -2
B34: B35 | C34: 0 | D34: 30 | E34: -2
B35: B40 | C35: 0 | D35: 30 | E35: -2
B36: B51s | C36: 0 | D36: 30 | E36: -2
B37: B52 | C37: 0 | D37: 30 | E37: -2
B38: B63 | C38: 0 | D38: 30 | E38: -2
B39: B64s | C39: 0 | D39: 30 | E39: -2
... B55: CBI2 | C55: 27 | D55: 28 | E55: 4

Sheet BMP.smu
F1: syntax | L1: example variables | M1: IVDxREG | N1: currrent by conductance and regulation | T1: example synapses
A2: smu | B2: name | C2: BMP | D2: graph | E2: 1 | F2: conductance | G2: variable.conductance.neuron | M2: V | N2: voltage | Q2: Ics | R2: chem syn current | T2: f_exc | U2: fast excitatory
B3: duration | C3: 240 | D3: store | E3: 1 | F3: example | G3: Ivd.Na.N1 | I3: fBR | J3: fBR.ion.ch.neuron | M3: Ivd | N3: current by voltage gated conductance | Q3: Cion | R3: amount of ion | T3: s_exc | U3: slow excitatory
B4: stepsize | C4: 5e-05 | D4: method | E4: 1 | F4: neuron | G4: variable.neuron | I4: synapse | J4: variable.pre.post.type | M4: A | N4: activation of conductance | Q4: Ies | R4: elec syn current | T4: f_inh | U4: fast inhibitory
B5: red indicates simlation longer than graph duration | F5: example | G5: V.N1 | I5: example | J5: Ics.N1.N4.f_exc | M5: B | N5: Inactivation of conductance | Q5: slex | R5: trt current | T5: s_inh | U5: slow inhibitory
A6: graph (ous) | J6: Ies.N1.N4 | M6: sIVD_reg | N6: for total current
B7: time | G7: variable 1 | L7: variable 2 | Q7: variable 3 | V7: variable 4
A8: Size | B8: variable | C8: # ticks | D8: start | E8: stop | F8: color | G8: variable | H8: # ticks | I8: min | J8: max | K8: color | L8: variable | M8: # ticks | N8: min | O8: max | P8: color | Q8: variable | R8: # ticks | S8: min | T8: max | U8: color | V8: variable | W8: # ticks | X8: min | Y8: max | Z8: color
A9: 1 | B9: time | C9: 24 | D9: 0 | E9: 240 | F9: red | G9: V.CBI2 | H9: 10 | I9: -80 | J9: 20 | K9: red
A10: 1 | B10: time | C10: 24 | D10: 0 | E10: 240 | F10: white | G10: V.B31a | H10: 10 | I10: -80 | J10: 20 | K10: white
A11: 1 | B11: time | C11: 24 | D11: 0 | E11: 240 | F11: orange | G11: V.B20 | H11: 10 | I11: -80 | J11: 20 | K11: orange
A12: 1 | B12: time | C12: 24 | D12: 0 | E12: 240 | F12: cyan | G12: V.B30 | H12: 10 | I12: -80 | J12: 20 | K12: cyan
A13: 1 | B13: time | C13: 24 | D13: 0 | E13: 240 | F13: orange | G13: V.B40 | H13: 10 | I13: -80 | J13: 20 | K13: orange
A14: 1 | B14: time | C14: 24 | D14: 0 | E14: 240 | F14: red | G14: V.B34 | H14: 10 | I14: -80 | J14: 20 | K14: red
A15: 1 | B15: time | C15: 24 | D15: 0 | E15: 240 | F15: white | G15: V.B35 | H15: 10 | I15: -80 | J15: 20 | K15: white
A16: 1 | B16: time | C16: 24 | D16: 0 | E16: 240 | F16: orange | G16: V.B63 | H16: 10 | I16: -80 | J16: 20 | K16: orange
A17: 1 | B17: time | C17: 24 | D17: 0 | E17: 240 | F17: cyan | G17: V.B4 | H17: 10 | I17: -80 | J17: 20 | K17: cyan
A18: 1 | B18: time | C18: 24 | D18: 0 | E18: 240 | F18: orange | G18: V.B8 | H18: 10 | I18: -80 | J18: 20 | K18: orange
A19: 1 | B19: time | C19: 24 | D19: 0 | E19: 240 | F19: red | G19: V.B51a | H19: 10 | I19: -80 | J19: 20 | K19: red
A20: 1 | B20: time | C20: 24 | D20: 0 | E20: 240 | F20: white | G20: V.B64a | H20: 10 | I20: -80 | J20: 20 | K20: white
A21: 1 | B21: time | C21: 24 | D21: 0 | E21: 240 | F21: orange | G21: V.B52 | H21: 10 | I21: -80 | J21: 20 | K21: orange
A26: stimulation (.trt) | L26: output variables
B27: Current injection | G27: Voltage clamp | L27: all | M27: type "all" in first cell to output all graphed variables or type individual channels
B28: neuron | C28: start | D28: stop | E28: magnitude | G28: neuron | H28: start | I28: stop | J28: potential
B29: CBI2 | C29: 2 | D29: 500 | E29: 1.87

Sheet cs_g
C1: Postsynaptic
C2: =Neu!$B4 -> B4 | D2: =Neu!$B5 -> B8 | E2: =Neu!$B6 -> B20 | F2: =Neu!$B7 -> B30 | G2: =Neu!$B8 -> B31s | H2: =Neu!$B9 -> B31a | I2: =Neu!$B10 -> B34 | J2: =Neu!$B11 -> B35 | K2: =Neu!$B12 -> B40 | L2: =Neu!$B13 -> B51s | M2: =Neu!$B14 -> B51a | N2: =Neu!$B15 -> B52 | O2: =Neu!$B16 -> B63 | P2: =Neu!$B17 -> B64s | Q2: =Neu!$B18 -> B64a | R2: =Neu!$B19 -> B65 | S2: =Neu!$B20 -> CBI2 | T2: =Neu!$B21 -> 0 | U2: =Neu!$B22 -> 0 | V2: =Neu!$B23 -> 0 | W2: =Neu!$B24 -> 0
A3: Presynaptic | B3: =Neu!B4 -> B4 | D3: 0.6 | G3: 0.1 | L3: 0.841 | N3: 0.6 | P3: 0.2 | X3: fast | Y3: Colorbar
X4: slow | Y4: =MAX($C$3:$W$44)-(ROW(Y4)-4)*0.5 -> 5
B5: =Neu!B5 -> B8 | Y5: =MAX($C$3:$W$44)-(ROW(Y5)-4)*0.5 -> 4.5
Y6: =MAX($C$3:$W$44)-(ROW(Y6)-4)*0.5 -> 4
B7: =Neu!B6 -> B20 | C7: 0.1 | D7: 0.6 | Y7: =MAX($C$3:$W$44)-(ROW(Y7)-4)*0.5 -> 3.5
C8: 0.18 | D8: 0.9 | Y8: =MAX($C$3:$W$44)-(ROW(Y8)-4)*0.5 -> 3
B9: =Neu!B7 -> B30 | D9: 0.7 | G9: 0.5 | O9: 0.25 | P9: 0.2 | Y9: =MAX($C$3:$W$44)-(ROW(Y9)-4)*0.5 -> 2.5
D10: 1 | P10: 5 | Y10: =MAX($C$3:$W$44)-(ROW(Y10)-4)*0.5 -> 2
B11: =Neu!B8 -> B31s | Y11: =MAX($C$3:$W$44)-(ROW(Y11)-4)*0.5 -> 1.5
Y12: =MAX($C$3:$W$44)-(ROW(Y12)-4)*0.5 -> 1
B13: =Neu!B9 -> B31a | P13: 0.3 | Y13: =MAX($C$3:$W$44)-(ROW(Y13)-4)*0.5 -> 0.5
G14: 3.8 | Y14: =MAX($C$3:$W$44)-(ROW(Y14)-4)*0.5 -> 0
B15: =Neu!B10 -> B34 | D15: 0.2 | E15: 0.5 | G15: 0.125 | O15: 0.4 | P15: 0.6 | Y15: =MAX($C$3:$W$44)-(ROW(Y15)-4)*0.5 -> -0.5
D16: 0 | G16: 0.05 | Y16: =MAX($C$3:$W$44)-(ROW(Y16)-4)*0.5 -> -1
B17: =Neu!B11 -> B35 | C17: 1.8 | M17: 0.56 | N17: 0.15 | Y17: =MAX($C$3:$W$44)-(ROW(Y17)-4)*0.5 -> -1.5
C18: 1.3 | N18: 0.05 | Y18: =MAX($C$3:$W$44)-(ROW(Y18)-4)*0.5 -> -2
B19: =Neu!B12 -> B40 | D19: 0.3 | G19: 0.6 | P19: 0.6 | Y19: =MAX($C$3:$W$44)-(ROW(Y19)-4)*0.5 -> -2.5
D20: -0.03 | Y20: =MAX($C$3:$W$44)-(ROW(Y20)-4)*0.5 -> -3
B21: =Neu!B13 -> B51s | Y21: =MAX($C$3:$W$44)-(ROW(Y21)-4)*0.5 -> -3.5
Y22: =MAX($C$3:$W$44)-(ROW(Y22)-4)*0.5 -> -4
B23: =Neu!B14 -> B51a | D23: 0.8 | N23: 4 | P23: 0.8 | Y23: =MAX($C$3:$W$44)-(ROW(Y23)-4)*0.5 -> -4.5
Y24: =MAX($C$3:$W$44)-(ROW(Y24)-4)*0.5 -> -5
B25: =Neu!B15 -> B52 | D25: 1.2 | L25: 2 | P25: 3 | Y25: =MAX($C$3:$W$44)-(ROW(Y25)-4)*0.5 -> -5.5
L26: 1 | Y26: =MAX($C$3:$W$44)-(ROW(Y26)-4)*0.5 -> -6
B27: =Neu!B16 -> B63 | D27: 0.4 | E27: 0.4 | G27: 0.6 | H27: 0 | I27: 0.9 | P27: 0.05
E28: 0.04 | G28: 3.8 | P28: 0.3 | R28: 0.5
B29: =Neu!B17 -> B64s
B31: =Neu!B18 -> B64a | C31: 0.9 | D31: 0 | E31: 2 | F31: 2 | G31: 5 | H31: 2 | I31: 2 | J31: 5 | K31: 2 | N31: 3 | O31: 2 | R31: 2 | S31: 4.5
B33: =Neu!B19 -> B65 | C33: 2.8 | D33: 0 | E33: 0.5 | F33: 0.8 | G33: 0.1 | O33: 0.07 | P33: 0.6
D34: 0.25 | E34: -0.01 | K34: 4 | P34: 0.8
B35: =Neu!B20 -> CBI2 | G35: 0.05 | I35: 0.07 | K35: 0.07 | O35: 0.06
D36: 0.1 | E36: 0.2 | G36: 0.02 | I36: 0.1 | K36: 0.2 | O36: 0.06
B37: =Neu!B21 -> 0
B39: =Neu!B22 -> 0
B41: =Neu!B23 -> 0
B43: =Neu!B24 -> 0

Sheet cs_E
C1: Postsynaptic
C2: =Neu!$B4 -> B4 | D2: =Neu!$B5 -> B8 | E2: =Neu!$B6 -> B20 | F2: =Neu!$B7 -> B30 | G2: =Neu!$B8 -> B31s | H2: =Neu!$B9 -> B31a | I2: =Neu!$B10 -> B34 | J2: =Neu!$B11 -> B35 | K2: =Neu!$B12 -> B40 | L2: =Neu!$B13 -> B51s | M2: =Neu!$B14 -> B51a | N2: =Neu!$B15 -> B52 | O2: =Neu!$B16 -> B63 | P2: =Neu!$B17 -> B64s | Q2: =Neu!$B18 -> B64a | R2: =Neu!$B19 -> B65 | S2: =Neu!$B20 -> CBI2 | T2: =Neu!$B21 -> 0 | U2: =Neu!$B22 -> 0 | V2: =Neu!$B23 -> 0 | W2: =Neu!$B24 -> 0
A3: Presynaptic | B3: =Neu!B4 -> B4 | D3: -80 | G3: 0 | L3: -100 | N3: -80 | P3: -80 | X3: fast | Y3: Colorbar
X4: slow | Y4: =MAX($C$3:$W$44)-(ROW(Y4)-4)*10 -> 20
B5: =Neu!B5 -> B8 | Y5: =MAX($C$3:$W$44)-(ROW(Y5)-4)*10 -> 10
Y6: =MAX($C$3:$W$44)-(ROW(Y6)-4)*10 -> 0
B7: =Neu!B6 -> B20 | C7: 0 | D7: 0 | Y7: =MAX($C$3:$W$44)-(ROW(Y7)-4)*10 -> -10
C8: 0 | D8: 0 | Y8: =MAX($C$3:$W$44)-(ROW(Y8)-4)*10 -> -20
B9: =Neu!B7 -> B30 | D9: -70 | G9: 0 | O9: 0 | P9: -80 | Y9: =MAX($C$3:$W$44)-(ROW(Y9)-4)*10 -> -30
D10: 0 | P10: 0 | Y10: =MAX($C$3:$W$44)-(ROW(Y10)-4)*10 -> -40
B11: =Neu!B8 -> B31s | Y11: =MAX($C$3:$W$44)-(ROW(Y11)-4)*10 -> -50
Y12: =MAX($C$3:$W$44)-(ROW(Y12)-4)*10 -> -60
B13: =Neu!B9 -> B31a | P13: -80 | Y13: =MAX($C$3:$W$44)-(ROW(Y13)-4)*10 -> -70
G14: 0 | Y14: =MAX($C$3:$W$44)-(ROW(Y14)-4)*10 -> -80
B15: =Neu!B10 -> B34 | D15: -80 | E15: 0 | G15: 0 | O15: 0 | P15: -80 | Y15: =MAX($C$3:$W$44)-(ROW(Y15)-4)*10 -> -90
D16: -65 | G16: 0 | Y16: =MAX($C$3:$W$44)-(ROW(Y16)-4)*10 -> -100
B17: =Neu!B11 -> B35 | C17: -10 | M17: -70 | N17: 0 | Y17: =MAX($C$3:$W$44)-(ROW(Y17)-4)*10 -> -110
C18: 20 | N18: 0 | Y18: =MAX($C$3:$W$44)-(ROW(Y18)-4)*10 -> -120
B19: =Neu!B12 -> B40 | D19: -75 | G19: -55 | P19: -65 | Y19: =MAX($C$3:$W$44)-(ROW(Y19)-4)*10 -> -130
D20: -64 | Y20: =MAX($C$3:$W$44)-(ROW(Y20)-4)*10 -> -140
B21: =Neu!B13 -> B51s | Y21: =MAX($C$3:$W$44)-(ROW(Y21)-4)*10 -> -150
Y22: =MAX($C$3:$W$44)-(ROW(Y22)-4)*10 -> -160
B23: =Neu!B14 -> B51a | D23: 0 | N23: -85 | P23: 0 | Y23: =MAX($C$3:$W$44)-(ROW(Y23)-4)*10 -> -170
Y24: =MAX($C$3:$W$44)-(ROW(Y24)-4)*10 -> -180
B25: =Neu!B15 -> B52 | D25: -80 | L25: -80 | P25: -80 | Y25: =MAX($C$3:$W$44)-(ROW(Y25)-4)*10 -> -190
L26: -80 | Y26: =MAX($C$3:$W$44)-(ROW(Y26)-4)*10 -> -200
B27: =Neu!B16 -> B63 | D27: -80 | E27: 0 | G27: 0 | H27: 0 | I27: 0 | P27: -80 | Y27: =MAX($C$3:$W$44)-(ROW(Y27)-4)*10 -> -210
E28: 0 | G28: 0 | P28: 0 | R28: 0 | Y28: =MAX($C$3:$W$44)-(ROW(Y28)-4)*10 -> -220
B29: =Neu!B17 -> B64s | Y29: =MAX($C$3:$W$44)-(ROW(Y29)-4)*10 -> -230
Y30: =MAX($C$3:$W$44)-(ROW(Y30)-4)*10 -> -240
B31: =Neu!B18 -> B64a | C31: 0 | D31: 0 | E31: -80 | F31: -80 | G31: -80 | H31: -80 | I31: -80 | J31: -70 | K31: -80 | N31: -80 | O31: -80 | R31: -80 | S31: -80 | Y31: =MAX($C$3:$W$44)-(ROW(Y31)-4)*10 -> -250
Y32: =MAX($C$3:$W$44)-(ROW(Y32)-4)*10 -> -260
B33: =Neu!B19 -> B65 | C33: 0 | D33: 0 | E33: 0 | F33: 0 | G33: 0 | O33: 0 | P33: 0
D34: 0 | E34: -60 | K34: -60 | P34: -80
B35: =Neu!B20 -> CBI2 | G35: 0 | I35: 0 | K35: 0 | O35: 0
D36: 0 | E36: 0 | G36: 0 | I36: -50 | K36: 0 | O36: 0
B37: =Neu!B21 -> 0
B39: =Neu!B22 -> 0
B41: =Neu!B23 -> 0
B43: =Neu!B24 -> 0

Sheet cs_FAT
C1: Postsynaptic | AA1: taus | AC1: depression | AE1: Voltage dependence | AI1: facilitation
C2: =Neu!$B4 -> B4 | D2: =Neu!$B5 -> B8 | E2: =Neu!$B6 -> B20 | F2: =Neu!$B7 -> B30 | G2: =Neu!$B8 -> B31s | H2: =Neu!$B9 -> B31a | I2: =Neu!$B10 -> B34 | J2: =Neu!$B11 -> B35 | K2: =Neu!$B12 -> B40 | L2: =Neu!$B13 -> B51s | M2: =Neu!$B14 -> B51a | N2: =Neu!$B15 -> B52 | O2: =Neu!$B16 -> B63 | P2: =Neu!$B17 -> B64s | Q2: =Neu!$B18 -> B64a | R2: =Neu!$B19 -> B65 | S2: =Neu!$B20 -> CBI2 | T2: =Neu!$B21 -> 0 | U2: =Neu!$B22 -> 0 | V2: =Neu!$B23 -> 0 | W2: =Neu!$B24 -> 0 | AA2: u1 | AB2: u2 | AC2: ud | AD2: ur | AE2: h | AF2: s | AG2: p | AH2: tx | AI2: ion | AJ2: u
A3: Presynaptic | B3: =Neu!B4 -> B4 | D3: 2 | G3: 2 | L3: 36 | N3: 2 | P3: 2 | X3: fast | Y3: =COUNTIF($C$3:$W$44,ROW(Z3)-2) -> 11 | Z3: =IF(ROW(AA3)-2<=MAX($C$3:$W$44),ROW(AA3)-2,"") -> 1 | AA3: 0.01
X4: slow | Y4: =COUNTIF($C$3:$W$44,ROW(Z4)-2) -> 11 | Z4: =IF(ROW(AA4)-2<=MAX($C$3:$W$44),ROW(AA4)-2,"") -> 2 | AA4: 0.015
B5: =Neu!B5 -> B8 | Y5: =COUNTIF($C$3:$W$44,ROW(Z5)-2) -> 3 | Z5: =IF(ROW(AA5)-2<=MAX($C$3:$W$44),ROW(AA5)-2,"") -> 3 | AA5: 0.1
Y6: =COUNTIF($C$3:$W$44,ROW(Z6)-2) -> 3 | Z6: =IF(ROW(AA6)-2<=MAX($C$3:$W$44),ROW(AA6)-2,"") -> 4 | AA6: 0.2
B7: =Neu!B6 -> B20 | C7: 10 | D7: 5 | Y7: =COUNTIF($C$3:$W$44,ROW(Z7)-2) -> 3 | Z7: =IF(ROW(AA7)-2<=MAX($C$3:$W$44),ROW(AA7)-2,"") -> 5 | AA7: 0.004 | AB7: 0.0015 | AI7: Na | AJ7: 0.5
C8: 25 | D8: 6 | Y8: =COUNTIF($C$3:$W$44,ROW(Z8)-2) -> 2 | Z8: =IF(ROW(AA8)-2<=MAX($C$3:$W$44),ROW(AA8)-2,"") -> 6 | AA8: 1 | AE8: -31 | AF8: 3 | AG8: 1 | AH8: 0.5 | AI8: Na | AJ8: 0.5
B9: =Neu!B7 -> B30 | D9: 7 | G9: 8 | O9: 9 | P9: 10 | Y9: =COUNTIF($C$3:$W$44,ROW(Z9)-2) -> 1 | Z9: =IF(ROW(AA9)-2<=MAX($C$3:$W$44),ROW(AA9)-2,"") -> 7 | AA9: 0.2 | AB9: 0.001 | AK9: if u2 is empty it is assumed equal to u1
D10: 26 | P10: 11 | Y10: =COUNTIF($C$3:$W$44,ROW(Z10)-2) -> 1 | Z10: =IF(ROW(AA10)-2<=MAX($C$3:$W$44),ROW(AA10)-2,"") -> 8 | AA10: 0.005 | AI10: Na | AJ10: 0.5
B11: =Neu!B8 -> B31s | Y11: =COUNTIF($C$3:$W$44,ROW(Z11)-2) -> 9 | Z11: =IF(ROW(AA11)-2<=MAX($C$3:$W$44),ROW(AA11)-2,"") -> 9 | AA11: 0.01 | AI11: Na | AJ11: 0.5
Y12: =COUNTIF($C$3:$W$44,ROW(Z12)-2) -> 3 | Z12: =IF(ROW(AA12)-2<=MAX($C$3:$W$44),ROW(AA12)-2,"") -> 10 | AA12: 0.02
B13: =Neu!B9 -> B31a | P13: 3 | Y13: =COUNTIF($C$3:$W$44,ROW(Z13)-2) -> 1 | Z13: =IF(ROW(AA13)-2<=MAX($C$3:$W$44),ROW(AA13)-2,"") -> 11 | AA13: 0.5 | AB13: 5 | AE13: -30 | AF13: 15 | AG13: 1 | AH13: 0.5 | AK13: Ach
G14: 12 | Y14: =COUNTIF($C$3:$W$44,ROW(Z14)-2) -> 2 | Z14: =IF(ROW(AA14)-2<=MAX($C$3:$W$44),ROW(AA14)-2,"") -> 12 | AA14: 0.2 | AE14: -48 | AF14: 4 | AG14: 3 | AH14: 0.1 | AI14: Na | AJ14: 0.5
B15: =Neu!B10 -> B34 | D15: 1 | E15: 4 | G15: 9 | O15: 14 | P15: 4 | Y15: =COUNTIF($C$3:$W$44,ROW(Z15)-2) -> 1 | Z15: =IF(ROW(AA15)-2<=MAX($C$3:$W$44),ROW(AA15)-2,"") -> 13 | AA15: 1.5
D16: 29 | G16: 37 | Y16: =COUNTIF($C$3:$W$44,ROW(Z16)-2) -> 1 | Z16: =IF(ROW(AA16)-2<=MAX($C$3:$W$44),ROW(AA16)-2,"") -> 14 | AA16: 0.025 | AC16: 0.5 | AD16: 1
B17: =Neu!B11 -> B35 | C17: 15 | M17: 2 | N17: 17 | Y17: =COUNTIF($C$3:$W$44,ROW(Z17)-2) -> 1 | Z17: =IF(ROW(AA17)-2<=MAX($C$3:$W$44),ROW(AA17)-2,"") -> 15 | AA17: 0.02 | AC17: 0.042 | AD17: 15
C18: 16 | N18: 18 | Y18: =COUNTIF($C$3:$W$44,ROW(Z18)-2) -> 1 | Z18: =IF(ROW(AA18)-2<=MAX($C$3:$W$44),ROW(AA18)-2,"") -> 16 | AA18: 1.3
B19: =Neu!B12 -> B40 | D19: 2 | G19: 2 | P19: 2 | Y19: =COUNTIF($C$3:$W$44,ROW(Z19)-2) -> 1 | Z19: =IF(ROW(AA19)-2<=MAX($C$3:$W$44),ROW(AA19)-2,"") -> 17 | AA19: 0.002
D20: 19 | Y20: =COUNTIF($C$3:$W$44,ROW(Z20)-2) -> 1 | Z20: =IF(ROW(AA20)-2<=MAX($C$3:$W$44),ROW(AA20)-2,"") -> 18 | AA20: 4
B21: =Neu!B13 -> B51s | Y21: =COUNTIF($C$3:$W$44,ROW(Z21)-2) -> 1 | Z21: =IF(ROW(AA21)-2<=MAX($C$3:$W$44),ROW(AA21)-2,"") -> 19 | AA21: 5 | AB21: 0.001 | AE21: -31 | AF21: 3 | AG21: 1
Y22: =COUNTIF($C$3:$W$44,ROW(Z22)-2) -> 2 | Z22: =IF(ROW(AA22)-2<=MAX($C$3:$W$44),ROW(AA22)-2,"") -> 20 | AA22: 0.005
B23: =Neu!B14 -> B51a | D23: 2 | N23: 20 | P23: 2 | Y23: =COUNTIF($C$3:$W$44,ROW(Z23)-2) -> 1 | Z23: =IF(ROW(AA23)-2<=MAX($C$3:$W$44),ROW(AA23)-2,"") -> 21 | AA23: 0.03
Y24: =COUNTIF($C$3:$W$44,ROW(Z24)-2) -> 1 | Z24: =IF(ROW(AA24)-2<=MAX($C$3:$W$44),ROW(AA24)-2,"") -> 22 | AA24: 0.5 | AI24: Na | AJ24: 0.5
B25: =Neu!B15 -> B52 | D25: 2 | L25: 20 | P25: 27 | Y25: =COUNTIF($C$3:$W$44,ROW(Z25)-2) -> 1 | Z25: =IF(ROW(AA25)-2<=MAX($C$3:$W$44),ROW(AA25)-2,"") -> 23 | AA25: 0.015 | AI25: Na | AJ25: 0.5
L26: 4 | Y26: =COUNTIF($C$3:$W$44,ROW(Z26)-2) -> 1 | Z26: =IF(ROW(AA26)-2<=MAX($C$3:$W$44),ROW(AA26)-2,"") -> 24 | AA26: 0.1 | AI26: Na | AJ26: 0.5
B27: =Neu!B16 -> B63 | D27: 21 | E27: 9 | G27: 9 | H27: 9 | I27: 23 | P27: 38 | Y27: =COUNTIF($C$3:$W$44,ROW(Z27)-2) -> 1 | Z27: =IF(ROW(AA27)-2<=MAX($C$3:$W$44),ROW(AA27)-2,"") -> 25 | AA27: 1.6 | AB27: 1.6
E28: 22 | G28: 12 | P28: 24 | R28: 3 | Y28: =COUNTIF($C$3:$W$44,ROW(Z28)-2) -> 1 | Z28: =IF(ROW(AA28)-2<=MAX($C$3:$W$44),ROW(AA28)-2,"") -> 26 | AA28: 3
B29: =Neu!B17 -> B64s | Y29: =COUNTIF($C$3:$W$44,ROW(Z29)-2) -> 3 | Z29: =IF(ROW(AA29)-2<=MAX($C$3:$W$44),ROW(AA29)-2,"") -> 27 | AA29: 0.05
Y30: =COUNTIF($C$3:$W$44,ROW(Z30)-2) -> 1 | Z30: =IF(ROW(AA30)-2<=MAX($C$3:$W$44),ROW(AA30)-2,"") -> 28 | AA30: 0.03 | AB30: 0.08 | AC30: 0.06 | AD30: 7
B31: =Neu!B18 -> B64a | C31: 1 | D31: 1 | E31: 1 | F31: 1 | G31: 1 | H31: 1 | I31: 3 | J31: 10 | K31: 1 | N31: 1 | O31: 1 | R31: 1 | S31: 27 | Y31: =COUNTIF($C$3:$W$44,ROW(Z31)-2) -> 2 | Z31: =IF(ROW(AA31)-2<=MAX($C$3:$W$44),ROW(AA31)-2,"") -> 29 | AA31: 1
Y32: =COUNTIF($C$3:$W$44,ROW(Z32)-2) -> 3 | Z32: =IF(ROW(AA32)-2<=MAX($C$3:$W$44),ROW(AA32)-2,"") -> 30 | AA32: 0.5
B33: =Neu!B19 -> B65 | C33: 28 | D33: 32 | E33: 27 | F33: 31 | G33: 5 | O33: 5 | P33: 32 | Y33: =COUNTIF($C$3:$W$44,ROW(Z33)-2) -> 1 | Z33: =IF(ROW(AA33)-2<=MAX($C$3:$W$44),ROW(AA33)-2,"") -> 31 | AA33: 0.01 | AC33: 0.01 | AD33: 2.5
D34: 29 | E34: 30 | K34: 13 | P34: 30 | Y34: =COUNTIF($C$3:$W$44,ROW(Z34)-2) -> 2 | Z34: =IF(ROW(AA34)-2<=MAX($C$3:$W$44),ROW(AA34)-2,"") -> 32 | AA34: 0.004 | AB34: 0.0015
B35: =Neu!B20 -> CBI2 | G35: 9 | I35: 9 | K35: 9 | O35: 9 | Y35: =COUNTIF($C$3:$W$44,ROW(Z35)-2) -> 1 | Z35: =IF(ROW(AA35)-2<=MAX($C$3:$W$44),ROW(AA35)-2,"") -> 33 | AA35: 0.5 | AB35: 5
D36: 33 | E36: 30 | G36: 34 | I36: 6 | K36: 35 | O36: 34 | Y36: =COUNTIF($C$3:$W$44,ROW(Z36)-2) -> 2 | Z36: =IF(ROW(AA36)-2<=MAX($C$3:$W$44),ROW(AA36)-2,"") -> 34 | AA36: 0.5 | AB36: 5 | AI36: Na | AJ36: 0.5
B37: =Neu!B21 -> 0 | Y37: =COUNTIF($C$3:$W$44,ROW(Z37)-2) -> 1 | Z37: =IF(ROW(AA37)-2<=MAX($C$3:$W$44),ROW(AA37)-2,"") -> 35 | AA37: 0.2 | AB37: 2 | AI37: Na | AJ37: 0.5
Y38: =COUNTIF($C$3:$W$44,ROW(Z38)-2) -> 1 | Z38: 36 | AA38: 0.005 | AB38: 0.2
B39: =Neu!B22 -> 0 | Y39: =COUNTIF($C$3:$W$44,ROW(Z39)-2) -> 1 | Z39: 37 | AA39: 1.5 | AI39: Na | AJ39: 0.5
Y40: =COUNTIF($C$3:$W$44,ROW(Z40)-2) -> 1 | Z40: 38 | AA40: 0.15 | AI40: Na | AJ40: 0.5
...

Sheet es
C1: Postsynaptic
C2: =Neu!B4 -> B4 | D2: =Neu!B5 -> B8 | E2: =Neu!B6 -> B20 | F2: =Neu!B7 -> B30 | G2: =Neu!B8 -> B31s | H2: =Neu!B9 -> B31a | I2: =Neu!B10 -> B34 | J2: =Neu!B11 -> B35 | K2: =Neu!B12 -> B40 | L2: =Neu!B13 -> B51s | M2: =Neu!B14 -> B51a | N2: =Neu!B15 -> B52 | O2: =Neu!B16 -> B63 | P2: =Neu!B17 -> B64s | Q2: =Neu!$B18 -> B64a | R2: =Neu!$B19 -> B65 | S2: =Neu!$B20 -> CBI2 | T2: =Neu!$B21 -> 0 | U2: =Neu!$B22 -> 0 | V2: =Neu!$B23 -> 0 | W2: =Neu!$B24 -> 0
A3: Presynaptic | B3: =Neu!B4 -> B4 | D3: =C4 -> 0 | E3: =C5 -> 0 | F3: =C6 -> 0 | G3: 0.0086 | H3: =C8 -> 0 | I3: =C9 -> 0 | J3: =C10 -> 0 | K3: =C11 -> 0 | L3: =C12 -> 0 | M3: 0.09 | N3: =C14 -> 0 | O3: =C14 -> 0 | P3: 0.014 | Q3: =C17 -> 0 | R3: =C18 -> 0 | S3: =C19 -> 0 | T3: =C20 -> 0 | U3: =C21 -> 0 | V3: =C22 -> 0 | W3: =C23 -> 0
B4: =Neu!B5 -> B8 | E4: =D5 -> 0 | F4: =D6 -> 0 | G4: =D7 -> 0 | H4: =D8 -> 0 | I4: =D9 -> 0 | J4: =D10 -> 0 | K4: =D11 -> 0 | L4: =D12 -> 0 | M4: =D13 -> 0 | N4: =D14 -> 0 | O4: =D15 -> 0 | P4: =D16 -> 0 | Q4: =D17 -> 0 | R4: =D18 -> 0 | S4: =D19 -> 0 | T4: =D20 -> 0 | U4: =D21 -> 0 | V4: =D22 -> 0 | W4: =D23 -> 0
B5: =Neu!B6 -> B20 | F5: =E6 -> 0 | G5: =E7 -> 0.004 | H5: =E8 -> 0 | I5: =E9 -> 0 | J5: =E10 -> 0 | K5: =E11 -> 0 | L5: =E12 -> 0 | M5: =E13 -> 0 | N5: =E14 -> 0 | O5: =E15 -> 0.004 | P5: =E16 -> 0 | Q5: =E17 -> 0 | R5: =E18 -> 0.004 | S5: =E19 -> 0 | T5: =E20 -> 0 | U5: =E21 -> 0 | V5: =E22 -> 0 | W5: =E23 -> 0
B6: =Neu!B7 -> B30 | G6: =F7 -> 0.009 | H6: =F8 -> 0 | I6: =F9 -> 0 | J6: =F10 -> 0 | K6: =F11 -> 0 | L6: =F12 -> 0 | M6: =F13 -> 0 | N6: =F14 -> 0 | O6: =F15 -> 0.006 | P6: =F16 -> 0 | Q6: =F17 -> 0 | R6: =F18 -> 0 | S6: =F19 -> 0 | T6: =F20 -> 0 | U6: =F21 -> 0 | V6: =F22 -> 0 | W6: =F23 -> 0
B7: =Neu!B8 -> B31s | C7: 0.0082 | E7: 0.004 | F7: 0.009 | H7: =G8 -> 0.012 | I7: =G9 -> 0.008 | J7: =G10 -> 0.0075 | K7: =G11 -> 0 | L7: =G12 -> 0 | M7: =G13 -> 0 | N7: =G14 -> 0 | O7: =G15 -> 0.015 | P7: =G16 -> 0 | Q7: =G17 -> 0 | R7: =G18 -> 0.004 | S7: =G19 -> 0 | T7: =G20 -> 0 | U7: =G21 -> 0 | V7: =G22 -> 0 | W7: =G23 -> 0
B8: =Neu!B9 -> B31a | G8: 0.012 | I8: =H9 -> 0 | J8: =H10 -> 0 | K8: =H11 -> 0 | L8: =H12 -> 0 | M8: =H13 -> 0 | N8: =H14 -> 0 | O8: =H15 -> 0 | P8: =H16 -> 0 | Q8: =H17 -> 0 | R8: =H18 -> 0 | S8: =H19 -> 0 | T8: =H20 -> 0 | U8: =H21 -> 0 | V8: =H22 -> 0 | W8: =H23 -> 0
B9: =Neu!B10 -> B34 | G9: 0.008 | J9: =I10 -> 0 | K9: =I11 -> 0.008 | L9: =I12 -> 0 | M9: =I13 -> 0 | N9: =I14 -> 0 | O9: =I15 -> 0 | P9: =I16 -> 0 | Q9: =I17 -> 0 | R9: =I18 -> 0.008 | S9: =I19 -> 0 | T9: =I20 -> 0 | U9: =I21 -> 0 | V9: =I22 -> 0 | W9: =I23 -> 0
B10: =Neu!B11 -> B35 | G10: 0.0075 | K10: =J11 -> 0 | L10: =J12 -> 0 | M10: =J13 -> 0 | N10: =J14 -> 0 | O10: =J15 -> 0 | P10: =J16 -> 0 | Q10: =J17 -> 0 | R10: =J18 -> 0 | S10: =J19 -> 0 | T10: =J20 -> 0 | U10: =J21 -> 0 | V10: =J22 -> 0 | W10: =J23 -> 0
B11: =Neu!B12 -> B40 | I11: 0.008 | L11: =K12 -> 0 | M11: =K13 -> 0 | N11: =K14 -> 0 | O11: =K15 -> 0.004 | P11: =K16 -> 0 | Q11: =K17 -> 0 | R11: =K18 -> 0.008 | S11: =K19 -> 0 | T11: =K20 -> 0 | U11: =K21 -> 0 | V11: =K22 -> 0 | W11: =K23 -> 0
B12: =Neu!B13 -> B51s | M12: =L13 -> 0.2 | N12: =L14 -> 0 | O12: =L15 -> 0 | P12: 0.038 | Q12: =L17 -> 0 | R12: =L18 -> 0 | S12: =L19 -> 0 | T12: =L20 -> 0 | U12: =L21 -> 0 | V12: =L22 -> 0 | W12: =L23 -> 0
B13: =Neu!B14 -> B51a | C13: 0.135 | L13: 0.2 | N13: =M14 -> 0 | O13: =M15 -> 0 | P13: =M16 -> 0 | Q13: =M17 -> 0.02 | R13: =M18 -> 0 | S13: =M19 -> 0 | T13: =M20 -> 0 | U13: =M21 -> 0 | V13: =M22 -> 0 | W13: =M23 -> 0
B14: =Neu!B15 -> B52 | O14: =N15 -> 0 | P14: =N16 -> 0 | Q14: =N17 -> 0 | R14: =N18 -> 0 | S14: =N19 -> 0 | T14: =N20 -> 0 | U14: =N21 -> 0 | V14: =N22 -> 0 | W14: =N23 -> 0
B15: =Neu!B16 -> B63 | E15: 0.004 | F15: 0.006 | G15: 0.015 | K15: 0.004 | P15: =O16 -> 0 | Q15: =O17 -> 0 | R15: =O18 -> 0.006 | S15: =O19 -> 0 | T15: =O20 -> 0 | U15: =O21 -> 0 | V15: =O22 -> 0 | W15: =O23 -> 0
B16: =Neu!B17 -> B64s | C16: 0.034 | L16: 0.12 | Q16: =P17 -> 0.25 | R16: =P18 -> 0 | S16: =P19 -> 0 | T16: =P20 -> 0 | U16: =P21 -> 0 | V16: =P22 -> 0 | W16: =P23 -> 0
B17: =Neu!B18 -> B64a | M17: 0.02 | P17: 0.25 | R17: =Q18 -> 0 | S17: =Q19 -> 0 | T17: =Q20 -> 0 | U17: =Q21 -> 0 | V17: =Q22 -> 0 | W17: =Q23 -> 0
B18: =Neu!B19 -> B65 | E18: 0.004 | G18: 0.004 | I18: 0.008 | K18: 0.008 | O18: 0.006 | S18: =R19 -> 0 | T18: =R20 -> 0 | U18: =R21 -> 0 | V18: =R22 -> 0 | W18: =R23 -> 0
B19: =Neu!B20 -> CBI2 | T19: =S20 -> 0 | U19: =S21 -> 0 | V19: =S22 -> 0 | W19: =S23 -> 0
B20: =Neu!B21 -> 0 | U20: =T21 -> 0 | V20: =T22 -> 0 | W20: =T23 -> 0
B21: =Neu!B22 -> 0 | V21: =U22 -> 0 | W21: =U23 -> 0
B22: =Neu!B23 -> 0 | W22: =V23 -> 0
B23: =Neu!B24 -> 0

Sheet noise
B1: Amplitude | C1: step size | D1: jitter in step size
A2: votage-dependent conductance (.vdg) | B2: 0 | C2: 50 | D2: 10
A3: chemical synapse (.cs) | B3: 0 | C3: 200 | D3: 10
A4: electrical synapse (.es) | B4: 0 | C4: 200 | D4: 10
