Workbook

Sheet Neu
D1: File | E1: leak | G1: Na | AH1: K | BI1: KA | CJ1: CaL | DK1: CaR | EL1: CaN | FM1: Kcas | GN1: Kcaf | HO1: Napp | IP1: HCN | JQ1: K_pp
E2: vdg | G2: vdg | J2: A | V2: B | AH2: vdg | AK2: A | AW2: B | BI2: vdg | BL2: A | BX2: B | CJ2: vdg | CM2: A | CY2: B | DK2: vdg | DN2: A | DZ2: B | EL2: vdg | EO2: A | FA2: B | FM2: vdg | FP2: A | GB2: B | GN2: vdg | GQ2: A | HC2: B | HO2: vdg | HR2: A | ID2: B | IP2: vdg | IS2: A | JE2: B | JQ2: vdg | JT2: A | KF2: B
B3: Name | C3: Template | D3: cm | E3: g | F3: E | G3: g | H3: p | I3: E | J3: An | K3: h | L3: s | M3: p | N3: tmx | O3: tmin | P3: th1 | Q3: ts1 | R3: tp1 | S3: th2 | T3: ts2 | U3: tp2 | V3: Bn | W3: h | X3: s | Y3: p | Z3: tmx | AA3: tmin | AB3: th1 | AC3: ts1 | AD3: tp1 | AE3: th2 | AF3: ts2 | AG3: tp2 | AH3: g | AI3: p | AJ3: E | AK3: An | AL3: h | AM3: s | AN3: p | AO3: tmx | AP3: tmin | AQ3: th1 | AR3: ts1 | AS3: tp1 | AT3: th2 | AU3: ts2 | AV3: tp2 | AW3: Bn | AX3: h | AY3: s | AZ3: p | BA3: tmx | BB3: tmin | BC3: th1 | BD3: ts1 | BE3: tp1 | BF3: th2 | BG3: ts2 | BH3: tp2 | BI3: g | BJ3: p | BK3: E | BL3: An | BM3: h | BN3: s | BO3: p | BP3: tmx | BQ3: tmin | BR3: th1 | BS3: ts1 | BT3: tp1 | BU3: th2 | BV3: ts2 | BW3: tp2 | BX3: Bn | BY3: h | BZ3: s | CA3: p | CB3: tmx | CC3: tmin | CD3: th1 | CE3: ts1 | CF3: tp1 | CG3: th2 | CH3: ts2 | CI3: tp2 | CJ3: g | CK3: p | CL3: E | CM3: An | CN3: h | CO3: s | CP3: p | CQ3: tmx | CR3: tmin | CS3: th1 | CT3: ts1 | CU3: tp1 | CV3: th2 | CW3: ts2 | CX3: tp2 | CY3: Bn | CZ3: h | DA3: s | DB3: p | DC3: tmx | DD3: tmin | DE3: th1 | DF3: ts1 | DG3: tp1 | DH3: th2 | DI3: ts2 | DJ3: tp2 | DK3: g | DL3: p | DM3: E | DN3: An | DO3: h | DP3: s | DQ3: p | DR3: tmx | DS3: tmin | DT3: th1 | DU3: ts1 | DV3: tp1 | DW3: th2 | DX3: ts2 | DY3: tp2 | DZ3: Bn | EA3: h | EB3: s | EC3: p | ED3: tmx | EE3: tmin | EF3: th1 | EG3: ts1 | EH3: tp1 | EI3: th2 | EJ3: ts2 | EK3: tp2 | EL3: g | EM3: p | EN3: E | EO3: An | EP3: h | EQ3: s | ER3: p | ES3: tmx | ET3: tmin | EU3: th1 | EV3: ts1 | EW3: tp1 | EX3: th2 | EY3: ts2 | EZ3: tp2 | FA3: Bn | FB3: h | FC3: s | FD3: p | FE3: tmx | FF3: tmin | FG3: th1 | FH3: ts1 | FI3: tp1 | FJ3: th2 | FK3: ts2 | FL3: tp2 | FM3: g | FN3: p | FO3: E | FP3: An | FQ3: h | FR3: s | FS3: p | FT3: tmx | FU3: tmin | FV3: th1 | FW3: ts1 | FX3: tp1 | FY3: th2 | FZ3: ts2 | GA3: tp2 | GB3: Bn | GC3: h | GD3: s | GE3: p | GF3: tmx | GG3: tmin | GH3: th1 | GI3: ts1 | GJ3: tp1 | GK3: th2 | GL3: ts2 | GM3: tp2 | GN3: g | GO3: p | GP3: E | GQ3: An | GR3: h | GS3: s | GT3: p | GU3: tmx | GV3: tmin | GW3: th1 | GX3: ts1 | GY3: tp1 | GZ3: th2 | HA3: ts2 | HB3: tp2 | HC3: Bn | HD3: h | HE3: s | HF3: p | HG3: tmx | HH3: tmin | HI3: th1 | HJ3: ts1 | HK3: tp1 | HL3: th2 | HM3: ts2 | HN3: tp2 | HO3: g | HP3: p | HQ3: E | HR3: An | HS3: h | HT3: s | HU3: p | HV3: tmx | HW3: tmin | HX3: th1 | HY3: ts1 | HZ3: tp1 | IA3: th2 | IB3: ts2 | IC3: tp2 | ID3: Bn | IE3: h | IF3: s | IG3: p | IH3: tmx | II3: tmin | IJ3: th1 | IK3: ts1 | IL3: tp1 | IM3: th2 | IN3: ts2 | IO3: tp2 | IP3: g | IQ3: p | IR3: E | IS3: An | IT3: h | IU3: s | IV3: p | IW3: tmx | IX3: tmin | IY3: th1 | IZ3: ts1 | JA3: tp1 | JB3: th2 | JC3: ts2 | JD3: tp2 | JE3: Bn | JF3: h | JG3: s | JH3: p | JI3: tmx | JJ3: tmin | JK3: th1 | JL3: ts1 | JM3: tp1 | JN3: th2 | JO3: ts2 | JP3: tp2 | JQ3: g | JR3: p | JS3: E | JT3: An | JU3: h | JV3: s | JW3: p | JX3: tmx | JY3: tmin | JZ3: th1 | KA3: ts1 | KB3: tp1 | KC3: th2 | KD3: ts2 | KE3: tp2 | KF3: Bn | KG3: h | KH3: s | KI3: p | KJ3: tmx | KK3: tmin | KL3: th1 | KM3: ts1 | KN3: tp1 | KO3: th2 | KP3: ts2 | KQ3: tp2
A4: =Neu!B4 -> B4 | B4: B4 | D4: 0.007 | E4: 0.14 | F4: -56 | G4: 60 | H4: 3 | I4: 30 | J4: 0 | K4: -28.5 | L4: 8.6 | M4: 1 | N4: 0.0006 | O4: 0.0001 | P4: -40.5 | Q4: 6 | R4: 1 | V4: 0 | W4: -38 | X4: 5 | Y4: 1 | Z4: 0.005 | AA4: 0.0002 | AB4: -37 | AC4: 11.6 | AD4: 1 | AH4: 100 | AI4: 4 | AJ4: -80 | AK4: 0 | AL4: -30 | AM4: 9.8 | AN4: 1 | AO4: 0.025 | AP4: 0.0002 | AQ4: 0 | AR4: 9 | AS4: 1 | BI4: 5 | BJ4: 3 | BK4: -70 | BL4: 0 | BM4: -55 | BN4: 15 | BO4: 1 | BP4: 0.017 | BQ4: 0.001 | BR4: -30 | BS4: 20 | BT4: 1 | BU4: -120 | BV4: 24 | BW4: 1 | BX4: 0 | BY4: -65 | BZ4: 5 | CA4: 1 | CB4: 0.224 | CC4: 0.0001 | CD4: -54.4 | CE4: 30.8 | CF4: 1 | CJ4: 0.23 | CK4: 1 | CL4: 60 | CM4: 0 | CN4: -3 | CO4: 7.89 | CP4: 1 | CQ4: 0.06 | CR4: 0.002 | CS4: -10 | CT4: -13 | CU4: 1 | CV4: 10 | CW4: 13 | CX4: 1 | CY4: 0 | CZ4: -17 | DA4: 0.95 | DB4: 1 | DC4: 0.12 | DK4: 0.4 | DL4: 1 | DM4: 60 | DN4: 0 | DO4: 2 | DP4: 7.25 | DQ4: 1 | DR4: 0.03 | DS4: 0.001 | DT4: -10 | DU4: -5.3 | DV4: 1 | DW4: 14 | DX4: 5.6 | DY4: 1 | DZ4: 0 | EA4: -18.2 | EB4: 1.5 | EC4: 1 | ED4: 0.08 | EE4: 0.038 | EF4: 0 | EG4: 5 | EH4: 1 | FM4: 250 | FN4: 1 | FO4: -70 | FP4: 0 | FQ4: -11 | FR4: 8 | FS4: 1 | FT4: 0.03 | GN4: 0.15 | GO4: 1 | GP4: -70 | GQ4: 0 | GR4: 12 | GS4: 0.24 | GT4: 1 | GU4: 0.01 | HC4: 0.1 | HD4: -35 | HE4: 5 | HF4: 1 | HG4: 0.8 | HH4: 0.08 | HI4: 18 | HJ4: -2 | HK4: 1 | HL4: 20 | HM4: 2 | HN4: 1
A5: =Neu!B5 -> B8 | B5: B8 | D5: 0.01 | E5: 0.15 | F5: -64 | G5: 50 | H5: 3 | I5: 60 | J5: 0 | K5: -16.6 | L5: 6.66 | M5: 1 | N5: 0.035 | O5: 0.00024 | P5: -30 | Q5: 5.382 | R5: 1 | S5: -17 | T5: -9.9 | U5: 1 | V5: 0 | W5: -24 | X5: 3.807 | Y5: 1 | Z5: 0.042 | AA5: 0.001 | AB5: -32 | AC5: 14.472 | AD5: 1 | AH5: 3.9 | AI5: 1 | AJ5: -70 | AK5: 0 | AL5: 2 | AM5: 8 | AN5: 1 | AO5: 0.01 | AW5: 0.274 | AX5: -13 | AY5: 5.7 | AZ5: 1 | BA5: 2 | BB5: 0.15 | BC5: -14 | BD5: 8 | BE5: 1 | BI5: 3.2 | BJ5: 1 | BK5: -70 | BL5: 0 | BM5: -6 | BN5: 10 | BO5: 1 | BP5: 0.025 | BQ5: 0.007 | BR5: -20 | BS5: 6 | BT5: 1 | BX5: 0 | BY5: -51 | BZ5: 9.4 | CA5: 1 | CB5: 0.14 | CJ5: 0.68 | CK5: 1 | CL5: 60 | CM5: 0 | CN5: -14 | CO5: 6.5 | CP5: 1 | CQ5: 0.08 | CR5: 0.002 | CS5: -20.5 | CT5: -13 | CU5: 1 | CV5: 15 | CW5: 13 | CX5: 1 | CY5: 0 | CZ5: -34.4 | DA5: 6.26 | DB5: 1 | DC5: 0.035 | DK5: 2.4 | DL5: 1 | DM5: 60 | DN5: 0 | DO5: 2 | DP5: 5.7 | DQ5: 1 | DR5: 0.076 | DS5: 0.001 | DT5: -1 | DU5: -7.2 | DV5: 1 | DW5: 23 | DX5: 7.2 | DY5: 1 | DZ5: 0 | EA5: -25 | EB5: 5.95 | EC5: 1 | ED5: 0.043 | EE5: 0.025 | EF5: 1 | EG5: 6 | EH5: 1 | FM5: 1.1 | FN5: 1 | FO5: -70 | FP5: 0 | FQ5: 5 | FR5: 9 | FS5: 1 | FT5: 0.009 | GN5: 0.85 | GO5: 1 | GP5: -70 | GQ5: 0 | GR5: 7 | GS5: 6.1 | GT5: 1 | GU5: 0.01 | HC5: 0.4 | HD5: -5 | HE5: 5 | HF5: 1 | HG5: 1.4 | HH5: 0.2 | HI5: -2 | HJ5: -1.5 | HK5: 1 | HL5: 3.5 | HM5: 1.5 | HN5: 1 | HO5: 0.11 | HP5: 1 | HQ5: 60 | HR5: 0 | HS5: -48 | HT5: 3 | HU5: 1 | HV5: 0.01 | ID5: 0.6 | IE5: -62 | IF5: 1 | IG5: 1 | IH5: 2.5 | II5: 0.25 | IJ5: -55 | IK5: -1.5 | IL5: 1 | IM5: -42 | IN5: 1.5 | IO5: 1 | IP5: 0.085 | IQ5: 1 | IR5: -40 | IS5: 0 | IT5: -68 | IU5: -4.8 | IV5: 1 | IW5: 14 | IX5: 0.9 | IY5: -73 | IZ5: -9 | JA5: 1 | JB5: -75 | JC5: 9 | JD5: 1
A6: =Neu!B6 -> B20 | B6: B20 | D6: 0.01 | E6: 0.04 | F6: -60 | G6: 33 | H6: 3 | I6: 30 | J6: 0 | K6: -43 | L6: 5 | M6: 1 | N6: 0.006 | O6: 0.001 | P6: -48 | Q6: 4 | R6: 1 | V6: 0 | W6: -48 | X6: 5 | Y6: 1 | Z6: 0.02 | AA6: 0.005 | AB6: -43 | AC6: 10 | AD6: 1 | AH6: 38 | AI6: 4 | AJ6: -70 | AK6: 0 | AL6: -28 | AM6: 9 | AN6: 1 | AO6: 0.03 | AP6: 0.003 | AQ6: -10 | AR6: 10 | AS6: 1 | BI6: 1.25 | BJ6: 2 | BK6: -60 | BL6: 0 | BM6: -60 | BN6: 1 | BO6: 1 | BP6: 0.2 | BQ6: 0.02 | BR6: -56 | BS6: 1 | BT6: 2 | BX6: 0 | BY6: -55 | BZ6: 1 | CA6: 2 | CB6: 0.5
A7: =Neu!B7 -> B30 | B7: B30 | D7: 0.01 | E7: =OC_effects!X5 -> 0.04 | F7: -55 | G7: 25 | H7: 3 | I7: 30 | J7: 0 | K7: -37 | L7: 5 | M7: 1 | N7: 0.006 | O7: 0.001 | P7: -43 | Q7: 4 | R7: 1 | V7: 0 | W7: -43 | X7: 5 | Y7: 1 | Z7: 0.02 | AA7: 0.005 | AB7: -38 | AC7: 10 | AD7: 1 | AH7: 16 | AI7: 4 | AJ7: -70 | AK7: 0 | AL7: -23 | AM7: 9 | AN7: 1 | AO7: 0.04 | AP7: 0.004 | AQ7: -8 | AR7: 10 | AS7: 1
A8: =Neu!B8 -> B31s | B8: B31s | D8: 0.01 | E8: 0.05 | F8: -60
A9: =Neu!B9 -> B31a | B9: B31a | D9: 0.01 | E9: 0.04 | F9: -57 | G9: 25 | H9: 3 | I9: 30 | J9: 0 | K9: -37 | L9: 5 | M9: 1 | N9: 0.006 | O9: 0.001 | P9: -43 | Q9: 4 | R9: 1 | V9: 0 | W9: -43 | X9: 5 | Y9: 1 | Z9: 0.02 | AA9: 0.005 | AB9: -38 | AC9: 10 | AD9: 1 | AH9: 12 | AI9: 4 | AJ9: -70 | AK9: 0 | AL9: -23 | AM9: 9 | AN9: 1 | AO9: 0.04 | AP9: 0.004 | AQ9: -8 | AR9: 10 | AS9: 1
A10: =Neu!B10 -> B34 | B10: B34 | D10: 0.01 | E10: 0.09 | F10: -59 | G10: 25 | H10: 3 | I10: 30 | J10: 0 | K10: -39 | L10: 5 | M10: 1 | N10: 0.006 | O10: 0.001 | P10: -45 | Q10: 4 | R10: 1 | V10: 0 | W10: -45 | X10: 5 | Y10: 1 | Z10: 0.02 | AA10: 0.005 | AB10: -40 | AC10: 10 | AD10: 1 | AH10: 19 | AI10: 4 | AJ10: -70 | AK10: 0 | AL10: -25 | AM10: 9 | AN10: 1 | AO10: 0.04 | AP10: 0.004 | AQ10: -10 | AR10: 10 | AS10: 1 | BI10: 1.25 | BJ10: 2 | BK10: -60 | BL10: 0 | BM10: -60 | BN10: 1 | BO10: 1 | BP10: 0.2 | BQ10: 0.02 | BR10: -56 | BS10: 1 | BT10: 2 | BX10: 0 | BY10: -55 | BZ10: 1 | CA10: 2 | CB10: 0.5
A11: =Neu!B11 -> B35 | B11: B35 | D11: 0.0005 | E11: 0.1 | F11: -60 | G11: 20 | H11: 3 | I11: 50 | J11: 0 | K11: -39 | L11: 5 | M11: 1 | N11: 0.003 | O11: 0.0009 | P11: -40 | Q11: 2 | R11: 1 | V11: 0 | W11: -49 | X11: 9 | Y11: 1 | Z11: 0.02 | AA11: 0.0048 | AB11: -36 | AC11: 3.5 | AD11: 1 | AH11: 45 | AI11: 4 | AJ11: -70 | AK11: 0 | AL11: -23.5 | AM11: 9 | AN11: 1 | AO11: 0.034 | AP11: 0.003 | AQ11: -10 | AR11: 10 | AS11: 1 | HO11: 0.12 | HP11: 1 | HQ11: -28 | HR11: 0 | HS11: -48 | HT11: 2.5 | HU11: 1 | HV11: 0.2 | ID11: 0 | IE11: -48 | IF11: 0.5 | IG11: 1 | IH11: 9.5
A12: =Neu!B12 -> B40 | B12: B40 | D12: 0.01 | E12: 0.1 | F12: -57 | G12: 25 | H12: 3 | I12: 30 | J12: 0 | K12: -37 | L12: 5 | M12: 1 | N12: 0.006 | O12: 0.001 | P12: -43 | Q12: 4 | R12: 1 | V12: 0 | W12: -43 | X12: 5 | Y12: 1 | Z12: 0.02 | AA12: 0.005 | AB12: -38 | AC12: 10 | AD12: 1 | AH12: 16 | AI12: 4 | AJ12: -70 | AK12: 0 | AL12: -23 | AM12: 9 | AN12: 1 | AO12: 0.04 | AP12: 0.004 | AQ12: -8 | AR12: 10 | AS12: 1
A13: =Neu!B13 -> B51s | B13: B51s | D13: 0.002 | E13: 0.155 | F13: -72 | G13: 70 | H13: 3 | I13: 60 | J13: 0 | K13: -16.6 | L13: 6.66 | M13: 1 | N13: 0.035 | O13: 0.00024 | P13: -30 | Q13: 5.382 | R13: 1 | S13: -17 | T13: -9.9 | U13: 1 | V13: 0 | W13: -24 | X13: 3.807 | Y13: 1 | Z13: 0.042 | AA13: 0.001 | AB13: -32 | AC13: 14.472 | AD13: 1 | AH13: 1.9 | AI13: 1 | AJ13: -70 | AK13: 0 | AL13: 2 | AM13: 8 | AN13: 1 | AO13: 0.01 | AW13: 0.364 | AX13: -10.5 | AY13: 4.6 | AZ13: 1 | BA13: 3 | BB13: 0.26 | BC13: -14 | BD13: 7 | BE13: 1 | BI13: 1.4 | BJ13: 1 | BK13: -70 | BL13: 0 | BM13: -29 | BN13: 5.6 | BO13: 1 | BP13: 0.03 | BQ13: 0.001 | BR13: -30 | BS13: 5.7 | BT13: 1 | BX13: 0 | BY13: -56 | BZ13: 4.3 | CA13: 1 | CB13: 0.06 | CJ13: 0.23 | CK13: 1 | CL13: 60 | CM13: 0 | CN13: -8 | CO13: 7.89 | CP13: 1 | CQ13: 0.06 | CR13: 0.002 | CS13: -15 | CT13: -13 | CU13: 1 | CV13: 5 | CW13: 13 | CX13: 1 | CY13: 0 | CZ13: -22 | DA13: 0.95 | DB13: 1 | DC13: 0.12 | DK13: 0.4 | DL13: 1 | DM13: 60 | DN13: 0 | DO13: 2 | DP13: 7.25 | DQ13: 1 | DR13: 0.03 | DS13: 0.001 | DT13: -10 | DU13: -5.3 | DV13: 1 | DW13: 14 | DX13: 5.6 | DY13: 1 | DZ13: 0 | EA13: -18.2 | EB13: 1.5 | EC13: 1 | ED13: 0.08 | EE13: 0.038 | EF13: 0 | EG13: 5 | EH13: 1 | FM13: 0.8 | FN13: 1 | FO13: -70 | FP13: 0 | FQ13: -8 | FR13: 8 | FS13: 1 | FT13: 0.009 | GN13: 0.15 | GO13: 1 | GP13: -70 | GQ13: 0 | GR13: 12 | GS13: 0.24 | GT13: 1 | GU13: 0.01 | HC13: 0.1 | HD13: -35 | HE13: 5 | HF13: 1 | HG13: 0.8 | HH13: 0.08 | HI13: 18 | HJ13: -2 | HK13: 1 | HL13: 20 | HM13: 2 | HN13: 1 | HO13: 0.1 | HP13: 1 | HQ13: 60 | HR13: 0 | HS13: -48 | HT13: 3 | HU13: 1 | HV13: 0.01 | ID13: 0.6 | IE13: -62 | IF13: 1 | IG13: 1 | IH13: 2.5 | II13: 0.25 | IJ13: -55 | IK13: -1.5 | IL13: 1 | IM13: -42 | IN13: 1.5 | IO13: 1
A14: =Neu!B14 -> B71 | B14: B71 | D14: 0.002 | G14: 20 | H14: 3 | I14: 30 | J14: 0 | K14: -20 | L14: 5 | M14: 1 | N14: 0.006 | O14: 0.001 | P14: -26 | Q14: 4 | R14: 1 | V14: 0 | W14: -26 | X14: 5 | Y14: 1 | Z14: 0.02 | AA14: 0.005 | AB14: -21 | AC14: 10 | AD14: 1 | AH14: 10 | AI14: 4 | AJ14: -70 | AK14: 0 | AL14: -23 | AM14: 9 | AN14: 1 | AO14: 0.04 | AP14: 0.004 | AQ14: -8 | AR14: 10 | AS14: 1 | BI14: 5 | BJ14: 1 | BK14: -70 | BL14: 0 | BM14: -45 | BN14: 5.6 | BO14: 1 | BP14: 0.03 | BQ14: 0.001 | BR14: -35 | BS14: 5.7 | BT14: 1 | BX14: 0 | BY14: -68 | BZ14: 4.3 | CA14: 1 | CB14: 0.2
A15: =Neu!B15 -> B52 | B15: B52 | D15: 0.0047 | E15: 0.0487 | F15: -62 | G15: 25 | H15: 3 | I15: 30 | J15: 0 | K15: -35.75 | L15: 4 | M15: 1 | N15: 0.006 | O15: 0.001 | P15: -41.75 | Q15: 3 | R15: 1 | V15: 0 | W15: -41.75 | X15: 4 | Y15: 1 | Z15: 0.02 | AA15: 0.005 | AB15: -36.75 | AC15: 9 | AD15: 1 | AH15: 18 | AI15: 4 | AJ15: -70 | AK15: 0 | AL15: -21.75 | AM15: 8 | AN15: 1 | AO15: 0.04 | AP15: 0.004 | AQ15: -6.75 | AR15: 9 | AS15: 1 | CJ15: 0.23 | CK15: 1 | CL15: 60 | CM15: 0 | CN15: -3 | CO15: 7.89 | CP15: 1 | CQ15: 0.06 | CR15: 0.002 | CS15: -10 | CT15: -13 | CU15: 1 | CV15: 10 | CW15: 13 | CX15: 1 | CY15: 0 | CZ15: -17 | DA15: 0.95 | DB15: 1 | DC15: 0.12 | DK15: 0.4 | DL15: 1 | DM15: 60 | DN15: 0 | DO15: 2 | DP15: 7.25 | DQ15: 1 | DR15: 0.03 | DS15: 0.001 | DT15: -10 | DU15: -5.3 | DV15: 1 | DW15: 14 | DX15: 5.6 | DY15: 1 | DZ15: 0 | EA15: -18.2 | EB15: 1.5 | EC15: 1 | ED15: 0.08 | EE15: 0.038 | EF15: 0 | EG15: 5 | EH15: 1 | FM15: 5 | FN15: 1 | FO15: -70 | FP15: 0 | FQ15: -11 | FR15: 8 | FS15: 1 | FT15: 0.009 | IP15: 0.0465 | IQ15: 1 | IR15: -40 | IS15: 0 | IT15: -64 | IU15: -4.8 | IV15: 1 | IW15: 45 | IX15: 6 | IY15: -73 | IZ15: -9 | JA15: 1 | JB15: -75 | JC15: 9 | JD15: 1
A16: =Neu!B16 -> B63 | B16: B63 | D16: 0.01 | E16: 0.04 | F16: -60 | G16: 25 | H16: 3 | I16: 30 | J16: 0 | K16: -37 | L16: 5 | M16: 1 | N16: 0.006 | O16: 0.001 | P16: -43 | Q16: 4 | R16: 1 | V16: 0 | W16: -43 | X16: 5 | Y16: 1 | Z16: 0.02 | AA16: 0.005 | AB16: -38 | AC16: 10 | AD16: 1 | AH16: 20 | AI16: 4 | AJ16: -70 | AK16: 0 | AL16: -23 | AM16: 9 | AN16: 1 | AO16: 0.04 | AP16: 0.004 | AQ16: -8 | AR16: 10 | AS16: 1
A17: =Neu!B17 -> B64s | B17: B64s | D17: 0.0023 | E17: 0.12 | F17: -60 | G17: 60 | H17: 3 | I17: 60 | J17: 0 | K17: -16.6 | L17: 6.66 | M17: 1 | N17: 0.035 | O17: 0.00024 | P17: -30 | Q17: 5.382 | R17: 1 | S17: -17 | T17: -9.9 | U17: 1 | V17: 0 | W17: -24 | X17: 3.807 | Y17: 1 | Z17: 0.042 | AA17: 0.001 | AB17: -32 | AC17: 14.472 | AD17: 1 | AH17: 3.1 | AI17: 1 | AJ17: -70 | AK17: 0 | AL17: 2 | AM17: 8 | AN17: 1 | AO17: 0.01 | AW17: 0.4 | AX17: -10.5 | AY17: 4.5 | AZ17: 1 | BA17: 5.8 | BB17: 0.18 | BC17: -60 | BD17: 15 | BE17: 1 | BI17: 0.9 | BJ17: 1 | BK17: -70 | BL17: 0 | BM17: -11 | BN17: 11.2 | BO17: 1 | BP17: 0.02 | BQ17: 0.002 | BR17: -20 | BS17: 5.7 | BT17: 1 | BX17: 0 | BY17: -46.3 | BZ17: 7.38 | CA17: 1 | CB17: 0.035 | CJ17: 0.178 | CK17: 1 | CL17: 60 | CM17: 0 | CN17: -5 | CO17: 12.1 | CP17: 1 | CQ17: 0.0088 | CR17: 0.002 | CS17: 0 | CT17: -4 | CU17: 1 | CV17: 35 | CW17: 4 | CX17: 1 | CY17: 0 | CZ17: -26.5 | DA17: 7.47 | DB17: 1 | DC17: 0.14 | DK17: 0.7 | DL17: 1 | DM17: 60 | DN17: 0 | DO17: 2 | DP17: 8.2 | DQ17: 1 | DR17: 0.02 | DS17: 0.001 | DT17: 13 | DU17: -12.7 | DV17: 1 | DW17: 25 | DX17: 13 | DY17: 1 | DZ17: 0 | EA17: -25 | EB17: 6.71 | EC17: 1 | ED17: 0.036 | EE17: 0.025 | EF17: 0 | EG17: 0.46 | EH17: 1 | GN17: 0.26 | GO17: 1 | GP17: -70 | GQ17: 0 | GR17: 9 | GS17: 4.6 | GT17: 1 | GU17: 0.01 | HC17: 0 | HD17: -5 | HE17: 5 | HF17: 1 | HG17: 1.1 | HH17: 0.2 | HI17: -13 | HJ17: -2 | HK17: 1 | HL17: -6 | HM17: 2 | HN17: 1 | HO17: 0.12 | HP17: 1 | HQ17: 60 | HR17: 0 | HS17: -37 | HT17: 4.5 | HU17: 1 | HV17: 0.01 | ID17: 0.6 | IE17: -62 | IF17: 1 | IG17: 1 | IH17: 2.5 | II17: 0.25 | IJ17: -55 | IK17: -1.5 | IL17: 1 | IM17: -42 | IN17: 1.5 | IO17: 1
A18: =Neu!B18 -> B65 | B18: B65 | D18: 0.005 | E18: 0.08 | F18: -50 | G18: 28 | H18: 3 | I18: 30 | J18: 0 | K18: -38 | L18: 5 | M18: 1 | N18: 0.006 | O18: 0.001 | P18: -44 | Q18: 4 | R18: 1 | V18: 0 | W18: -44 | X18: 5 | Y18: 1 | Z18: 0.02 | AA18: 0.005 | AB18: -39 | AC18: 10 | AD18: 1 | AH18: 35 | AI18: 4 | AJ18: -70 | AK18: 0 | AL18: -23 | AM18: 9 | AN18: 1 | AO18: 0.2 | AP18: 0.004 | AQ18: -8 | AR18: 10 | AS18: 1 | BI18: 1.5 | BJ18: 2 | BK18: -60 | BL18: 0 | BM18: -60 | BN18: 1 | BO18: 1 | BP18: 0.2 | BQ18: 0.02 | BR18: -56 | BS18: 1 | BT18: 2 | BX18: 0 | BY18: -55 | BZ18: 1 | CA18: 2 | CB18: 0.5 | HO18: 0.3 | HP18: 1 | HQ18: -40 | HR18: 0 | HS18: -45 | HT18: 5 | HU18: 3 | HV18: 2 | JQ18: 0.01 | JR18: 1 | JS18: -60 | JT18: 0 | JU18: -40 | JV18: -5 | JW18: 4 | JX18: 1
A19: =Neu!B19 -> CBI2 | B19: CBI2 | D19: 0.01 | E19: 0.1 | F19: -60 | G19: 25 | H19: 3 | I19: 30 | J19: 0 | K19: -37 | L19: 5 | M19: 1 | N19: 0.006 | O19: 0.001 | P19: -43 | Q19: 4 | R19: 1 | V19: 0 | W19: -43 | X19: 5 | Y19: 1 | Z19: 0.02 | AA19: 0.005 | AB19: -38 | AC19: 10 | AD19: 1 | AH19: 20 | AI19: 4 | AJ19: -70 | AK19: 0 | AL19: -23 | AM19: 9 | AN19: 1 | AO19: 0.04 | AP19: 0.004 | AQ19: -8 | AR19: 10 | AS19: 1
A20: =Neu!B20 -> B6 | B20: B6 | D20: 0.01386 | E20: 0.45 | F20: -64 | G20: 85 | H20: 3 | I20: 30 | J20: 0 | K20: -19.4 | L20: 15 | M20: 1 | N20: 0.006 | O20: 0.001 | P20: -25.4 | Q20: 12 | R20: 1 | V20: 0 | W20: -14 | X20: 15 | Y20: 1 | Z20: 0.02 | AA20: 0.005 | AB20: -9 | AC20: 30 | AD20: 1 | AH20: 60 | AI20: 4 | AJ20: -70 | AK20: 0 | AL20: -19 | AM20: 9 | AN20: 1 | AO20: 0.05 | AP20: 0.004 | AQ20: -4 | AR20: 10 | AS20: 1 | CJ20: 0.23 | CK20: 1 | CL20: 60 | CM20: 0 | CN20: -3 | CO20: 7.89 | CP20: 1 | CQ20: 0.06 | CR20: 0.002 | CS20: -10 | CT20: -13 | CU20: 1 | CV20: 10 | CW20: 13 | CX20: 1 | CY20: 0 | CZ20: -17 | DA20: 0.95 | DB20: 1 | DC20: 0.12 | DK20: 0.4 | DL20: 1 | DM20: 60 | DN20: 0 | DO20: 2 | DP20: 7.25 | DQ20: 1 | DR20: 0.03 | DS20: 0.001 | DT20: -10 | DU20: -5.3 | DV20: 1 | DW20: 14 | DX20: 5.6 | DY20: 1 | DZ20: 0 | EA20: -18.2 | EB20: 1.5 | EC20: 1 | ED20: 0.08 | EE20: 0.038 | EF20: 0 | EG20: 5 | EH20: 1 | FM20: 47 | FN20: 1 | FO20: -70 | FP20: 0 | FQ20: -11 | FR20: 8 | FS20: 1 | FT20: 0.03
A21: =Neu!B21 -> B9 | B21: B9 | D21: 0.0114 | E21: 0.45 | F21: -67 | G21: 85 | H21: 3 | I21: 30 | J21: 0 | K21: -22.2 | L21: 15 | M21: 1 | N21: 0.006 | O21: 0.001 | P21: -28.2 | Q21: 12 | R21: 1 | V21: 0 | W21: -12 | X21: 15 | Y21: 1 | Z21: 0.02 | AA21: 0.005 | AB21: -7 | AC21: 30 | AD21: 1 | AH21: 60 | AI21: 4 | AJ21: -70 | AK21: 0 | AL21: -19 | AM21: 9 | AN21: 1 | AO21: 0.05 | AP21: 0.004 | AQ21: -4 | AR21: 10 | AS21: 1 | BI21: 3.3 | BJ21: 1 | BK21: -70 | BL21: 0 | BM21: -54 | BN21: 5.6 | BO21: 1 | BP21: 0.03 | BQ21: 0.001 | BR21: -40 | BS21: 5.7 | BT21: 1 | BX21: 0 | BY21: -76 | BZ21: 4.3 | CA21: 1 | CB21: 0.03 | CJ21: 0.23 | CK21: 1 | CL21: 60 | CM21: 0 | CN21: -3 | CO21: 7.89 | CP21: 1 | CQ21: 0.06 | CR21: 0.002 | CS21: -10 | CT21: -13 | CU21: 1 | CV21: 10 | CW21: 13 | CX21: 1 | CY21: 0 | CZ21: -17 | DA21: 0.95 | DB21: 1 | DC21: 0.12 | DK21: 0.4 | DL21: 1 | DM21: 60 | DN21: 0 | DO21: 2 | DP21: 7.25 | DQ21: 1 | DR21: 0.03 | DS21: 0.001 | DT21: -10 | DU21: -5.3 | DV21: 1 | DW21: 14 | DX21: 5.6 | DY21: 1 | DZ21: 0 | EA21: -18.2 | EB21: 1.5 | EC21: 1 | ED21: 0.08 | EE21: 0.038 | EF21: 0 | EG21: 5 | EH21: 1 | FM21: 70 | FN21: 1 | FO21: -70 | FP21: 0 | FQ21: -11 | FR21: 8 | FS21: 1 | FT21: 0.03
A22: =Neu!B22 -> B3 | B22: B3 | D22: 0.0165 | G22: 60 | H22: 3 | I22: 30 | J22: 0 | K22: -39.5 | L22: 5 | M22: 1 | N22: 0.006 | O22: 0.001 | P22: -45.5 | Q22: 4 | R22: 1 | V22: 0 | W22: -45.5 | X22: 5 | Y22: 1 | Z22: 0.02 | AA22: 0.005 | AB22: -40.5 | AC22: 10 | AD22: 1 | AH22: 100 | AI22: 4 | AJ22: -70 | AK22: 0 | AL22: -19 | AM22: 9 | AN22: 1 | AO22: 0.05 | AP22: 0.004 | AQ22: -4 | AR22: 10 | AS22: 1 | BI22: 25 | BJ22: 1 | BK22: -70 | BL22: 0 | BM22: -54 | BN22: 5.6 | BO22: 1 | BP22: 0.03 | BQ22: 0.001 | BR22: -40 | BS22: 5.7 | BT22: 1 | BX22: 0 | BY22: -76 | BZ22: 4.3 | CA22: 1 | CB22: 0.03 | CJ22: 0.23 | CK22: 1 | CL22: 60 | CM22: 0 | CN22: -3 | CO22: 7.89 | CP22: 1 | CQ22: 0.06 | CR22: 0.002 | CS22: -10 | CT22: -13 | CU22: 1 | CV22: 10 | CW22: 13 | CX22: 1 | CY22: 0 | CZ22: -17 | DA22: 0.95 | DB22: 1 | DC22: 0.12 | DK22: 0.4 | DL22: 1 | DM22: 60 | DN22: 0 | DO22: 2 | DP22: 7.25 | DQ22: 1 | DR22: 0.03 | DS22: 0.001 | DT22: -10 | DU22: -5.3 | DV22: 1 | DW22: 14 | DX22: 5.6 | DY22: 1 | DZ22: 0 | EA22: -18.2 | EB22: 1.5 | EC22: 1 | ED22: 0.08 | EE22: 0.038 | EF22: 0 | EG22: 5 | EH22: 1 | FM22: 70 | FN22: 1 | FO22: -70 | FP22: 0 | FQ22: -11 | FR22: 8 | FS22: 1 | FT22: 0.009
A23: =Neu!B23 -> B91 | B23: B91 | D23: 0.002 | E23: 0.3 | F23: -72 | G23: 70 | H23: 3 | I23: 60 | J23: 0 | K23: -16.6 | L23: 6.66 | M23: 1 | N23: 0.035 | O23: 0.00024 | P23: -30 | Q23: 5.382 | R23: 1 | S23: -17 | T23: -9.9 | U23: 1 | V23: 0 | W23: -24 | X23: 3.807 | Y23: 1 | Z23: 0.042 | AA23: 0.001 | AB23: -32 | AC23: 14.472 | AD23: 1 | AH23: 3 | AI23: 1 | AJ23: -70 | AK23: 0 | AL23: 2 | AM23: 8 | AN23: 1 | AO23: 0.01 | AW23: 0.364 | AX23: -10.5 | AY23: 4.6 | AZ23: 1 | BA23: 3 | BB23: 0.26 | BC23: -14 | BD23: 7 | BE23: 1 | BI23: 1.4 | BJ23: 1 | BK23: -70 | BL23: 0 | BM23: -29 | BN23: 5.6 | BO23: 1 | BP23: 0.03 | BQ23: 0.001 | BR23: -30 | BS23: 5.7 | BT23: 1 | BX23: 0 | BY23: -56 | BZ23: 4.3 | CA23: 1 | CB23: 0.06 | CJ23: 0.23 | CK23: 1 | CL23: 60 | CM23: 0 | CN23: -8 | CO23: 7.89 | CP23: 1 | CQ23: 0.06 | CR23: 0.002 | CS23: -15 | CT23: -13 | CU23: 1 | CV23: 5 | CW23: 13 | CX23: 1 | CY23: 0 | CZ23: -22 | DA23: 0.95 | DB23: 1 | DC23: 0.12 | DK23: 0.4 | DL23: 1 | DM23: 60 | DN23: 0 | DO23: 2 | DP23: 7.25 | DQ23: 1 | DR23: 0.03 | DS23: 0.001 | DT23: -10 | DU23: -5.3 | DV23: 1 | DW23: 14 | DX23: 5.6 | DY23: 1 | DZ23: 0 | EA23: -18.2 | EB23: 1.5 | EC23: 1 | ED23: 0.08 | EE23: 0.038 | EF23: 0 | EG23: 5 | EH23: 1 | FM23: 1 | FN23: 1 | FO23: -70 | FP23: 0 | FQ23: -8 | FR23: 8 | FS23: 1 | FT23: 0.009 | GN23: 0.15 | GO23: 1 | GP23: -70 | GQ23: 0 | GR23: 12 | GS23: 0.24 | GT23: 1 | GU23: 0.01 | HC23: 0.1 | HD23: -35 | HE23: 5 | HF23: 1 | HG23: 0.8 | HH23: 0.08 | HI23: 18 | HJ23: -2 | HK23: 1 | HL23: 20 | HM23: 2 | HN23: 1 | HO23: 0.1 | HP23: 1 | HQ23: 60 | HR23: 0 | HS23: -48 | HT23: 3 | HU23: 1 | HV23: 0.01 | ID23: 0.6 | IE23: -62 | IF23: 1 | IG23: 1 | IH23: 2.5 | II23: 0.25 | IJ23: -55 | IK23: -1.5 | IL23: 1 | IM23: -42 | IN23: 1.5 | IO23: 1
A24: =Neu!B24 -> B52b | B24: B52b | D24: 0.0047 | E24: =E15 -> 0.0487 | F24: =F15 -> -62 | G24: 25 | H24: 3 | I24: 30 | J24: 0 | K24: -35.75 | L24: 4 | M24: 1 | N24: 0.006 | O24: 0.001 | P24: -41.75 | Q24: 3 | R24: 1 | V24: 0 | W24: -41.75 | X24: 4 | Y24: 1 | Z24: 0.02 | AA24: 0.005 | AB24: -36.75 | AC24: 9 | AD24: 1 | AH24: 18 | AI24: 4 | AJ24: -70 | AK24: 0 | AL24: -21.75 | AM24: 8 | AN24: 1 | AO24: 0.04 | AP24: 0.004 | AQ24: -6.75 | AR24: 9 | AS24: 1 | CJ24: 0.23 | CK24: 1 | CL24: 60 | CM24: 0 | CN24: -3 | CO24: 7.89 | CP24: 1 | CQ24: 0.06 | CR24: 0.002 | CS24: -10 | CT24: -13 | CU24: 1 | CV24: 10 | CW24: 13 | CX24: 1 | CY24: 0 | CZ24: -17 | DA24: 0.95 | DB24: 1 | DC24: 0.12 | DK24: 0.4 | DL24: 1 | DM24: 60 | DN24: 0 | DO24: 2 | DP24: 7.25 | DQ24: 1 | DR24: 0.03 | DS24: 0.001 | DT24: -10 | DU24: -5.3 | DV24: 1 | DW24: 14 | DX24: 5.6 | DY24: 1 | DZ24: 0 | EA24: -18.2 | EB24: 1.5 | EC24: 1 | ED24: 0.08 | EE24: 0.038 | EF24: 0 | EG24: 5 | EH24: 1 | FM24: 5 | FN24: 1 | FO24: -70 | FP24: 0 | FQ24: -11 | FR24: 8 | FS24: 1 | FT24: 0.009 | IP24: 0.0465 | IQ24: 1 | IR24: -40 | IS24: 0 | IT24: -64 | IU24: -4.8 | IV24: 1 | IW24: 45 | IX24: 6 | IY24: -73 | IZ24: -9 | JA24: 1 | JB24: -75 | JC24: 9 | JD24: 1
D25: B51 | E25: 0.3 | F25: -63 | FM25: 1.9 | IP25: 0.5 | IQ25: 1 | IR25: 30 | IS25: 0 | IT25: -61 | IU25: -1 | IV25: 3 | IW25: 15 | IX25: 5 | IY25: -60 | IZ25: 5 | JA25: 1
D26: B52 | E26: 0.0487 | F26: -57
D27: B51 | E27: 0.22
FN28: B6 | FO28: 130 | FR28: 4
D29: Ion pools | O29: Conductance to ion | Z29: Ion to conductance | BD29: Initial voltage | FN29: B6O | FO29: 47
D30: Name | E30: ion | F30: K1 | G30: K2 | H30: ion | I30: K1 | J30: K2 | K30: ion | L30: K1 | M30: K2 | O30: Name | P30: ch | Q30: ion | R30: ch | S30: ion | T30: ch | U30: ion | V30: ch | W30: ion | Z30: Name | AA30: ion | AB30: ch | AC30: opt1 | AD30: opt2 | AE30: p1 | AF30: p2 | AG30: b | AH30: ion | AI30: ch | AJ30: opt1 | AK30: opt2 | AL30: p1 | AM30: p2 | AN30: b | AO30: ion | AP30: ch | AQ30: opt1 | AR30: opt2 | AS30: p1 | AT30: p2 | AU30: b | AV30: ion | AW30: ch | AX30: opt1 | AY30: opt2 | AZ30: p1 | BA30: p2 | BB30: b | BD30: Name | BE30: mV | FN30: B9 | FO30: 180
D31: =Neu!$B4 -> B4 | E31: Ca | F31: 8 | G31: 1 | O31: =Neu!$B4 -> B4 | P31: CaR | Q31: Ca | R31: CaL | S31: Ca | Z31: =Neu!$B4 -> B4 | AA31: Ca | AB31: Kcas | AC31: 1 | AD31: 1 | AE31: 10 | AF31: 0 | BD31: =Neu!$B4 -> B4 | BE31: -60 | FN31: B9O | FO31: 70
D32: =Neu!$B5 -> B8 | E32: Ca | F32: 80 | G32: 1 | O32: =Neu!$B5 -> B8 | P32: CaR | Q32: Ca | R32: CaL | S32: Ca | Z32: =Neu!$B5 -> B8 | AA32: Ca | AB32: Kcas | AC32: 1 | AD32: 1 | AE32: 0.7 | AF32: 0 | BD32: =Neu!$B5 -> B8 | BE32: -60
D33: =Neu!$B6 -> B20 | E33: Na | F33: 1 | G33: 0.2 | O33: =Neu!$B6 -> B20 | P33: Na | Q33: Na | Z33: =Neu!$B6 -> B20 | BD33: =Neu!$B6 -> B20 | BE33: -60
D34: =Neu!$B7 -> B30 | E34: Na | F34: 1 | G34: 0.2 | O34: =Neu!$B7 -> B30 | P34: Na | Q34: Na | Z34: =Neu!$B7 -> B30 | BD34: =Neu!$B7 -> B30 | BE34: -60
D35: =Neu!$B8 -> B31s | O35: =Neu!$B8 -> B31s | Z35: =Neu!$B8 -> B31s | BD35: =Neu!$B8 -> B31s | BE35: -60
D36: =Neu!$B9 -> B31a | E36: Na | F36: 14 | G36: 0.4 | O36: =Neu!$B9 -> B31a | P36: Na | Q36: Na | Z36: =Neu!$B9 -> B31a | BD36: =Neu!$B9 -> B31a | BE36: -60
D37: =Neu!$B10 -> B34 | E37: Na | F37: 1 | G37: 0.2 | O37: =Neu!$B10 -> B34 | P37: Na | Q37: Na | Z37: =Neu!$B10 -> B34 | BD37: =Neu!$B10 -> B34 | BE37: -60
D38: =Neu!$B11 -> B35 | O38: =Neu!$B11 -> B35 | Z38: =Neu!$B11 -> B35 | BD38: =Neu!$B11 -> B35 | BE38: -60
D39: =Neu!$B12 -> B40 | O39: =Neu!$B12 -> B40 | Z39: =Neu!$B12 -> B40 | BD39: =Neu!$B12 -> B40 | BE39: -60
D40: =Neu!$B13 -> B51s | E40: Ca | F40: 8 | G40: 1 | O40: =Neu!$B13 -> B51s | P40: CaR | Q40: Ca | R40: CaL | S40: Ca | Z40: =Neu!$B13 -> B51s | AA40: Ca | AB40: Kcas | AC40: 1 | AD40: 1 | AE40: 20 | AF40: 0 | BD40: =Neu!$B13 -> B51s | BE40: -60
...

Sheet excitability1.smu
F1: syntax | L1: example variables | M1: IVDxREG | N1: currrent by conductance and regulation | T1: example synapses
A2: smu | B2: name | C2: excitability1 | D2: graph | E2: 1 | F2: conductance | G2: variable.conductance.neuron | M2: V | N2: voltage | Q2: Ics | R2: chem syn current | T2: f_exc | U2: fast excitatory
B3: duration | C3: 51 | D3: store | E3: 1 | F3: example | G3: Ivd.Na.N1 | I3: fBR | J3: fBR.ion.ch.neuron | M3: Ivd | N3: current by voltage gated conductance | Q3: Cion | R3: amount of ion | T3: s_exc | U3: slow excitatory
B4: stepsize | C4: 5e-05 | D4: method | E4: 1 | F4: neuron | G4: variable.neuron | I4: synapse | J4: variable.pre.post.type | M4: A | N4: activation of conductance | Q4: Ies | R4: elec syn current | T4: f_inh | U4: fast inhibitory
B5: red indicates simlation longer than graph duration | F5: example | G5: V.N1 | I5: example | J5: Ics.N1.N4.f_exc | M5: B | N5: Inactivation of conductance | Q5: slex | R5: trt current | T5: s_inh | U5: slow inhibitory
A6: graph (ous) | J6: Ies.N1.N4 | M6: sIVD_reg | N6: for total current
B7: time | G7: variable 1 | L7: variable 2 | Q7: variable 3 | V7: variable 4
A8: Size | B8: variable | C8: # ticks | D8: start | E8: stop | F8: color | G8: variable | H8: # ticks | I8: min | J8: max | K8: color | L8: variable | M8: # ticks | N8: min | O8: max | P8: color | Q8: variable | R8: # ticks | S8: min | T8: max | U8: color | V8: variable | W8: # ticks | X8: min | Y8: max | Z8: color
A10: 1 | B10: time | C10: 7 | D10: 14 | E10: 21 | F10: white | G10: V.B3 | H10: 8 | I10: -80 | J10: 0 | K10: red
A11: 1 | B11: time | C11: 7 | D11: 34 | E11: 41 | F11: white | G11: V.B6 | H11: 8 | I11: -80 | J11: 0 | K11: red
A12: 1 | B12: time | C12: 7 | D12: 44 | E12: 51 | F12: white | G12: V.B9 | H12: 8 | I12: -80 | J12: 0 | K12: red
A24: stimulation (.trt)
B25: Current injection | G25: Voltage clamp | L25: output variables
B26: neuron | C26: start | D26: stop | E26: magnitude | G26: neuron | H26: start | I26: stop | J26: potential | L26: all | M26: type "all" in first cell to output all graphed variables or type individual channels
B27: B3 | C27: 0 | D27: 51 | E27: -5.5
B28: B6 | C28: 0 | D28: 51 | E28: -1.8
B29: B9 | C29: 0 | D29: 51 | E29: -1.95
B30: B3 | C30: 15 | D30: 20 | E30: 8.25
B31: B6 | C31: 35 | D31: 40 | E31: 3.5
B32: B9 | C32: 45 | D32: 50 | E32: 2.85
B33: B3 | C33: 0 | D33: 0 | E33: -10
B34: B6 | C34: 0 | D34: 0 | E34: -10
B35: B9 | C35: 0 | D35: 0 | E35: -10
Q37: 5 to 6, 10 to 11, 15-16, 25-30.

Sheet excitB52.smu
F1: syntax | L1: example variables | M1: IVDxREG | N1: currrent by conductance and regulation | T1: example synapses
A2: smu | B2: name | C2: excitB52 | D2: graph | E2: 1 | F2: conductance | G2: variable.conductance.neuron | M2: V | N2: voltage | Q2: Ics | R2: chem syn current | T2: f_exc | U2: fast excitatory
B3: duration | C3: 115.5 | D3: store | E3: 1 | F3: example | G3: Ivd.Na.N1 | I3: fBR | J3: fBR.ion.ch.neuron | M3: Ivd | N3: current by voltage gated conductance | Q3: Cion | R3: amount of ion | T3: s_exc | U3: slow excitatory
B4: stepsize | C4: 0.0001 | D4: method | E4: 1 | F4: neuron | G4: variable.neuron | I4: synapse | J4: variable.pre.post.type | M4: A | N4: activation of conductance | Q4: Ies | R4: elec syn current | T4: f_inh | U4: fast inhibitory
B5: red indicates simlation longer than graph duration | F5: example | G5: V.N1 | I5: example | J5: Ics.N1.N4.f_exc | M5: B | N5: Inactivation of conductance | Q5: slex | R5: trt current | T5: s_inh | U5: slow inhibitory
A6: graph (ous) | J6: Ies.N1.N4 | M6: sIVD_reg | N6: for total current
B7: time | G7: variable 1 | L7: variable 2 | Q7: variable 3 | V7: variable 4
A8: Size | B8: variable | C8: # ticks | D8: start | E8: stop | F8: color | G8: variable | H8: # ticks | I8: min | J8: max | K8: color | L8: variable | M8: # ticks | N8: min | O8: max | P8: color | Q8: variable | R8: # ticks | S8: min | T8: max | U8: color | V8: variable | W8: # ticks | X8: min | Y8: max | Z8: color
A9: 1 | B9: time | C9: 8 | D9: 25 | E9: 115 | F9: white | G9: V.B52 | H9: 10 | I9: -60.5 | J9: -59.5 | K9: red
A10: 1 | B10: time | C10: 12 | D10: 29.5 | E10: 35.5 | F10: white | G10: V.B52 | H10: 3 | I10: -80 | J10: 10 | K10: red
A11: 1 | B11: time | C11: 12 | D11: 69.5 | E11: 75.5 | F11: white | G11: V.B52 | H11: 3 | I11: -80 | J11: 10 | K11: red
A12: 1 | B12: time | C12: 12 | D12: 109.5 | E12: 115.5 | F12: white | G12: V.B52 | H12: 3 | I12: -80 | J12: 10 | K12: red
A25: stimulation (.trt) | L25: output variables
B26: Current injection | G26: Voltage clamp | L26: all | M26: type "all" in first cell to output all graphed variables or type individual channels
B27: neuron | C27: start | D27: stop | E27: magnitude | G27: neuron | H27: start | I27: stop | J27: potential
B28: B52 | C28: 0 | D28: 166 | E28: -0.46
B29: B52 | C29: 30 | D29: 35 | E29: 0.69
B30: B52 | C30: 70 | D30: 75 | E30: 0.7
B31: B52 | C31: 110 | D31: 115 | E31: 0.75
C91: B6 | D91: 0 | E91: 166
C92: B6 | D92: 20 | E92: 25 | F92: 0 | K92: 1
C93: B6 | D93: 55 | E93: 60 | F93: 1 | K93: 1 | L93: time | M93: 12 | N93: 19 | O93: 26 | P93: white | Q93: V.B6 | R93: 5 | S93: -80 | T93: 30 | U93: red
C94: B6 | D94: 70 | E94: 75 | F94: 1.7 | K94: 1 | L94: time | M94: 12 | N94: 54 | O94: 61 | P94: white | Q94: V.B6 | R94: 5 | S94: -80 | T94: 30 | U94: red
F95: 2 | L95: time | M95: 12 | N95: 69 | O95: 76 | P95: white | Q95: V.B6 | R95: 5 | S95: -80 | T95: 30 | U95: red

Sheet excitability.smu
F1: syntax | L1: example variables | M1: IVDxREG | N1: currrent by conductance and regulation | T1: example synapses
A2: smu | B2: name | C2: excitability | D2: graph | E2: 1 | F2: conductance | G2: variable.conductance.neuron | M2: V | N2: voltage | Q2: Ics | R2: chem syn current | T2: f_exc | U2: fast excitatory
B3: duration | C3: 20 | D3: store | E3: 0 | F3: example | G3: Ivd.Na.N1 | I3: fBR | J3: fBR.ion.ch.neuron | M3: Ivd | N3: current by voltage gated conductance | Q3: Cion | R3: amount of ion | T3: s_exc | U3: slow excitatory
B4: stepsize | C4: 5e-05 | D4: method | E4: 1 | F4: neuron | G4: variable.neuron | I4: synapse | J4: variable.pre.post.type | M4: A | N4: activation of conductance | Q4: Ies | R4: elec syn current | T4: f_inh | U4: fast inhibitory
B5: red indicates simlation longer than graph duration | F5: example | G5: V.N1 | I5: example | J5: Ics.N1.N4.f_exc | M5: B | N5: Inactivation of conductance | Q5: slex | R5: trt current | T5: s_inh | U5: slow inhibitory
A6: graph (ous) | J6: Ies.N1.N4 | M6: sIVD_reg | N6: for total current
B7: time | G7: variable 1 | L7: variable 2 | Q7: variable 3 | V7: variable 4
A8: Size | B8: variable | C8: # ticks | D8: start | E8: stop | F8: color | G8: variable | H8: # ticks | I8: min | J8: max | K8: color | L8: variable | M8: # ticks | N8: min | O8: max | P8: color | Q8: variable | R8: # ticks | S8: min | T8: max | U8: color | V8: variable | W8: # ticks | X8: min | Y8: max | Z8: color
A9: 1 | B9: time | C9: 20 | D9: 0 | E9: 20 | F9: white | G9: V.B71 | H9: 10 | I9: -80 | J9: 20 | K9: green
A10: 1 | B10: time | C10: 20 | D10: 0 | E10: 20 | F10: white | G10: V.B6 | H10: 10 | I10: -80 | J10: 20 | K10: green
A25: stimulation (.trt) | L25: output variables
B26: Current injection | G26: Voltage clamp | L26: all | M26: type "all" in first cell to output all graphed variables or type individual channels
B27: neuron | C27: start | D27: stop | E27: magnitude | G27: neuron | H27: start | I27: stop | J27: potential
B28: B71 | C28: 5 | D28: 7 | E28: 2.9
B29: B71 | C29: 9 | D29: 11 | E29: 3.1
B30: B71 | C30: 13 | D30: 15 | E30: 3.3
B31: B71 | C31: 17 | D31: 19 | E31: 4
B32: B52 | C32: 0 | D32: 20 | E32: -1
B33: B6 | C33: 0 | D33: 20 | E33: -0.5
B34: B51s | C34: 0 | D34: 20 | E34: -0.5

Sheet B52-B8B52.smu
F1: syntax | L1: example variables | M1: IVDxREG | N1: currrent by conductance and regulation | T1: example synapses
A2: smu | B2: name | C2: B52-B8B52 | D2: graph | E2: 1 | F2: conductance | G2: variable.conductance.neuron | M2: V | N2: voltage | Q2: Ics | R2: chem syn current | T2: f_exc | U2: fast excitatory
B3: duration | C3: 8 | D3: store | E3: 1 | F3: example | G3: Ivd.Na.N1 | I3: fBR | J3: fBR.ion.ch.neuron | M3: Ivd | N3: current by voltage gated conductance | Q3: Cion | R3: amount of ion | T3: s_exc | U3: slow excitatory
B4: stepsize | C4: 5e-05 | D4: method | E4: 1 | F4: neuron | G4: variable.neuron | I4: synapse | J4: variable.pre.post.type | M4: A | N4: activation of conductance | Q4: Ies | R4: elec syn current | T4: f_inh | U4: fast inhibitory
B5: red indicates simlation longer than graph duration | F5: example | G5: V.N1 | I5: example | J5: Ics.N1.N4.f_exc | M5: B | N5: Inactivation of conductance | Q5: slex | R5: trt current | T5: s_inh | U5: slow inhibitory
A6: graph (ous) | J6: Ies.N1.N4 | M6: sIVD_reg | N6: for total current
B7: time | G7: variable 1 | L7: variable 2 | Q7: variable 3 | V7: variable 4
A8: Size | B8: variable | C8: # ticks | D8: start | E8: stop | F8: color | G8: variable | H8: # ticks | I8: min | J8: max | K8: color | L8: variable | M8: # ticks | N8: min | O8: max | P8: color | Q8: variable | R8: # ticks | S8: min | T8: max | U8: color | V8: variable | W8: # ticks | X8: min | Y8: max | Z8: color
A9: 1 | B9: time | C9: 8 | D9: 4 | E9: 8 | F9: white | G9: V.B52 | H9: 10 | I9: -80 | J9: 20 | K9: magenta
A10: 1 | B10: time | C10: 8 | D10: 4 | E10: 8 | F10: white | G10: V.B52b | H10: 10 | I10: -60 | J10: -50 | K10: orange
A11: 1 | B11: time | C11: 8 | D11: 4 | E11: 8 | F11: white | G11: V.B8 | H11: 10 | I11: -70 | J11: -60 | K11: orange
A25: stimulation (.trt) | L25: output variables
B26: Current injection | G26: Voltage clamp | L26: all | M26: type "all" in first cell to output all graphed variables or type individual channels
B27: neuron | C27: start | D27: stop | E27: magnitude | G27: neuron | H27: start | I27: stop | J27: potential
B28: B8 | C28: 0.1 | D28: 8.5 | E28: 0
B29: B52 | C29: 5 | D29: 5.05 | E29: 5
B30: B52 | C30: 5.72 | D30: 5.77 | E30: 5
B31: B52 | C31: 6.44 | D31: 6.49 | E31: 5

Sheet B52-B4.smu
F1: syntax | L1: example variables | M1: IVDxREG | N1: currrent by conductance and regulation | T1: example synapses
A2: smu | B2: name | C2: B52-B4 | D2: graph | E2: 1 | F2: conductance | G2: variable.conductance.neuron | M2: V | N2: voltage | Q2: Ics | R2: chem syn current | T2: f_exc | U2: fast excitatory
B3: duration | C3: 10 | D3: store | E3: 1 | F3: example | G3: Ivd.Na.N1 | I3: fBR | J3: fBR.ion.ch.neuron | M3: Ivd | N3: current by voltage gated conductance | Q3: Cion | R3: amount of ion | T3: s_exc | U3: slow excitatory
B4: stepsize | C4: 0.0001 | D4: method | E4: 1 | F4: neuron | G4: variable.neuron | I4: synapse | J4: variable.pre.post.type | M4: A | N4: activation of conductance | Q4: Ies | R4: elec syn current | T4: f_inh | U4: fast inhibitory
B5: red indicates simlation longer than graph duration | F5: example | G5: V.N1 | I5: example | J5: Ics.N1.N4.f_exc | M5: B | N5: Inactivation of conductance | Q5: slex | R5: trt current | T5: s_inh | U5: slow inhibitory
A6: graph (ous) | J6: Ies.N1.N4 | M6: sIVD_reg | N6: for total current
B7: time | G7: variable 1 | L7: variable 2 | Q7: variable 3 | V7: variable 4
A8: Size | B8: variable | C8: # ticks | D8: start | E8: stop | F8: color | G8: variable | H8: # ticks | I8: min | J8: max | K8: color | L8: variable | M8: # ticks | N8: min | O8: max | P8: color | Q8: variable | R8: # ticks | S8: min | T8: max | U8: color | V8: variable | W8: # ticks | X8: min | Y8: max | Z8: color
A9: 1 | B9: time | C9: 10 | D9: 0 | E9: 10 | F9: magenta | G9: V.B52 | H9: 10 | I9: -80 | J9: 20 | K9: magenta
A10: 1 | B10: time | C10: 10 | D10: 0 | E10: 10 | F10: orange | G10: V.B4 | H10: 10 | I10: -65 | J10: -55 | K10: orange
A25: stimulation (.trt) | L25: output variables
B26: Current injection | G26: Voltage clamp | L26: all | M26: type "all" in first cell to output all graphed variables or type individual channels
B27: neuron | C27: start | D27: stop | E27: magnitude | G27: neuron | H27: start | I27: stop | J27: potential
B28: B4 | C28: 0.1 | D28: 16 | E28: 0
B29: B52 | C29: 5 | D29: 10 | E29: 5
B30: B52b | C30: 5 | D30: 10 | E30: -2
B31: B52 | C31: 0 | D31: 10 | E31: -2

Sheet B65-B8.smu
F1: syntax | L1: example variables | M1: IVDxREG | N1: currrent by conductance and regulation | T1: example synapses
A2: smu | B2: name | C2: B65-B8 | D2: graph | E2: 1 | F2: conductance | G2: variable.conductance.neuron | M2: V | N2: voltage | Q2: Ics | R2: chem syn current | T2: f_exc | U2: fast excitatory
B3: duration | C3: 16 | D3: store | E3: 1 | F3: example | G3: Ivd.Na.N1 | I3: fBR | J3: fBR.ion.ch.neuron | M3: Ivd | N3: current by voltage gated conductance | Q3: Cion | R3: amount of ion | T3: s_exc | U3: slow excitatory
B4: stepsize | C4: 5e-05 | D4: method | E4: 1 | F4: neuron | G4: variable.neuron | I4: synapse | J4: variable.pre.post.type | M4: A | N4: activation of conductance | Q4: Ies | R4: elec syn current | T4: f_inh | U4: fast inhibitory
B5: red indicates simlation longer than graph duration | F5: example | G5: V.N1 | I5: example | J5: Ics.N1.N4.f_exc | M5: B | N5: Inactivation of conductance | Q5: slex | R5: trt current | T5: s_inh | U5: slow inhibitory
A6: graph (ous) | J6: Ies.N1.N4 | M6: sIVD_reg | N6: for total current
B7: time | G7: variable 1 | L7: variable 2 | Q7: variable 3 | V7: variable 4
A8: Size | B8: variable | C8: # ticks | D8: start | E8: stop | F8: color | G8: variable | H8: # ticks | I8: min | J8: max | K8: color | L8: variable | M8: # ticks | N8: min | O8: max | P8: color | Q8: variable | R8: # ticks | S8: min | T8: max | U8: color | V8: variable | W8: # ticks | X8: min | Y8: max | Z8: color
A9: 1 | B9: time | C9: 8 | D9: 8 | E9: 16 | F9: magenta | G9: V.B65 | H9: 10 | I9: -80 | J9: 20 | K9: magenta
A11: 1 | B11: time | C11: 8 | D11: 8 | E11: 16 | F11: orange | G11: V.B8 | H11: 10 | I11: -65 | J11: -55 | K11: orange
A25: stimulation (.trt) | L25: output variables
B26: Current injection | G26: Voltage clamp | L26: all | M26: type "all" in first cell to output all graphed variables or type individual channels
B27: neuron | C27: start | D27: stop | E27: magnitude | G27: neuron | H27: start | I27: stop | J27: potential
B28: B52 | C28: 0.1 | D28: 16 | E28: 0.1
B29: B65 | C29: 10 | D29: 14.2 | E29: 7
B30: B63 | C30: 0.1 | D30: 16 | E30: -5
B31: B31s | C31: 0.1 | D31: 16 | E31: -5

Sheet B65-B52.smu
F1: syntax | L1: example variables | M1: IVDxREG | N1: currrent by conductance and regulation | T1: example synapses
A2: smu | B2: name | C2: B65-B52 | D2: graph | E2: 1 | F2: conductance | G2: variable.conductance.neuron | M2: V | N2: voltage | Q2: Ics | R2: chem syn current | T2: f_exc | U2: fast excitatory
B3: duration | C3: 23 | D3: store | E3: 1 | F3: example | G3: Ivd.Na.N1 | I3: fBR | J3: fBR.ion.ch.neuron | M3: Ivd | N3: current by voltage gated conductance | Q3: Cion | R3: amount of ion | T3: s_exc | U3: slow excitatory
B4: stepsize | C4: 5e-05 | D4: method | E4: 1 | F4: neuron | G4: variable.neuron | I4: synapse | J4: variable.pre.post.type | M4: A | N4: activation of conductance | Q4: Ies | R4: elec syn current | T4: f_inh | U4: fast inhibitory
B5: red indicates simlation longer than graph duration | F5: example | G5: V.N1 | I5: example | J5: Ics.N1.N4.f_exc | M5: B | N5: Inactivation of conductance | Q5: slex | R5: trt current | T5: s_inh | U5: slow inhibitory
A6: graph (ous) | J6: Ies.N1.N4 | M6: sIVD_reg | N6: for total current
B7: time | G7: variable 1 | L7: variable 2 | Q7: variable 3 | V7: variable 4
A8: Size | B8: variable | C8: # ticks | D8: start | E8: stop | F8: color | G8: variable | H8: # ticks | I8: min | J8: max | K8: color | L8: variable | M8: # ticks | N8: min | O8: max | P8: color | Q8: variable | R8: # ticks | S8: min | T8: max | U8: color | V8: variable | W8: # ticks | X8: min | Y8: max | Z8: color
A9: 1 | B9: time | C9: 15 | D9: 8 | E9: 23 | F9: magenta | G9: V.B65 | H9: 10 | I9: -80 | J9: 20 | K9: magenta
A10: 1 | B10: time | C10: 15 | D10: 8 | E10: 23 | F10: orange | G10: V.B52 | H10: 10 | I10: -55 | J10: -45 | K10: orange
A11: 1 | B11: time | C11: 15 | D11: 8 | E11: 23 | F11: orange | G11: V.B8 | H11: 10 | I11: -65 | J11: -55 | K11: orange
A25: stimulation (.trt) | L25: output variables
B26: Current injection | G26: Voltage clamp | L26: all | M26: type "all" in first cell to output all graphed variables or type individual channels
B27: neuron | C27: start | D27: stop | E27: magnitude | G27: neuron | H27: start | I27: stop | J27: potential
B28: B52 | C28: 0.1 | D28: 23 | E28: 0.1
B29: B65 | C29: 10 | D29: 21.62 | E29: 7
B30: B63 | C30: 0.1 | D30: 23 | E30: -5
B31: B31s | C31: 0.1 | D31: 23 | E31: -5

Sheet B35-B52.smu
F1: syntax | L1: example variables | M1: IVDxREG | N1: currrent by conductance and regulation | T1: example synapses
A2: smu | B2: name | C2: B35-B52 | D2: graph | E2: 1 | F2: conductance | G2: variable.conductance.neuron | M2: V | N2: voltage | Q2: Ics | R2: chem syn current | T2: f_exc | U2: fast excitatory
B3: duration | C3: 30 | D3: store | E3: 1 | F3: example | G3: Ivd.Na.N1 | I3: fBR | J3: fBR.ion.ch.neuron | M3: Ivd | N3: current by voltage gated conductance | Q3: Cion | R3: amount of ion | T3: s_exc | U3: slow excitatory
B4: stepsize | C4: 5e-05 | D4: method | E4: 1 | F4: neuron | G4: variable.neuron | I4: synapse | J4: variable.pre.post.type | M4: A | N4: activation of conductance | Q4: Ies | R4: elec syn current | T4: f_inh | U4: fast inhibitory
B5: red indicates simlation longer than graph duration | F5: example | G5: V.N1 | I5: example | J5: Ics.N1.N4.f_exc | M5: B | N5: Inactivation of conductance | Q5: slex | R5: trt current | T5: s_inh | U5: slow inhibitory
A6: graph (ous) | J6: Ies.N1.N4 | M6: sIVD_reg | N6: for total current
B7: time | G7: variable 1 | L7: variable 2 | Q7: variable 3 | V7: variable 4
A8: Size | B8: variable | C8: # ticks | D8: start | E8: stop | F8: color | G8: variable | H8: # ticks | I8: min | J8: max | K8: color | L8: variable | M8: # ticks | N8: min | O8: max | P8: color | Q8: variable | R8: # ticks | S8: min | T8: max | U8: color | V8: variable | W8: # ticks | X8: min | Y8: max | Z8: color
A9: 1 | B9: time | C9: 15 | D9: 0 | E9: 30 | F9: magenta | G9: V.B35 | H9: 10 | I9: -80 | J9: 20 | K9: magenta
A10: 1 | B10: time | C10: 15 | D10: 0 | E10: 30 | F10: orange | G10: V.B52 | H10: 14 | I10: -70 | J10: -56 | K10: orange
A25: stimulation (.trt) | L25: output variables
B26: Current injection | G26: Voltage clamp | L26: all | M26: type "all" in first cell to output all graphed variables or type individual channels
B27: neuron | C27: start | D27: stop | E27: magnitude | G27: neuron | H27: start | I27: stop | J27: potential
B28: B52 | C28: 0.1 | D28: 30 | E28: -1.2
B29: B35 | C29: 10 | D29: 26.75 | E29: 0.677
B30: B63 | C30: 0.1 | D30: 30 | E30: -5
B31: B31s | C31: 0.1 | D31: 30 | E31: -5
B32: B52b | C32: 0.1 | D32: 30 | E32: -1.2

Sheet B20-B8.smu
F1: syntax | L1: example variables | M1: IVDxREG | N1: currrent by conductance and regulation | T1: example synapses
A2: smu | B2: name | C2: B20-B8 | D2: graph | E2: 1 | F2: conductance | G2: variable.conductance.neuron | M2: V | N2: voltage | Q2: Ics | R2: chem syn current | T2: f_exc | U2: fast excitatory
B3: duration | C3: 8.5 | D3: store | E3: 1 | F3: example | G3: Ivd.Na.N1 | I3: fBR | J3: fBR.ion.ch.neuron | M3: Ivd | N3: current by voltage gated conductance | Q3: Cion | R3: amount of ion | T3: s_exc | U3: slow excitatory
B4: stepsize | C4: 5e-05 | D4: method | E4: 1 | F4: neuron | G4: variable.neuron | I4: synapse | J4: variable.pre.post.type | M4: A | N4: activation of conductance | Q4: Ies | R4: elec syn current | T4: f_inh | U4: fast inhibitory
B5: red indicates simlation longer than graph duration | F5: example | G5: V.N1 | I5: example | J5: Ics.N1.N4.f_exc | M5: B | N5: Inactivation of conductance | Q5: slex | R5: trt current | T5: s_inh | U5: slow inhibitory
A6: graph (ous) | J6: Ies.N1.N4 | M6: sIVD_reg | N6: for total current
B7: time | G7: variable 1 | L7: variable 2 | Q7: variable 3 | V7: variable 4
A8: Size | B8: variable | C8: # ticks | D8: start | E8: stop | F8: color | G8: variable | H8: # ticks | I8: min | J8: max | K8: color | L8: variable | M8: # ticks | N8: min | O8: max | P8: color | Q8: variable | R8: # ticks | S8: min | T8: max | U8: color | V8: variable | W8: # ticks | X8: min | Y8: max | Z8: color
A9: 1 | B9: time | C9: 10 | D9: 7.5 | E9: 8.5 | F9: white | G9: V.B20 | H9: 10 | I9: -80 | J9: 20 | K9: magenta
A10: 1 | B10: time | C10: 10 | D10: 7.5 | E10: 8.5 | F10: white | G10: V.B8 | H10: 10 | I10: -81 | J10: -71 | K10: orange
A25: stimulation (.trt) | L25: output variables
B26: Current injection | G26: Voltage clamp | L26: all | M26: type "all" in first cell to output all graphed variables or type individual channels
B27: neuron | C27: start | D27: stop | E27: magnitude | G27: neuron | H27: start | I27: stop | J27: potential
B28: B8 | C28: 1 | D28: 8.5 | E28: -5.5673
B29: B8 | C29: 0.1 | D29: 2 | E29: -30
B30: B20 | C30: 8 | D30: 8.05 | E30: 10

Sheet CBI2-B8.smu
F1: syntax | L1: example variables | M1: IVDxREG | N1: currrent by conductance and regulation | T1: example synapses
A2: smu | B2: name | C2: CBI2-B8 | D2: graph | E2: 1 | F2: conductance | G2: variable.conductance.neuron | M2: V | N2: voltage | Q2: Ics | R2: chem syn current | T2: f_exc | U2: fast excitatory
B3: duration | C3: 20 | D3: store | E3: 1 | F3: example | G3: Ivd.Na.N1 | I3: fBR | J3: fBR.ion.ch.neuron | M3: Ivd | N3: current by voltage gated conductance | Q3: Cion | R3: amount of ion | T3: s_exc | U3: slow excitatory
B4: stepsize | C4: 5e-05 | D4: method | E4: 1 | F4: neuron | G4: variable.neuron | I4: synapse | J4: variable.pre.post.type | M4: A | N4: activation of conductance | Q4: Ies | R4: elec syn current | T4: f_inh | U4: fast inhibitory
B5: red indicates simlation longer than graph duration | F5: example | G5: V.N1 | I5: example | J5: Ics.N1.N4.f_exc | M5: B | N5: Inactivation of conductance | Q5: slex | R5: trt current | T5: s_inh | U5: slow inhibitory
A6: graph (ous) | J6: Ies.N1.N4 | M6: sIVD_reg | N6: for total current
B7: time | G7: variable 1 | L7: variable 2 | Q7: variable 3 | V7: variable 4
A8: Size | B8: variable | C8: # ticks | D8: start | E8: stop | F8: color | G8: variable | H8: # ticks | I8: min | J8: max | K8: color | L8: variable | M8: # ticks | N8: min | O8: max | P8: color | Q8: variable | R8: # ticks | S8: min | T8: max | U8: color | V8: variable | W8: # ticks | X8: min | Y8: max | Z8: color
A9: 1 | B9: time | C9: 10 | D9: 0 | E9: 20 | F9: white | G9: V.CBI2 | H9: 10 | I9: -80 | J9: 20 | K9: magenta
A10: 1 | B10: time | C10: 10 | D10: 0 | E10: 20 | F10: white | G10: V.B8 | H10: 10 | I10: -70 | J10: -60 | K10: orange
A25: stimulation (.trt) | L25: output variables
B26: Current injection | G26: Voltage clamp | L26: all | M26: type "all" in first cell to output all graphed variables or type individual channels
B27: neuron | C27: start | D27: stop | E27: magnitude | G27: neuron | H27: start | I27: stop | J27: potential
B28: B8 | C28: 0.5 | D28: 20 | E28: -1
B29: CBI2 | C29: 10 | D29: 12 | E29: 10
B30: B31s | C30: 0 | D30: 20 | E30: -5
B31: B63 | C31: 0 | D31: 20 | E31: -5
B32: B20 | C32: 0 | D32: 20 | E32: -5
B33: B40 | C33: 0 | D33: 20 | E33: -5

Sheet B63.smu
F1: syntax | L1: example variables | M1: IVDxREG | N1: currrent by conductance and regulation | T1: example synapses
A2: smu | B2: name | C2: B63 | D2: graph | E2: 1 | F2: conductance | G2: variable.conductance.neuron | M2: V | N2: voltage | Q2: Ics | R2: chem syn current | T2: f_exc | U2: fast excitatory
B3: duration | C3: 10 | D3: store | E3: 1 | F3: example | G3: Ivd.Na.N1 | I3: fBR | J3: fBR.ion.ch.neuron | M3: Ivd | N3: current by voltage gated conductance | Q3: Cion | R3: amount of ion | T3: s_exc | U3: slow excitatory
B4: stepsize | C4: 5e-05 | D4: method | E4: 1 | F4: neuron | G4: variable.neuron | I4: synapse | J4: variable.pre.post.type | M4: A | N4: activation of conductance | Q4: Ies | R4: elec syn current | T4: f_inh | U4: fast inhibitory
B5: red indicates simlation longer than graph duration | F5: example | G5: V.N1 | I5: example | J5: Ics.N1.N4.f_exc | M5: B | N5: Inactivation of conductance | Q5: slex | R5: trt current | T5: s_inh | U5: slow inhibitory
A6: graph (ous) | J6: Ies.N1.N4 | M6: sIVD_reg | N6: for total current
B7: time | G7: variable 1 | L7: variable 2 | Q7: variable 3 | V7: variable 4
A8: Size | B8: variable | C8: # ticks | D8: start | E8: stop | F8: color | G8: variable | H8: # ticks | I8: min | J8: max | K8: color | L8: variable | M8: # ticks | N8: min | O8: max | P8: color | Q8: variable | R8: # ticks | S8: min | T8: max | U8: color | V8: variable | W8: # ticks | X8: min | Y8: max | Z8: color
A9: 1 | B9: time | C9: 10 | D9: 0 | E9: 10 | F9: white | G9: V.B63 | H9: 10 | I9: -80 | J9: 20 | K9: magenta
A10: 1 | B10: time | C10: 10 | D10: 0 | E10: 10 | F10: white | G10: V.B65 | H10: 10 | I10: -60 | J10: -55 | K10: orange
A25: stimulation (.trt) | L25: output variables
B26: Current injection | G26: Voltage clamp | L26: all | M26: type "all" in first cell to output all graphed variables or type individual channels
B27: neuron | C27: start | D27: stop | E27: magnitude | G27: neuron | H27: start | I27: stop | J27: potential
B28: B63 | C28: 2 | D28: 7 | E28: 1.65
B29: B31a | C29: 0 | D29: 10 | E29: -5
B30: B31s | C30: 0 | D30: 10 | E30: -5
B31: B64s | C31: 0 | D31: 10 | E31: -15
B32: B34 | C32: 0 | D32: 10 | E32: -2

Sheet B52.smu
F1: syntax | L1: example variables | M1: IVDxREG | N1: currrent by conductance and regulation | T1: example synapses
A2: smu | B2: name | C2: B52 | D2: graph | E2: 1 | F2: conductance | G2: variable.conductance.neuron | M2: V | N2: voltage | Q2: Ics | R2: chem syn current | T2: f_exc | U2: fast excitatory
B3: duration | C3: 3.3 | D3: store | E3: 1 | F3: example | G3: Ivd.Na.N1 | I3: fBR | J3: fBR.ion.ch.neuron | M3: Ivd | N3: current by voltage gated conductance | Q3: Cion | R3: amount of ion | T3: s_exc | U3: slow excitatory
B4: stepsize | C4: 5e-05 | D4: method | E4: 1 | F4: neuron | G4: variable.neuron | I4: synapse | J4: variable.pre.post.type | M4: A | N4: activation of conductance | Q4: Ies | R4: elec syn current | T4: f_inh | U4: fast inhibitory
B5: red indicates simlation longer than graph duration | F5: example | G5: V.N1 | I5: example | J5: Ics.N1.N4.f_exc | M5: B | N5: Inactivation of conductance | Q5: slex | R5: trt current | T5: s_inh | U5: slow inhibitory
A6: graph (ous) | J6: Ies.N1.N4 | M6: sIVD_reg | N6: for total current
B7: time | G7: variable 1 | L7: variable 2 | Q7: variable 3 | V7: variable 4
A8: Size | B8: variable | C8: # ticks | D8: start | E8: stop | F8: color | G8: variable | H8: # ticks | I8: min | J8: max | K8: color | L8: variable | M8: # ticks | N8: min | O8: max | P8: color | Q8: variable | R8: # ticks | S8: min | T8: max | U8: color | V8: variable | W8: # ticks | X8: min | Y8: max | Z8: color
A9: 1 | B9: time | C9: 10 | D9: 0 | E9: 3.3 | F9: white | G9: V.B52 | H9: 10 | I9: -80 | J9: 20 | K9: magenta
A10: 1 | B10: time | C10: 10 | D10: 0 | E10: 3.3 | F10: white | G10: V.B51s | H10: 10 | I10: -75 | J10: -55 | K10: orange
A11: 1 | B11: time | C11: 10 | D11: 0 | E11: 3.3 | F11: white | G11: V.B64s | H11: 10 | I11: -75 | J11: -55 | K11: cyan
A12: 1 | B12: time | C12: 10 | D12: 0 | E12: 3.3 | F12: white | G12: V.B52b | H12: 10 | I12: -75 | J12: -55 | K12: cyan
A25: stimulation (.trt) | L25: output variables
B26: Current injection | G26: Voltage clamp | L26: all | M26: type "all" in first cell to output all graphed variables or type individual channels
B27: neuron | C27: start | D27: stop | E27: magnitude | G27: neuron | H27: start | I27: stop | J27: potential
B28: B51s | C28: 0.1 | D28: 3.3 | E28: 3.4
B29: B64s | C29: 0.1 | D29: 3.3 | E29: -1.85
B30: B52 | C30: 0.3 | D30: 0.35 | E30: 5

Sheet IR.smu
F1: syntax | L1: example variables | M1: IVDxREG | N1: currrent by conductance and regulation | T1: example synapses
A2: smu | B2: name | C2: IR | D2: graph | E2: 1 | F2: conductance | G2: variable.conductance.neuron | M2: V | N2: voltage | Q2: Ics | R2: chem syn current | T2: f_exc | U2: fast excitatory
B3: duration | C3: 43 | D3: store | E3: 1 | F3: example | G3: Ivd.Na.N1 | M3: Ivd | N3: current by voltage gated conductance | Q3: Cion | R3: amount of ion | T3: s_exc | U3: slow excitatory
B4: stepsize | C4: 0.0001 | D4: method | E4: 1 | F4: neuron | G4: variable.neuron | I4: synapse | J4: variable.pre.post.type | M4: A | N4: activation of conductance | Q4: Ies | R4: elec syn current | T4: f_inh | U4: fast inhibitory
B5: red indicates simlation longer than graph duration | F5: example | G5: V.N1 | I5: example | J5: Ics.N1.N4.f_exc | M5: B | N5: Inactivation of conductance | T5: s_inh | U5: slow inhibitory
A6: graph (ous) | J6: Ies.N1.N4 | M6: sIvd_reg | N6: for total current
B7: time | G7: variable 1 | L7: variable 2 | Q7: variable 3 | V7: variable 4
A8: Size | B8: variable | C8: # ticks | D8: start | E8: stop | F8: color | G8: variable | H8: # ticks | I8: min | J8: max | K8: color | L8: variable | M8: # ticks | N8: min | O8: max | P8: color | Q8: variable | R8: # ticks | S8: min | T8: max | U8: color | V8: variable | W8: # ticks | X8: min | Y8: max | Z8: color
A9: 1 | B9: time | C9: 20 | D9: 3 | E9: 43 | F9: white | G9: V.B51s | H9: 5 | I9: -75 | J9: -50 | K9: red | L9: V.B64s | M9: 5 | N9: -75 | O9: -50 | P9: green | Q9: V.B8 | R9: 5 | S9: -75 | T9: -50 | U9: cyan | V9: V.B4 | W9: 5 | X9: -75 | Y9: -50 | Z9: yellow
A10: 1 | B10: time | C10: 20 | D10: 3 | E10: 43 | F10: white | G10: V.B71 | H10: 5 | I10: -75 | J10: -50 | K10: orange | L10: V.B20 | M10: 5 | N10: -75 | O10: -50 | P10: yellow
A11: 1 | B11: time | C11: 20 | D11: 3 | E11: 43 | F11: white | G11: V.B3 | H11: 5 | I11: -75 | J11: -50 | K11: green | L11: V.B6 | M11: 5 | N11: -75 | O11: -50 | P11: blue | Q11: V.B9 | R11: 5 | S11: -75 | T11: -50 | U11: orange
A25: stimulation (.trt) | L25: output variables
B26: Current injection | G26: Voltage clamp | L26: all | M26: type "all" in first cell to output all graphed variables or type individual channels
B27: neuron | C27: start | D27: stop | E27: magnitude | G27: neuron | H27: start | I27: stop | J27: potential
B28: B52 | C28: 0 | D28: 43 | E28: -2
B29: B64s | C29: 0 | D29: 43 | E29: 0
B30: B8 | C30: 0 | D30: 43 | E30: 0
B31: B4 | C31: 0 | D31: 43 | E31: 0
B32: B51s | C32: 10 | D32: 12 | E32: -1
B33: B64s | C33: 13 | D33: 15 | E33: -1
B34: B8 | C34: 17 | D34: 19 | E34: -1
B35: B4 | C35: 21 | D35: 23 | E35: -1
B36: B71 | C36: 25 | D36: 27 | E36: -1
B37: B6 | C37: 29 | D37: 31 | E37: -1
B38: B3 | C38: 33 | D38: 35 | E38: -1
B39: B9 | C39: 37 | D39: 39 | E39: -1
B40: B20 | C40: 40 | D40: 42 | E40: -1

Sheet B65.smu
F1: syntax | L1: example variables | M1: IVDxREG | N1: currrent by conductance and regulation | T1: example synapses
A2: smu | B2: name | C2: B65 | D2: graph | E2: 1 | F2: conductance | G2: variable.conductance.neuron | M2: V | N2: voltage | Q2: Ics | R2: chem syn current | T2: f_exc | U2: fast excitatory
B3: duration | C3: 3 | D3: store | E3: 1 | F3: example | G3: Ivd.Na.N1 | I3: fBR | J3: fBR.ion.ch.neuron | M3: Ivd | N3: current by voltage gated conductance | Q3: Cion | R3: amount of ion | T3: s_exc | U3: slow excitatory
B4: stepsize | C4: 5e-05 | D4: method | E4: 1 | F4: neuron | G4: variable.neuron | I4: synapse | J4: variable.pre.post.type | M4: A | N4: activation of conductance | Q4: Ies | R4: elec syn current | T4: f_inh | U4: fast inhibitory
B5: red indicates simlation longer than graph duration | F5: example | G5: V.N1 | I5: example | J5: Ics.N1.N4.f_exc | M5: B | N5: Inactivation of conductance | Q5: slex | R5: trt current | T5: s_inh | U5: slow inhibitory
A6: graph (ous) | J6: Ies.N1.N4 | M6: sIVD_reg | N6: for total current
B7: time | G7: variable 1 | L7: variable 2 | Q7: variable 3 | V7: variable 4
A8: Size | B8: variable | C8: # ticks | D8: start | E8: stop | F8: color | G8: variable | H8: # ticks | I8: min | J8: max | K8: color | L8: variable | M8: # ticks | N8: min | O8: max | P8: color | Q8: variable | R8: # ticks | S8: min | T8: max | U8: color | V8: variable | W8: # ticks | X8: min | Y8: max | Z8: color
A9: 1 | B9: time | C9: 3 | D9: 0 | E9: 3 | F9: white | G9: V.B65 | H9: 10 | I9: -85 | J9: -55 | K9: white
A10: 1 | B10: time | C10: 3 | D10: 0 | E10: 3 | F10: white | G10: V.B20 | H10: 8 | I10: -72 | J10: -68 | K10: white
A11: 1 | B11: time | C11: 3 | D11: 0 | E11: 3 | F11: white | G11: V.B31s | H11: 10 | I11: -90 | J11: -80 | K11: white
A12: 1 | B12: time | C12: 3 | D12: 0 | E12: 3 | F12: white | G12: V.B34 | H12: 10 | I12: -90 | J12: -80 | K12: white
A13: 1 | B13: time | C13: 3 | D13: 0 | E13: 3 | F13: white | G13: V.B63 | H13: 10 | I13: -90 | J13: -80 | K13: white
A14: 1 | B14: time | C14: 3 | D14: 0 | E14: 3 | F14: white | G14: V.B40 | H14: 10 | I14: -90 | J14: -80 | K14: white
A25: stimulation (.trt) | L25: output variables
B26: Current injection | G26: Voltage clamp | L26: all | M26: type "all" in first cell to output all graphed variables or type individual channels
B27: neuron | C27: start | D27: stop | E27: magnitude | G27: neuron | H27: start | I27: stop | J27: potential
B28: B65 | C28: 1 | D28: 2 | E28: -1

Sheet B20.smu
F1: syntax | L1: example variables | M1: IVDxREG | N1: currrent by conductance and regulation | T1: example synapses
A2: smu | B2: name | C2: B20 | D2: graph | E2: 1 | F2: conductance | G2: variable.conductance.neuron | M2: V | N2: voltage | Q2: Ics | R2: chem syn current | T2: f_exc | U2: fast excitatory
B3: duration | C3: 17 | D3: store | E3: 1 | F3: example | G3: Ivd.Na.N1 | I3: fBR | J3: fBR.ion.ch.neuron | M3: Ivd | N3: current by voltage gated conductance | Q3: Cion | R3: amount of ion | T3: s_exc | U3: slow excitatory
B4: stepsize | C4: 5e-05 | D4: method | E4: 1 | F4: neuron | G4: variable.neuron | I4: synapse | J4: variable.pre.post.type | M4: A | N4: activation of conductance | Q4: Ies | R4: elec syn current | T4: f_inh | U4: fast inhibitory
B5: red indicates simlation longer than graph duration | F5: example | G5: V.N1 | I5: example | J5: Ics.N1.N4.f_exc | M5: B | N5: Inactivation of conductance | Q5: slex | R5: trt current | T5: s_inh | U5: slow inhibitory
A6: graph (ous) | J6: Ies.N1.N4 | M6: sIVD_reg | N6: for total current
B7: time | G7: variable 1 | L7: variable 2 | Q7: variable 3 | V7: variable 4
