Workbook

Sheet Neu
D1: File | E1: leak | G1: Na | AH1: K
E2: vdg | G2: vdg | J2: A | V2: B | AH2: vdg | AK2: A | AW2: B
B3: Name | C3: Template | D3: cm | E3: g | F3: E | G3: g | H3: p | I3: E | J3: An | K3: h | L3: s | M3: p | N3: tmx | O3: tmin | P3: th1 | Q3: ts1 | R3: tp1 | S3: th2 | T3: ts2 | U3: tp2 | V3: Bn | W3: h | X3: s | Y3: p | Z3: tmx | AA3: tmin | AB3: th1 | AC3: ts1 | AD3: tp1 | AE3: th2 | AF3: ts2 | AG3: tp2 | AH3: g | AI3: p | AJ3: E | AK3: An | AL3: h | AM3: s | AN3: p | AO3: tmx | AP3: tmin | AQ3: th1 | AR3: ts1 | AS3: tp1 | AT3: th2 | AU3: ts2 | AV3: tp2 | AW3: Bn | AX3: h | AY3: s | AZ3: p | BA3: tmx | BB3: tmin | BC3: th1 | BD3: ts1 | BE3: tp1 | BF3: th2 | BG3: ts2 | BH3: tp2
A4: =Neu!B4 -> A | B4: A | D4: 0.003 | E4: 0.1 | F4: -70 | G4: 8 | H4: 3 | I4: 50 | J4: 0 | K4: -49 | L4: 5 | M4: 1 | N4: 0.006 | O4: 0.001 | P4: -55 | Q4: 4 | R4: 1 | V4: 0 | W4: -55 | X4: 5 | Y4: 1 | Z4: 0.02 | AA4: 0.005 | AB4: -50 | AC4: 10 | AD4: 1 | AH4: 32 | AI4: 4 | AJ4: -80 | AK4: 0 | AL4: -35 | AM4: 9 | AN4: 1 | AO4: 0.08 | AP4: 0.008 | AQ4: -20 | AR4: 10 | AS4: 1
A5: B | B5: B | D5: 0.003 | E5: 0.1 | F5: -70
A6: =Neu!B6 -> 0
A7: =Neu!B7 -> 0
A8: =Neu!B8 -> 0
A9: =Neu!B9 -> 0
A10: =Neu!B10 -> 0
A11: =Neu!B11 -> 0
A12: =Neu!B12 -> 0
A13: =Neu!B13 -> 0
A14: =Neu!B14 -> 0
A15: =Neu!B15 -> 0
A16: =Neu!B16 -> 0
A17: =Neu!B17 -> 0
... A24: =Neu!B24 -> 0
D29: Ion pools | O29: Conductance to ion | Z29: Ion to conductance | BD29: Initial voltage
D30: Name | E30: ion | F30: K1 | G30: K2 | H30: ion | I30: K1 | J30: K2 | K30: ion | L30: K1 | M30: K2 | O30: Name | P30: ch | Q30: ion | R30: ch | S30: ion | T30: ch | U30: ion | V30: ch | W30: ion | Z30: Name | AA30: ion | AB30: ch | AC30: opt1 | AD30: opt2 | AE30: p1 | AF30: p2 | AG30: b | AH30: ion | AI30: ch | AJ30: opt1 | AK30: opt2 | AL30: p1 | AM30: p2 | AN30: b | AO30: ion | AP30: ch | AQ30: opt1 | AR30: opt2 | AS30: p1 | AT30: p2 | AU30: b | AV30: ion | AW30: ch | AX30: opt1 | AY30: opt2 | AZ30: p1 | BA30: p2 | BB30: b | BD30: Name | BE30: mV
Z31: =Neu!$B4 -> A | BD31: =Neu!$B4 -> A | BE31: -70
Z32: =Neu!$B5 -> B | BD32: =Neu!$B5 -> B | BE32: -70
Z34: =Neu!$B7 -> 0
D35: =Neu!$B8 -> 0 | O35: =Neu!$B8 -> 0 | Z35: =Neu!$B8 -> 0
D36: =Neu!$B9 -> 0 | O36: =Neu!$B9 -> 0 | Z36: =Neu!$B9 -> 0 | BD36: =Neu!$B9 -> 0
D37: =Neu!$B10 -> 0 | O37: =Neu!$B10 -> 0 | Z37: =Neu!$B10 -> 0 | BD37: =Neu!$B10 -> 0
D38: =Neu!$B11 -> 0 | O38: =Neu!$B11 -> 0 | Z38: =Neu!$B11 -> 0 | BD38: =Neu!$B11 -> 0
D39: =Neu!$B12 -> 0 | O39: =Neu!$B12 -> 0 | Z39: =Neu!$B12 -> 0 | BD39: =Neu!$B12 -> 0
D40: =Neu!$B13 -> 0 | O40: =Neu!$B13 -> 0 | Z40: =Neu!$B13 -> 0 | BD40: =Neu!$B13 -> 0
D41: =Neu!$B14 -> 0 | O41: =Neu!$B14 -> 0 | Z41: =Neu!$B14 -> 0 | BD41: =Neu!$B14 -> 0
D42: =Neu!$B15 -> 0 | O42: =Neu!$B15 -> 0 | Z42: =Neu!$B15 -> 0 | BD42: =Neu!$B15 -> 0
D43: =Neu!$B16 -> 0 | O43: =Neu!$B16 -> 0 | Z43: =Neu!$B16 -> 0 | BD43: =Neu!$B16 -> 0
D44: =Neu!$B17 -> 0 | O44: =Neu!$B17 -> 0 | Z44: =Neu!$B17 -> 0 | BD44: =Neu!$B17 -> 0
D45: =Neu!$B18 -> 0 | O45: =Neu!$B18 -> 0 | Z45: =Neu!$B18 -> 0 | BD45: =Neu!$B18 -> 0
D46: =Neu!$B19 -> 0 | O46: =Neu!$B19 -> 0 | Z46: =Neu!$B19 -> 0 | BD46: =Neu!$B19 -> 0
D47: =Neu!$B20 -> 0 | O47: =Neu!$B20 -> 0 | Z47: =Neu!$B20 -> 0 | BD47: =Neu!$B20 -> 0
... D51: =Neu!$B24 -> 0 | O51: =Neu!$B24 -> 0 | Z51: =Neu!$B24 -> 0 | BD51: =Neu!$B24 -> 0
F52: 40 | I52: 0.3 | J52: 9 | AE52: 0.7 | AL52: 1.5
AE53: 0.1 | AL53: 0.5
F54: d(ion)/dt = K1*(K2*sum(Ivd) - ion) | AC54: opt1 1: | AD54: fBr = BR | AG54: channel requires ion | AM54: opt2 1: | AN54: dBR/dt = (ion - BR)/p1 initial: p2
...

Sheet main.smu
F1: syntax | L1: example variables | M1: IVDxREG | N1: currrent by conductance and regulation | T1: example synapses
A2: smu | B2: name | C2: synapse | D2: graph | E2: 1 | F2: conductance | G2: variable.conductance.neuron | M2: V | N2: voltage | Q2: Ics | R2: chem syn current | T2: f_exc | U2: fast excitatory
B3: duration | C3: 13 | D3: store | E3: 1 | F3: example | G3: Ivd.Na.N1 | I3: fBR | J3: fBR.ion.ch.neuron | M3: Ivd | N3: current by voltage gated conductance | Q3: Cion | R3: amount of ion | T3: s_exc | U3: slow excitatory
B4: stepsize | C4: 5e-05 | D4: method | E4: 1 | F4: neuron | G4: variable.neuron | I4: synapse | J4: variable.pre.post.type | M4: A | N4: activation of conductance | Q4: Ies | R4: elec syn current | T4: f_inh | U4: fast inhibitory
B5: red indicates simlation longer than graph duration | F5: example | G5: V.N1 | I5: example | J5: Ics.N1.N4.f_exc | M5: B | N5: Inactivation of conductance | Q5: slex | R5: trt current | T5: s_inh | U5: slow inhibitory
A6: graph (ous) | J6: Ies.N1.N4 | M6: sIVD_reg | N6: for total current
B7: time | G7: variable 1 | L7: variable 2 | Q7: variable 3 | V7: variable 4
A8: Size | B8: variable | C8: # ticks | D8: start | E8: stop | F8: color | G8: variable | H8: # ticks | I8: min | J8: max | K8: color | L8: variable | M8: # ticks | N8: min | O8: max | P8: color | Q8: variable | R8: # ticks | S8: min | T8: max | U8: color | V8: variable | W8: # ticks | X8: min | Y8: max | Z8: color
A9: 1 | B9: time | C9: 13 | D9: 0 | E9: 13 | F9: red | G9: V.A | H9: 5 | I9: -90 | J9: -40 | K9: red
A10: 1 | B10: time | C10: 13 | D10: 0 | E10: 13 | F10: green | G10: V.B | H10: 5 | I10: -90 | J10: -40 | K10: green
G12: A.A.C.f_exc
A25: stimulation (.trt) | L25: output variables
B26: Current injection | G26: Voltage clamp | L26: all | M26: type "all" in first cell to output all graphed variables or type individual channels
B27: neuron | C27: start | D27: stop | E27: magnitude | G27: neuron | H27: start | I27: stop | J27: potential
B28: A | C28: 0.25 | D28: 0.4 | E28: 1
B29: A | C29: 0.75 | D29: 0.9 | E29: 1
B30: A | C30: 1.25 | D30: 1.4 | E30: 1
B31: A | C31: 1.75 | D31: 1.9 | E31: 1
B32: A | C32: 2.25 | D32: 2.4 | E32: 1
B33: A | C33: 2.75 | D33: 2.9 | E33: 1
B34: A | C34: 3.25 | D34: 3.4 | E34: 1
B35: A | C35: 3.75 | D35: 3.9 | E35: 1
B36: A | C36: 4.25 | D36: 4.35 | E36: 1
B37: A | C37: 4.75 | D37: 4.85 | E37: 1
B38: A | C38: 5.25 | D38: 5.35 | E38: 1
B39: A | C39: 5.75 | D39: 5.85 | E39: 1
... B51: B | C51: 5.5 | D51: 6 | E51: 8

Sheet cs_g
C1: Postsynaptic
C2: =Neu!$B4 -> A | D2: B | F2: =Neu!$B7 -> 0 | G2: =Neu!$B8 -> 0 | H2: =Neu!$B9 -> 0 | I2: =Neu!$B10 -> 0 | J2: =Neu!$B11 -> 0 | K2: =Neu!$B12 -> 0 | L2: =Neu!$B13 -> 0 | M2: =Neu!$B14 -> 0 | N2: =Neu!$B15 -> 0 | O2: =Neu!$B16 -> 0 | P2: =Neu!$B17 -> 0 | Q2: =Neu!$B18 -> 0 | R2: =Neu!$B19 -> 0 | S2: =Neu!$B20 -> 0 | T2: =Neu!$B21 -> 0 | U2: =Neu!$B22 -> 0 | V2: =Neu!$B23 -> 0 | W2: =Neu!$B24 -> 0
A3: Presynaptic | B3: =Neu!B4 -> A | D3: 0.01 | X3: fast | Y3: Colorbar
X4: slow | Y4: =MAX($C$3:$W$44)-(ROW(Y4)-4)*0.5 -> 0.05
B5: B | C5: 0.05 | Y5: =MAX($C$3:$W$44)-(ROW(Y5)-4)*0.5 -> -0.45
Y6: =MAX($C$3:$W$44)-(ROW(Y6)-4)*0.5 -> -0.95
Y7: =MAX($C$3:$W$44)-(ROW(Y7)-4)*0.5 -> -1.45
Y8: =MAX($C$3:$W$44)-(ROW(Y8)-4)*0.5 -> -1.95
B9: =Neu!B7 -> 0 | Y9: =MAX($C$3:$W$44)-(ROW(Y9)-4)*0.5 -> -2.45
Y10: =MAX($C$3:$W$44)-(ROW(Y10)-4)*0.5 -> -2.95
B11: =Neu!B8 -> 0 | Y11: =MAX($C$3:$W$44)-(ROW(Y11)-4)*0.5 -> -3.45
Y12: =MAX($C$3:$W$44)-(ROW(Y12)-4)*0.5 -> -3.95
B13: =Neu!B9 -> 0 | Y13: =MAX($C$3:$W$44)-(ROW(Y13)-4)*0.5 -> -4.45
Y14: =MAX($C$3:$W$44)-(ROW(Y14)-4)*0.5 -> -4.95
B15: =Neu!B10 -> 0 | Y15: =MAX($C$3:$W$44)-(ROW(Y15)-4)*0.5 -> -5.45
Y16: =MAX($C$3:$W$44)-(ROW(Y16)-4)*0.5 -> -5.95
B17: =Neu!B11 -> 0 | Y17: =MAX($C$3:$W$44)-(ROW(Y17)-4)*0.5 -> -6.45
Y18: =MAX($C$3:$W$44)-(ROW(Y18)-4)*0.5 -> -6.95
B19: =Neu!B12 -> 0 | Y19: =MAX($C$3:$W$44)-(ROW(Y19)-4)*0.5 -> -7.45
Y20: =MAX($C$3:$W$44)-(ROW(Y20)-4)*0.5 -> -7.95
B21: =Neu!B13 -> 0 | Y21: =MAX($C$3:$W$44)-(ROW(Y21)-4)*0.5 -> -8.45
Y22: =MAX($C$3:$W$44)-(ROW(Y22)-4)*0.5 -> -8.95
B23: =Neu!B14 -> 0 | Y23: =MAX($C$3:$W$44)-(ROW(Y23)-4)*0.5 -> -9.45
Y24: =MAX($C$3:$W$44)-(ROW(Y24)-4)*0.5 -> -9.95
B25: =Neu!B15 -> 0 | Y25: =MAX($C$3:$W$44)-(ROW(Y25)-4)*0.5 -> -10.45
Y26: =MAX($C$3:$W$44)-(ROW(Y26)-4)*0.5 -> -10.95
B27: =Neu!B16 -> 0
B29: =Neu!B17 -> 0
B31: =Neu!B18 -> 0
B33: =Neu!B19 -> 0
B35: =Neu!B20 -> 0
B37: =Neu!B21 -> 0
B39: =Neu!B22 -> 0
B41: =Neu!B23 -> 0
B43: =Neu!B24 -> 0

Sheet cs_E
C1: Postsynaptic
C2: =Neu!$B4 -> A | D2: B | F2: =Neu!$B7 -> 0 | G2: =Neu!$B8 -> 0 | H2: =Neu!$B9 -> 0 | I2: =Neu!$B10 -> 0 | J2: =Neu!$B11 -> 0 | K2: =Neu!$B12 -> 0 | L2: =Neu!$B13 -> 0 | M2: =Neu!$B14 -> 0 | N2: =Neu!$B15 -> 0 | O2: =Neu!$B16 -> 0 | P2: =Neu!$B17 -> 0 | Q2: =Neu!$B18 -> 0 | R2: =Neu!$B19 -> 0 | S2: =Neu!$B20 -> 0 | T2: =Neu!$B21 -> 0 | U2: =Neu!$B22 -> 0 | V2: =Neu!$B23 -> 0 | W2: =Neu!$B24 -> 0
A3: Presynaptic | B3: =Neu!B4 -> A | D3: 300 | X3: fast | Y3: Colorbar
X4: slow | Y4: =MAX($C$3:$W$44)-(ROW(Y4)-4)*10 -> 300
B5: B | C5: 20 | Y5: =MAX($C$3:$W$44)-(ROW(Y5)-4)*10 -> 290
Y6: =MAX($C$3:$W$44)-(ROW(Y6)-4)*10 -> 280
Y7: =MAX($C$3:$W$44)-(ROW(Y7)-4)*10 -> 270
Y8: =MAX($C$3:$W$44)-(ROW(Y8)-4)*10 -> 260
B9: =Neu!B7 -> 0 | Y9: =MAX($C$3:$W$44)-(ROW(Y9)-4)*10 -> 250
Y10: =MAX($C$3:$W$44)-(ROW(Y10)-4)*10 -> 240
B11: =Neu!B8 -> 0 | Y11: =MAX($C$3:$W$44)-(ROW(Y11)-4)*10 -> 230
Y12: =MAX($C$3:$W$44)-(ROW(Y12)-4)*10 -> 220
B13: =Neu!B9 -> 0 | Y13: =MAX($C$3:$W$44)-(ROW(Y13)-4)*10 -> 210
Y14: =MAX($C$3:$W$44)-(ROW(Y14)-4)*10 -> 200
B15: =Neu!B10 -> 0 | Y15: =MAX($C$3:$W$44)-(ROW(Y15)-4)*10 -> 190
Y16: =MAX($C$3:$W$44)-(ROW(Y16)-4)*10 -> 180
B17: =Neu!B11 -> 0 | Y17: =MAX($C$3:$W$44)-(ROW(Y17)-4)*10 -> 170
Y18: =MAX($C$3:$W$44)-(ROW(Y18)-4)*10 -> 160
B19: =Neu!B12 -> 0 | Y19: =MAX($C$3:$W$44)-(ROW(Y19)-4)*10 -> 150
Y20: =MAX($C$3:$W$44)-(ROW(Y20)-4)*10 -> 140
B21: =Neu!B13 -> 0 | Y21: =MAX($C$3:$W$44)-(ROW(Y21)-4)*10 -> 130
Y22: =MAX($C$3:$W$44)-(ROW(Y22)-4)*10 -> 120
B23: =Neu!B14 -> 0 | Y23: =MAX($C$3:$W$44)-(ROW(Y23)-4)*10 -> 110
Y24: =MAX($C$3:$W$44)-(ROW(Y24)-4)*10 -> 100
B25: =Neu!B15 -> 0 | Y25: =MAX($C$3:$W$44)-(ROW(Y25)-4)*10 -> 90
Y26: =MAX($C$3:$W$44)-(ROW(Y26)-4)*10 -> 80
B27: =Neu!B16 -> 0 | Y27: =MAX($C$3:$W$44)-(ROW(Y27)-4)*10 -> 70
Y28: =MAX($C$3:$W$44)-(ROW(Y28)-4)*10 -> 60
B29: =Neu!B17 -> 0 | Y29: =MAX($C$3:$W$44)-(ROW(Y29)-4)*10 -> 50
Y30: =MAX($C$3:$W$44)-(ROW(Y30)-4)*10 -> 40
B31: =Neu!B18 -> 0 | Y31: =MAX($C$3:$W$44)-(ROW(Y31)-4)*10 -> 30
Y32: =MAX($C$3:$W$44)-(ROW(Y32)-4)*10 -> 20
B33: =Neu!B19 -> 0
B35: =Neu!B20 -> 0
B37: =Neu!B21 -> 0
B39: =Neu!B22 -> 0
B41: =Neu!B23 -> 0
B43: =Neu!B24 -> 0

Sheet cs_FAT
C1: Postsynaptic | AA1: taus | AC1: depression | AE1: Voltage dependence | AI1: facilitation
C2: =Neu!$B4 -> A | D2: B | F2: =Neu!$B7 -> 0 | G2: =Neu!$B8 -> 0 | H2: =Neu!$B9 -> 0 | I2: =Neu!$B10 -> 0 | J2: =Neu!$B11 -> 0 | K2: =Neu!$B12 -> 0 | L2: =Neu!$B13 -> 0 | M2: =Neu!$B14 -> 0 | N2: =Neu!$B15 -> 0 | O2: =Neu!$B16 -> 0 | P2: =Neu!$B17 -> 0 | Q2: =Neu!$B18 -> 0 | R2: =Neu!$B19 -> 0 | S2: =Neu!$B20 -> 0 | T2: =Neu!$B21 -> 0 | U2: =Neu!$B22 -> 0 | V2: =Neu!$B23 -> 0 | W2: =Neu!$B24 -> 0 | AA2: u1 | AB2: u2 | AC2: ud | AD2: ur | AE2: h | AF2: s | AG2: p | AH2: tx | AI2: ion | AJ2: u
A3: Presynaptic | B3: =Neu!B4 -> A | D3: 1 | X3: fast | Y3: =COUNTIF($C$3:$W$44,ROW(Z3)-2) -> 1 | Z3: =IF(ROW(AA3)-2<=MAX($C$3:$W$44),ROW(AA3)-2,"") -> 1 | AA3: 0.05 | AE3: -50 | AF3: 15 | AG3: 1
X4: slow | Y4: =COUNTIF($C$3:$W$44,ROW(Z4)-2) -> 1 | Z4: =IF(ROW(AA4)-2<=MAX($C$3:$W$44),ROW(AA4)-2,"") -> 2 | AA4: 0.05
B5: B | C5: 2 | Y5: =COUNTIF($C$3:$W$44,ROW(Z5)-2) -> 0 | Z5: =IF(ROW(AA5)-2<=MAX($C$3:$W$44),ROW(AA5)-2,"")
Y6: =COUNTIF($C$3:$W$44,ROW(Z6)-2) -> 0 | Z6: =IF(ROW(AA6)-2<=MAX($C$3:$W$44),ROW(AA6)-2,"")
Y7: =COUNTIF($C$3:$W$44,ROW(Z7)-2) -> 0 | Z7: =IF(ROW(AA7)-2<=MAX($C$3:$W$44),ROW(AA7)-2,"")
Y8: =COUNTIF($C$3:$W$44,ROW(Z8)-2) -> 0 | Z8: =IF(ROW(AA8)-2<=MAX($C$3:$W$44),ROW(AA8)-2,"")
B9: =Neu!B7 -> 0 | Y9: =COUNTIF($C$3:$W$44,ROW(Z9)-2) -> 0 | Z9: =IF(ROW(AA9)-2<=MAX($C$3:$W$44),ROW(AA9)-2,"") | AK9: if u2 is empty it is assumed equal to u1
Y10: =COUNTIF($C$3:$W$44,ROW(Z10)-2) -> 0 | Z10: =IF(ROW(AA10)-2<=MAX($C$3:$W$44),ROW(AA10)-2,"")
B11: =Neu!B8 -> 0 | Y11: =COUNTIF($C$3:$W$44,ROW(Z11)-2) -> 0 | Z11: =IF(ROW(AA11)-2<=MAX($C$3:$W$44),ROW(AA11)-2,"")
Y12: =COUNTIF($C$3:$W$44,ROW(Z12)-2) -> 0 | Z12: =IF(ROW(AA12)-2<=MAX($C$3:$W$44),ROW(AA12)-2,"")
B13: =Neu!B9 -> 0 | Y13: =COUNTIF($C$3:$W$44,ROW(Z13)-2) -> 0 | Z13: =IF(ROW(AA13)-2<=MAX($C$3:$W$44),ROW(AA13)-2,"") | AK13: Ach
Y14: =COUNTIF($C$3:$W$44,ROW(Z14)-2) -> 0 | Z14: =IF(ROW(AA14)-2<=MAX($C$3:$W$44),ROW(AA14)-2,"")
B15: =Neu!B10 -> 0 | Y15: =COUNTIF($C$3:$W$44,ROW(Z15)-2) -> 0 | Z15: =IF(ROW(AA15)-2<=MAX($C$3:$W$44),ROW(AA15)-2,"")
Y16: =COUNTIF($C$3:$W$44,ROW(Z16)-2) -> 0 | Z16: =IF(ROW(AA16)-2<=MAX($C$3:$W$44),ROW(AA16)-2,"")
B17: =Neu!B11 -> 0 | Y17: =COUNTIF($C$3:$W$44,ROW(Z17)-2) -> 0 | Z17: =IF(ROW(AA17)-2<=MAX($C$3:$W$44),ROW(AA17)-2,"")
Y18: =COUNTIF($C$3:$W$44,ROW(Z18)-2) -> 0 | Z18: =IF(ROW(AA18)-2<=MAX($C$3:$W$44),ROW(AA18)-2,"")
B19: =Neu!B12 -> 0 | Y19: =COUNTIF($C$3:$W$44,ROW(Z19)-2) -> 0 | Z19: =IF(ROW(AA19)-2<=MAX($C$3:$W$44),ROW(AA19)-2,"")
Y20: =COUNTIF($C$3:$W$44,ROW(Z20)-2) -> 0 | Z20: =IF(ROW(AA20)-2<=MAX($C$3:$W$44),ROW(AA20)-2,"")
B21: =Neu!B13 -> 0 | Y21: =COUNTIF($C$3:$W$44,ROW(Z21)-2) -> 0 | Z21: =IF(ROW(AA21)-2<=MAX($C$3:$W$44),ROW(AA21)-2,"")
Y22: =COUNTIF($C$3:$W$44,ROW(Z22)-2) -> 0 | Z22: =IF(ROW(AA22)-2<=MAX($C$3:$W$44),ROW(AA22)-2,"")
B23: =Neu!B14 -> 0 | Y23: =COUNTIF($C$3:$W$44,ROW(Z23)-2) -> 0 | Z23: =IF(ROW(AA23)-2<=MAX($C$3:$W$44),ROW(AA23)-2,"")
Y24: =COUNTIF($C$3:$W$44,ROW(Z24)-2) -> 0 | Z24: =IF(ROW(AA24)-2<=MAX($C$3:$W$44),ROW(AA24)-2,"")
B25: =Neu!B15 -> 0 | Y25: =COUNTIF($C$3:$W$44,ROW(Z25)-2) -> 0 | Z25: =IF(ROW(AA25)-2<=MAX($C$3:$W$44),ROW(AA25)-2,"")
Y26: =COUNTIF($C$3:$W$44,ROW(Z26)-2) -> 0 | Z26: =IF(ROW(AA26)-2<=MAX($C$3:$W$44),ROW(AA26)-2,"")
B27: =Neu!B16 -> 0 | Y27: =COUNTIF($C$3:$W$44,ROW(Z27)-2) -> 0 | Z27: =IF(ROW(AA27)-2<=MAX($C$3:$W$44),ROW(AA27)-2,"")
Y28: =COUNTIF($C$3:$W$44,ROW(Z28)-2) -> 0 | Z28: =IF(ROW(AA28)-2<=MAX($C$3:$W$44),ROW(AA28)-2,"")
B29: =Neu!B17 -> 0 | Y29: =COUNTIF($C$3:$W$44,ROW(Z29)-2) -> 0 | Z29: =IF(ROW(AA29)-2<=MAX($C$3:$W$44),ROW(AA29)-2,"")
Y30: =COUNTIF($C$3:$W$44,ROW(Z30)-2) -> 0 | Z30: =IF(ROW(AA30)-2<=MAX($C$3:$W$44),ROW(AA30)-2,"")
B31: =Neu!B18 -> 0 | Y31: =COUNTIF($C$3:$W$44,ROW(Z31)-2) -> 0 | Z31: =IF(ROW(AA31)-2<=MAX($C$3:$W$44),ROW(AA31)-2,"")
Y32: =COUNTIF($C$3:$W$44,ROW(Z32)-2) -> 0 | Z32: =IF(ROW(AA32)-2<=MAX($C$3:$W$44),ROW(AA32)-2,"")
B33: =Neu!B19 -> 0 | Y33: =COUNTIF($C$3:$W$44,ROW(Z33)-2) -> 0 | Z33: =IF(ROW(AA33)-2<=MAX($C$3:$W$44),ROW(AA33)-2,"")
Y34: =COUNTIF($C$3:$W$44,ROW(Z34)-2) -> 0 | Z34: =IF(ROW(AA34)-2<=MAX($C$3:$W$44),ROW(AA34)-2,"")
B35: =Neu!B20 -> 0 | Y35: =COUNTIF($C$3:$W$44,ROW(Z35)-2) -> 0 | Z35: =IF(ROW(AA35)-2<=MAX($C$3:$W$44),ROW(AA35)-2,"")
Y36: =COUNTIF($C$3:$W$44,ROW(Z36)-2) -> 0 | Z36: =IF(ROW(AA36)-2<=MAX($C$3:$W$44),ROW(AA36)-2,"")
B37: =Neu!B21 -> 0 | Y37: =COUNTIF($C$3:$W$44,ROW(Z37)-2) -> 0 | Z37: =IF(ROW(AA37)-2<=MAX($C$3:$W$44),ROW(AA37)-2,"")
Y38: =COUNTIF($C$3:$W$44,ROW(Z38)-2) -> 0 | Z38: =IF(ROW(AA38)-2<=MAX($C$3:$W$44),ROW(AA38)-2,"")
B39: =Neu!B22 -> 0 | Y39: =COUNTIF($C$3:$W$44,ROW(Z39)-2) -> 0 | Z39: =IF(ROW(AA39)-2<=MAX($C$3:$W$44),ROW(AA39)-2,"")
Y40: =COUNTIF($C$3:$W$44,ROW(Z40)-2) -> 0 | Z40: =IF(ROW(AA40)-2<=MAX($C$3:$W$44),ROW(AA40)-2,"")
...

Sheet es
C1: Postsynaptic
C2: =Neu!B4 -> A | D2: B | F2: =Neu!B7 -> 0 | G2: =Neu!B8 -> 0 | H2: =Neu!B9 -> 0 | I2: =Neu!B10 -> 0 | J2: =Neu!B11 -> 0 | K2: =Neu!B12 -> 0 | L2: =Neu!B13 -> 0 | M2: =Neu!B14 -> 0 | N2: =Neu!B15 -> 0 | O2: =Neu!B16 -> 0 | P2: =Neu!B17 -> 0 | Q2: =Neu!$B18 -> 0 | R2: =Neu!$B19 -> 0 | S2: =Neu!$B20 -> 0 | T2: =Neu!$B21 -> 0 | U2: =Neu!$B22 -> 0 | V2: =Neu!$B23 -> 0 | W2: =Neu!$B24 -> 0
A3: Presynaptic | B3: =Neu!B4 -> A
B4: B
B6: =Neu!B7 -> 0
B7: =Neu!B8 -> 0
B8: =Neu!B9 -> 0
B9: =Neu!B10 -> 0
B10: =Neu!B11 -> 0
B11: =Neu!B12 -> 0
B12: =Neu!B13 -> 0
B13: =Neu!B14 -> 0
B14: =Neu!B15 -> 0
B15: =Neu!B16 -> 0
B16: =Neu!B17 -> 0
B17: =Neu!B18 -> 0
... B23: =Neu!B24 -> 0

Sheet noise
B1: Amplitude | C1: step size | D1: jitter in step size
A2: votage-dependent conductance (.vdg) | B2: 0 | C2: 200 | D2: 10
A3: chemical synapse (.cs) | B3: 0 | C3: 200 | D3: 10
A4: electrical synapse (.es) | B4: 0 | C4: 200 | D4: 10
