Workbook

Sheet Neu
D1: File | E1: leak | G1: Na | AH1: K | BI1: KA | CJ1: CaL | DK1: CaR | EL1: CaN | FM1: Kca | GN1: KTEA | HO1: Napp | IP1: HCN | JQ1: K_pp
E2: vdg | G2: vdg | J2: A | V2: B | AH2: vdg | AK2: A | AW2: B | BI2: vdg | BL2: A | BX2: B | CJ2: vdg | CM2: A | CY2: B | DK2: vdg | DN2: A | DZ2: B | EL2: vdg | EO2: A | FA2: B | FM2: vdg | FP2: A | GB2: B | GN2: vdg | GQ2: A | HC2: B | HO2: vdg | HR2: A | ID2: B | IP2: vdg | IS2: A | JE2: B | JQ2: vdg | JT2: A | KF2: B
B3: Name | C3: Template | D3: cm | E3: g | F3: E | G3: g | H3: p | I3: E | J3: An | K3: h | L3: s | M3: p | N3: tmx | O3: tmin | P3: th1 | Q3: ts1 | R3: tp1 | S3: th2 | T3: ts2 | U3: tp2 | V3: Bn | W3: h | X3: s | Y3: p | Z3: tmx | AA3: tmin | AB3: th1 | AC3: ts1 | AD3: tp1 | AE3: th2 | AF3: ts2 | AG3: tp2 | AH3: g | AI3: p | AJ3: E | AK3: An | AL3: h | AM3: s | AN3: p | AO3: tmx | AP3: tmin | AQ3: th1 | AR3: ts1 | AS3: tp1 | AT3: th2 | AU3: ts2 | AV3: tp2 | AW3: Bn | AX3: h | AY3: s | AZ3: p | BA3: tmx | BB3: tmin | BC3: th1 | BD3: ts1 | BE3: tp1 | BF3: th2 | BG3: ts2 | BH3: tp2 | BI3: g | BJ3: p | BK3: E | BL3: An | BM3: h | BN3: s | BO3: p | BP3: tmx | BQ3: tmin | BR3: th1 | BS3: ts1 | BT3: tp1 | BU3: th2 | BV3: ts2 | BW3: tp2 | BX3: Bn | BY3: h | BZ3: s | CA3: p | CB3: tmx | CC3: tmin | CD3: th1 | CE3: ts1 | CF3: tp1 | CG3: th2 | CH3: ts2 | CI3: tp2 | CJ3: g | CK3: p | CL3: E | CM3: An | CN3: h | CO3: s | CP3: p | CQ3: tmx | CR3: tmin | CS3: th1 | CT3: ts1 | CU3: tp1 | CV3: th2 | CW3: ts2 | CX3: tp2 | CY3: Bn | CZ3: h | DA3: s | DB3: p | DC3: tmx | DD3: tmin | DE3: th1 | DF3: ts1 | DG3: tp1 | DH3: th2 | DI3: ts2 | DJ3: tp2 | DK3: g | DL3: p | DM3: E | DN3: An | DO3: h | DP3: s | DQ3: p | DR3: tmx | DS3: tmin | DT3: th1 | DU3: ts1 | DV3: tp1 | DW3: th2 | DX3: ts2 | DY3: tp2 | DZ3: Bn | EA3: h | EB3: s | EC3: p | ED3: tmx | EE3: tmin | EF3: th1 | EG3: ts1 | EH3: tp1 | EI3: th2 | EJ3: ts2 | EK3: tp2 | EL3: g | EM3: p | EN3: E | EO3: An | EP3: h | EQ3: s | ER3: p | ES3: tmx | ET3: tmin | EU3: th1 | EV3: ts1 | EW3: tp1 | EX3: th2 | EY3: ts2 | EZ3: tp2 | FA3: Bn | FB3: h | FC3: s | FD3: p | FE3: tmx | FF3: tmin | FG3: th1 | FH3: ts1 | FI3: tp1 | FJ3: th2 | FK3: ts2 | FL3: tp2 | FM3: g | FN3: p | FO3: E | FP3: An | FQ3: h | FR3: s | FS3: p | FT3: tmx | FU3: tmin | FV3: th1 | FW3: ts1 | FX3: tp1 | FY3: th2 | FZ3: ts2 | GA3: tp2 | GB3: Bn | GC3: h | GD3: s | GE3: p | GF3: tmx | GG3: tmin | GH3: th1 | GI3: ts1 | GJ3: tp1 | GK3: th2 | GL3: ts2 | GM3: tp2 | GN3: g | GO3: p | GP3: E | GQ3: An | GR3: h | GS3: s | GT3: p | GU3: tmx | GV3: tmin | GW3: th1 | GX3: ts1 | GY3: tp1 | GZ3: th2 | HA3: ts2 | HB3: tp2 | HC3: Bn | HD3: h | HE3: s | HF3: p | HG3: tmx | HH3: tmin | HI3: th1 | HJ3: ts1 | HK3: tp1 | HL3: th2 | HM3: ts2 | HN3: tp2 | HO3: g | HP3: p | HQ3: E | HR3: An | HS3: h | HT3: s | HU3: p | HV3: tmx | HW3: tmin | HX3: th1 | HY3: ts1 | HZ3: tp1 | IA3: th2 | IB3: ts2 | IC3: tp2 | ID3: Bn | IE3: h | IF3: s | IG3: p | IH3: tmx | II3: tmin | IJ3: th1 | IK3: ts1 | IL3: tp1 | IM3: th2 | IN3: ts2 | IO3: tp2 | IP3: g | IQ3: p | IR3: E | IS3: An | IT3: h | IU3: s | IV3: p | IW3: tmx | IX3: tmin | IY3: th1 | IZ3: ts1 | JA3: tp1 | JB3: th2 | JC3: ts2 | JD3: tp2 | JE3: Bn | JF3: h | JG3: s | JH3: p | JI3: tmx | JJ3: tmin | JK3: th1 | JL3: ts1 | JM3: tp1 | JN3: th2 | JO3: ts2 | JP3: tp2 | JQ3: g | JR3: p | JS3: E | JT3: An | JU3: h | JV3: s | JW3: p | JX3: tmx | JY3: tmin | JZ3: th1 | KA3: ts1 | KB3: tp1 | KC3: th2 | KD3: ts2 | KE3: tp2 | KF3: Bn | KG3: h | KH3: s | KI3: p | KJ3: tmx | KK3: tmin | KL3: th1 | KM3: ts1 | KN3: tp1 | KO3: th2 | KP3: ts2 | KQ3: tp2
A4: =Neu!B4 -> A | B4: A | D4: 0.003 | E4: 0.1 | F4: -70 | G4: 8 | H4: 3 | I4: 50 | J4: 0 | K4: -49 | L4: 5 | M4: 1 | N4: 0.006 | O4: 0.001 | P4: -55 | Q4: 4 | R4: 1 | V4: 0 | W4: -55 | X4: 5 | Y4: 1 | Z4: 0.02 | AA4: 0.005 | AB4: -50 | AC4: 10 | AD4: 1 | AH4: 32 | AI4: 4 | AJ4: -80 | AK4: 0 | AL4: -35 | AM4: 9 | AN4: 1 | AO4: 0.08 | AP4: 0.008 | AQ4: -20 | AR4: 10 | AS4: 1
A5: =Neu!B5 -> B | B5: B | D5: =D4 -> 0.003 | E5: 0.1 | F5: -70 | G5: 8 | H5: 3 | I5: 50 | J5: 0 | K5: -49 | L5: 5 | M5: 1 | N5: 0.006 | O5: 0.001 | P5: -55 | Q5: 4 | R5: 1 | V5: 0 | W5: -55 | X5: 5 | Y5: 1 | Z5: 0.02 | AA5: 0.005 | AB5: -50 | AC5: 10 | AD5: 1 | AH5: 32 | AI5: 4 | AJ5: -80 | AK5: 0 | AL5: -35 | AM5: 9 | AN5: 1 | AO5: 0.08 | AP5: 0.008 | AQ5: -20 | AR5: 10 | AS5: 1
A6: =Neu!B6 -> C | B6: C | D6: =D5 -> 0.003 | E6: 0.1 | F6: -70
A7: =Neu!B7 -> 0
A8: =Neu!B8 -> 0
A9: =Neu!B9 -> 0
A10: =Neu!B10 -> 0
A11: =Neu!B11 -> 0
A12: =Neu!B12 -> 0
A13: =Neu!B13 -> 0
A14: =Neu!B14 -> 0
A15: =Neu!B15 -> 0
A16: =Neu!B16 -> 0
A17: =Neu!B17 -> 0
A18: =Neu!B18 -> 0
... A24: =Neu!B24 -> 0
FM25: 2.3 | FN25: 1 | FO25: -70 | FP25: 0 | FQ25: -5 | FR25: 9 | FS25: 1 | FT25: 0.005 | GN25: 0.15 | HI25: 0.3 | HJ25: 0.14 | HK25: 0.33 | HL25: 0.1 | HM25: 0.3 | HO25: 0.1 | HP25: 1 | HQ25: 60 | HR25: 0 | HS25: -48 | HT25: 3 | HU25: 1 | HV25: 0.01 | ID25: 0.6 | IE25: -62 | IF25: 1 | IG25: 1 | IH25: 2.5 | II25: 0.25 | IJ25: -55 | IK25: -1.5 | IL25: 1 | IM25: -42 | IN25: 1.5 | IO25: 1
FM26: 0 | FN26: =FN25 -> 1 | FO26: =FO25 -> -70 | FP26: =FP25 -> 0 | FQ26: -5 | FR26: =FR25 -> 9 | FS26: =FS25 -> 1 | FT26: =FT25 -> 0.005 | GN26: 0.26 | HJ26: 0.08 | HK26: 0.33 | HL26: 0.1 | HM26: 0.5 | HO26: 0.12 | HP26: =HP25 -> 1 | HQ26: =HQ25 -> 60 | HR26: =HR25 -> 0 | HS26: -43 | HT26: =HT25 -> 3 | HU26: =HU25 -> 1 | HV26: =HV25 -> 0.01 | ID26: =ID25 -> 0.6 | IE26: =IE25 -> -62 | IF26: =IF25 -> 1 | IG26: =IG25 -> 1 | IH26: =IH25 -> 2.5 | II26: =II25 -> 0.25 | IJ26: =IJ25 -> -55 | IK26: =IK25 -> -1.5 | ... IO26: =IO25 -> 1
FM27: 1.1 | FN27: 1 | FO27: =FO25 -> -70 | FP27: =FP25 -> 0 | FQ27: 5 | FR27: 9 | FS27: =FS25 -> 1 | FT27: =FT25 -> 0.005 | GN27: 0.85 | HJ27: 0.15 | HK27: 0.33 | HL27: 0.1 | HM27: 0.3 | HO27: 0.12 | HP27: =HP25 -> 1 | HQ27: =HQ25 -> 60 | HR27: =HR25 -> 0 | HS27: =HS25 -> -48 | HT27: =HT25 -> 3 | HU27: =HU25 -> 1 | HV27: =HV25 -> 0.01 | ID27: =ID25 -> 0.6 | IE27: =IE25 -> -62 | IF27: =IF25 -> 1 | IG27: =IG25 -> 1 | IH27: =IH25 -> 2.5 | II27: =II25 -> 0.25 | IJ27: =IJ25 -> -55 | IK27: =IK25 -> -1.5 | ... IO27: =IO25 -> 1 | IP27: 0.085 | IQ27: 1 | IR27: -40 | IS27: 0 | IT27: -68 | IU27: -4.8 | IV27: 1 | IW27: 14 | IX27: 0.9 | IY27: -73 | IZ27: -9 | JA27: 1 | JB27: -75 | JC27: 9 | JD27: 1
D29: Ion pools | O29: Conductance to ion | Z29: Ion to conductance | BD29: Initial voltage
D30: Name | E30: ion | F30: K1 | G30: K2 | H30: ion | I30: K1 | J30: K2 | K30: ion | L30: K1 | M30: K2 | O30: Name | P30: ch | Q30: ion | R30: ch | S30: ion | T30: ch | U30: ion | V30: ch | W30: ion | Z30: Name | AA30: ion | AB30: ch | AC30: opt1 | AD30: opt2 | AE30: p1 | AF30: p2 | AG30: b | AH30: ion | AI30: ch | AJ30: opt1 | AK30: opt2 | AL30: p1 | AM30: p2 | AN30: b | AO30: ion | AP30: ch | AQ30: opt1 | AR30: opt2 | AS30: p1 | AT30: p2 | AU30: b | AV30: ion | AW30: ch | AX30: opt1 | AY30: opt2 | AZ30: p1 | BA30: p2 | BB30: b | BD30: Name | BE30: mV
Z31: =Neu!$B4 -> A | BD31: =Neu!$B4 -> A | BE31: -70
Z32: =Neu!$B5 -> B | BD32: =Neu!$B5 -> B | BE32: -70
Z33: =Neu!$B6 -> C | BD33: =Neu!$B6 -> C | BE33: -70
Z34: =Neu!$B7 -> 0 | BD34: =Neu!$B7 -> 0 | BE34: -70
D35: =Neu!$B8 -> 0 | O35: =Neu!$B8 -> 0 | Z35: =Neu!$B8 -> 0 | BD35: =Neu!$B8 -> 0 | BE35: -70
D36: =Neu!$B9 -> 0 | O36: =Neu!$B9 -> 0 | Z36: =Neu!$B9 -> 0 | BD36: =Neu!$B9 -> 0
D37: =Neu!$B10 -> 0 | O37: =Neu!$B10 -> 0 | Z37: =Neu!$B10 -> 0 | BD37: =Neu!$B10 -> 0
D38: =Neu!$B11 -> 0 | O38: =Neu!$B11 -> 0 | Z38: =Neu!$B11 -> 0 | BD38: =Neu!$B11 -> 0
D39: =Neu!$B12 -> 0 | O39: =Neu!$B12 -> 0 | Z39: =Neu!$B12 -> 0 | BD39: =Neu!$B12 -> 0
D40: =Neu!$B13 -> 0 | O40: =Neu!$B13 -> 0 | Z40: =Neu!$B13 -> 0 | BD40: =Neu!$B13 -> 0
D41: =Neu!$B14 -> 0 | O41: =Neu!$B14 -> 0 | Z41: =Neu!$B14 -> 0 | BD41: =Neu!$B14 -> 0
D42: =Neu!$B15 -> 0 | O42: =Neu!$B15 -> 0 | Z42: =Neu!$B15 -> 0 | BD42: =Neu!$B15 -> 0
D43: =Neu!$B16 -> 0 | O43: =Neu!$B16 -> 0 | Z43: =Neu!$B16 -> 0 | BD43: =Neu!$B16 -> 0
D44: =Neu!$B17 -> 0 | O44: =Neu!$B17 -> 0 | Z44: =Neu!$B17 -> 0 | BD44: =Neu!$B17 -> 0
D45: =Neu!$B18 -> 0 | O45: =Neu!$B18 -> 0 | Z45: =Neu!$B18 -> 0 | BD45: =Neu!$B18 -> 0
D46: =Neu!$B19 -> 0 | O46: =Neu!$B19 -> 0 | Z46: =Neu!$B19 -> 0 | BD46: =Neu!$B19 -> 0
...

Sheet rockon.smu
F1: syntax | L1: example variables | M1: IVDxREG | N1: currrent by conductance and regulation | T1: example synapses
A2: smu | B2: name | C2: rockon | D2: graph | E2: 1 | F2: conductance | G2: variable.conductance.neuron | M2: V | N2: voltage | Q2: Ics | R2: chem syn current | T2: f_exc | U2: fast excitatory
B3: duration | C3: 60 | D3: store | E3: 1 | F3: example | G3: Ivd.Na.N1 | I3: fBR | J3: fBR.ion.ch.neuron | M3: Ivd | N3: current by voltage gated conductance | Q3: Cion | R3: amount of ion | T3: s_exc | U3: slow excitatory
B4: stepsize | C4: 5e-05 | D4: method | E4: 1 | F4: neuron | G4: variable.neuron | I4: synapse | J4: variable.pre.post.type | M4: A | N4: activation of conductance | Q4: Ies | R4: elec syn current | T4: f_inh | U4: fast inhibitory
B5: red indicates simlation longer than graph duration | F5: example | G5: V.N1 | I5: example | J5: Ics.N1.N4.f_exc | M5: B | N5: Inactivation of conductance | Q5: slex | R5: trt current | T5: s_inh | U5: slow inhibitory
A6: graph (ous) | J6: Ies.N1.N4 | M6: sIVD_reg | N6: for total current
B7: time | G7: variable 1 | L7: variable 2 | Q7: variable 3 | V7: variable 4
A8: Size | B8: variable | C8: # ticks | D8: start | E8: stop | F8: color | G8: variable | H8: # ticks | I8: min | J8: max | K8: color | L8: variable | M8: # ticks | N8: min | O8: max | P8: color | Q8: variable | R8: # ticks | S8: min | T8: max | U8: color | V8: variable | W8: # ticks | X8: min | Y8: max | Z8: color
A9: 1 | B9: time | C9: 12 | D9: 0 | E9: 60 | F9: red | G9: V.A | H9: 8 | I9: -90 | J9: 70 | K9: red
A10: 1 | B10: time | C10: 12 | D10: 0 | E10: 60 | F10: red | G10: V.B | H10: 8 | I10: -90 | J10: 70 | K10: green
A11: 1 | B11: time | C11: 12 | D11: 0 | E11: 60 | F11: red | G11: V.C | H11: 8 | I11: -90 | J11: 70 | K11: cyan
A25: stimulation (.trt) | L25: output variables
B26: Current injection | G26: Voltage clamp | L26: all | M26: type "all" in first cell to output all graphed variables or type individual channels
B27: neuron | C27: start | D27: stop | E27: magnitude | G27: neuron | H27: start | I27: stop | J27: potential
B28: A | C28: 0 | D28: 60 | E28: 1
B29: B | C29: 0 | D29: 60 | E29: 1

Sheet synapse.smu
F1: syntax | L1: example variables | M1: IVDxREG | N1: currrent by conductance and regulation | T1: example synapses
A2: smu | B2: name | C2: synapse | D2: graph | E2: 1 | F2: conductance | G2: variable.conductance.neuron | M2: V | N2: voltage | Q2: Ics | R2: chem syn current | T2: f_exc | U2: fast excitatory
B3: duration | C3: 13 | D3: store | E3: 1 | F3: example | G3: Ivd.Na.N1 | I3: fBR | J3: fBR.ion.ch.neuron | M3: Ivd | N3: current by voltage gated conductance | Q3: Cion | R3: amount of ion | T3: s_exc | U3: slow excitatory
B4: stepsize | C4: 5e-05 | D4: method | E4: 1 | F4: neuron | G4: variable.neuron | I4: synapse | J4: variable.pre.post.type | M4: A | N4: activation of conductance | Q4: Ies | R4: elec syn current | T4: f_inh | U4: fast inhibitory
B5: red indicates simlation longer than graph duration | F5: example | G5: V.N1 | I5: example | J5: Ics.N1.N4.f_exc | M5: B | N5: Inactivation of conductance | Q5: slex | R5: trt current | T5: s_inh | U5: slow inhibitory
A6: graph (ous) | J6: Ies.N1.N4 | M6: sIVD_reg | N6: for total current
B7: time | G7: variable 1 | L7: variable 2 | Q7: variable 3 | V7: variable 4
A8: Size | B8: variable | C8: # ticks | D8: start | E8: stop | F8: color | G8: variable | H8: # ticks | I8: min | J8: max | K8: color | L8: variable | M8: # ticks | N8: min | O8: max | P8: color | Q8: variable | R8: # ticks | S8: min | T8: max | U8: color | V8: variable | W8: # ticks | X8: min | Y8: max | Z8: color
A9: 1 | B9: time | C9: 13 | D9: 0 | E9: 13 | F9: red | G9: V.A | H9: 5 | I9: -90 | J9: -40 | K9: red
A10: 1 | B10: time | C10: 13 | D10: 0 | E10: 13 | F10: green | G10: V.B | H10: 5 | I10: -90 | J10: -40 | K10: green
A11: 1 | B11: time | C11: 13 | D11: 0 | E11: 13 | F11: cyan | G11: V.C | H11: 5 | I11: -90 | J11: -40 | K11: cyan
G12: A.A.C.f_exc
A25: stimulation (.trt) | L25: output variables
B26: Current injection | G26: Voltage clamp | L26: all | M26: type "all" in first cell to output all graphed variables or type individual channels
B27: neuron | C27: start | D27: stop | E27: magnitude | G27: neuron | H27: start | I27: stop | J27: potential
B28: A | C28: 0 | D28: 5 | E28: -1
B29: A | C29: 0.25 | D29: 0.4 | E29: 2
B30: A | C30: 0.75 | D30: 0.9 | E30: 2
B31: A | C31: 1.25 | D31: 1.4 | E31: 2
B32: A | C32: 1.75 | D32: 1.9 | E32: 2
B33: A | C33: 2.25 | D33: 2.4 | E33: 2
B34: A | C34: 2.75 | D34: 2.9 | E34: 2
B35: A | C35: 3.25 | D35: 3.4 | E35: 2
B36: A | C36: 3.75 | D36: 3.9 | E36: 2
B37: A | C37: 4.25 | D37: 4.35 | E37: 2
B38: A | C38: 4.75 | D38: 4.85 | E38: 2
B39: A | C39: 5.25 | D39: 5.35 | E39: 2
... B52: C | C52: 5.5 | D52: 6 | E52: 8

Sheet cs_g
C1: Postsynaptic
C2: =Neu!$B4 -> A | D2: =Neu!$B5 -> B | E2: =Neu!$B6 -> C | F2: =Neu!$B7 -> 0 | G2: =Neu!$B8 -> 0 | H2: =Neu!$B9 -> 0 | I2: =Neu!$B10 -> 0 | J2: =Neu!$B11 -> 0 | K2: =Neu!$B12 -> 0 | L2: =Neu!$B13 -> 0 | M2: =Neu!$B14 -> 0 | N2: =Neu!$B15 -> 0 | O2: =Neu!$B16 -> 0 | P2: =Neu!$B17 -> 0 | Q2: =Neu!$B18 -> 0 | R2: =Neu!$B19 -> 0 | S2: =Neu!$B20 -> 0 | T2: =Neu!$B21 -> 0 | U2: =Neu!$B22 -> 0 | V2: =Neu!$B23 -> 0 | W2: =Neu!$B24 -> 0
A3: Presynaptic | B3: =Neu!B4 -> A | D3: 0.5 | E3: 0.01 | X3: fast | Y3: Colorbar
X4: slow | Y4: =MAX($C$3:$W$44)-(ROW(Y4)-4)*0.5 -> 0.5
B5: =Neu!B5 -> B | C5: 0.5 | Y5: =MAX($C$3:$W$44)-(ROW(Y5)-4)*0.5 -> 0
Y6: =MAX($C$3:$W$44)-(ROW(Y6)-4)*0.5 -> -0.5
B7: =Neu!B6 -> C | C7: 0.05 | Y7: =MAX($C$3:$W$44)-(ROW(Y7)-4)*0.5 -> -1
Y8: =MAX($C$3:$W$44)-(ROW(Y8)-4)*0.5 -> -1.5
B9: =Neu!B7 -> 0 | Y9: =MAX($C$3:$W$44)-(ROW(Y9)-4)*0.5 -> -2
Y10: =MAX($C$3:$W$44)-(ROW(Y10)-4)*0.5 -> -2.5
B11: =Neu!B8 -> 0 | Y11: =MAX($C$3:$W$44)-(ROW(Y11)-4)*0.5 -> -3
Y12: =MAX($C$3:$W$44)-(ROW(Y12)-4)*0.5 -> -3.5
B13: =Neu!B9 -> 0 | Y13: =MAX($C$3:$W$44)-(ROW(Y13)-4)*0.5 -> -4
Y14: =MAX($C$3:$W$44)-(ROW(Y14)-4)*0.5 -> -4.5
B15: =Neu!B10 -> 0 | Y15: =MAX($C$3:$W$44)-(ROW(Y15)-4)*0.5 -> -5
Y16: =MAX($C$3:$W$44)-(ROW(Y16)-4)*0.5 -> -5.5
B17: =Neu!B11 -> 0 | Y17: =MAX($C$3:$W$44)-(ROW(Y17)-4)*0.5 -> -6
Y18: =MAX($C$3:$W$44)-(ROW(Y18)-4)*0.5 -> -6.5
B19: =Neu!B12 -> 0 | Y19: =MAX($C$3:$W$44)-(ROW(Y19)-4)*0.5 -> -7
Y20: =MAX($C$3:$W$44)-(ROW(Y20)-4)*0.5 -> -7.5
B21: =Neu!B13 -> 0 | Y21: =MAX($C$3:$W$44)-(ROW(Y21)-4)*0.5 -> -8
Y22: =MAX($C$3:$W$44)-(ROW(Y22)-4)*0.5 -> -8.5
B23: =Neu!B14 -> 0 | Y23: =MAX($C$3:$W$44)-(ROW(Y23)-4)*0.5 -> -9
Y24: =MAX($C$3:$W$44)-(ROW(Y24)-4)*0.5 -> -9.5
B25: =Neu!B15 -> 0 | Y25: =MAX($C$3:$W$44)-(ROW(Y25)-4)*0.5 -> -10
Y26: =MAX($C$3:$W$44)-(ROW(Y26)-4)*0.5 -> -10.5
B27: =Neu!B16 -> 0
B29: =Neu!B17 -> 0
B31: =Neu!B18 -> 0
B33: =Neu!B19 -> 0
B35: =Neu!B20 -> 0
B37: =Neu!B21 -> 0
B39: =Neu!B22 -> 0
B41: =Neu!B23 -> 0
B43: =Neu!B24 -> 0

Sheet cs_E
C1: Postsynaptic
C2: =Neu!$B4 -> A | D2: =Neu!$B5 -> B | E2: =Neu!$B6 -> C | F2: =Neu!$B7 -> 0 | G2: =Neu!$B8 -> 0 | H2: =Neu!$B9 -> 0 | I2: =Neu!$B10 -> 0 | J2: =Neu!$B11 -> 0 | K2: =Neu!$B12 -> 0 | L2: =Neu!$B13 -> 0 | M2: =Neu!$B14 -> 0 | N2: =Neu!$B15 -> 0 | O2: =Neu!$B16 -> 0 | P2: =Neu!$B17 -> 0 | Q2: =Neu!$B18 -> 0 | R2: =Neu!$B19 -> 0 | S2: =Neu!$B20 -> 0 | T2: =Neu!$B21 -> 0 | U2: =Neu!$B22 -> 0 | V2: =Neu!$B23 -> 0 | W2: =Neu!$B24 -> 0
A3: Presynaptic | B3: =Neu!B4 -> A | D3: -100 | E3: 300 | X3: fast | Y3: Colorbar
X4: slow | Y4: =MAX($C$3:$W$44)-(ROW(Y4)-4)*10 -> 300
B5: =Neu!B5 -> B | C5: -100 | Y5: =MAX($C$3:$W$44)-(ROW(Y5)-4)*10 -> 290
Y6: =MAX($C$3:$W$44)-(ROW(Y6)-4)*10 -> 280
B7: =Neu!B6 -> C | C7: 20 | Y7: =MAX($C$3:$W$44)-(ROW(Y7)-4)*10 -> 270
Y8: =MAX($C$3:$W$44)-(ROW(Y8)-4)*10 -> 260
B9: =Neu!B7 -> 0 | Y9: =MAX($C$3:$W$44)-(ROW(Y9)-4)*10 -> 250
Y10: =MAX($C$3:$W$44)-(ROW(Y10)-4)*10 -> 240
B11: =Neu!B8 -> 0 | Y11: =MAX($C$3:$W$44)-(ROW(Y11)-4)*10 -> 230
Y12: =MAX($C$3:$W$44)-(ROW(Y12)-4)*10 -> 220
B13: =Neu!B9 -> 0 | Y13: =MAX($C$3:$W$44)-(ROW(Y13)-4)*10 -> 210
Y14: =MAX($C$3:$W$44)-(ROW(Y14)-4)*10 -> 200
B15: =Neu!B10 -> 0 | Y15: =MAX($C$3:$W$44)-(ROW(Y15)-4)*10 -> 190
Y16: =MAX($C$3:$W$44)-(ROW(Y16)-4)*10 -> 180
B17: =Neu!B11 -> 0 | Y17: =MAX($C$3:$W$44)-(ROW(Y17)-4)*10 -> 170
Y18: =MAX($C$3:$W$44)-(ROW(Y18)-4)*10 -> 160
B19: =Neu!B12 -> 0 | Y19: =MAX($C$3:$W$44)-(ROW(Y19)-4)*10 -> 150
Y20: =MAX($C$3:$W$44)-(ROW(Y20)-4)*10 -> 140
B21: =Neu!B13 -> 0 | Y21: =MAX($C$3:$W$44)-(ROW(Y21)-4)*10 -> 130
Y22: =MAX($C$3:$W$44)-(ROW(Y22)-4)*10 -> 120
B23: =Neu!B14 -> 0 | Y23: =MAX($C$3:$W$44)-(ROW(Y23)-4)*10 -> 110
Y24: =MAX($C$3:$W$44)-(ROW(Y24)-4)*10 -> 100
B25: =Neu!B15 -> 0 | Y25: =MAX($C$3:$W$44)-(ROW(Y25)-4)*10 -> 90
Y26: =MAX($C$3:$W$44)-(ROW(Y26)-4)*10 -> 80
B27: =Neu!B16 -> 0 | Y27: =MAX($C$3:$W$44)-(ROW(Y27)-4)*10 -> 70
Y28: =MAX($C$3:$W$44)-(ROW(Y28)-4)*10 -> 60
B29: =Neu!B17 -> 0 | Y29: =MAX($C$3:$W$44)-(ROW(Y29)-4)*10 -> 50
Y30: =MAX($C$3:$W$44)-(ROW(Y30)-4)*10 -> 40
B31: =Neu!B18 -> 0 | Y31: =MAX($C$3:$W$44)-(ROW(Y31)-4)*10 -> 30
Y32: =MAX($C$3:$W$44)-(ROW(Y32)-4)*10 -> 20
B33: =Neu!B19 -> 0
B35: =Neu!B20 -> 0
B37: =Neu!B21 -> 0
B39: =Neu!B22 -> 0
B41: =Neu!B23 -> 0
B43: =Neu!B24 -> 0

Sheet cs_FAT
C1: Postsynaptic | AA1: taus | AC1: depression | AE1: Voltage dependence | AI1: facilitation
C2: =Neu!$B4 -> A | D2: =Neu!$B5 -> B | E2: =Neu!$B6 -> C | F2: =Neu!$B7 -> 0 | G2: =Neu!$B8 -> 0 | H2: =Neu!$B9 -> 0 | I2: =Neu!$B10 -> 0 | J2: =Neu!$B11 -> 0 | K2: =Neu!$B12 -> 0 | L2: =Neu!$B13 -> 0 | M2: =Neu!$B14 -> 0 | N2: =Neu!$B15 -> 0 | O2: =Neu!$B16 -> 0 | P2: =Neu!$B17 -> 0 | Q2: =Neu!$B18 -> 0 | R2: =Neu!$B19 -> 0 | S2: =Neu!$B20 -> 0 | T2: =Neu!$B21 -> 0 | U2: =Neu!$B22 -> 0 | V2: =Neu!$B23 -> 0 | W2: =Neu!$B24 -> 0 | AA2: u1 | AB2: u2 | AC2: ud | AD2: ur | AE2: h | AF2: s | AG2: p | AH2: tx | AI2: ion | AJ2: u
A3: Presynaptic | B3: =Neu!B4 -> A | D3: 1 | E3: 3 | X3: fast | Y3: =COUNTIF($C$3:$W$44,ROW(Z3)-2) -> 1 | Z3: =IF(ROW(AA3)-2<=MAX($C$3:$W$44),ROW(AA3)-2,"") -> 1 | AA3: 0.05
X4: slow | Y4: =COUNTIF($C$3:$W$44,ROW(Z4)-2) -> 1 | Z4: =IF(ROW(AA4)-2<=MAX($C$3:$W$44),ROW(AA4)-2,"") -> 2 | AA4: 0.05
B5: =Neu!B5 -> B | C5: 2 | Y5: =COUNTIF($C$3:$W$44,ROW(Z5)-2) -> 1 | Z5: =IF(ROW(AA5)-2<=MAX($C$3:$W$44),ROW(AA5)-2,"") -> 3 | AA5: 0.05 | AE5: -50 | AF5: 15 | AG5: 1
Y6: =COUNTIF($C$3:$W$44,ROW(Z6)-2) -> 1 | Z6: =IF(ROW(AA6)-2<=MAX($C$3:$W$44),ROW(AA6)-2,"") -> 4 | AA6: 0.05
B7: =Neu!B6 -> C | C7: 4 | Y7: =COUNTIF($C$3:$W$44,ROW(Z7)-2) -> 0 | Z7: =IF(ROW(AA7)-2<=MAX($C$3:$W$44),ROW(AA7)-2,"")
Y8: =COUNTIF($C$3:$W$44,ROW(Z8)-2) -> 0 | Z8: =IF(ROW(AA8)-2<=MAX($C$3:$W$44),ROW(AA8)-2,"")
B9: =Neu!B7 -> 0 | Y9: =COUNTIF($C$3:$W$44,ROW(Z9)-2) -> 0 | Z9: =IF(ROW(AA9)-2<=MAX($C$3:$W$44),ROW(AA9)-2,"") | AK9: if u2 is empty it is assumed equal to u1
Y10: =COUNTIF($C$3:$W$44,ROW(Z10)-2) -> 0 | Z10: =IF(ROW(AA10)-2<=MAX($C$3:$W$44),ROW(AA10)-2,"")
B11: =Neu!B8 -> 0 | Y11: =COUNTIF($C$3:$W$44,ROW(Z11)-2) -> 0 | Z11: =IF(ROW(AA11)-2<=MAX($C$3:$W$44),ROW(AA11)-2,"")
Y12: =COUNTIF($C$3:$W$44,ROW(Z12)-2) -> 0 | Z12: =IF(ROW(AA12)-2<=MAX($C$3:$W$44),ROW(AA12)-2,"")
B13: =Neu!B9 -> 0 | Y13: =COUNTIF($C$3:$W$44,ROW(Z13)-2) -> 0 | Z13: =IF(ROW(AA13)-2<=MAX($C$3:$W$44),ROW(AA13)-2,"") | AK13: Ach
Y14: =COUNTIF($C$3:$W$44,ROW(Z14)-2) -> 0 | Z14: =IF(ROW(AA14)-2<=MAX($C$3:$W$44),ROW(AA14)-2,"")
B15: =Neu!B10 -> 0 | Y15: =COUNTIF($C$3:$W$44,ROW(Z15)-2) -> 0 | Z15: =IF(ROW(AA15)-2<=MAX($C$3:$W$44),ROW(AA15)-2,"")
Y16: =COUNTIF($C$3:$W$44,ROW(Z16)-2) -> 0 | Z16: =IF(ROW(AA16)-2<=MAX($C$3:$W$44),ROW(AA16)-2,"")
B17: =Neu!B11 -> 0 | Y17: =COUNTIF($C$3:$W$44,ROW(Z17)-2) -> 0 | Z17: =IF(ROW(AA17)-2<=MAX($C$3:$W$44),ROW(AA17)-2,"")
Y18: =COUNTIF($C$3:$W$44,ROW(Z18)-2) -> 0 | Z18: =IF(ROW(AA18)-2<=MAX($C$3:$W$44),ROW(AA18)-2,"")
B19: =Neu!B12 -> 0 | Y19: =COUNTIF($C$3:$W$44,ROW(Z19)-2) -> 0 | Z19: =IF(ROW(AA19)-2<=MAX($C$3:$W$44),ROW(AA19)-2,"")
Y20: =COUNTIF($C$3:$W$44,ROW(Z20)-2) -> 0 | Z20: =IF(ROW(AA20)-2<=MAX($C$3:$W$44),ROW(AA20)-2,"")
B21: =Neu!B13 -> 0 | Y21: =COUNTIF($C$3:$W$44,ROW(Z21)-2) -> 0 | Z21: =IF(ROW(AA21)-2<=MAX($C$3:$W$44),ROW(AA21)-2,"")
Y22: =COUNTIF($C$3:$W$44,ROW(Z22)-2) -> 0 | Z22: =IF(ROW(AA22)-2<=MAX($C$3:$W$44),ROW(AA22)-2,"")
B23: =Neu!B14 -> 0 | Y23: =COUNTIF($C$3:$W$44,ROW(Z23)-2) -> 0 | Z23: =IF(ROW(AA23)-2<=MAX($C$3:$W$44),ROW(AA23)-2,"")
Y24: =COUNTIF($C$3:$W$44,ROW(Z24)-2) -> 0 | Z24: =IF(ROW(AA24)-2<=MAX($C$3:$W$44),ROW(AA24)-2,"")
B25: =Neu!B15 -> 0 | Y25: =COUNTIF($C$3:$W$44,ROW(Z25)-2) -> 0 | Z25: =IF(ROW(AA25)-2<=MAX($C$3:$W$44),ROW(AA25)-2,"")
Y26: =COUNTIF($C$3:$W$44,ROW(Z26)-2) -> 0 | Z26: =IF(ROW(AA26)-2<=MAX($C$3:$W$44),ROW(AA26)-2,"")
B27: =Neu!B16 -> 0 | Y27: =COUNTIF($C$3:$W$44,ROW(Z27)-2) -> 0 | Z27: =IF(ROW(AA27)-2<=MAX($C$3:$W$44),ROW(AA27)-2,"")
Y28: =COUNTIF($C$3:$W$44,ROW(Z28)-2) -> 0 | Z28: =IF(ROW(AA28)-2<=MAX($C$3:$W$44),ROW(AA28)-2,"")
B29: =Neu!B17 -> 0 | Y29: =COUNTIF($C$3:$W$44,ROW(Z29)-2) -> 0 | Z29: =IF(ROW(AA29)-2<=MAX($C$3:$W$44),ROW(AA29)-2,"")
Y30: =COUNTIF($C$3:$W$44,ROW(Z30)-2) -> 0 | Z30: =IF(ROW(AA30)-2<=MAX($C$3:$W$44),ROW(AA30)-2,"")
B31: =Neu!B18 -> 0 | Y31: =COUNTIF($C$3:$W$44,ROW(Z31)-2) -> 0 | Z31: =IF(ROW(AA31)-2<=MAX($C$3:$W$44),ROW(AA31)-2,"")
Y32: =COUNTIF($C$3:$W$44,ROW(Z32)-2) -> 0 | Z32: =IF(ROW(AA32)-2<=MAX($C$3:$W$44),ROW(AA32)-2,"")
B33: =Neu!B19 -> 0 | Y33: =COUNTIF($C$3:$W$44,ROW(Z33)-2) -> 0 | Z33: =IF(ROW(AA33)-2<=MAX($C$3:$W$44),ROW(AA33)-2,"")
Y34: =COUNTIF($C$3:$W$44,ROW(Z34)-2) -> 0 | Z34: =IF(ROW(AA34)-2<=MAX($C$3:$W$44),ROW(AA34)-2,"")
B35: =Neu!B20 -> 0 | Y35: =COUNTIF($C$3:$W$44,ROW(Z35)-2) -> 0 | Z35: =IF(ROW(AA35)-2<=MAX($C$3:$W$44),ROW(AA35)-2,"")
Y36: =COUNTIF($C$3:$W$44,ROW(Z36)-2) -> 0 | Z36: =IF(ROW(AA36)-2<=MAX($C$3:$W$44),ROW(AA36)-2,"")
B37: =Neu!B21 -> 0 | Y37: =COUNTIF($C$3:$W$44,ROW(Z37)-2) -> 0 | Z37: =IF(ROW(AA37)-2<=MAX($C$3:$W$44),ROW(AA37)-2,"")
Y38: =COUNTIF($C$3:$W$44,ROW(Z38)-2) -> 0 | Z38: =IF(ROW(AA38)-2<=MAX($C$3:$W$44),ROW(AA38)-2,"")
B39: =Neu!B22 -> 0 | Y39: =COUNTIF($C$3:$W$44,ROW(Z39)-2) -> 0 | Z39: =IF(ROW(AA39)-2<=MAX($C$3:$W$44),ROW(AA39)-2,"")
Y40: =COUNTIF($C$3:$W$44,ROW(Z40)-2) -> 0 | Z40: =IF(ROW(AA40)-2<=MAX($C$3:$W$44),ROW(AA40)-2,"")
...

Sheet es
C1: Postsynaptic
C2: =Neu!B4 -> A | D2: =Neu!B5 -> B | E2: =Neu!B6 -> C | F2: =Neu!B7 -> 0 | G2: =Neu!B8 -> 0 | H2: =Neu!B9 -> 0 | I2: =Neu!B10 -> 0 | J2: =Neu!B11 -> 0 | K2: =Neu!B12 -> 0 | L2: =Neu!B13 -> 0 | M2: =Neu!B14 -> 0 | N2: =Neu!B15 -> 0 | O2: =Neu!B16 -> 0 | P2: =Neu!B17 -> 0 | Q2: =Neu!$B18 -> 0 | R2: =Neu!$B19 -> 0 | S2: =Neu!$B20 -> 0 | T2: =Neu!$B21 -> 0 | U2: =Neu!$B22 -> 0 | V2: =Neu!$B23 -> 0 | W2: =Neu!$B24 -> 0
A3: Presynaptic | B3: =Neu!B4 -> A | D3: =C4 -> 0 | E3: =C5 -> 0 | F3: =C6 -> 0 | G3: =C7 -> 0 | H3: =C8 -> 0 | I3: =C9 -> 0 | J3: =C10 -> 0 | K3: =C11 -> 0 | L3: =C12 -> 0 | M3: =C13 -> 0 | N3: =C14 -> 0 | O3: =C14 -> 0 | P3: =C16 -> 0 | Q3: =C17 -> 0 | R3: =C18 -> 0 | S3: =C19 -> 0 | T3: =C20 -> 0 | U3: =C21 -> 0 | V3: =C22 -> 0 | W3: =C23 -> 0
B4: =Neu!B5 -> B | E4: =D5 -> 0 | F4: =D6 -> 0 | G4: =D7 -> 0 | H4: =D8 -> 0 | I4: =D9 -> 0 | J4: =D10 -> 0 | K4: =D11 -> 0 | L4: =D12 -> 0 | M4: =D13 -> 0 | N4: =D14 -> 0 | O4: =D15 -> 0 | P4: =D16 -> 0 | Q4: =D17 -> 0 | R4: =D18 -> 0 | S4: =D19 -> 0 | T4: =D20 -> 0 | U4: =D21 -> 0 | V4: =D22 -> 0 | W4: =D23 -> 0
B5: =Neu!B6 -> C | F5: =E6 -> 0 | G5: =E7 -> 0 | H5: =E8 -> 0 | I5: =E9 -> 0 | J5: =E10 -> 0 | K5: =E11 -> 0 | L5: =E12 -> 0 | M5: =E13 -> 0 | N5: =E14 -> 0 | O5: =E15 -> 0 | P5: =E16 -> 0 | Q5: =E17 -> 0 | R5: =E18 -> 0 | S5: =E19 -> 0 | T5: =E20 -> 0 | U5: =E21 -> 0 | V5: =E22 -> 0 | W5: =E23 -> 0
B6: =Neu!B7 -> 0 | G6: =F7 -> 0 | H6: =F8 -> 0 | I6: =F9 -> 0 | J6: =F10 -> 0 | K6: =F11 -> 0 | L6: =F12 -> 0 | M6: =F13 -> 0 | N6: =F14 -> 0 | O6: =F15 -> 0 | P6: =F16 -> 0 | Q6: =F17 -> 0 | R6: =F18 -> 0 | S6: =F19 -> 0 | T6: =F20 -> 0 | U6: =F21 -> 0 | V6: =F22 -> 0 | W6: =F23 -> 0
B7: =Neu!B8 -> 0 | H7: =G8 -> 0 | I7: =G9 -> 0 | J7: =G10 -> 0 | K7: =G11 -> 0 | L7: =G12 -> 0 | M7: =G13 -> 0 | N7: =G14 -> 0 | O7: =G15 -> 0 | P7: =G16 -> 0 | Q7: =G17 -> 0 | R7: =G18 -> 0 | S7: =G19 -> 0 | T7: =G20 -> 0 | U7: =G21 -> 0 | V7: =G22 -> 0 | W7: =G23 -> 0
B8: =Neu!B9 -> 0 | I8: =H9 -> 0 | J8: =H10 -> 0 | K8: =H11 -> 0 | L8: =H12 -> 0 | M8: =H13 -> 0 | N8: =H14 -> 0 | O8: =H15 -> 0 | P8: =H16 -> 0 | Q8: =H17 -> 0 | R8: =H18 -> 0 | S8: =H19 -> 0 | T8: =H20 -> 0 | U8: =H21 -> 0 | V8: =H22 -> 0 | W8: =H23 -> 0
B9: =Neu!B10 -> 0 | J9: =I10 -> 0 | K9: =I11 -> 0 | L9: =I12 -> 0 | M9: =I13 -> 0 | N9: =I14 -> 0 | O9: =I15 -> 0 | P9: =I16 -> 0 | Q9: =I17 -> 0 | R9: =I18 -> 0 | S9: =I19 -> 0 | T9: =I20 -> 0 | U9: =I21 -> 0 | V9: =I22 -> 0 | W9: =I23 -> 0
B10: =Neu!B11 -> 0 | K10: =J11 -> 0 | L10: =J12 -> 0 | M10: =J13 -> 0 | N10: =J14 -> 0 | O10: =J15 -> 0 | P10: =J16 -> 0 | Q10: =J17 -> 0 | R10: =J18 -> 0 | S10: =J19 -> 0 | T10: =J20 -> 0 | U10: =J21 -> 0 | V10: =J22 -> 0 | W10: =J23 -> 0
B11: =Neu!B12 -> 0 | L11: =K12 -> 0 | M11: =K13 -> 0 | N11: =K14 -> 0 | O11: =K15 -> 0 | P11: =K16 -> 0 | Q11: =K17 -> 0 | R11: =K18 -> 0 | S11: =K19 -> 0 | T11: =K20 -> 0 | U11: =K21 -> 0 | V11: =K22 -> 0 | W11: =K23 -> 0
B12: =Neu!B13 -> 0 | M12: =L13 -> 0 | N12: =L14 -> 0 | O12: =L15 -> 0 | P12: =L16 -> 0 | Q12: =L17 -> 0 | R12: =L18 -> 0 | S12: =L19 -> 0 | T12: =L20 -> 0 | U12: =L21 -> 0 | V12: =L22 -> 0 | W12: =L23 -> 0
B13: =Neu!B14 -> 0 | N13: =M14 -> 0 | O13: =M15 -> 0 | P13: =M16 -> 0 | Q13: =M17 -> 0 | R13: =M18 -> 0 | S13: =M19 -> 0 | T13: =M20 -> 0 | U13: =M21 -> 0 | V13: =M22 -> 0 | W13: =M23 -> 0
B14: =Neu!B15 -> 0 | O14: =N15 -> 0 | P14: =N16 -> 0 | Q14: =N17 -> 0 | R14: =N18 -> 0 | S14: =N19 -> 0 | T14: =N20 -> 0 | U14: =N21 -> 0 | V14: =N22 -> 0 | W14: =N23 -> 0
B15: =Neu!B16 -> 0 | P15: =O16 -> 0 | Q15: =O17 -> 0 | R15: =O18 -> 0 | S15: =O19 -> 0 | T15: =O20 -> 0 | U15: =O21 -> 0 | V15: =O22 -> 0 | W15: =O23 -> 0
B16: =Neu!B17 -> 0 | Q16: =P17 -> 0 | R16: =P18 -> 0 | S16: =P19 -> 0 | T16: =P20 -> 0 | U16: =P21 -> 0 | V16: =P22 -> 0 | W16: =P23 -> 0
B17: =Neu!B18 -> 0 | R17: =Q18 -> 0 | S17: =Q19 -> 0 | T17: =Q20 -> 0 | U17: =Q21 -> 0 | V17: =Q22 -> 0 | W17: =Q23 -> 0
B18: =Neu!B19 -> 0 | S18: =R19 -> 0 | T18: =R20 -> 0 | U18: =R21 -> 0 | V18: =R22 -> 0 | W18: =R23 -> 0
B19: =Neu!B20 -> 0 | T19: =S20 -> 0 | U19: =S21 -> 0 | V19: =S22 -> 0 | W19: =S23 -> 0
B20: =Neu!B21 -> 0 | U20: =T21 -> 0 | V20: =T22 -> 0 | W20: =T23 -> 0
B21: =Neu!B22 -> 0 | V21: =U22 -> 0 | W21: =U23 -> 0
B22: =Neu!B23 -> 0 | W22: =V23 -> 0
B23: =Neu!B24 -> 0

Sheet noise
B1: Amplitude | C1: step size | D1: jitter in step size
A2: votage-dependent conductance (.vdg) | B2: 0 | C2: 200 | D2: 10
A3: chemical synapse (.cs) | B3: 0 | C3: 200 | D3: 10
A4: electrical synapse (.es) | B4: 0 | C4: 200 | D4: 10
