Workbook

Sheet Neu
D1: File | E1: leak | G1: Na | AH1: K | BI1: KA | CJ1: CaL | DK1: CaR | EL1: CaN | FM1: Kca | GN1: KTEA | HO1: Napp | IP1: HCN | JQ1: K_pp
E2: vdg | G2: vdg | J2: A | V2: B | AH2: vdg | AK2: A | AW2: B | BI2: vdg | BL2: A | BX2: B | CJ2: vdg | CM2: A | CY2: B | DK2: vdg | DN2: A | DZ2: B | EL2: vdg | EO2: A | FA2: B | FM2: vdg | FP2: A | GB2: B | GN2: vdg | GQ2: A | HC2: B | HO2: vdg | HR2: A | ID2: B | IP2: vdg | IS2: A | JE2: B | JQ2: vdg | JT2: A | KF2: B
B3: Name | C3: Template | D3: cm | E3: g | F3: E | G3: g | H3: p | I3: E | J3: An | K3: h | L3: s | M3: p | N3: tmx | O3: tmin | P3: th1 | Q3: ts1 | R3: tp1 | S3: th2 | T3: ts2 | U3: tp2 | V3: Bn | W3: h | X3: s | Y3: p | Z3: tmx | AA3: tmin | AB3: th1 | AC3: ts1 | AD3: tp1 | AE3: th2 | AF3: ts2 | AG3: tp2 | AH3: g | AI3: p | AJ3: E | AK3: An | AL3: h | AM3: s | AN3: p | AO3: tmx | AP3: tmin | AQ3: th1 | AR3: ts1 | AS3: tp1 | AT3: th2 | AU3: ts2 | AV3: tp2 | AW3: Bn | AX3: h | AY3: s | AZ3: p | BA3: tmx | BB3: tmin | BC3: th1 | BD3: ts1 | BE3: tp1 | BF3: th2 | BG3: ts2 | BH3: tp2 | BI3: g | BJ3: p | BK3: E | BL3: An | BM3: h | BN3: s | BO3: p | BP3: tmx | BQ3: tmin | BR3: th1 | BS3: ts1 | BT3: tp1 | BU3: th2 | BV3: ts2 | BW3: tp2 | BX3: Bn | BY3: h | BZ3: s | CA3: p | CB3: tmx | CC3: tmin | CD3: th1 | CE3: ts1 | CF3: tp1 | CG3: th2 | CH3: ts2 | CI3: tp2 | CJ3: g | CK3: p | CL3: E | CM3: An | CN3: h | CO3: s | CP3: p | CQ3: tmx | CR3: tmin | CS3: th1 | CT3: ts1 | CU3: tp1 | CV3: th2 | CW3: ts2 | CX3: tp2 | CY3: Bn | CZ3: h | DA3: s | DB3: p | DC3: tmx | DD3: tmin | DE3: th1 | DF3: ts1 | DG3: tp1 | DH3: th2 | DI3: ts2 | DJ3: tp2 | DK3: g | DL3: p | DM3: E | DN3: An | DO3: h | DP3: s | DQ3: p | DR3: tmx | DS3: tmin | DT3: th1 | DU3: ts1 | DV3: tp1 | DW3: th2 | DX3: ts2 | DY3: tp2 | DZ3: Bn | EA3: h | EB3: s | EC3: p | ED3: tmx | EE3: tmin | EF3: th1 | EG3: ts1 | EH3: tp1 | EI3: th2 | EJ3: ts2 | EK3: tp2 | EL3: g | EM3: p | EN3: E | EO3: An | EP3: h | EQ3: s | ER3: p | ES3: tmx | ET3: tmin | EU3: th1 | EV3: ts1 | EW3: tp1 | EX3: th2 | EY3: ts2 | EZ3: tp2 | FA3: Bn | FB3: h | FC3: s | FD3: p | FE3: tmx | FF3: tmin | FG3: th1 | FH3: ts1 | FI3: tp1 | FJ3: th2 | FK3: ts2 | FL3: tp2 | FM3: g | FN3: p | FO3: E | FP3: An | FQ3: h | FR3: s | FS3: p | FT3: tmx | FU3: tmin | FV3: th1 | FW3: ts1 | FX3: tp1 | FY3: th2 | FZ3: ts2 | GA3: tp2 | GB3: Bn | GC3: h | GD3: s | GE3: p | GF3: tmx | GG3: tmin | GH3: th1 | GI3: ts1 | GJ3: tp1 | GK3: th2 | GL3: ts2 | GM3: tp2 | GN3: g | GO3: p | GP3: E | GQ3: An | GR3: h | GS3: s | GT3: p | GU3: tmx | GV3: tmin | GW3: th1 | GX3: ts1 | GY3: tp1 | GZ3: th2 | HA3: ts2 | HB3: tp2 | HC3: Bn | HD3: h | HE3: s | HF3: p | HG3: tmx | HH3: tmin | HI3: th1 | HJ3: ts1 | HK3: tp1 | HL3: th2 | HM3: ts2 | HN3: tp2 | HO3: g | HP3: p | HQ3: E | HR3: An | HS3: h | HT3: s | HU3: p | HV3: tmx | HW3: tmin | HX3: th1 | HY3: ts1 | HZ3: tp1 | IA3: th2 | IB3: ts2 | IC3: tp2 | ID3: Bn | IE3: h | IF3: s | IG3: p | IH3: tmx | II3: tmin | IJ3: th1 | IK3: ts1 | IL3: tp1 | IM3: th2 | IN3: ts2 | IO3: tp2 | IP3: g | IQ3: p | IR3: E | IS3: An | IT3: h | IU3: s | IV3: p | IW3: tmx | IX3: tmin | IY3: th1 | IZ3: ts1 | JA3: tp1 | JB3: th2 | JC3: ts2 | JD3: tp2 | JE3: Bn | JF3: h | JG3: s | JH3: p | JI3: tmx | JJ3: tmin | JK3: th1 | JL3: ts1 | JM3: tp1 | JN3: th2 | JO3: ts2 | JP3: tp2 | JQ3: g | JR3: p | JS3: E | JT3: An | JU3: h | JV3: s | JW3: p | JX3: tmx | JY3: tmin | JZ3: th1 | KA3: ts1 | KB3: tp1 | KC3: th2 | KD3: ts2 | KE3: tp2 | KF3: Bn | KG3: h | KH3: s | KI3: p | KJ3: tmx | KK3: tmin | KL3: th1 | KM3: ts1 | KN3: tp1 | KO3: th2 | KP3: ts2 | KQ3: tp2
A4: =Neu!B4 -> B51s | B4: B51s | D4: 0.002 | E4: 0.046 | F4: -63 | G4: 50 | H4: 3 | I4: 60 | J4: 0 | K4: -16.6 | L4: 6.66 | M4: 1 | N4: 0.035 | O4: 0.00024 | P4: -30 | Q4: 5.382 | R4: 1 | S4: -17 | T4: -9.9 | U4: 1 | V4: 0 | W4: -24 | X4: 3.807 | Y4: 1 | Z4: 0.042 | AA4: 0.001 | AB4: -32 | AC4: 14.472 | AD4: 1 | AH4: 1.9 | AI4: 1 | AJ4: -70 | AK4: 0 | AL4: 2 | AM4: 8 | AN4: 1 | AO4: 0.01 | AW4: 0.364 | AX4: -10.5 | AY4: 4.6 | AZ4: 1 | BA4: 3 | BB4: 0.26 | BC4: -14 | BD4: 7 | BE4: 1 | BI4: 1.4 | BJ4: 1 | BK4: -70 | BL4: 0 | BM4: -29 | BN4: 5.6 | BO4: 1 | BP4: 0.03 | BQ4: 0.001 | BR4: -30 | BS4: 5.7 | BT4: 1 | BX4: 0 | BY4: -56 | BZ4: 4.3 | CA4: 1 | CB4: 0.035 | CJ4: 0.23 | CK4: 1 | CL4: 60 | CM4: 0 | CN4: -8 | CO4: 7.89 | CP4: 1 | CQ4: 0.06 | CR4: 0.002 | CS4: -15 | CT4: -13 | CU4: 1 | CV4: 5 | CW4: 13 | CX4: 1 | CY4: 0 | CZ4: -22 | DA4: 0.95 | DB4: 1 | DC4: 0.12 | DK4: 0.4 | DL4: 1 | DM4: 60 | DN4: 0 | DO4: 2 | DP4: 7.25 | DQ4: 1 | DR4: 0.03 | DS4: 0.001 | DT4: -10 | DU4: -5.3 | DV4: 1 | DW4: 14 | DX4: 5.6 | DY4: 1 | DZ4: 0 | EA4: -18.2 | EB4: 1.5 | EC4: 1 | ED4: 0.08 | EE4: 0.038 | EF4: 0 | EG4: 5 | EH4: 1 | FM4: 2.3 | FN4: 1 | FO4: -70 | FP4: 0 | FQ4: -8 | FR4: 8 | FS4: 1 | FT4: 0.009 | GN4: 0.15 | GO4: 1 | GP4: -70 | GQ4: 0 | GR4: 12 | GS4: 0.24 | GT4: 1 | GU4: 0.01 | HC4: 0.1 | HD4: -35 | HE4: 5 | HF4: 1 | HG4: 0.8 | HH4: 0.08 | HI4: 18 | HJ4: -2 | HK4: 1 | HL4: 20 | HM4: 2 | HN4: 1 | HO4: 0.1 | HP4: 1 | HQ4: 60 | HR4: 0 | HS4: -48 | HT4: 3 | HU4: 1 | HV4: 0.01 | ID4: 0.6 | IE4: -62 | IF4: 1 | IG4: 1 | IH4: 2.5 | II4: 0.25 | IJ4: -55 | IK4: -1.5 | IL4: 1 | IM4: -42 | IN4: 1.5 | IO4: 1
A5: =Neu!B5 -> B64s | B5: B64s | D5: 0.0023 | E5: 0.065 | F5: -63 | G5: =G4 -> 50 | H5: 3 | I5: 60 | J5: 0 | K5: =K4 -> -16.6 | L5: 6.66 | M5: 1 | N5: =N4 -> 0.035 | O5: 0.00024 | P5: =P4 -> -30 | Q5: 5.382 | R5: 1 | S5: =S4 -> -17 | T5: -9.9 | U5: 1 | V5: 0 | W5: =W4 -> -24 | X5: 3.807 | Y5: 1 | Z5: 0.042 | AA5: 0.001 | AB5: -32 | AC5: 14.472 | AD5: 1 | AH5: 3.1 | AI5: 1 | AJ5: -70 | AK5: 0 | AL5: 2 | AM5: =AM4 -> 8 | AN5: 1 | AO5: 0.01 | AW5: 0.4 | AX5: -10.5 | AY5: 4.5 | AZ5: 1 | BA5: 5.8 | BB5: 0.18 | BC5: -60 | BD5: 15 | BE5: 1 | BI5: 0.9 | BJ5: 1 | BK5: -70 | BL5: 0 | BM5: -11 | BN5: 11.2 | BO5: 1 | BP5: 0.02 | BQ5: 0.002 | BR5: -20 | BS5: 5.7 | BT5: 1 | BX5: 0 | BY5: -46.3 | BZ5: 7.38 | CA5: 1 | CB5: 0.035 | CJ5: 0.178 | CK5: 1 | CL5: 60 | CM5: 0 | CN5: -5 | CO5: 12.1 | CP5: 1 | CQ5: 0.0088 | CR5: 0.002 | CS5: 0 | CT5: -4 | CU5: 1 | CV5: 35 | CW5: =-CT5 -> 4 | CX5: 1 | CY5: 0 | CZ5: -26.5 | DA5: 7.47 | DB5: 1 | DC5: 0.14 | DK5: 0.7 | DL5: 1 | DM5: 60 | DN5: 0 | DO5: 2 | DP5: 8.2 | DQ5: 1 | DR5: 0.02 | DS5: 0.001 | DT5: 13 | DU5: -12.7 | DV5: 1 | DW5: 25 | DX5: 13 | DY5: 1 | DZ5: 0 | EA5: -25 | EB5: 6.71 | EC5: 1 | ED5: 0.036 | EE5: 0.025 | EF5: 0 | EG5: 0.46 | EH5: 1 | FM5: 0 | FN5: =FN4 -> 1 | FO5: =FO4 -> -70 | FP5: =FP4 -> 0 | FQ5: =FQ4 -> -8 | FR5: =FR4 -> 8 | FS5: =FS4 -> 1 | FT5: =FT4 -> 0.009 | GN5: 0.26 | GO5: 1 | GP5: -70 | GQ5: 0 | GR5: 9 | GS5: 4.6 | GT5: 1 | GU5: 0.01 | HC5: 0 | HD5: -5 | HE5: 5 | HF5: 1 | HG5: 1.1 | HH5: 0.2 | HI5: -13 | HJ5: -2 | HK5: 1 | HL5: -6 | HM5: 2 | HN5: 1 | HO5: 0.12 | HP5: =HP4 -> 1 | HQ5: =HQ4 -> 60 | HR5: =HR4 -> 0 | HS5: -37 | HT5: 4.5 | HU5: =HU4 -> 1 | HV5: =HV4 -> 0.01 | ID5: =ID4 -> 0.6 | IE5: =IE4 -> -62 | IF5: =IF4 -> 1 | IG5: =IG4 -> 1 | IH5: =IH4 -> 2.5 | II5: =II4 -> 0.25 | IJ5: =IJ4 -> -55 | IK5: =IK4 -> -1.5 | ... IO5: =IO4 -> 1
A6: =Neu!B6 -> B8 | B6: B8 | D6: 0.01 | E6: 0 | F6: -63 | G6: =G4 -> 50 | H6: 3 | I6: 60 | J6: 0 | K6: =K4 -> -16.6 | L6: 6.66 | M6: 1 | N6: =N4 -> 0.035 | O6: 0.00024 | P6: =P4 -> -30 | Q6: 5.382 | R6: 1 | S6: =S4 -> -17 | T6: -9.9 | U6: 1 | V6: 0 | W6: =W4 -> -24 | X6: 3.807 | Y6: 1 | Z6: 0.042 | AA6: 0.001 | AB6: -32 | AC6: 14.472 | AD6: 1 | AH6: 3.9 | AI6: 1 | AJ6: -70 | AK6: 0 | AL6: =AL4 -> 2 | AM6: =AM4 -> 8 | AN6: 1 | AO6: 0.01 | AW6: 0.274 | AX6: -13 | AY6: 5.7 | AZ6: 1 | BA6: 2 | BB6: 0.15 | BC6: -14 | BD6: 8 | BE6: 1 | BI6: 3.2 | BJ6: 1 | BK6: -70 | BL6: 0 | BM6: -6 | BN6: 10 | BO6: 1 | BP6: 0.025 | BQ6: 0.007 | BR6: -20 | BS6: 6 | BT6: 1 | BX6: 0 | BY6: -51 | BZ6: 9.4 | CA6: 1 | CB6: 0.14 | CJ6: 0.68 | CK6: 1 | CL6: 60 | CM6: 0 | CN6: -14 | CO6: 6.5 | CP6: 1 | CQ6: 0.08 | CR6: 0.002 | CS6: -20.5 | CT6: -13 | CU6: 1 | CV6: 15 | CW6: 13 | CX6: 1 | CY6: 0 | CZ6: -34.4 | DA6: 6.26 | DB6: 1 | DC6: 0.035 | DK6: 2.4 | DL6: 1 | DM6: 60 | DN6: 0 | DO6: 2 | DP6: 5.7 | DQ6: 1 | DR6: 0.076 | DS6: 0.001 | DT6: -1 | DU6: -7.2 | DV6: 1 | DW6: 23 | DX6: 7.2 | DY6: 1 | DZ6: 0 | EA6: -25 | EB6: 5.95 | EC6: 1 | ED6: 0.043 | EE6: 0.025 | EF6: 1 | EG6: 6 | EH6: 1 | FM6: 1.1 | FN6: 1 | FO6: =FO4 -> -70 | FP6: =FP4 -> 0 | FQ6: 5 | FR6: 9 | FS6: =FS4 -> 1 | FT6: =FT4 -> 0.009 | GN6: 0.85 | GO6: 1 | GP6: -70 | GQ6: 0 | GR6: 7 | GS6: 6.1 | GT6: 1 | GU6: 0.01 | HC6: 0.4 | HD6: -5 | HE6: 5 | HF6: 1 | HG6: 1.4 | HH6: 0.2 | HI6: -2 | HJ6: -1.5 | HK6: 1 | HL6: 3.5 | HM6: 1.5 | HN6: 1 | HO6: 0.12 | HP6: =HP4 -> 1 | HQ6: =HQ4 -> 60 | HR6: =HR4 -> 0 | HS6: -48 | HT6: =HT4 -> 3 | HU6: =HU4 -> 1 | HV6: =HV4 -> 0.01 | ID6: =ID4 -> 0.6 | IE6: =IE4 -> -62 | IF6: =IF4 -> 1 | IG6: =IG4 -> 1 | IH6: =IH4 -> 2.5 | II6: =II4 -> 0.25 | IJ6: =IJ4 -> -55 | IK6: =IK4 -> -1.5 | ... IO6: =IO4 -> 1 | IP6: 0.085 | IQ6: 1 | IR6: -40 | IS6: 0 | IT6: -68 | IU6: -4.8 | IV6: 1 | IW6: 14 | IX6: 0.9 | IY6: -73 | IZ6: -9 | JA6: 1 | JB6: -75 | JC6: 9 | JD6: 1
A7: =Neu!B7 -> 0
A8: =Neu!B8 -> 0
A9: =Neu!B9 -> 0
A10: =Neu!B10 -> 0
A11: =Neu!B11 -> 0
A12: =Neu!B12 -> 0
A13: =Neu!B13 -> 0
A14: =Neu!B14 -> 0
A15: =Neu!B15 -> 0
A16: =Neu!B16 -> 0
A17: =Neu!B17 -> 0
A18: =Neu!B18 -> 0
... A24: =Neu!B24 -> 0
D29: Ion pools | O29: Conductance to ion | Z29: Ion to conductance | BD29: Initial voltage
D30: Name | E30: ion | F30: K1 | G30: K2 | H30: ion | I30: K1 | J30: K2 | K30: ion | L30: K1 | M30: K2 | O30: Name | P30: ch | Q30: ion | R30: ch | S30: ion | T30: ch | U30: ion | V30: ch | W30: ion | Z30: Name | AA30: ion | AB30: ch | AC30: opt1 | AD30: opt2 | AE30: p1 | AF30: p2 | AG30: b | AH30: ion | AI30: ch | AJ30: opt1 | AK30: opt2 | AL30: p1 | AM30: p2 | AN30: b | AO30: ion | AP30: ch | AQ30: opt1 | AR30: opt2 | AS30: p1 | AT30: p2 | AU30: b | AV30: ion | AW30: ch | AX30: opt1 | AY30: opt2 | AZ30: p1 | BA30: p2 | BB30: b | BD30: Name | BE30: mV
D31: =Neu!$B4 -> B51s | E31: Ca | F31: 8 | G31: 1 | O31: =Neu!$B4 -> B51s | P31: CaR | Q31: Ca | R31: CaL | S31: Ca | Z31: =Neu!$B4 -> B51s | AA31: Ca | AB31: Kca | AC31: 1 | AD31: 1 | AE31: 20 | AF31: 0 | BD31: =Neu!$B4 -> B51s | BE31: -80
D32: =Neu!$B5 -> B64s | E32: Ca | F32: =F$31 -> 8 | G32: =G$31 -> 1 | O32: =Neu!$B5 -> B64s | P32: CaR | Q32: Ca | R32: CaL | S32: Ca | Z32: =Neu!$B5 -> B64s | AA32: Ca | AB32: Kca | AC32: 1 | AD32: 1 | AE32: =AE31 -> 20 | AF32: 0 | BD32: =Neu!$B5 -> B64s | BE32: -80
D33: =Neu!$B6 -> B8 | E33: Ca | F33: 80 | G33: =G$31 -> 1 | O33: =Neu!$B6 -> B8 | P33: CaR | Q33: Ca | R33: CaL | S33: Ca | Z33: =Neu!$B6 -> B8 | AA33: Ca | AB33: Kca | AC33: =AC31 -> 1 | AD33: =AD31 -> 1 | AE33: 0.7 | AF33: 0 | BD33: =Neu!$B6 -> B8 | BE33: -80
D34: =Neu!$B7 -> 0 | O34: =Neu!$B7 -> 0 | Z34: =Neu!$B7 -> 0 | BD34: =Neu!$B7 -> 0
D35: =Neu!$B8 -> 0 | O35: =Neu!$B8 -> 0 | Z35: =Neu!$B8 -> 0 | BD35: =Neu!$B8 -> 0
D36: =Neu!$B9 -> 0 | O36: =Neu!$B9 -> 0 | Z36: =Neu!$B9 -> 0 | BD36: =Neu!$B9 -> 0
D37: =Neu!$B10 -> 0 | O37: =Neu!$B10 -> 0 | Z37: =Neu!$B10 -> 0 | BD37: =Neu!$B10 -> 0
D38: =Neu!$B11 -> 0 | O38: =Neu!$B11 -> 0 | Z38: =Neu!$B11 -> 0 | BD38: =Neu!$B11 -> 0
D39: =Neu!$B12 -> 0 | O39: =Neu!$B12 -> 0 | Z39: =Neu!$B12 -> 0 | BD39: =Neu!$B12 -> 0
D40: =Neu!$B13 -> 0 | O40: =Neu!$B13 -> 0 | Z40: =Neu!$B13 -> 0 | BD40: =Neu!$B13 -> 0
D41: =Neu!$B14 -> 0 | O41: =Neu!$B14 -> 0 | Z41: =Neu!$B14 -> 0 | BD41: =Neu!$B14 -> 0
D42: =Neu!$B15 -> 0 | O42: =Neu!$B15 -> 0 | Z42: =Neu!$B15 -> 0 | BD42: =Neu!$B15 -> 0
D43: =Neu!$B16 -> 0 | O43: =Neu!$B16 -> 0 | Z43: =Neu!$B16 -> 0 | BD43: =Neu!$B16 -> 0
D44: =Neu!$B17 -> 0 | O44: =Neu!$B17 -> 0 | Z44: =Neu!$B17 -> 0 | BD44: =Neu!$B17 -> 0
D45: =Neu!$B18 -> 0 | O45: =Neu!$B18 -> 0 | Z45: =Neu!$B18 -> 0 | BD45: =Neu!$B18 -> 0
... D51: =Neu!$B24 -> 0 | O51: =Neu!$B24 -> 0 | Z51: =Neu!$B24 -> 0 | BD51: =Neu!$B24 -> 0
F52: 40 | I52: 0.3 | J52: 9 | AE52: 0.7 | AL52: 1.5
AE53: 0.1 | AL53: 0.5
F54: d(ion)/dt = K1*(K2*sum(Ivd) - ion) | AC54: opt1 1: | AD54: fBr = BR | AG54: channel requires ion | AM54: opt2 1: | AN54: dBR/dt = (ion - BR)/p1 initial: p2
...

Sheet rockon.smu
F1: syntax | L1: example variables | M1: IVDxREG | N1: currrent by conductance and regulation | T1: example synapses
A2: smu | B2: name | C2: rockon | D2: graph | E2: 1 | F2: conductance | G2: variable.conductance.neuron | M2: V | N2: voltage | Q2: Ics | R2: chem syn current | T2: f_exc | U2: fast excitatory
B3: duration | C3: 20 | D3: store | E3: 1 | F3: example | G3: Ivd.Na.N1 | I3: fBR | J3: fBR.ion.ch.neuron | M3: Ivd | N3: current by voltage gated conductance | Q3: Cion | R3: amount of ion | T3: s_exc | U3: slow excitatory
B4: stepsize | C4: 1e-05 | D4: method | E4: 1 | F4: neuron | G4: variable.neuron | I4: synapse | J4: variable.pre.post.type | M4: A | N4: activation of conductance | Q4: Ies | R4: elec syn current | T4: f_inh | U4: fast inhibitory
B5: red indicates simlation longer than graph duration | F5: example | G5: V.N1 | I5: example | J5: Ics.N1.N4.f_exc | M5: B | N5: Inactivation of conductance | Q5: slex | R5: trt current | T5: s_inh | U5: slow inhibitory
A6: graph (ous) | J6: Ies.N1.N4 | M6: sIVD_reg | N6: for total current
B7: time | G7: variable 1 | L7: variable 2 | Q7: variable 3 | V7: variable 4
A8: Size | B8: variable | C8: # ticks | D8: start | E8: stop | F8: color | G8: variable | H8: # ticks | I8: min | J8: max | K8: color | L8: variable | M8: # ticks | N8: min | O8: max | P8: color | Q8: variable | R8: # ticks | S8: min | T8: max | U8: color | V8: variable | W8: # ticks | X8: min | Y8: max | Z8: color
A9: 1 | B9: time | C9: 20 | D9: 0 | E9: 20 | F9: red | G9: V.B51s | H9: 8 | I9: -90 | J9: 70 | K9: red
A12: 3 | B12: time | C12: 20 | D12: 0 | E12: 20 | F12: green | G12: Ivd.CaL.B51s | H12: 10 | I12: -30 | J12: 0 | K12: red | L12: Ivd.CaR.B51s | M12: 10 | N12: -30 | O12: 0 | P12: green
A25: stimulation (.trt) | L25: output variables
B26: Current injection | G26: Voltage clamp | L26: all | M26: type "all" in first cell to output all graphed variables or type individual channels
B27: neuron | C27: start | D27: stop | E27: magnitude | G27: neuron | H27: start | I27: stop | J27: potential
B28: B51s | C28: 0 | D28: 90 | E28: -0.79
B29: B64s | C29: 0 | D29: 90 | E29: -1.186
B30: B8 | C30: 0 | D30: 90 | E30: -3.1652
B31: B51s | C31: 3 | D31: 4 | E31: 3
B32: B64s | C32: 3 | D32: 4 | E32: =E31 -> 3
B33: B8 | C33: 3 | D33: 4 | E33: =E31 -> 3

Sheet rockon2.smu
F1: syntax | L1: example variables | M1: IVDxREG | N1: currrent by conductance and regulation | T1: example synapses
A2: smu | B2: name | C2: rockon2 | D2: graph | E2: 1 | F2: conductance | G2: variable.conductance.neuron | M2: V | N2: voltage | Q2: Ics | R2: chem syn current | T2: f_exc | U2: fast excitatory
B3: duration | C3: 4 | D3: store | E3: 1 | F3: example | G3: Ivd.Na.N1 | I3: fBR | J3: fBR.ion.ch.neuron | M3: Ivd | N3: current by voltage gated conductance | Q3: Cion | R3: amount of ion | T3: s_exc | U3: slow excitatory
B4: stepsize | C4: 1e-05 | D4: method | E4: 1 | F4: neuron | G4: variable.neuron | I4: synapse | J4: variable.pre.post.type | M4: A | N4: activation of conductance | Q4: Ies | R4: elec syn current | T4: f_inh | U4: fast inhibitory
B5: red indicates simlation longer than graph duration | F5: example | G5: V.N1 | I5: example | J5: Ics.N1.N4.f_exc | M5: B | N5: Inactivation of conductance | Q5: slex | R5: trt current | T5: s_inh | U5: slow inhibitory
A6: graph (ous) | J6: Ies.N1.N4 | M6: sIVD_reg | N6: for total current
B7: time | G7: variable 1 | L7: variable 2 | Q7: variable 3 | V7: variable 4
A8: Size | B8: variable | C8: # ticks | D8: start | E8: stop | F8: color | G8: variable | H8: # ticks | I8: min | J8: max | K8: color | L8: variable | M8: # ticks | N8: min | O8: max | P8: color | Q8: variable | R8: # ticks | S8: min | T8: max | U8: color | V8: variable | W8: # ticks | X8: min | Y8: max | Z8: color
A9: 3 | B9: V.B51s | C9: 15 | D9: -90 | E9: 60 | F9: red | G9: Ivd.Napp.B51s | H9: 10 | I9: -10 | J9: 0 | K9: red
A10: 3 | B10: V.B64s | C10: 15 | D10: -90 | E10: 60 | F10: green | G10: Ivd.Napp.B64s | H10: 10 | I10: -10 | J10: 0 | K10: green
A25: stimulation (.trt) | L25: output variables
B26: Current injection | G26: Voltage clamp | L26: all | M26: type "all" in first cell to output all graphed variables or type individual channels
B27: neuron | C27: start | D27: stop | E27: magnitude | G27: neuron | H27: start | I27: stop | J27: potential
B28: B51s | C28: 0 | D28: 90 | E28: -0.523
B29: B64s | C29: 0 | D29: 90 | E29: -2.16
B30: B8 | C30: 0 | D30: 90 | E30: -2.09
B31: B51s | C31: 3 | D31: 4 | E31: 3
B32: B64s | C32: 3 | D32: 4 | E32: =E31 -> 3
B33: B8 | C33: 3 | D33: 4 | E33: =E31 -> 3

Sheet threshold.smu
F1: syntax | L1: example variables | M1: IVDxREG | N1: currrent by conductance and regulation | T1: example synapses
A2: smu | B2: name | C2: threshold | D2: graph | E2: 1 | F2: conductance | G2: variable.conductance.neuron | M2: V | N2: voltage | Q2: Ics | R2: chem syn current | T2: f_exc | U2: fast excitatory
B3: duration | C3: 30 | D3: store | E3: 1 | F3: example | G3: Ivd.Na.N1 | I3: fBR | J3: fBR.ion.ch.neuron | M3: Ivd | N3: current by voltage gated conductance | Q3: Cion | R3: amount of ion | T3: s_exc | U3: slow excitatory
B4: stepsize | C4: 1e-05 | D4: method | E4: 1 | F4: neuron | G4: variable.neuron | I4: synapse | J4: variable.pre.post.type | M4: A | N4: activation of conductance | Q4: Ies | R4: elec syn current | T4: f_inh | U4: fast inhibitory
B5: red indicates simlation longer than graph duration | F5: example | G5: V.N1 | I5: example | J5: Ics.N1.N4.f_exc | M5: B | N5: Inactivation of conductance | Q5: slex | R5: trt current | T5: s_inh | U5: slow inhibitory
A6: graph (ous) | J6: Ies.N1.N4 | M6: sIVD_reg | N6: for total current
B7: time | G7: variable 1 | L7: variable 2 | Q7: variable 3 | V7: variable 4
A8: Size | B8: variable | C8: # ticks | D8: start | E8: stop | F8: color | G8: variable | H8: # ticks | I8: min | J8: max | K8: color | L8: variable | M8: # ticks | N8: min | O8: max | P8: color | Q8: variable | R8: # ticks | S8: min | T8: max | U8: color | V8: variable | W8: # ticks | X8: min | Y8: max | Z8: color
A9: 2 | B9: time | C9: 15 | D9: 0 | E9: 30 | F9: red | G9: V.B51s | H9: 14 | I9: -90 | J9: 50 | K9: red
A10: 3 | B10: time | C10: 15 | D10: 0 | E10: 30 | F10: cyan | G10: IVDxREG.Kca.B51s | H10: 10 | I10: 0 | J10: 100 | K10: red | L10: Cion.Ca2.B51s | M10: 10 | N10: 0 | O10: 100 | P10: white
A11: 1 | B11: time | C11: 15 | D11: 0 | E11: 30 | F11: red | G11: sIex.B51s | H11: 7 | I11: -3 | J11: 4 | K11: red
A25: stimulation (.trt) | L25: output variables
B26: Current injection | G26: Voltage clamp | L26: all | M26: type "all" in first cell to output all graphed variables or type individual channels
B27: neuron | C27: start | D27: stop | E27: magnitude | G27: neuron | H27: start | I27: stop | J27: potential
B28: B51s | C28: 0 | D28: 90 | E28: -0.63494
B29: B51s | C29: 3 | D29: 4 | E29: 0.8
B30: B51s | C30: 5 | D30: 6 | E30: 0
B31: B51s | C31: 7 | D31: 8 | E31: 0
B32: B51s | C32: 9 | D32: 10 | E32: 0
B33: B51s | C33: 11 | D33: 12 | E33: 0
B34: B51s | C34: 13 | D34: 14 | E34: 0
B35: B51s | C35: 15 | D35: 16 | E35: 0
B36: B51s | C36: 17 | D36: 18 | E36: 0
B37: B51s | C37: 26 | D37: 27 | E37: 4.5

Sheet Kca.smu
F1: syntax | L1: example variables | M1: IVDxREG | N1: currrent by conductance and regulation | T1: example synapses
A2: smu | B2: name | C2: Kca | D2: graph | E2: 1 | F2: conductance | G2: variable.conductance.neuron | M2: V | N2: voltage | Q2: Ics | R2: chem syn current | T2: f_exc | U2: fast excitatory
B3: duration | C3: =MAX(E9:E23) -> 251 | D3: store | E3: 1 | F3: example | G3: Ivd.Na.N1 | M3: Ivd | N3: current by voltage gated conductance | Q3: Cion | R3: amount of ion | T3: s_exc | U3: slow excitatory
B4: stepsize | C4: 0.001 | D4: method | E4: 1 | F4: neuron | G4: variable.neuron | I4: synapse | J4: variable.pre.post.type | M4: A | N4: activation of conductance | Q4: Ies | R4: elec syn current | T4: f_inh | U4: fast inhibitory
B5: red indicates simlation longer than graph duration | F5: example | G5: V.N1 | I5: example | J5: Ics.N1.N4.f_exc | M5: B | N5: Inactivation of conductance | T5: s_inh | U5: slow inhibitory
A6: graph (ous) | J6: Ies.N1.N4 | M6: sIvd_reg | N6: for total current
B7: time | G7: variable 1 | L7: variable 2 | Q7: variable 3 | V7: variable 4
A8: Size | B8: variable | C8: # ticks | D8: start | E8: stop | F8: color | G8: variable | H8: # ticks | I8: min | J8: max | K8: color | L8: variable | M8: # ticks | N8: min | O8: max | P8: color | Q8: variable | R8: # ticks | S8: min | T8: max | U8: color | V8: variable | W8: # ticks | X8: min | Y8: max | Z8: color
A11: 4 | B11: time | C11: 10 | D11: 0 | E11: 100 | F11: white | G11: fBR.Ca.Kca.B51s | H11: 10 | I11: 0.15 | J11: 0.25 | K11: red | L11: Cion.Ca.B51s | M11: 10 | N11: 0 | O11: 1 | P11: green
A12: 4 | B12: time | C12: 11 | D12: 150 | E12: 161 | F12: white | G12: IVDxREG.Kca.B51s | H12: 11 | I12: 0 | J12: 110 | K12: white | L12: Ivd.Kca.B51s | M12: 11 | N12: 0 | O12: 110 | P12: cyan | Q12: fBR.Ca.Kca.B51s | R12: 10 | S12: 0.15 | T12: 0.25 | U12: green
A13: 4 | B13: time | C13: 11 | D13: 180 | E13: 191 | F13: white | G13: IVDxREG.Kca.B51s | H13: 11 | I13: 0 | J13: 110 | K13: white | L13: Ivd.Kca.B51s | M13: 11 | N13: 0 | O13: 110 | P13: cyan | Q13: fBR.Ca.Kca.B51s | R13: =R12 -> 10 | S13: =S12 -> 0.15 | T13: =T12 -> 0.25 | U13: green
A14: 4 | B14: time | C14: 11 | D14: 210 | E14: 221 | F14: white | G14: IVDxREG.Kca.B51s | H14: 11 | I14: 0 | J14: 110 | K14: white | L14: Ivd.Kca.B51s | M14: 11 | N14: 0 | O14: 110 | P14: cyan | Q14: fBR.Ca.Kca.B51s | R14: =R12 -> 10 | S14: =S12 -> 0.15 | T14: =T12 -> 0.25 | U14: green
A15: 4 | B15: time | C15: 11 | D15: 240 | E15: 251 | F15: white | G15: IVDxREG.Kca.B51s | H15: 11 | I15: 0 | J15: 110 | K15: white | L15: Ivd.Kca.B51s | M15: 11 | N15: 0 | O15: 110 | P15: cyan | Q15: fBR.Ca.Kca.B51s | R15: =R13 -> 10 | S15: =S13 -> 0.15 | T15: =T13 -> 0.25 | U15: green
A25: stimulation (.trt) | L25: output variables
B26: Current injection | G26: Voltage clamp | L26: IVDxREG.Kca.B51s | M26: type "all" in first cell to output all graphed variables or type individual channels
B27: neuron | C27: start | D27: stop | E27: magnitude | G27: neuron | H27: start | I27: stop | J27: potential | L27: V.B51s
G28: B51s | H28: 0 | I28: 251 | J28: -80 | L28: Ivd.Kca.B64s
G29: B51s | H29: 0.43 | I29: 0.93 | J29: -60 | L29: V.B64s
G30: B51s | H30: 30.43 | I30: 30.93 | J30: -50 | L30: IVDxREG.Kca.B8
G31: B51s | H31: 60.43 | I31: 60.93 | J31: -40 | L31: V.B8
G32: B51s | H32: 90.43 | I32: 90.93 | J32: -30
G33: B51s | H33: 120.43 | I33: 120.93 | J33: -20
G34: B51s | H34: 150.43 | I34: 150.93 | J34: -10
G35: B51s | H35: 180.43 | I35: 180.93 | J35: 0
G36: B51s | H36: 210.43 | I36: 210.93 | J36: 10
G37: B51s | H37: 240.43 | I37: 240.93 | J37: 20
G38: B8 | H38: 0 | I38: 251 | J38: -80
G39: B8 | H39: 0.43 | I39: 0.93 | J39: -60
G40: B8 | H40: 30.43 | I40: 30.93 | J40: -50
G41: B8 | H41: 60.43 | I41: 60.93 | J41: -40
G42: B8 | H42: 90.43 | I42: 90.93 | J42: -30
G43: B8 | H43: 120.43 | I43: 120.93 | J43: -20
... G48: B64s | H48: 0 | I48: 251 | J48: -80

Sheet KTEA.smu
F1: syntax | L1: example variables | M1: IVDxREG | N1: currrent by conductance and regulation | T1: example synapses
A2: smu | B2: name | C2: KTEA | D2: graph | E2: 1 | F2: conductance | G2: variable.conductance.neuron | M2: V | N2: voltage | Q2: Ics | R2: chem syn current | T2: f_exc | U2: fast excitatory
B3: duration | C3: =MAX(E9:E23) -> 242 | D3: store | E3: 1 | F3: example | G3: Ivd.Na.N1 | M3: Ivd | N3: current by voltage gated conductance | Q3: Cion | R3: amount of ion | T3: s_exc | U3: slow excitatory
B4: stepsize | C4: 0.001 | D4: method | E4: 1 | F4: neuron | G4: variable.neuron | I4: synapse | J4: variable.pre.post.type | M4: A | N4: activation of conductance | Q4: Ies | R4: elec syn current | T4: f_inh | U4: fast inhibitory
B5: red indicates simlation longer than graph duration | F5: example | G5: V.N1 | I5: example | J5: Ics.N1.N4.f_exc | M5: B | N5: Inactivation of conductance | T5: s_inh | U5: slow inhibitory
A6: graph (ous) | J6: Ies.N1.N4 | M6: sIvd_reg | N6: for total current
B7: time | G7: variable 1 | L7: variable 2 | Q7: variable 3 | V7: variable 4
A8: Size | B8: variable | C8: # ticks | D8: start | E8: stop | F8: color | G8: variable | H8: # ticks | I8: min | J8: max | K8: color | L8: variable | M8: # ticks | N8: min | O8: max | P8: color | Q8: variable | R8: # ticks | S8: min | T8: max | U8: color | V8: variable | W8: # ticks | X8: min | Y8: max | Z8: color
A9: 4 | B9: time | C9: 10 | D9: 150 | E9: 152 | F9: white | G9: Ivd.KTEA.B51s | H9: 11 | I9: 0 | J9: 110 | K9: red | L9: Ivd.KTEA.B64s | M9: 11 | N9: 0 | O9: 110 | P9: green | Q9: Ivd.KTEA.B8 | R9: 11 | S9: 0 | T9: 110 | U9: cyan
A10: 4 | B10: time | C10: 10 | D10: 180 | E10: 182 | F10: white | G10: Ivd.KTEA.B51s | H10: 11 | I10: 0 | J10: 110 | K10: red | L10: Ivd.KTEA.B64s | M10: 11 | N10: 0 | O10: 110 | P10: green | Q10: Ivd.KTEA.B8 | R10: 11 | S10: 0 | T10: 110 | U10: cyan
A11: 4 | B11: time | C11: 10 | D11: 210 | E11: 212 | F11: white | G11: Ivd.KTEA.B51s | H11: 11 | I11: 0 | J11: 110 | K11: red | L11: Ivd.KTEA.B64s | M11: 11 | N11: 0 | O11: 110 | P11: green | Q11: Ivd.KTEA.B8 | R11: 11 | S11: 0 | T11: 110 | U11: cyan
A12: 4 | B12: time | C12: 10 | D12: 240 | E12: 242 | F12: white | G12: Ivd.KTEA.B51s | H12: 11 | I12: 0 | J12: 110 | K12: red | L12: Ivd.KTEA.B64s | M12: 11 | N12: 0 | O12: 110 | P12: green | Q12: Ivd.KTEA.B8 | R12: 11 | S12: 0 | T12: 110 | U12: cyan
A25: stimulation (.trt) | L25: output variables
B26: Current injection | G26: Voltage clamp | L26: IVDxREG.KTEA.B51s | M26: type "all" in first cell to output all graphed variables or type individual channels
B27: neuron | C27: start | D27: stop | E27: magnitude | G27: neuron | H27: start | I27: stop | J27: potential | L27: V.B51s
G28: B51s | H28: 0 | I28: 242 | J28: -80 | L28: Ivd.KTEA.B64s
G29: B51s | H29: 0.43 | I29: 0.93 | J29: -60 | L29: V.B64s
G30: B51s | H30: 30.43 | I30: 30.93 | J30: -50 | L30: IVDxREG.KTEA.B8
G31: B51s | H31: 60.43 | I31: 60.93 | J31: -40 | L31: V.B8
G32: B51s | H32: 90.43 | I32: 90.93 | J32: -30
G33: B51s | H33: 120.43 | I33: 120.93 | J33: -20
G34: B51s | H34: 150.43 | I34: 150.93 | J34: -10
G35: B51s | H35: 180.43 | I35: 180.93 | J35: 0
G36: B51s | H36: 210.43 | I36: 210.93 | J36: 10
G37: B51s | H37: 240.43 | I37: 240.93 | J37: 20
G38: B8 | H38: 0 | I38: 242 | J38: -80
G39: B8 | H39: 0.43 | I39: 0.93 | J39: -60
G40: B8 | H40: 30.43 | I40: 30.93 | J40: -50
G41: B8 | H41: 60.43 | I41: 60.93 | J41: -40
G42: B8 | H42: 90.43 | I42: 90.93 | J42: -30
G43: B8 | H43: 120.43 | I43: 120.93 | J43: -20
... G57: B64s | H57: 240.43 | I57: 240.93 | J57: 20

Sheet K.smu
F1: syntax | L1: example variables | M1: IVDxREG | N1: currrent by conductance and regulation | T1: example synapses
A2: smu | B2: name | C2: K | D2: graph | E2: 1 | F2: conductance | G2: variable.conductance.neuron | M2: V | N2: voltage | Q2: Ics | R2: chem syn current | T2: f_exc | U2: fast excitatory
B3: duration | C3: 302 | D3: store | E3: 1 | F3: example | G3: Ivd.Na.N1 | M3: Ivd | N3: current by voltage gated conductance | Q3: Cion | R3: amount of ion | T3: s_exc | U3: slow excitatory
B4: stepsize | C4: 0.0002 | D4: method | E4: 1 | F4: neuron | G4: variable.neuron | I4: synapse | J4: variable.pre.post.type | M4: A | N4: activation of conductance | Q4: Ies | R4: elec syn current | T4: f_inh | U4: fast inhibitory
B5: red indicates simlation longer than graph duration | F5: example | G5: V.N1 | I5: example | J5: Ics.N1.N4.f_exc | M5: B | N5: Inactivation of conductance | T5: s_inh | U5: slow inhibitory
A6: graph (ous) | J6: Ies.N1.N4 | M6: sIvd_reg | N6: for total current
B7: time | G7: variable 1 | L7: variable 2 | Q7: variable 3 | V7: variable 4
A8: Size | B8: variable | C8: # ticks | D8: start | E8: stop | F8: color | G8: variable | H8: # ticks | I8: min | J8: max | K8: color | L8: variable | M8: # ticks | N8: min | O8: max | P8: color | Q8: variable | R8: # ticks | S8: min | T8: max | U8: color | V8: variable | W8: # ticks | X8: min | Y8: max | Z8: color
A9: 1 | B9: time | C9: 10 | D9: 0 | E9: 2 | F9: white | G9: Ivd.K.B51s | H9: 4 | I9: 0 | J9: 200 | K9: red | L9: Ivd.K.B64s | M9: 4 | N9: 0 | O9: 200 | P9: green | Q9: Ivd.K.B8 | R9: 4 | S9: 0 | T9: 200 | U9: cyan
A10: 1 | B10: time | C10: 10 | D10: 60 | E10: 62 | F10: white | G10: Ivd.K.B51s | H10: 4 | I10: 0 | J10: 200 | K10: red | L10: Ivd.K.B64s | M10: 4 | N10: 0 | O10: 200 | P10: green | Q10: Ivd.K.B8 | R10: 4 | S10: 0 | T10: 200 | U10: cyan
A11: 1 | B11: time | C11: 10 | D11: 120 | E11: 122 | F11: white | G11: Ivd.K.B51s | H11: 4 | I11: 0 | J11: 200 | K11: red | L11: Ivd.K.B64s | M11: 4 | N11: 0 | O11: 200 | P11: green | Q11: Ivd.K.B8 | R11: 4 | S11: 0 | T11: 200 | U11: cyan
A12: 4 | B12: time | C12: 10 | D12: 180 | E12: 182 | F12: black | G12: Ivd.K.B51s | H12: 4 | I12: 0 | J12: 200 | K12: red | L12: Ivd.K.B64s | M12: 4 | N12: 0 | O12: 200 | P12: green | Q12: Ivd.K.B8 | R12: 4 | S12: 0 | T12: 200 | U12: cyan
A13: 1 | B13: time | C13: 10 | D13: 240 | E13: 242 | F13: white | G13: Ivd.K.B51s | H13: 4 | I13: 0 | J13: 200 | K13: red | L13: Ivd.K.B64s | M13: 4 | N13: 0 | O13: 200 | P13: green | Q13: Ivd.K.B8 | R13: 4 | S13: 0 | T13: 200 | U13: cyan
A14: 1 | B14: time | C14: 10 | D14: 300 | E14: 302 | F14: white | G14: Ivd.K.B51s | H14: 4 | I14: 0 | J14: 200 | K14: red | L14: Ivd.K.B64s | M14: 4 | N14: 0 | O14: 200 | P14: green | Q14: Ivd.K.B8 | R14: 4 | S14: 0 | T14: 200 | U14: cyan
A25: stimulation (.trt) | L25: output variables
B26: Current injection | G26: Voltage clamp | L26: Ivd.K.B51s | M26: type "all" in first cell to output all graphed variables or type individual channels
B27: neuron | C27: start | D27: stop | E27: magnitude | G27: neuron | H27: start | I27: stop | J27: potential | L27: V.B51s
G28: B51s | H28: 0 | I28: 302 | J28: -80 | L28: Ivd.K.B64s
G29: B51s | H29: 0.13 | I29: 0.43 | J29: -40 | L29: V.B64s
G30: B51s | H30: 60.13 | I30: 60.43 | J30: -40 | L30: Ivd.K.B8
G31: B51s | H31: 120.13 | I31: 120.43 | J31: -40 | L31: V.B8
G32: B51s | H32: 180.13 | I32: 180.43 | J32: -40
G33: B51s | H33: 240.13 | I33: 240.43 | J33: -40
G34: B51s | H34: 300.13 | I34: 300.43 | J34: -40
G35: B51s | H35: 0.43 | I35: 1.43 | J35: -30
G36: B51s | H36: 60.43 | I36: 61.43 | J36: -20
G37: B51s | H37: 120.43 | I37: 121.43 | J37: -10
G38: B51s | H38: 180.43 | I38: 181.43 | J38: 0
G39: B51s | H39: 240.43 | I39: 241.43 | J39: 10
G40: B51s | H40: 300.43 | I40: 301.43 | J40: 20
G41: B51s | H41: 1.43 | I41: 1.53 | J41: 30
G42: B51s | H42: 61.43 | I42: 61.53 | J42: 30
G43: B51s | H43: 121.43 | I43: 121.53 | J43: 30
... G84: B8 | H84: 301.43 | I84: 301.53 | J84: 30

Sheet KA.smu
F1: syntax | L1: example variables | M1: IVDxREG | N1: currrent by conductance and regulation | T1: example synapses
A2: smu | B2: name | C2: KA | D2: graph | E2: 1 | F2: conductance | G2: variable.conductance.neuron | M2: V | N2: voltage | Q2: Ics | R2: chem syn current | T2: f_exc | U2: fast excitatory
B3: duration | C3: 29 | D3: store | E3: 1 | F3: example | G3: Ivd.Na.N1 | M3: Ivd | N3: current by voltage gated conductance | Q3: Cion | R3: amount of ion | T3: s_exc | U3: slow excitatory
B4: stepsize | C4: 0.0005 | D4: method | E4: 1 | F4: neuron | G4: variable.neuron | I4: synapse | J4: variable.pre.post.type | M4: A | N4: activation of conductance | Q4: Ies | R4: elec syn current | T4: f_inh | U4: fast inhibitory
B5: red indicates simlation longer than graph duration | F5: example | G5: V.N1 | I5: example | J5: Ics.N1.N4.f_exc | M5: B | N5: Inactivation of conductance | T5: s_inh | U5: slow inhibitory
A6: graph (ous) | J6: Ies.N1.N4 | M6: sIvd_reg | N6: for total current
B7: time | G7: variable 1 | L7: variable 2 | Q7: variable 3 | V7: variable 4
A8: Size | B8: variable | C8: # ticks | D8: start | E8: stop | F8: color | G8: variable | H8: # ticks | I8: min | J8: max | K8: color | L8: variable | M8: # ticks | N8: min | O8: max | P8: color | Q8: variable | R8: # ticks | S8: min | T8: max | U8: color | V8: variable | W8: # ticks | X8: min | Y8: max | Z8: color
A9: 1 | B9: time | C9: 10 | D9: 0 | E9: 1 | F9: white | G9: Ivd.KA.B51s | H9: 4 | I9: 0 | J9: 200 | K9: red | L9: Ivd.KA.B64s | M9: 4 | N9: 0 | O9: 200 | P9: green | Q9: Ivd.KA.B8 | R9: 4 | S9: 0 | T9: 200 | U9: cyan
A10: 1 | B10: time | C10: 10 | D10: 4 | E10: 5 | F10: white | G10: Ivd.KA.B51s | H10: 4 | I10: 0 | J10: 200 | K10: red | L10: Ivd.KA.B64s | M10: 4 | N10: 0 | O10: 200 | P10: green | Q10: Ivd.KA.B8 | R10: 4 | S10: 0 | T10: 200 | U10: cyan
A11: 1 | B11: time | C11: 10 | D11: 8 | E11: 9 | F11: white | G11: Ivd.KA.B51s | H11: 4 | I11: 0 | J11: 200 | K11: red | L11: Ivd.KA.B64s | M11: 4 | N11: 0 | O11: 200 | P11: green | Q11: Ivd.KA.B8 | R11: 4 | S11: 0 | T11: 200 | U11: cyan
A12: 4 | B12: time | C12: 10 | D12: 12.3 | E12: 13.3 | F12: black | G12: Ivd.KA.B51s | H12: 5 | I12: 0 | J12: 50 | K12: red | L12: Ivd.KA.B64s | M12: 5 | N12: 0 | O12: 50 | P12: green | Q12: Ivd.KA.B8 | R12: 5 | S12: 0 | T12: 50 | U12: cyan
A13: 1 | B13: time | C13: 10 | D13: 16 | E13: 17 | F13: white | G13: Ivd.KA.B51s | H13: 4 | I13: 0 | J13: 200 | K13: red | L13: Ivd.KA.B64s | M13: 4 | N13: 0 | O13: 200 | P13: green | Q13: Ivd.KA.B8 | R13: 4 | S13: 0 | T13: 200 | U13: cyan
A14: 1 | B14: time | C14: 10 | D14: 20 | E14: 21 | F14: white | G14: Ivd.KA.B51s | H14: 4 | I14: 0 | J14: 200 | K14: red | L14: Ivd.KA.B64s | M14: 4 | N14: 0 | O14: 200 | P14: green | Q14: Ivd.KA.B8 | R14: 4 | S14: 0 | T14: 200 | U14: cyan
A15: 1 | B15: time | C15: 10 | D15: 24 | E15: 25 | F15: white | G15: Ivd.KA.B51s | H15: 4 | I15: 0 | J15: 200 | K15: red | L15: Ivd.KA.B64s | M15: 4 | N15: 0 | O15: 200 | P15: green | Q15: Ivd.KA.B8 | R15: 4 | S15: 0 | T15: 200 | U15: cyan
A16: 1 | B16: time | C16: 10 | D16: 28 | E16: 29 | F16: white | G16: Ivd.KA.B51s | H16: 4 | I16: 0 | J16: 200 | K16: red | L16: Ivd.KA.B64s | M16: 4 | N16: 0 | O16: 200 | P16: green | Q16: Ivd.KA.B8 | R16: 4 | S16: 0 | T16: 200 | U16: cyan
A25: stimulation (.trt) | L25: output variables
B26: Current injection | G26: Voltage clamp | L26: Ivd.KA.B51s | M26: type "all" in first cell to output all graphed variables or type individual channels
B27: neuron | C27: start | D27: stop | E27: magnitude | G27: neuron | H27: start | I27: stop | J27: potential | L27: V.B51s
G28: B51s | H28: 0 | I28: 29 | J28: -40 | L28: Ivd.KA.B64s
G29: B51s | H29: 0.13 | I29: 0.38 | J29: -110 | L29: V.B64s
G30: B51s | H30: 4.13 | I30: 4.38 | J30: -110 | L30: Ivd.KA.B8
G31: B51s | H31: 8.13 | I31: 8.38 | J31: -110 | L31: V.B8
G32: B51s | H32: 12.13 | I32: 12.38 | J32: -110
G33: B51s | H33: 16.13 | I33: 16.38 | J33: -110
G34: B51s | H34: 20.13 | I34: 20.38 | J34: -110
G35: B51s | H35: 24.13 | I35: 24.38 | J35: -110
G36: B51s | H36: 28.13 | I36: 28.38 | J36: -110
G37: B51s | H37: 0.38 | I37: 0.88 | J37: -50
G38: B51s | H38: 4.38 | I38: 4.88 | J38: -40
G39: B51s | H39: 8.38 | I39: 8.88 | J39: -30
G40: B51s | H40: 12.38 | I40: 12.88 | J40: -20
G41: B51s | H41: 16.38 | I41: 16.88 | J41: -10
G42: B51s | H42: 20.38 | I42: 20.88 | J42: 0
G43: B51s | H43: 24.38 | I43: 24.88 | J43: 10
... G78: B8 | H78: 28.38 | I78: 28.88 | J78: 20

Sheet CaR2.smu
F1: syntax | L1: example variables | M1: IVDxREG | N1: currrent by conductance and regulation | T1: example synapses
A2: smu | B2: name | C2: CaR2 | D2: graph | E2: 1 | F2: conductance | G2: variable.conductance.neuron | M2: V | N2: voltage | Q2: Ics | R2: chem syn current | T2: f_exc | U2: fast excitatory
B3: duration | C3: 181 | D3: store | E3: 1 | F3: example | G3: Ivd.Na.N1 | M3: Ivd | N3: current by voltage gated conductance | Q3: Cion | R3: amount of ion | T3: s_exc | U3: slow excitatory
B4: stepsize | C4: 0.0005 | D4: method | E4: 1 | F4: neuron | G4: variable.neuron | I4: synapse | J4: variable.pre.post.type | M4: A | N4: activation of conductance | Q4: Ies | R4: elec syn current | T4: f_inh | U4: fast inhibitory
B5: red indicates simlation longer than graph duration | F5: example | G5: V.N1 | I5: example | J5: Ics.N1.N4.f_exc | M5: B | N5: Inactivation of conductance | T5: s_inh | U5: slow inhibitory
A6: graph (ous) | J6: Ies.N1.N4 | M6: sIvd_reg | N6: for total current
B7: time | G7: variable 1 | L7: variable 2 | Q7: variable 3 | V7: variable 4
A8: Size | B8: variable | C8: # ticks | D8: start | E8: stop | F8: color | G8: variable | H8: # ticks | I8: min | J8: max | K8: color | L8: variable | M8: # ticks | N8: min | O8: max | P8: color | Q8: variable | R8: # ticks | S8: min | T8: max | U8: color | V8: variable | W8: # ticks | X8: min | Y8: max | Z8: color
A9: 1 | B9: time | C9: 10 | D9: 0 | E9: 1 | F9: white | G9: Ivd.CaR.B51s | H9: 5 | I9: -10 | J9: 0 | K9: orange | L9: Ivd.CaR.B64s | M9: 5 | N9: -10 | O9: 0 | P9: green | Q9: Ivd.CaR.B8 | R9: 5 | S9: -10 | T9: 0 | U9: cyan
A10: 1 | B10: time | C10: 10 | D10: 30 | E10: 31 | F10: white | G10: Ivd.CaR.B51s | H10: 5 | I10: -10 | J10: 0 | K10: orange | L10: Ivd.CaR.B64s | M10: 5 | N10: -10 | O10: 0 | P10: green | Q10: Ivd.CaR.B8 | R10: 5 | S10: -10 | T10: 0 | U10: cyan
A11: 1 | B11: time | C11: 10 | D11: 60 | E11: 61 | F11: white | G11: Ivd.CaR.B51s | H11: 5 | I11: -10 | J11: 0 | K11: orange | L11: Ivd.CaR.B64s | M11: 5 | N11: -10 | O11: 0 | P11: green | Q11: Ivd.CaR.B8 | R11: 5 | S11: -10 | T11: 0 | U11: cyan
A12: 1 | B12: time | C12: 10 | D12: 90 | E12: 91 | F12: white | G12: Ivd.CaR.B51s | H12: 5 | I12: -10 | J12: 0 | K12: orange | L12: Ivd.CaR.B64s | M12: 5 | N12: -10 | O12: 0 | P12: green | Q12: Ivd.CaR.B8 | R12: 5 | S12: -10 | T12: 0 | U12: cyan
A13: 1 | B13: time | C13: 10 | D13: 120 | E13: 121 | F13: white | G13: Ivd.CaR.B51s | H13: 5 | I13: -10 | J13: 0 | K13: orange | L13: Ivd.CaR.B64s | M13: 5 | N13: -10 | O13: 0 | P13: green | Q13: Ivd.CaR.B8 | R13: 5 | S13: -10 | T13: 0 | U13: cyan
A14: 1 | B14: time | C14: 10 | D14: 150 | E14: 151 | F14: white | G14: Ivd.CaR.B51s | H14: 5 | I14: -10 | J14: 0 | K14: orange | L14: Ivd.CaR.B64s | M14: 5 | N14: -10 | O14: 0 | P14: green | Q14: Ivd.CaR.B8 | R14: 5 | S14: -10 | T14: 0 | U14: cyan
A15: 1 | B15: time | C15: 10 | D15: 180 | E15: 181 | F15: white | G15: Ivd.CaR.B51s | H15: 5 | I15: -10 | J15: 0 | K15: orange | L15: Ivd.CaR.B64s | M15: 5 | N15: -10 | O15: 0 | P15: green | Q15: Ivd.CaR.B8 | R15: 5 | S15: -10 | T15: 0 | U15: cyan
A25: stimulation (.trt) | L25: output variables
B26: Current injection | G26: Voltage clamp | L26: Ivd.CaR.B51s | M26: type "all" in first cell to output all graphed variables or type individual channels
B27: neuron | C27: start | D27: stop | E27: magnitude | G27: neuron | H27: start | I27: stop | J27: potential | L27: V.B51s
G28: B51s | H28: 0 | I28: 181 | J28: -80 | L28: Ivd.CaR.B64s
G29: B51s | H29: 0.43 | I29: 0.68 | J29: -40 | L29: V.B64s
G30: B51s | H30: 30.43 | I30: 30.68 | J30: -30 | L30: Ivd.CaR.B8
G31: B51s | H31: 60.43 | I31: 60.68 | J31: -20 | L31: V.B8
G32: B51s | H32: 90.43 | I32: 90.68 | J32: -10
G33: B51s | H33: 120.43 | I33: 120.68 | J33: 0
G34: B51s | H34: 150.43 | I34: 150.68 | J34: 10
G35: B51s | H35: 180.43 | I35: 180.68 | J35: 20
G36: B64s | H36: 0 | I36: 181 | J36: -80
G37: B64s | H37: 0.43 | I37: 0.68 | J37: -40
G38: B64s | H38: 30.43 | I38: 30.68 | J38: -30
G39: B64s | H39: 60.43 | I39: 60.68 | J39: -20
G40: B64s | H40: 90.43 | I40: 90.68 | J40: -10
G41: B64s | H41: 120.43 | I41: 120.68 | J41: 0
G42: B64s | H42: 150.43 | I42: 150.68 | J42: 10
G43: B64s | H43: 180.43 | I43: 180.68 | J43: 20
... G72: B8 | H72: 180.13 | I72: 180.43 | J72: -10

Sheet CaR1.smu
F1: syntax | L1: example variables | M1: IVDxREG | N1: currrent by conductance and regulation | T1: example synapses
A2: smu | B2: name | C2: CaR1 | D2: graph | E2: 1 | F2: conductance | G2: variable.conductance.neuron | M2: V | N2: voltage | Q2: Ics | R2: chem syn current | T2: f_exc | U2: fast excitatory
B3: duration | C3: 181 | D3: store | E3: 1 | F3: example | G3: Ivd.Na.N1 | M3: Ivd | N3: current by voltage gated conductance | Q3: Cion | R3: amount of ion | T3: s_exc | U3: slow excitatory
B4: stepsize | C4: 0.0005 | D4: method | E4: 1 | F4: neuron | G4: variable.neuron | I4: synapse | J4: variable.pre.post.type | M4: A | N4: activation of conductance | Q4: Ies | R4: elec syn current | T4: f_inh | U4: fast inhibitory
B5: red indicates simlation longer than graph duration | F5: example | G5: V.N1 | I5: example | J5: Ics.N1.N4.f_exc | M5: B | N5: Inactivation of conductance | T5: s_inh | U5: slow inhibitory
A6: graph (ous) | J6: Ies.N1.N4 | M6: sIvd_reg | N6: for total current
B7: time | G7: variable 1 | L7: variable 2 | Q7: variable 3 | V7: variable 4
A8: Size | B8: variable | C8: # ticks | D8: start | E8: stop | F8: color | G8: variable | H8: # ticks | I8: min | J8: max | K8: color | L8: variable | M8: # ticks | N8: min | O8: max | P8: color | Q8: variable | R8: # ticks | S8: min | T8: max | U8: color | V8: variable | W8: # ticks | X8: min | Y8: max | Z8: color
A9: 1 | B9: time | C9: 10 | D9: 0 | E9: 1 | F9: white | G9: Ivd.CaR.B51s | H9: 5 | I9: -10 | J9: 0 | K9: orange | L9: Ivd.CaR.B64s | M9: 5 | N9: -10 | O9: 0 | P9: green | Q9: Ivd.CaR.B8 | R9: 5 | S9: -10 | T9: 0 | U9: cyan
A10: 1 | B10: time | C10: 10 | D10: 30 | E10: 31 | F10: white | G10: Ivd.CaR.B51s | H10: 5 | I10: -10 | J10: 0 | K10: orange | L10: Ivd.CaR.B64s | M10: 5 | N10: -10 | O10: 0 | P10: green | Q10: Ivd.CaR.B8 | R10: 5 | S10: -10 | T10: 0 | U10: cyan
A11: 1 | B11: time | C11: 10 | D11: 60 | E11: 61 | F11: white | G11: Ivd.CaR.B51s | H11: 5 | I11: -10 | J11: 0 | K11: orange | L11: Ivd.CaR.B64s | M11: 5 | N11: -10 | O11: 0 | P11: green | Q11: Ivd.CaR.B8 | R11: 5 | S11: -10 | T11: 0 | U11: cyan
A12: 1 | B12: time | C12: 10 | D12: 90 | E12: 91 | F12: white | G12: Ivd.CaR.B51s | H12: 5 | I12: -10 | J12: 0 | K12: orange | L12: Ivd.CaR.B64s | M12: 5 | N12: -10 | O12: 0 | P12: green | Q12: Ivd.CaR.B8 | R12: 5 | S12: -10 | T12: 0 | U12: cyan
A13: 1 | B13: time | C13: 10 | D13: 120 | E13: 121 | F13: white | G13: Ivd.CaR.B51s | H13: 5 | I13: -10 | J13: 0 | K13: orange | L13: Ivd.CaR.B64s | M13: 5 | N13: -10 | O13: 0 | P13: green | Q13: Ivd.CaR.B8 | R13: 5 | S13: -10 | T13: 0 | U13: cyan
A14: 1 | B14: time | C14: 10 | D14: 150 | E14: 151 | F14: white | G14: Ivd.CaR.B51s | H14: 5 | I14: -10 | J14: 0 | K14: orange | L14: Ivd.CaR.B64s | M14: 5 | N14: -10 | O14: 0 | P14: green | Q14: Ivd.CaR.B8 | R14: 5 | S14: -10 | T14: 0 | U14: cyan
A15: 1 | B15: time | C15: 10 | D15: 180 | E15: 181 | F15: white | G15: Ivd.CaR.B51s | H15: 5 | I15: -10 | J15: 0 | K15: orange | L15: Ivd.CaR.B64s | M15: 5 | N15: -10 | O15: 0 | P15: green | Q15: Ivd.CaR.B8 | R15: 5 | S15: -10 | T15: 0 | U15: cyan
A25: stimulation (.trt) | L25: output variables
B26: Current injection | G26: Voltage clamp | L26: Ivd.CaR.B51s | M26: type "all" in first cell to output all graphed variables or type individual channels
B27: neuron | C27: start | D27: stop | E27: magnitude | G27: neuron | H27: start | I27: stop | J27: potential | L27: V.B51s
G28: B51s | H28: 0 | I28: 181 | J28: -80 | L28: Ivd.CaR.B64s
G29: B51s | H29: 0.43 | I29: 0.68 | J29: -40 | L29: V.B64s
G30: B51s | H30: 30.43 | I30: 30.68 | J30: -30 | L30: Ivd.CaR.B8
G31: B51s | H31: 60.43 | I31: 60.68 | J31: -20 | L31: V.B8
G32: B51s | H32: 90.43 | I32: 90.68 | J32: -10
G33: B51s | H33: 120.43 | I33: 120.68 | J33: 0
G34: B51s | H34: 150.43 | I34: 150.68 | J34: 10
G35: B51s | H35: 180.43 | I35: 180.68 | J35: 20
G36: B64s | H36: 0 | I36: 181 | J36: -80
G37: B64s | H37: 0.43 | I37: 0.68 | J37: -40
G38: B64s | H38: 30.43 | I38: 30.68 | J38: -30
G39: B64s | H39: 60.43 | I39: 60.68 | J39: -20
G40: B64s | H40: 90.43 | I40: 90.68 | J40: -10
G41: B64s | H41: 120.43 | I41: 120.68 | J41: 0
G42: B64s | H42: 150.43 | I42: 150.68 | J42: 10
G43: B64s | H43: 180.43 | I43: 180.68 | J43: 20
... G51: B8 | H51: 180.43 | I51: 180.68 | J51: 20

Sheet CaL.smu
F1: syntax | L1: example variables | M1: IVDxREG | N1: currrent by conductance and regulation | T1: example synapses
A2: smu | B2: name | C2: CaL | D2: graph | E2: 1 | F2: conductance | G2: variable.conductance.neuron | M2: V | N2: voltage | Q2: Ics | R2: chem syn current | T2: f_exc | U2: fast excitatory
B3: duration | C3: =MAX(E9:E23) -> 181 | D3: store | E3: 1 | F3: example | G3: Ivd.Na.N1 | M3: Ivd | N3: current by voltage gated conductance | Q3: Cion | R3: amount of ion | T3: s_exc | U3: slow excitatory
B4: stepsize | C4: 0.0005 | D4: method | E4: 1 | F4: neuron | G4: variable.neuron | I4: synapse | J4: variable.pre.post.type | M4: A | N4: activation of conductance | Q4: Ies | R4: elec syn current | T4: f_inh | U4: fast inhibitory
B5: red indicates simlation longer than graph duration | F5: example | G5: V.N1 | I5: example | J5: Ics.N1.N4.f_exc | M5: B | N5: Inactivation of conductance | T5: s_inh | U5: slow inhibitory
A6: graph (ous) | J6: Ies.N1.N4 | M6: sIvd_reg | N6: for total current
B7: time | G7: variable 1 | L7: variable 2 | Q7: variable 3 | V7: variable 4
A8: Size | B8: variable | C8: # ticks | D8: start | E8: stop | F8: color | G8: variable | H8: # ticks | I8: min | J8: max | K8: color | L8: variable | M8: # ticks | N8: min | O8: max | P8: color | Q8: variable | R8: # ticks | S8: min | T8: max | U8: color | V8: variable | W8: # ticks | X8: min | Y8: max | Z8: color
A9: 1 | B9: time | C9: 10 | D9: 0 | E9: 1 | F9: white | G9: Ivd.CaL.B51s | H9: 5 | I9: -10 | J9: 0 | K9: orange | L9: Ivd.CaL.B64s | M9: 5 | N9: -10 | O9: 0 | P9: green | Q9: Ivd.CaL.B8 | R9: 5 | S9: -10 | T9: 0 | U9: cyan
A10: 1 | B10: time | C10: 10 | D10: 30 | E10: 31 | F10: white | G10: Ivd.CaL.B51s | H10: 5 | I10: -10 | J10: 0 | K10: orange | L10: Ivd.CaL.B64s | M10: 5 | N10: -10 | O10: 0 | P10: green | Q10: Ivd.CaL.B8 | R10: 5 | S10: -10 | T10: 0 | U10: cyan
A11: 1 | B11: time | C11: 10 | D11: 60 | E11: 61 | F11: white | G11: Ivd.CaL.B51s | H11: 5 | I11: -10 | J11: 0 | K11: orange | L11: Ivd.CaL.B64s | M11: 5 | N11: -10 | O11: 0 | P11: green | Q11: Ivd.CaL.B8 | R11: 5 | S11: -10 | T11: 0 | U11: cyan
A12: 1 | B12: time | C12: 10 | D12: 90 | E12: 91 | F12: white | G12: Ivd.CaL.B51s | H12: 5 | I12: -10 | J12: 0 | K12: orange | L12: Ivd.CaL.B64s | M12: 5 | N12: -10 | O12: 0 | P12: green | Q12: Ivd.CaL.B8 | R12: 5 | S12: -10 | T12: 0 | U12: cyan
A13: 1 | B13: time | C13: 10 | D13: 120 | E13: 121 | F13: white | G13: Ivd.CaL.B51s | H13: 5 | I13: -10 | J13: 0 | K13: orange | L13: Ivd.CaL.B64s | M13: 5 | N13: -10 | O13: 0 | P13: green | Q13: Ivd.CaL.B8 | R13: 5 | S13: -10 | T13: 0 | U13: cyan
A14: 1 | B14: time | C14: 10 | D14: 150 | E14: 151 | F14: white | G14: Ivd.CaL.B51s | H14: 5 | I14: -10 | J14: 0 | K14: orange | L14: Ivd.CaL.B64s | M14: 5 | N14: -10 | O14: 0 | P14: green | Q14: Ivd.CaL.B8 | R14: 5 | S14: -10 | T14: 0 | U14: cyan
A15: 1 | B15: time | C15: 10 | D15: 180 | E15: 181 | F15: white | G15: Ivd.CaL.B51s | H15: 5 | I15: -10 | J15: 0 | K15: orange | L15: Ivd.CaL.B64s | M15: 5 | N15: -10 | O15: 0 | P15: green | Q15: Ivd.CaL.B8 | R15: 5 | S15: -10 | T15: 0 | U15: cyan
A25: stimulation (.trt) | L25: output variables
B26: Current injection | G26: Voltage clamp | L26: Ivd.CaL.B51s | M26: type "all" in first cell to output all graphed variables or type individual channels
B27: neuron | C27: start | D27: stop | E27: magnitude | G27: neuron | H27: start | I27: stop | J27: potential | L27: V.B51s
G28: B51s | H28: 0 | I28: 181 | J28: -80 | L28: Ivd.CaL.B64s
G29: B51s | H29: 0.43 | I29: 0.93 | J29: -40 | L29: V.B64s
G30: B51s | H30: 30.43 | I30: 30.93 | J30: -30 | L30: Ivd.CaL.B8
G31: B51s | H31: 60.43 | I31: 60.93 | J31: -20 | L31: V.B8
G32: B51s | H32: 90.43 | I32: 90.93 | J32: -10
G33: B51s | H33: 120.43 | I33: 120.93 | J33: 0
G34: B51s | H34: 150.43 | I34: 150.93 | J34: 10
G35: B51s | H35: 180.43 | I35: 180.93 | J35: 20
G36: B64s | H36: 0 | I36: 181 | J36: -80
G37: B64s | H37: 0.43 | I37: 0.93 | J37: -40
G38: B64s | H38: 30.43 | I38: 30.93 | J38: -30
G39: B64s | H39: 60.43 | I39: 60.93 | J39: -20
G40: B64s | H40: 90.43 | I40: 90.93 | J40: -10
G41: B64s | H41: 120.43 | I41: 120.93 | J41: 0
G42: B64s | H42: 150.43 | I42: 150.93 | J42: 10
G43: B64s | H43: 180.43 | I43: 180.93 | J43: 20
... G51: B8 | H51: 180.43 | I51: 180.93 | J51: 20

Sheet textv.smu
F1: syntax | L1: example variables | M1: IVDxREG | N1: currrent by conductance and regulation | T1: example synapses
A2: smu | B2: name | C2: testv | D2: graph | E2: 1 | F2: conductance | G2: variable.conductance.neuron | M2: V | N2: voltage | Q2: Ics | R2: chem syn current | T2: f_exc | U2: fast excitatory
B3: duration | C3: 12 | D3: store | E3: 0 | F3: example | G3: Ivd.Na.N1 | M3: Ivd | N3: current by voltage gated conductance | Q3: Cion | R3: amount of ion | T3: s_exc | U3: slow excitatory
B4: stepsize | C4: 0.0001 | D4: method | E4: 1 | F4: neuron | G4: variable.neuron | I4: synapse | J4: variable.pre.post.type | M4: A | N4: activation of conductance | Q4: Ies | R4: elec syn current | T4: f_inh | U4: fast inhibitory
B5: red indicates simlation longer than graph duration | F5: example | G5: V.N1 | I5: example | J5: Ics.N1.N4.f_exc | M5: B | N5: Inactivation of conductance | Q5: slex | R5: trt current | T5: s_inh | U5: slow inhibitory
A6: graph (ous) | J6: Ies.N1.N4 | M6: sIVD_reg | N6: for total current
B7: time | G7: variable 1 | L7: variable 2 | Q7: variable 3 | V7: variable 4
A8: Size | B8: variable | C8: # ticks | D8: start | E8: stop | F8: color | G8: variable | H8: # ticks | I8: min | J8: max | K8: color | L8: variable | M8: # ticks | N8: min | O8: max | P8: color | Q8: variable | R8: # ticks | S8: min | T8: max | U8: color | V8: variable | W8: # ticks | X8: min | Y8: max | Z8: color
A9: 4 | B9: time | C9: 12 | D9: 0 | E9: 12 | F9: white | G9: Ivd.Na.B51a | H9: 5 | I9: -10 | J9: 0 | K9: red | L9: Ivd.K.B51a | M9: 5 | N9: 0 | O9: 10 | P9: orange
A10: 1 | B10: time | C10: 12 | D10: 0 | E10: 12 | F10: white | G10: V.B51a | H10: 9 | I10: -90 | J10: 0 | K10: white
A25: stimulation (.trt) | L25: output variables
B26: Current injection | G26: Voltage clamp | L26: all | M26: type "all" in first cell to output all graphed variables or type individual channels
B27: neuron | C27: start | D27: stop | E27: magnitude | G27: neuron | H27: start | I27: stop | J27: potential
G28: B51a | H28: 0 | I28: 12 | J28: -80
G29: B51a | H29: 2 | I29: 3 | J29: -40
G30: B51a | H30: 4 | I30: 5 | J30: -30
G31: B51a | H31: 6 | I31: 7 | J31: -20
G32: B51a | H32: 8 | I32: 9 | J32: -10
G33: B51a | H33: 10 | I33: 11 | J33: 0

Sheet Napp.smu
F1: syntax | L1: example variables | M1: IVDxREG | N1: currrent by conductance and regulation | T1: example synapses
A2: smu | B2: name | C2: Napp | D2: graph | E2: 1 | F2: conductance | G2: variable.conductance.neuron | M2: V | N2: voltage | Q2: Ics | R2: chem syn current | T2: f_exc | U2: fast excitatory
B3: duration | C3: 152 | D3: store | E3: 1 | F3: example | G3: Ivd.Na.N1 | M3: Ivd | N3: current by voltage gated conductance | Q3: Cion | R3: amount of ion | T3: s_exc | U3: slow excitatory
B4: stepsize | C4: 0.0005 | D4: method | E4: 1 | F4: neuron | G4: variable.neuron | I4: synapse | J4: variable.pre.post.type | M4: A | N4: activation of conductance | Q4: Ies | R4: elec syn current | T4: f_inh | U4: fast inhibitory
B5: red indicates simlation longer than graph duration | F5: example | G5: V.N1 | I5: example | J5: Ics.N1.N4.f_exc | M5: B | N5: Inactivation of conductance | T5: s_inh | U5: slow inhibitory
A6: graph (ous) | J6: Ies.N1.N4 | M6: sIvd_reg | N6: for total current
B7: time | G7: variable 1 | L7: variable 2 | Q7: variable 3 | V7: variable 4
A8: Size | B8: variable | C8: # ticks | D8: start | E8: stop | F8: color | G8: variable | H8: # ticks | I8: min | J8: max | K8: color | L8: variable | M8: # ticks | N8: min | O8: max | P8: color | Q8: variable | R8: # ticks | S8: min | T8: max | U8: color | V8: variable | W8: # ticks | X8: min | Y8: max | Z8: color
A9: 1 | B9: time | C9: 10 | D9: 0 | E9: 2 | F9: white | G9: Ivd.Napp.B51s | H9: 5 | I9: -20 | J9: 5 | K9: red | L9: Ivd.Napp.B64s | M9: 5 | N9: -20 | O9: 5 | P9: green | Q9: Ivd.Napp.B8 | R9: 5 | S9: -20 | T9: 5 | U9: cyan
A10: 1 | B10: time | C10: 10 | D10: 30 | E10: 32 | F10: white | G10: Ivd.Napp.B51s | H10: 5 | I10: -20 | J10: 5 | K10: red | L10: Ivd.Napp.B64s | M10: 5 | N10: -20 | O10: 5 | P10: green | Q10: Ivd.Napp.B8 | R10: 5 | S10: -20 | T10: 5 | U10: cyan
A11: 1 | B11: time | C11: 10 | D11: 60 | E11: 62 | F11: white | G11: Ivd.Napp.B51s | H11: 5 | I11: -20 | J11: 5 | K11: red | L11: Ivd.Napp.B64s | M11: 5 | N11: -20 | O11: 5 | P11: green | Q11: Ivd.Napp.B8 | R11: 5 | S11: -20 | T11: 5 | U11: cyan
A12: 1 | B12: time | C12: 10 | D12: 90 | E12: 92 | F12: white | G12: Ivd.Napp.B51s | H12: 5 | I12: -20 | J12: 5 | K12: red | L12: Ivd.Napp.B64s | M12: 5 | N12: -20 | O12: 5 | P12: green | Q12: Ivd.Napp.B8 | R12: 5 | S12: -20 | T12: 5 | U12: cyan
A13: 1 | B13: time | C13: 10 | D13: 120 | E13: 122 | F13: white | G13: Ivd.Napp.B51s | H13: 5 | I13: -20 | J13: 5 | K13: red | L13: Ivd.Napp.B64s | M13: 5 | N13: -20 | O13: 5 | P13: green | Q13: Ivd.Napp.B8 | R13: 5 | S13: -20 | T13: 5 | U13: cyan
A14: 1 | B14: time | C14: 10 | D14: 150 | E14: 152 | F14: white | G14: Ivd.Napp.B51s | H14: 5 | I14: -20 | J14: 5 | K14: red | L14: Ivd.Napp.B64s | M14: 5 | N14: -20 | O14: 5 | P14: green | Q14: Ivd.Napp.B8 | R14: 5 | S14: -20 | T14: 5 | U14: cyan
A25: stimulation (.trt) | L25: output variables
B26: Current injection | G26: Voltage clamp | L26: Ivd.Napp.B51s | M26: type "all" in first cell to output all graphed variables or type individual channels
B27: neuron | C27: start | D27: stop | E27: magnitude | G27: neuron | H27: start | I27: stop | J27: potential | L27: V.B51s
G28: B51s | H28: 0 | I28: 152 | J28: -100 | L28: Ivd.Napp.B64s
G29: B51s | H29: 0.37 | I29: 0.87 | J29: -60 | L29: V.B64s
G30: B51s | H30: 30.37 | I30: 30.87 | J30: -50 | L30: Ivd.Napp.B8
G31: B51s | H31: 60.37 | I31: 60.87 | J31: -40 | L31: V.B8
G32: B51s | H32: 90.37 | I32: 90.87 | J32: -30
G33: B51s | H33: 120.37 | I33: 120.87 | J33: -20
G34: B51s | H34: 150.37 | I34: 150.87 | J34: -10
G35: B64s | H35: 0 | I35: 152 | J35: -100
G36: B64s | H36: 0.37 | I36: 0.87 | J36: -60
G37: B64s | H37: 30.37 | I37: 30.87 | J37: -50
G38: B64s | H38: 60.37 | I38: 60.87 | J38: -40
G39: B64s | H39: 90.37 | I39: 90.87 | J39: -30
G40: B64s | H40: 120.37 | I40: 120.87 | J40: -20
G41: B64s | H41: 150.37 | I41: 150.87 | J41: -10
G42: B8 | H42: 0 | I42: 152 | J42: -100
G43: B8 | H43: 0.37 | I43: 0.87 | J43: -60
... G66: B8 | H66: 150.87 | I66: 151.87 | J66: -10

Sheet IR.smu
F1: syntax | L1: example variables | M1: IVDxREG | N1: currrent by conductance and regulation | T1: example synapses
A2: smu | B2: name | C2: IR | D2: graph | E2: 1 | F2: conductance | G2: variable.conductance.neuron | M2: V | N2: voltage | Q2: Ics | R2: chem syn current | T2: f_exc | U2: fast excitatory
B3: duration | C3: 30 | D3: store | E3: 1 | F3: example | G3: Ivd.Na.N1 | M3: Ivd | N3: current by voltage gated conductance | Q3: Cion | R3: amount of ion | T3: s_exc | U3: slow excitatory
B4: stepsize | C4: 0.0001 | D4: method | E4: 1 | F4: neuron | G4: variable.neuron | I4: synapse | J4: variable.pre.post.type | M4: A | N4: activation of conductance | Q4: Ies | R4: elec syn current | T4: f_inh | U4: fast inhibitory
B5: red indicates simlation longer than graph duration | F5: example | G5: V.N1 | I5: example | J5: Ics.N1.N4.f_exc | M5: B | N5: Inactivation of conductance | T5: s_inh | U5: slow inhibitory
A6: graph (ous) | J6: Ies.N1.N4 | M6: sIvd_reg | N6: for total current
B7: time | G7: variable 1 | L7: variable 2 | Q7: variable 3 | V7: variable 4
A8: Size | B8: variable | C8: # ticks | D8: start | E8: stop | F8: color | G8: variable | H8: # ticks | I8: min | J8: max | K8: color | L8: variable | M8: # ticks | N8: min | O8: max | P8: color | Q8: variable | R8: # ticks | S8: min | T8: max | U8: color | V8: variable | W8: # ticks | X8: min | Y8: max | Z8: color
A9: 1 | B9: time | C9: 15 | D9: 0 | E9: 30 | F9: white | G9: V.B51s | H9: 8 | I9: -110 | J9: -70 | K9: red | L9: V.B64s | M9: 8 | N9: -110 | O9: -70 | P9: green | Q9: V.B8 | R9: 8 | S9: -110 | T9: -70 | U9: cyan
A25: stimulation (.trt) | L25: output variables
B26: Current injection | G26: Voltage clamp | L26: V.B51s | M26: type "all" in first cell to output all graphed variables or type individual channels
B27: neuron | C27: start | D27: stop | E27: magnitude | G27: neuron | H27: start | I27: stop | J27: potential | L27: V.B64s
B28: B51s | C28: 0 | D28: 30 | E28: -0.63494 | L28: V.B8
B29: B64s | C29: 0 | D29: 30 | E29: -2.4771
B30: B8 | C30: 0 | D30: 30 | E30: -2.0858
B31: B51s | C31: 24 | D31: 29 | E31: -1
B32: B64s | C32: 24 | D32: 29 | E32: -1
B33: B8 | C33: 24 | D33: 29 | E33: -1

Sheet HCN.smu
F1: syntax | L1: example variables | M1: IVDxREG | N1: currrent by conductance and regulation | T1: example synapses
A2: smu | B2: name | C2: HCN | D2: graph | E2: 1 | F2: conductance | G2: variable.conductance.neuron | M2: V | N2: voltage | Q2: Ics | R2: chem syn current | T2: f_exc | U2: fast excitatory
B3: duration | C3: 430 | D3: store | E3: 1 | F3: example | G3: Ivd.Na.N1 | M3: Ivd | N3: current by voltage gated conductance | Q3: Cion | R3: amount of ion | T3: s_exc | U3: slow excitatory
B4: stepsize | C4: 0.0005 | D4: method | E4: 1 | F4: neuron | G4: variable.neuron | I4: synapse | J4: variable.pre.post.type | M4: A | N4: activation of conductance | Q4: Ies | R4: elec syn current | T4: f_inh | U4: fast inhibitory
B5: red indicates simlation longer than graph duration | F5: example | G5: V.N1 | I5: example | J5: Ics.N1.N4.f_exc | M5: B | N5: Inactivation of conductance | T5: s_inh | U5: slow inhibitory
A6: graph (ous) | J6: Ies.N1.N4 | M6: sIvd_reg | N6: for total current
B7: time | G7: variable 1 | L7: variable 2 | Q7: variable 3 | V7: variable 4
A8: Size | B8: variable | C8: # ticks | D8: start | E8: stop | F8: color | G8: variable | H8: # ticks | I8: min | J8: max | K8: color | L8: variable | M8: # ticks | N8: min | O8: max | P8: color | Q8: variable | R8: # ticks | S8: min | T8: max | U8: color | V8: variable | W8: # ticks | X8: min | Y8: max | Z8: color
A9: 1 | B9: time | C9: 10 | D9: 0 | E9: 30 | F9: white | G9: Ivd.HCN.B8 | H9: 4 | I9: -15 | J9: 5 | K9: cyan
A10: 1 | B10: time | C10: 10 | D10: 80 | E10: 110 | F10: white | G10: Ivd.HCN.B8 | H10: 4 | I10: -15 | J10: 5 | K10: cyan
A11: 1 | B11: time | C11: 10 | D11: 160 | E11: 190 | F11: white | G11: Ivd.HCN.B8 | H11: 4 | I11: -15 | J11: 5 | K11: cyan
A12: 1 | B12: time | C12: 10 | D12: 240 | E12: 270 | F12: white | G12: Ivd.HCN.B8 | H12: 4 | I12: -15 | J12: 5 | K12: cyan
A13: 1 | B13: time | C13: 10 | D13: 320 | E13: 350 | F13: white | G13: Ivd.HCN.B8 | H13: 4 | I13: -15 | J13: 5 | K13: cyan
A14: 1 | B14: time | C14: 10 | D14: 400 | E14: 430 | F14: white | G14: Ivd.HCN.B8 | H14: 4 | I14: -15 | J14: 5 | K14: cyan
A25: stimulation (.trt) | L25: output variables
B26: Current injection | G26: Voltage clamp | L26: Ivd.leak.B51s | M26: type "all" in first cell to output all graphed variables or type individual channels
B27: neuron | C27: start | D27: stop | E27: magnitude | G27: neuron | H27: start | I27: stop | J27: potential | L27: V.B51s
G28: B8 | H28: 0 | I28: 430 | J28: -40 | L28: Ivd.leak.B64s
G29: B8 | H29: 6.25 | I29: 10.25 | J29: -110 | L29: V.B64s
G30: B8 | H30: 86.25 | I30: 90.25 | J30: -100 | L30: Ivd.HCN.B8
G31: B8 | H31: 166.25 | I31: 170.25 | J31: -90 | L31: V.B8
G32: B8 | H32: 246.25 | I32: 250.25 | J32: -80
G33: B8 | H33: 326.25 | I33: 330.25 | J33: -70
G34: B8 | H34: 406.25 | I34: 410.25 | J34: -60
G35: B51s | H35: 0 | I35: 430 | J35: -40
G36: B64s | H36: 0 | I36: 430 | J36: -40

Sheet cs_g
C1: Postsynaptic
C2: =Neu!$B4 -> B51s | D2: =Neu!$B5 -> B64s | E2: =Neu!$B6 -> B8 | F2: =Neu!$B7 -> 0 | G2: =Neu!$B8 -> 0 | H2: =Neu!$B9 -> 0 | I2: =Neu!$B10 -> 0 | J2: =Neu!$B11 -> 0 | K2: =Neu!$B12 -> 0 | L2: =Neu!$B13 -> 0 | M2: =Neu!$B14 -> 0 | N2: =Neu!$B15 -> 0 | O2: =Neu!$B16 -> 0 | P2: =Neu!$B17 -> 0 | Q2: =Neu!$B18 -> 0 | R2: =Neu!$B19 -> 0 | S2: =Neu!$B20 -> 0 | T2: =Neu!$B21 -> 0 | U2: =Neu!$B22 -> 0 | V2: =Neu!$B23 -> 0 | W2: =Neu!$B24 -> 0
A3: Presynaptic | B3: =Neu!B4 -> B51s | X3: fast | Y3: Colorbar
X4: slow | Y4: =MAX($C$3:$W$44)-(ROW(Y4)-4)*0.5 -> 0
