Workbook

Sheet Neu
D1: File | E1: leak | G1: Na | AH1: Ka | BI1: Kv | CJ1: K_main | DK1: K_main_FALSE | EL1: CaN | FM1: Kca | GN1: Kcaf | HO1: Napp | IP1: HCN | JQ1: K_pp
E2: vdg | G2: vdg | J2: A | V2: B | AH2: vdg | AK2: A | AW2: B | BI2: vdg | BL2: A | BX2: B | CJ2: vdg | CM2: A | CY2: B | DK2: vdg | DN2: A | DZ2: B | EL2: vdg | EO2: A | FA2: B | FM2: vdg | FP2: A | GB2: B | GN2: vdg | GQ2: A | HC2: B | HO2: vdg | HR2: A | ID2: B | IP2: vdg | IS2: A | JE2: B | JQ2: vdg | JT2: A | KF2: B
B3: Name | C3: Template | D3: cm | E3: g | F3: E | G3: g | H3: p | I3: E | J3: An | K3: h | L3: s | M3: p | N3: tmx | O3: tmin | P3: th1 | Q3: ts1 | R3: tp1 | S3: th2 | T3: ts2 | U3: tp2 | V3: Bn | W3: h | X3: s | Y3: p | Z3: tmx | AA3: tmin | AB3: th1 | AC3: ts1 | AD3: tp1 | AE3: th2 | AF3: ts2 | AG3: tp2 | AH3: g | AI3: p | AJ3: E | AK3: An | AL3: h | AM3: s | AN3: p | AO3: tmx | AP3: tmin | AQ3: th1 | AR3: ts1 | AS3: tp1 | AT3: th2 | AU3: ts2 | AV3: tp2 | AW3: Bn | AX3: h | AY3: s | AZ3: p | BA3: tmx | BB3: tmin | BC3: th1 | BD3: ts1 | BE3: tp1 | BF3: th2 | BG3: ts2 | BH3: tp2 | BI3: g | BJ3: p | BK3: E | BL3: An | BM3: h | BN3: s | BO3: p | BP3: tmx | BQ3: tmin | BR3: th1 | BS3: ts1 | BT3: tp1 | BU3: th2 | BV3: ts2 | BW3: tp2 | BX3: Bn | BY3: h | BZ3: s | CA3: p | CB3: tmx | CC3: tmin | CD3: th1 | CE3: ts1 | CF3: tp1 | CG3: th2 | CH3: ts2 | CI3: tp2 | CJ3: g | CK3: p | CL3: E | CM3: An | CN3: h | CO3: s | CP3: p | CQ3: tmx | CR3: tmin | CS3: th1 | CT3: ts1 | CU3: tp1 | CV3: th2 | CW3: ts2 | CX3: tp2 | CY3: Bn | CZ3: h | DA3: s | DB3: p | DC3: tmx | DD3: tmin | DE3: th1 | DF3: ts1 | DG3: tp1 | DH3: th2 | DI3: ts2 | DJ3: tp2 | DK3: g | DL3: p | DM3: E | DN3: An | DO3: h | DP3: s | DQ3: p | DR3: tmx | DS3: tmin | DT3: th1 | DU3: ts1 | DV3: tp1 | DW3: th2 | DX3: ts2 | DY3: tp2 | DZ3: Bn | EA3: h | EB3: s | EC3: p | ED3: tmx | EE3: tmin | EF3: th1 | EG3: ts1 | EH3: tp1 | EI3: th2 | EJ3: ts2 | EK3: tp2 | EL3: g | EM3: p | EN3: E | EO3: An | EP3: h | EQ3: s | ER3: p | ES3: tmx | ET3: tmin | EU3: th1 | EV3: ts1 | EW3: tp1 | EX3: th2 | EY3: ts2 | EZ3: tp2 | FA3: Bn | FB3: h | FC3: s | FD3: p | FE3: tmx | FF3: tmin | FG3: th1 | FH3: ts1 | FI3: tp1 | FJ3: th2 | FK3: ts2 | FL3: tp2 | FM3: g | FN3: p | FO3: E | FP3: An | FQ3: h | FR3: s | FS3: p | FT3: tmx | FU3: tmin | FV3: th1 | FW3: ts1 | FX3: tp1 | FY3: th2 | FZ3: ts2 | GA3: tp2 | GB3: Bn | GC3: h | GD3: s | GE3: p | GF3: tmx | GG3: tmin | GH3: th1 | GI3: ts1 | GJ3: tp1 | GK3: th2 | GL3: ts2 | GM3: tp2 | GN3: g | GO3: p | GP3: E | GQ3: An | GR3: h | GS3: s | GT3: p | GU3: tmx | GV3: tmin | GW3: th1 | GX3: ts1 | GY3: tp1 | GZ3: th2 | HA3: ts2 | HB3: tp2 | HC3: Bn | HD3: h | HE3: s | HF3: p | HG3: tmx | HH3: tmin | HI3: th1 | HJ3: ts1 | HK3: tp1 | HL3: th2 | HM3: ts2 | HN3: tp2 | HO3: g | HP3: p | HQ3: E | HR3: An | HS3: h | HT3: s | HU3: p | HV3: tmx | HW3: tmin | HX3: th1 | HY3: ts1 | HZ3: tp1 | IA3: th2 | IB3: ts2 | IC3: tp2 | ID3: Bn | IE3: h | IF3: s | IG3: p | IH3: tmx | II3: tmin | IJ3: th1 | IK3: ts1 | IL3: tp1 | IM3: th2 | IN3: ts2 | IO3: tp2 | IP3: g | IQ3: p | IR3: E | IS3: An | IT3: h | IU3: s | IV3: p | IW3: tmx | IX3: tmin | IY3: th1 | IZ3: ts1 | JA3: tp1 | JB3: th2 | JC3: ts2 | JD3: tp2 | JE3: Bn | JF3: h | JG3: s | JH3: p | JI3: tmx | JJ3: tmin | JK3: th1 | JL3: ts1 | JM3: tp1 | JN3: th2 | JO3: ts2 | JP3: tp2 | JQ3: g | JR3: p | JS3: E | JT3: An | JU3: h | JV3: s | JW3: p | JX3: tmx | JY3: tmin | JZ3: th1 | KA3: ts1 | KB3: tp1 | KC3: th2 | KD3: ts2 | KE3: tp2 | KF3: Bn | KG3: h | KH3: s | KI3: p | KJ3: tmx | KK3: tmin | KL3: th1 | KM3: ts1 | KN3: tp1 | KO3: th2 | KP3: ts2 | KQ3: tp2
A4: =Neu!B4 -> B63ls | B4: B63ls | D4: 0.003 | E4: 0.025 | F4: -60 | G4: 7.5 | H4: 1 | I4: 50 | J4: 0 | K4: -42.1 | L4: 4.8 | M4: 3 | N4: 0.0015 | O4: 0.00045 | P4: -32.7 | Q4: 1.85 | R4: 1 | V4: 0 | W4: -51.5 | X4: 9.2 | Y4: 1 | Z4: 0.01 | AA4: 0.0024 | AB4: -39.2 | AC4: 3.5 | AD4: 1 | AH4: 50 | AI4: 4 | AJ4: -70 | AK4: 0 | AL4: -26.4 | AM4: 8.8 | AN4: 1 | AO4: 0.027 | AP4: 0.00216 | AQ4: -24 | AR4: 11.7 | AS4: 1 | AW4: 0.15 | AX4: -16.4 | AY4: 1.5 | AZ4: 2 | BA4: 0.2 | BB4: 0.02 | BC4: -24 | BD4: 8.3 | BE4: 1
A5: =Neu!B5 -> B63la | B5: B63la | D5: 0.003 | E5: 0.0012 | F5: -60 | G5: 7.5 | H5: 1 | I5: 50 | J5: 0 | K5: -42.1 | L5: 4.8 | M5: 3 | N5: 0.0015 | O5: 0.00045 | P5: -32.7 | Q5: 1.85 | R5: 1 | V5: 0 | W5: -51.5 | X5: 9.2 | Y5: 1 | Z5: 0.01 | AA5: 0.0024 | AB5: -39.2 | AC5: 3.5 | AD5: 1 | AH5: 60 | AI5: 4 | AJ5: -70 | AK5: 0 | AL5: -26.4 | AM5: 8.8 | AN5: 1 | AO5: 0.027 | AP5: 0.00216 | AQ5: -24 | AR5: 11.7 | AS5: 1 | AW5: 0.15 | AX5: -16.4 | AY5: 1.5 | AZ5: 2 | BA5: 0.2 | BB5: 0.02 | BC5: -24 | BD5: 8.3 | BE5: 1
A6: =Neu!B6 -> B31rs | B6: B31rs | D6: 0.011 | E6: 0.37 | F6: -60 | AH6: 9.5 | AI6: 1 | AJ6: -85 | AK6: 0 | AL6: -14 | AM6: 20 | AN6: 3 | AO6: 0.02 | AP6: 0.000275 | AQ6: -88 | AR6: 30 | AS6: 1 | AT6: -50 | AU6: -5 | AV6: 1 | AW6: 0 | AX6: -30 | AY6: 11 | AZ6: 1 | BA6: 0.33 | BB6: 0.008 | BC6: -80 | BD6: 70 | BE6: 1 | BF6: -73 | BG6: -9 | BH6: 1 | BI6: 15 | BJ6: 1 | BK6: -70 | BL6: 0 | BM6: 6 | BN6: 14 | BO6: 1 | BP6: 0.014 | BQ6: 0.003 | BR6: 20 | BS6: 7 | BT6: 1 | BU6: -15 | BV6: -6 | BW6: 1 | BX6: 0 | BY6: -31 | BZ6: 7 | CA6: 1 | CB6: 0.875 | CC6: 0.11 | CD6: -15 | CE6: 6 | CF6: 1 | CG6: -73 | CH6: -9 | CI6: 1 | CJ6: 5 | CK6: 1 | CL6: -35 | CM6: 0 | CN6: 19 | CO6: 11 | CP6: 1 | CQ6: 0.014 | CR6: 0.003 | CS6: 20 | CT6: 7 | CU6: 1 | CV6: -15 | CW6: -6 | CX6: 1 | CY6: 0 | CZ6: 1000 | DA6: 7 | DB6: 1 | DK6: 200 | DL6: 1 | DM6: -35 | DN6: 0 | DO6: -20 | DP6: 2 | DQ6: 1 | DR6: 0.014 | DS6: 0.003 | DT6: 20 | DU6: 7 | DV6: 1 | DW6: -15 | DX6: -6 | DY6: 1 | DZ6: 0 | EA6: 1000 | EB6: 7 | EC6: 1
A7: =Neu!B7 -> B64ls | B7: B64ls | D7: 0.003 | E7: 0.05 | F7: -60 | G7: 0.9 | H7: 1 | I7: 50 | J7: 0 | K7: -42.1 | L7: 4.8 | M7: 3 | N7: 0.0015 | O7: 0.00045 | P7: -32.7 | Q7: 1.85 | R7: 1 | V7: 0 | W7: -51.5 | X7: 9.2 | Y7: 1 | Z7: 0.01 | AA7: 0.0024 | AB7: -39.2 | AC7: 3.5 | AD7: 1 | AH7: 3 | AI7: 4 | AJ7: -70 | AK7: 0 | AL7: -33 | AM7: 8.8 | AN7: 1 | AO7: 0.027 | AP7: 0.003 | AQ7: -24 | AR7: 11.7 | AS7: 1 | AW7: 0.15 | AX7: -16.4 | AY7: 1.5 | AZ7: 2 | BA7: 0.2 | BB7: 0.02 | BC7: -24 | BD7: 8.3 | BE7: 1 | BI7: 70 | BJ7: 4 | BK7: -70 | BL7: 0 | BM7: -19 | BN7: 8.8 | BO7: 1 | BP7: 0.27 | BQ7: 0.0216 | BR7: -24 | BS7: 11.7 | BT7: 1 | BX7: 0.15 | BY7: -16.4 | BZ7: 1.5 | CA7: 2 | CB7: 2 | CC7: 0.2 | CD7: -24 | CE7: 8.3 | CF7: 1 | HO7: 4.6 | HP7: 3 | HQ7: 50 | HR7: 0 | HS7: -48 | HT7: 4 | HU7: 2 | HV7: 0.16 | HW7: 0.00015 | HX7: -30 | HY7: 4 | HZ7: 4 | IA7: -50 | IB7: -4 | IC7: 4 | ID7: 0 | IE7: -57 | IF7: 5 | IG7: 2 | IH7: 2 | II7: 0.2 | IJ7: -44 | IK7: -3 | IL7: 4
A8: =Neu!B8 -> B64la | B8: B64la | D8: 0.003 | E8: 0.03 | F8: -60 | G8: 4 | H8: 1 | I8: 50 | J8: 0 | K8: -42.1 | L8: 4.8 | M8: 3 | N8: 0.0015 | O8: 0.00045 | P8: -32.7 | Q8: 1.85 | R8: 1 | V8: 0 | W8: -51.5 | X8: 9.2 | Y8: 1 | Z8: 0.01 | AA8: 0.0024 | AB8: -39.2 | AC8: 3.5 | AD8: 1 | AH8: 19 | AI8: 4 | AJ8: -70 | AK8: 0 | AL8: -33 | AM8: 8.8 | AN8: 1 | AO8: 0.027 | AP8: 0.003 | AQ8: -24 | AR8: 11.7 | AS8: 1 | AW8: 0.15 | AX8: -16.4 | AY8: 1.5 | AZ8: 2 | BA8: 0.2 | BB8: 0.02 | BC8: -24 | BD8: 8.3 | BE8: 1 | HO8: 0.01 | HP8: 3 | HQ8: 50 | HR8: 0 | HS8: -48 | HT8: 4 | HU8: 2 | HV8: 0.005 | HW8: 0.04 | HX8: -56 | HY8: -3 | HZ8: 4 | IA8: -30 | IB8: -3 | IC8: 4 | ID8: 0 | IE8: -56 | IF8: 5 | IG8: 2 | IH8: 3 | II8: 0.05 | IJ8: -40 | IK8: -2 | IL8: 4
A9: =Neu!B9 -> B63rs | B9: B63rs | D9: 0.003 | E9: 0.025 | F9: -60 | G9: 7.5 | H9: 1 | I9: 50 | J9: 0 | K9: -42.1 | L9: 4.8 | M9: 3 | N9: 0.0015 | O9: 0.00045 | P9: -32.7 | Q9: 1.85 | R9: 1 | V9: 0 | W9: -51.5 | X9: 9.2 | Y9: 1 | Z9: 0.01 | AA9: 0.0024 | AB9: -39.2 | AC9: 3.5 | AD9: 1 | AH9: 50 | AI9: 4 | AJ9: -70 | AK9: 0 | AL9: -26.4 | AM9: 8.8 | AN9: 1 | AO9: 0.027 | AP9: 0.00216 | AQ9: -24 | AR9: 11.7 | AS9: 1 | AW9: 0.15 | AX9: -16.4 | AY9: 1.5 | AZ9: 2 | BA9: 0.2 | BB9: 0.02 | BC9: -24 | BD9: 8.3 | BE9: 1
A10: =Neu!B10 -> B63ra | B10: B63ra | D10: 0.003 | E10: 0.0012 | F10: -60 | G10: 7.5 | H10: 1 | I10: 50 | J10: 0 | K10: -42.1 | L10: 4.8 | M10: 3 | N10: 0.0015 | O10: 0.00045 | P10: -32.7 | Q10: 1.85 | R10: 1 | V10: 0 | W10: -51.5 | X10: 9.2 | Y10: 1 | Z10: 0.01 | AA10: 0.0024 | AB10: -39.2 | AC10: 3.5 | AD10: 1 | AH10: 60 | AI10: 4 | AJ10: -70 | AK10: 0 | AL10: -26.4 | AM10: 8.8 | AN10: 1 | AO10: 0.027 | AP10: 0.00216 | AQ10: -24 | AR10: 11.7 | AS10: 1 | AW10: 0.15 | AX10: -16.4 | AY10: 1.5 | AZ10: 2 | BA10: 0.2 | BB10: 0.02 | BC10: -24 | BD10: 8.3 | BE10: 1
A11: =Neu!B11 -> B31ls | B11: B31ls | D11: 0.011 | E11: 0.37 | F11: -60 | G11: 0.8 | H11: 3 | I11: -2 | J11: 0 | K11: -50 | L11: 4 | M11: 1 | N11: 1.6 | AH11: 9.5 | AI11: 1 | AJ11: -85 | AK11: 0 | AL11: -14 | AM11: 20 | AN11: 3 | AO11: 0.02 | AP11: 0.000275 | AQ11: -88 | AR11: 30 | AS11: 1 | AT11: -50 | AU11: -5 | AV11: 1 | AW11: 0 | AX11: -30 | AY11: 11 | AZ11: 1 | BA11: 0.33 | BB11: 0.008 | BC11: -80 | BD11: 70 | BE11: 1 | BF11: -73 | BG11: -9 | BH11: 1 | BI11: 15 | BJ11: 1 | BK11: -70 | BL11: 0 | BM11: 6 | BN11: 14 | BO11: 1 | BP11: 0.014 | BQ11: 0.003 | BR11: 20 | BS11: 7 | BT11: 1 | BU11: -15 | BV11: -6 | BW11: 1 | BX11: 0 | BY11: -31 | BZ11: 7 | CA11: 1 | CB11: 0.875 | CC11: 0.11 | CD11: -15 | CE11: 6 | CF11: 1 | CG11: -73 | CH11: -9 | CI11: 1 | CJ11: 5 | CK11: 1 | CL11: -35 | CM11: 0 | CN11: 19 | CO11: 11 | CP11: 1 | CQ11: 0.014 | CR11: 0.003 | CS11: 20 | CT11: 7 | CU11: 1 | CV11: -15 | CW11: -6 | CX11: 1 | CY11: 0 | CZ11: 1000 | DA11: 7 | DB11: 1 | DK11: 200 | DL11: 1 | DM11: -35 | DN11: 0 | DO11: -20 | DP11: 2 | DQ11: 1 | DR11: 0.014 | DS11: 0.003 | DT11: 20 | DU11: 7 | DV11: 1 | DW11: -15 | DX11: -6 | DY11: 1 | DZ11: 0 | EA11: 1000 | EB11: 7 | EC11: 1
A12: =Neu!B12 -> B64rs | B12: B64rs | D12: 0.003 | E12: 0.05 | F12: -60 | G12: 0.9 | H12: 1 | I12: 50 | J12: 0 | K12: -42.1 | L12: 4.8 | M12: 3 | N12: 0.0015 | O12: 0.00045 | P12: -32.7 | Q12: 1.85 | R12: 1 | V12: 0 | W12: -51.5 | X12: 9.2 | Y12: 1 | Z12: 0.01 | AA12: 0.0024 | AB12: -39.2 | AC12: 3.5 | AD12: 1 | AH12: 3 | AI12: 4 | AJ12: -70 | AK12: 0 | AL12: -33 | AM12: 8.8 | AN12: 1 | AO12: 0.027 | AP12: 0.003 | AQ12: -24 | AR12: 11.7 | AS12: 1 | AW12: 0.15 | AX12: -16.4 | AY12: 1.5 | AZ12: 2 | BA12: 0.2 | BB12: 0.02 | BC12: -24 | BD12: 8.3 | BE12: 1 | BI12: 70 | BJ12: 4 | BK12: -70 | BL12: 0 | BM12: -19 | BN12: 8.8 | BO12: 1 | BP12: 0.27 | BQ12: 0.0216 | BR12: -24 | BS12: 11.7 | BT12: 1 | BX12: 0.15 | BY12: -16.4 | BZ12: 1.5 | CA12: 2 | CB12: 2 | CC12: 0.2 | CD12: -24 | CE12: 8.3 | CF12: 1 | HO12: 4.6 | HP12: 3 | HQ12: 50 | HR12: 0 | HS12: -48 | HT12: 4 | HU12: 2 | HV12: 0.16 | HW12: 0.00015 | HX12: -30 | HY12: 4 | HZ12: 4 | IA12: -50 | IB12: -4 | IC12: 4 | ID12: 0 | IE12: -57 | IF12: 5 | IG12: 2 | IH12: 2 | II12: 0.2 | IJ12: -44 | IK12: -3 | IL12: 4
A13: =Neu!B13 -> B64ra | B13: B64ra | D13: 0.003 | E13: 0.01 | F13: -60 | G13: 4 | H13: 1 | I13: 50 | J13: 0 | K13: -42.1 | L13: 4.8 | M13: 3 | N13: 0.0015 | O13: 0.00045 | P13: -32.7 | Q13: 1.85 | R13: 1 | V13: 0 | W13: -51.5 | X13: 9.2 | Y13: 1 | Z13: 0.01 | AA13: 0.0024 | AB13: -39.2 | AC13: 3.5 | AD13: 1 | AH13: 19 | AI13: 4 | AJ13: -70 | AK13: 0 | AL13: -33 | AM13: 8.8 | AN13: 1 | AO13: 0.027 | AP13: 0.003 | AQ13: -24 | AR13: 11.7 | AS13: 1 | AW13: 0.15 | AX13: -16.4 | AY13: 1.5 | AZ13: 2 | BA13: 0.2 | BB13: 0.02 | BC13: -24 | BD13: 8.3 | BE13: 1 | HO13: 0.01 | HP13: 3 | HQ13: 50 | HR13: 0 | HS13: -48 | HT13: 4 | HU13: 2 | HV13: 0.005 | HW13: 0.04 | HX13: -56 | HY13: -3 | HZ13: 4 | IA13: -30 | IB13: -3 | IC13: 4 | ID13: 0 | IE13: -56 | IF13: 5 | IG13: 2 | IH13: 3 | II13: 0.05 | IJ13: -40 | IK13: -2 | IL13: 4
JX25: 4
D29: Ion pools | O29: Conductance to ion | Z29: Ion to conductance | BD29: Initial voltage
D30: Name | E30: ion | F30: K1 | G30: K2 | H30: ion | I30: K1 | J30: K2 | K30: ion | L30: K1 | M30: K2 | O30: Name | P30: ch | Q30: ion | R30: ch | S30: ion | T30: ch | U30: ion | V30: ch | W30: ion | Z30: Name | AA30: ion | AB30: ch | AC30: opt1 | AD30: opt2 | AE30: p1 | AF30: p2 | AG30: b | AH30: ion | AI30: ch | AJ30: opt1 | AK30: opt2 | AL30: p1 | AM30: p2 | AN30: b | AO30: ion | AP30: ch | AQ30: opt1 | AR30: opt2 | AS30: p1 | AT30: p2 | AU30: b | AV30: ion | AW30: ch | AX30: opt1 | AY30: opt2 | AZ30: p1 | BA30: p2 | BB30: b | BD30: Name | BE30: mV
D31: =Neu!$B4 -> B63ls | O31: =Neu!$B4 -> B63ls | Z31: =Neu!$B4 -> B63ls | BD31: =Neu!$B4 -> B63ls | BE31: -62
D32: =Neu!$B5 -> B63la | E32: Na | F32: 14 | G32: 0.4 | O32: =Neu!$B5 -> B63la | P32: Na | Q32: Na | Z32: =Neu!$B5 -> B63la | BD32: =Neu!$B5 -> B63la | BE32: -62
D33: =Neu!$B6 -> B31rs | O33: =Neu!$B6 -> B31rs | Z33: =Neu!$B6 -> B31rs | BD33: =Neu!$B6 -> B31rs | BE33: -62
D34: =Neu!$B7 -> B64ls | O34: =Neu!$B7 -> B64ls | Z34: =Neu!$B7 -> B64ls | BD34: =Neu!$B7 -> B64ls | BE34: -62
D35: =Neu!$B8 -> B64la | O35: =Neu!$B8 -> B64la | Z35: =Neu!$B8 -> B64la | BD35: =Neu!$B8 -> B64la | BE35: -62
D36: =Neu!$B9 -> B63rs | O36: =Neu!$B9 -> B63rs | Z36: =Neu!$B9 -> B63rs | BD36: =Neu!$B9 -> B63rs | BE36: -62
D37: =Neu!$B10 -> B63ra | O37: =Neu!$B10 -> B63ra | Z37: =Neu!$B10 -> B63ra | BD37: =Neu!$B10 -> B63ra | BE37: -62
D38: =Neu!$B11 -> B31ls | O38: =Neu!$B11 -> B31ls | Z38: =Neu!$B11 -> B31ls | BD38: =Neu!$B11 -> B31ls | BE38: -62
D39: =Neu!$B12 -> B64rs | O39: =Neu!$B12 -> B64rs | Z39: =Neu!$B12 -> B64rs | BD39: =Neu!$B12 -> B64rs | BE39: -62
D40: =Neu!$B13 -> B64ra | O40: =Neu!$B13 -> B64ra | Z40: =Neu!$B13 -> B64ra | BD40: =Neu!$B13 -> B64ra | BE40: -62
D41: =Neu!$B14 -> 0 | O41: =Neu!$B14 -> 0 | Z41: =Neu!$B14 -> 0
D42: =Neu!$B15 -> 0 | O42: =Neu!$B15 -> 0 | Z42: =Neu!$B15 -> 0
D43: =Neu!$B16 -> 0 | O43: =Neu!$B16 -> 0 | Z43: =Neu!$B16 -> 0
BD47: =Neu!$B21 -> 0
BD48: =Neu!$B22 -> 0
D49: =Neu!$B17 -> 0 | O49: =Neu!$B17 -> 0 | Z49: =Neu!$B17 -> 0 | BD49: =Neu!$B23 -> 0
BD50: =Neu!$B24 -> 0
D51: =Neu!$B24 -> 0 | O51: =Neu!$B24 -> 0 | Z51: =Neu!$B24 -> 0 | BD51: =Neu!$B25 -> 0
F54: d(ion)/dt = K1*(K2*sum(Ivd) - ion) | AC54: opt1 1: | AD54: fBr = BR | AG54: channel requires ion | AM54: opt2 1: | AN54: dBR/dt = (ion - BR)/p1
AC55: 2: | AD55: fBr = 1 + BR | AG55: ion enhances channel only | AM55: 2: | AN55: BR = ion/(p1 + ion)
AC56: 3: | AD56: fBr = 1/(1 + b*(BR)) | AG56: ion inhibits channel only | AM56: 3: | AN56: BR = ion/(p1+ ion) + 1
C57: An | D57: minimum activation | AM57: 4: | AN57: BR = 1/(1 + p1*ion)
C58: h | D58: half in/activation | AM58: 5: | AN58: BR = exp((p1+ ion)/p2)
C59: s | D59: slope
...

Sheet FOR AVY31.smu
F1: syntax | L1: example variables | M1: IVDxREG | N1: currrent by conductance and regulation | T1: example synapses
A2: smu | B2: name | C2: FOR AVY31 | D2: graph | E2: 1 | F2: conductance | G2: variable.conductance.neuron | M2: V | N2: voltage | Q2: Ics | R2: chem syn current | T2: f_exc | U2: fast excitatory
B3: duration | C3: 60 | D3: store | E3: 1 | F3: example | G3: Ivd.Na.N1 | I3: fBR | J3: fBR.ion.ch.neuron | M3: Ivd | N3: current by voltage gated conductance | Q3: Cion | R3: amount of ion | T3: s_exc | U3: slow excitatory
B4: stepsize | C4: 5e-05 | D4: method | E4: 1 | F4: neuron | G4: variable.neuron | I4: synapse | J4: variable.pre.post.type | M4: A | N4: activation of conductance | Q4: Ies | R4: elec syn current | T4: f_inh | U4: fast inhibitory
B5: red indicates simlation longer than graph duration | F5: example | G5: V.N1 | I5: example | J5: Ics.N1.N4.f_exc | M5: B | N5: Inactivation of conductance | Q5: slex | R5: trt current | T5: s_inh | U5: slow inhibitory
A6: graph (ous) | J6: Ies.N1.N4 | M6: SIVD_reg | N6: for total current
B7: time | G7: variable 1 | L7: variable 2 | Q7: variable 3 | V7: variable 4
A8: Size | B8: variable | C8: # ticks | D8: start | E8: stop | F8: color | G8: variable | H8: # ticks | I8: min | J8: max | K8: color | L8: variable | M8: # ticks | N8: min | O8: max | P8: color | Q8: variable | R8: # ticks | S8: min | T8: max | U8: color | V8: variable | W8: # ticks | X8: min | Y8: max | Z8: color
A9: 1 | B9: time | C9: 12 | D9: 0 | E9: 60 | F9: blue | G9: V.B31rs | H9: 7 | I9: -70 | J9: 0 | K9: red
A10: 1 | B10: time | C10: 12 | D10: 0 | E10: 60 | F10: blue | G10: V.B63ls | H10: 7 | I10: -70 | J10: 0 | K10: blue
A18: stimulation (.trt) | L18: output variables
B19: Current injection | G19: Voltage clamp | L19: all | M19: type "all" in first cell to output all graphed variables or type individual channels
B20: neuron | C20: start | D20: stop | E20: magnitude | G20: neuron | H20: start | I20: stop | J20: potential
B21: B31rs | C21: 0.5 | D21: 10.5 | E21: 10

Sheet FOR AVY31P.smu
F1: syntax | L1: example variables | M1: IVDxREG | N1: currrent by conductance and regulation | T1: example synapses
A2: smu | B2: name | C2: FOR AVY31P | D2: graph | E2: 1 | F2: conductance | G2: variable.conductance.neuron | M2: V | N2: voltage | Q2: Ics | R2: chem syn current | T2: f_exc | U2: fast excitatory
B3: duration | C3: 60 | D3: store | E3: 1 | F3: example | G3: Ivd.Na.N1 | I3: fBR | J3: fBR.ion.ch.neuron | M3: Ivd | N3: current by voltage gated conductance | Q3: Cion | R3: amount of ion | T3: s_exc | U3: slow excitatory
B4: stepsize | C4: 5e-05 | D4: method | E4: 1 | F4: neuron | G4: variable.neuron | I4: synapse | J4: variable.pre.post.type | M4: A | N4: activation of conductance | Q4: Ies | R4: elec syn current | T4: f_inh | U4: fast inhibitory
B5: red indicates simlation longer than graph duration | F5: example | G5: V.N1 | I5: example | J5: Ics.N1.N4.f_exc | M5: B | N5: Inactivation of conductance | Q5: slex | R5: trt current | T5: s_inh | U5: slow inhibitory
A6: graph (ous) | J6: Ies.N1.N4 | M6: SIVD_reg | N6: for total current
B7: time | G7: variable 1 | L7: variable 2 | Q7: variable 3 | V7: variable 4
A8: Size | B8: variable | C8: # ticks | D8: start | E8: stop | F8: color | G8: variable | H8: # ticks | I8: min | J8: max | K8: color | L8: variable | M8: # ticks | N8: min | O8: max | P8: color | Q8: variable | R8: # ticks | S8: min | T8: max | U8: color | V8: variable | W8: # ticks | X8: min | Y8: max | Z8: color
A9: 1 | B9: time | C9: 12 | D9: 0 | E9: 60 | F9: blue | G9: V.B31ls | H9: 7 | I9: -70 | J9: 0 | K9: red
A10: 1 | B10: time | C10: 12 | D10: 0 | E10: 60 | F10: blue | G10: V.B63rs | H10: 7 | I10: -70 | J10: 0 | K10: blue
A18: stimulation (.trt) | L18: output variables
B19: Current injection | G19: Voltage clamp | L19: all | M19: type "all" in first cell to output all graphed variables or type individual channels
B20: neuron | C20: start | D20: stop | E20: magnitude | G20: neuron | H20: start | I20: stop | J20: potential
B21: B31ls | C21: 0.5 | D21: 10.5 | E21: 10

Sheet FOR AVY63.smu
F1: syntax | L1: example variables | M1: IVDxREG | N1: currrent by conductance and regulation | T1: example synapses
A2: smu | B2: name | C2: FOR AVY63 | D2: graph | E2: 1 | F2: conductance | G2: variable.conductance.neuron | M2: V | N2: voltage | Q2: Ics | R2: chem syn current | T2: f_exc | U2: fast excitatory
B3: duration | C3: 60 | D3: store | E3: 1 | F3: example | G3: Ivd.Na.N1 | I3: fBR | J3: fBR.ion.ch.neuron | M3: Ivd | N3: current by voltage gated conductance | Q3: Cion | R3: amount of ion | T3: s_exc | U3: slow excitatory
B4: stepsize | C4: 5e-05 | D4: method | E4: 1 | F4: neuron | G4: variable.neuron | I4: synapse | J4: variable.pre.post.type | M4: A | N4: activation of conductance | Q4: Ies | R4: elec syn current | T4: f_inh | U4: fast inhibitory
B5: red indicates simlation longer than graph duration | F5: example | G5: V.N1 | I5: example | J5: Ics.N1.N4.f_exc | M5: B | N5: Inactivation of conductance | Q5: slex | R5: trt current | T5: s_inh | U5: slow inhibitory
A6: graph (ous) | J6: Ies.N1.N4 | M6: SIVD_reg | N6: for total current
B7: time | G7: variable 1 | L7: variable 2 | Q7: variable 3 | V7: variable 4
A8: Size | B8: variable | C8: # ticks | D8: start | E8: stop | F8: color | G8: variable | H8: # ticks | I8: min | J8: max | K8: color | L8: variable | M8: # ticks | N8: min | O8: max | P8: color | Q8: variable | R8: # ticks | S8: min | T8: max | U8: color | V8: variable | W8: # ticks | X8: min | Y8: max | Z8: color
A9: 1 | B9: time | C9: 12 | D9: 0 | E9: 60 | F9: blue | G9: V.B31rs | H9: 7 | I9: -70 | J9: 0 | K9: red
A10: 1 | B10: time | C10: 12 | D10: 0 | E10: 60 | F10: blue | G10: V.B63ls | H10: 7 | I10: -70 | J10: 0 | K10: blue
A18: stimulation (.trt) | L18: output variables
B19: Current injection | G19: Voltage clamp | L19: all | M19: type "all" in first cell to output all graphed variables or type individual channels
B20: neuron | C20: start | D20: stop | E20: magnitude | G20: neuron | H20: start | I20: stop | J20: potential
B21: B63ls | C21: 0.5 | D21: 10.5 | E21: 1

Sheet For AVY63P.smu
F1: syntax | L1: example variables | M1: IVDxREG | N1: currrent by conductance and regulation | T1: example synapses
A2: smu | B2: name | C2: FOR AVY63P | D2: graph | E2: 1 | F2: conductance | G2: variable.conductance.neuron | M2: V | N2: voltage | Q2: Ics | R2: chem syn current | T2: f_exc | U2: fast excitatory
B3: duration | C3: 60 | D3: store | E3: 1 | F3: example | G3: Ivd.Na.N1 | I3: fBR | J3: fBR.ion.ch.neuron | M3: Ivd | N3: current by voltage gated conductance | Q3: Cion | R3: amount of ion | T3: s_exc | U3: slow excitatory
B4: stepsize | C4: 5e-05 | D4: method | E4: 1 | F4: neuron | G4: variable.neuron | I4: synapse | J4: variable.pre.post.type | M4: A | N4: activation of conductance | Q4: Ies | R4: elec syn current | T4: f_inh | U4: fast inhibitory
B5: red indicates simlation longer than graph duration | F5: example | G5: V.N1 | I5: example | J5: Ics.N1.N4.f_exc | M5: B | N5: Inactivation of conductance | Q5: slex | R5: trt current | T5: s_inh | U5: slow inhibitory
A6: graph (ous) | J6: Ies.N1.N4 | M6: SIVD_reg | N6: for total current
B7: time | G7: variable 1 | L7: variable 2 | Q7: variable 3 | V7: variable 4
A8: Size | B8: variable | C8: # ticks | D8: start | E8: stop | F8: color | G8: variable | H8: # ticks | I8: min | J8: max | K8: color | L8: variable | M8: # ticks | N8: min | O8: max | P8: color | Q8: variable | R8: # ticks | S8: min | T8: max | U8: color | V8: variable | W8: # ticks | X8: min | Y8: max | Z8: color
A9: 1 | B9: time | C9: 12 | D9: 0 | E9: 60 | F9: blue | G9: V.B31ls | H9: 7 | I9: -70 | J9: 0 | K9: red
A10: 1 | B10: time | C10: 12 | D10: 0 | E10: 60 | F10: blue | G10: V.B63rs | H10: 7 | I10: -70 | J10: 0 | K10: blue
A18: stimulation (.trt) | L18: output variables
B19: Current injection | G19: Voltage clamp | L19: all | M19: type "all" in first cell to output all graphed variables or type individual channels
B20: neuron | C20: start | D20: stop | E20: magnitude | G20: neuron | H20: start | I20: stop | J20: potential
B21: B63rs | C21: 0.5 | D21: 10.5 | E21: 1

Sheet BMP64_l.smu
F1: syntax | L1: example variables | M1: IVDxREG | N1: currrent by conductance and regulation | T1: example synapses
A2: smu | B2: name | C2: BMP64_l | D2: graph | E2: 1 | F2: conductance | G2: variable.conductance.neuron | M2: V | N2: voltage | Q2: Ics | R2: chem syn current | T2: f_exc | U2: fast excitatory
B3: duration | C3: 7 | D3: store | E3: 1 | F3: example | G3: Ivd.Na.N1 | I3: fBR | J3: fBR.ion.ch.neuron | M3: Ivd | N3: current by voltage gated conductance | Q3: Cion | R3: amount of ion | T3: s_exc | U3: slow excitatory
B4: stepsize | C4: 5e-05 | D4: method | E4: 1 | F4: neuron | G4: variable.neuron | I4: synapse | J4: variable.pre.post.type | M4: A | N4: activation of conductance | Q4: Ies | R4: elec syn current | T4: f_inh | U4: fast inhibitory
B5: red indicates simlation longer than graph duration | F5: example | G5: V.N1 | I5: example | J5: Ics.N1.N4.f_exc | M5: B | N5: Inactivation of conductance | Q5: slex | R5: trt current | T5: s_inh | U5: slow inhibitory
A6: graph (ous) | J6: Ies.N1.N4 | M6: sIVD_reg | N6: for total current
B7: time | G7: variable 1 | L7: variable 2 | Q7: variable 3 | V7: variable 4
A8: Size | B8: variable | C8: # ticks | D8: start | E8: stop | F8: color | G8: variable | H8: # ticks | I8: min | J8: max | K8: color | L8: variable | M8: # ticks | N8: min | O8: max | P8: color | Q8: variable | R8: # ticks | S8: min | T8: max | U8: color | V8: variable | W8: # ticks | X8: min | Y8: max | Z8: color
A9: 2 | B9: time | C9: 7 | D9: 0 | E9: 7 | F9: blue | G9: V.B64la | H9: 6 | I9: -80 | J9: 160 | K9: yellow | L9: V.B64ls | M9: 8 | N9: -80 | O9: 0 | P9: pink
A10: 1 | B10: time | C10: 7 | D10: 0 | E10: 7 | F10: blue | G10: Ivd.Napp.B64ls | H10: 6 | I10: -5 | J10: 1 | K10: red | L10: Ivd.Ka.B64ls | M10: 6 | N10: 0 | O10: 60 | P10: orange | Q10: Ivd.Kv.B64ls | R10: 6 | S10: -1 | T10: 5 | U10: green
A18: stimulation (.trt) | L18: output variables
B19: Current injection | G19: Voltage clamp | L19: all | M19: type "all" in first cell to output all graphed variables or type individual channels
B20: neuron | C20: start | D20: stop | E20: magnitude | G20: neuron | H20: start | I20: stop | J20: potential
B21: B64ls | C21: 1 | D21: 1.025 | E21: 3

Sheet BMP64_r.smu
F1: syntax | L1: example variables | M1: IVDxREG | N1: currrent by conductance and regulation | T1: example synapses
A2: smu | B2: name | C2: BMP64_r | D2: graph | E2: 1 | F2: conductance | G2: variable.conductance.neuron | M2: V | N2: voltage | Q2: Ics | R2: chem syn current | T2: f_exc | U2: fast excitatory
B3: duration | C3: 7 | D3: store | E3: 1 | F3: example | G3: Ivd.Na.N1 | I3: fBR | J3: fBR.ion.ch.neuron | M3: Ivd | N3: current by voltage gated conductance | Q3: Cion | R3: amount of ion | T3: s_exc | U3: slow excitatory
B4: stepsize | C4: 5e-05 | D4: method | E4: 1 | F4: neuron | G4: variable.neuron | I4: synapse | J4: variable.pre.post.type | M4: A | N4: activation of conductance | Q4: Ies | R4: elec syn current | T4: f_inh | U4: fast inhibitory
B5: red indicates simlation longer than graph duration | F5: example | G5: V.N1 | I5: example | J5: Ics.N1.N4.f_exc | M5: B | N5: Inactivation of conductance | Q5: slex | R5: trt current | T5: s_inh | U5: slow inhibitory
A6: graph (ous) | J6: Ies.N1.N4 | M6: sIVD_reg | N6: for total current
B7: time | G7: variable 1 | L7: variable 2 | Q7: variable 3 | V7: variable 4
A8: Size | B8: variable | C8: # ticks | D8: start | E8: stop | F8: color | G8: variable | H8: # ticks | I8: min | J8: max | K8: color | L8: variable | M8: # ticks | N8: min | O8: max | P8: color | Q8: variable | R8: # ticks | S8: min | T8: max | U8: color | V8: variable | W8: # ticks | X8: min | Y8: max | Z8: color
A9: 1 | B9: time | C9: 7 | D9: 0 | E9: 7 | F9: blue | G9: V.B64ra | H9: 8 | I9: -80 | J9: 0 | K9: yellow | L9: V.B64rs | M9: 8 | N9: -80 | O9: 0 | P9: pink
A10: 1 | B10: time | C10: 7 | D10: 0 | E10: 7 | F10: blue | G10: Ivd.Napp.B64rs | H10: 6 | I10: -5 | J10: 1 | K10: red | L10: Ivd.Ka.B64rs | M10: 6 | N10: -2 | O10: 34 | P10: orange | Q10: Ivd.Kv.B64rs | R10: 6 | S10: -2 | T10: 34 | U10: green
A18: stimulation (.trt) | L18: output variables
B19: Current injection | G19: Voltage clamp | L19: all | M19: type "all" in first cell to output all graphed variables or type individual channels
B20: neuron | C20: start | D20: stop | E20: magnitude | G20: neuron | H20: start | I20: stop | J20: potential
B21: B64rs | C21: 1 | D21: 1.025 | E21: 1.4

Sheet BMP2SIMPLE_l.smu
F1: syntax | L1: example variables | M1: IVDxREG | N1: currrent by conductance and regulation | T1: example synapses
A2: smu | B2: name | C2: BMP2SIMPLE_l | D2: graph | E2: 1 | F2: conductance | G2: variable.conductance.neuron | M2: V | N2: voltage | Q2: Ics | R2: chem syn current | T2: f_exc | U2: fast excitatory
B3: duration | C3: 24 | D3: store | E3: 1 | F3: example | G3: Ivd.Na.N1 | I3: fBR | J3: fBR.ion.ch.neuron | M3: Ivd | N3: current by voltage gated conductance | Q3: Cion | R3: amount of ion | T3: s_exc | U3: slow excitatory
B4: stepsize | C4: 5e-05 | D4: method | E4: 1 | F4: neuron | G4: variable.neuron | I4: synapse | J4: variable.pre.post.type | M4: A | N4: activation of conductance | Q4: Ies | R4: elec syn current | T4: f_inh | U4: fast inhibitory
B5: red indicates simlation longer than graph duration | F5: example | G5: V.N1 | I5: example | J5: Ics.N1.N4.f_exc | M5: B | N5: Inactivation of conductance | Q5: slex | R5: trt current | T5: s_inh | U5: slow inhibitory
A6: graph (ous) | J6: Ies.N1.N4 | M6: SIVD_reg | N6: for total current
B7: time | G7: variable 1 | L7: variable 2 | Q7: variable 3 | V7: variable 4
A8: Size | B8: variable | C8: # ticks | D8: start | E8: stop | F8: color | G8: variable | H8: # ticks | I8: min | J8: max | K8: color | L8: variable | M8: # ticks | N8: min | O8: max | P8: color | Q8: variable | R8: # ticks | S8: min | T8: max | U8: color | V8: variable | W8: # ticks | X8: min | Y8: max | Z8: color
A9: 1 | B9: time | C9: 6 | D9: 0 | E9: 24 | F9: blue | G9: V.B31rs | H9: 7 | I9: -70 | J9: 0 | K9: red
A10: 1 | B10: time | C10: 6 | D10: 0 | E10: 24 | F10: blue | G10: V.B63ls | H10: 7 | I10: -70 | J10: 0 | K10: magenta
A11: 1 | B11: time | C11: 6 | D11: 0 | E11: 24 | F11: blue | G11: V.B64ls | H11: 7 | I11: -70 | J11: 0 | K11: pink | L11: V.B64la | M11: 7 | N11: -70 | O11: 0 | P11: yellow
A12: 1 | B12: time | C12: 6 | D12: 0 | E12: 24 | F12: blue | G12: Ics.B63la.B31rs.s_exc | H12: 5 | I12: -60 | J12: 0 | K12: magenta | L12: Ics.B63la.B64ls.s_exc | M12: 5 | N12: -2 | O12: 0 | P12: blue
A13: 1 | B13: time | C13: 6 | D13: 0 | E13: 24 | F13: blue | G13: Ivd.Napp.B64ls | H13: 6 | I13: -5 | J13: 1 | K13: red | L13: Ivd.Ka.B64ls | M13: 6 | N13: -2 | O13: 34 | P13: orange | Q13: Ivd.Kv.B64ls | R13: 6 | S13: -2 | T13: 34 | U13: green
A16: stimulation (.trt) | L16: output variables
B17: Current injection | G17: Voltage clamp | L17: all | M17: type "all" in first cell to output all graphed variables or type individual channels
B18: neuron | C18: start | D18: stop | E18: magnitude | G18: neuron | H18: start | I18: stop | J18: potential
B19: B63ls | C19: 0.5 | D19: 1.5 | E19: 1.2
B20: B63ls | C20: 2.5 | D20: 3.5 | E20: 1.2
B21: B63ls | C21: 4.5 | D21: 5.5 | E21: 1.2
B22: B63ls | C22: 6.5 | D22: 7.5 | E22: 1.2

Sheet BMP2SIMPLE_r.smu
F1: syntax | L1: example variables | M1: IVDxREG | N1: currrent by conductance and regulation | T1: example synapses
A2: smu | B2: name | C2: BMP2SIMPLE_r | D2: graph | E2: 1 | F2: conductance | G2: variable.conductance.neuron | M2: V | N2: voltage | Q2: Ics | R2: chem syn current | T2: f_exc | U2: fast excitatory
B3: duration | C3: 24 | D3: store | E3: 1 | F3: example | G3: Ivd.Na.N1 | I3: fBR | J3: fBR.ion.ch.neuron | M3: Ivd | N3: current by voltage gated conductance | Q3: Cion | R3: amount of ion | T3: s_exc | U3: slow excitatory
B4: stepsize | C4: 5e-05 | D4: method | E4: 1 | F4: neuron | G4: variable.neuron | I4: synapse | J4: variable.pre.post.type | M4: A | N4: activation of conductance | Q4: Ies | R4: elec syn current | T4: f_inh | U4: fast inhibitory
B5: red indicates simlation longer than graph duration | F5: example | G5: V.N1 | I5: example | J5: Ics.N1.N4.f_exc | M5: B | N5: Inactivation of conductance | Q5: slex | R5: trt current | T5: s_inh | U5: slow inhibitory
A6: graph (ous) | J6: Ies.N1.N4 | M6: SIVD_reg | N6: for total current
B7: time | G7: variable 1 | L7: variable 2 | Q7: variable 3 | V7: variable 4
A8: Size | B8: variable | C8: # ticks | D8: start | E8: stop | F8: color | G8: variable | H8: # ticks | I8: min | J8: max | K8: color | L8: variable | M8: # ticks | N8: min | O8: max | P8: color | Q8: variable | R8: # ticks | S8: min | T8: max | U8: color | V8: variable | W8: # ticks | X8: min | Y8: max | Z8: color
A9: 1 | B9: time | C9: 6 | D9: 0 | E9: 24 | F9: blue | G9: V.B31ls | H9: 7 | I9: -70 | J9: 0 | K9: red
A10: 1 | B10: time | C10: 6 | D10: 0 | E10: 24 | F10: blue | G10: V.B63rs | H10: 7 | I10: -70 | J10: 0 | K10: magenta
A11: 1 | B11: time | C11: 6 | D11: 0 | E11: 24 | F11: blue | G11: V.B64rs | H11: 7 | I11: -70 | J11: 0 | K11: pink | L11: V.B64ra | M11: 7 | N11: -70 | O11: 0 | P11: yellow
A12: 1 | B12: time | C12: 6 | D12: 0 | E12: 24 | F12: blue | G12: Ics.B63ra.B31ls.s_exc | H12: 5 | I12: -60 | J12: 0 | K12: magenta | L12: Ics.B63ra.B64rs.s_exc | M12: 5 | N12: -2 | O12: 0 | P12: blue
A13: 1 | B13: time | C13: 6 | D13: 0 | E13: 24 | F13: blue | G13: Ivd.Kv.B31ls | H13: 3 | I13: 0 | J13: 30 | K13: orange | L13: Ivd.K_main.B31ls | M13: 3 | N13: 0 | O13: 30 | P13: pink | Q13: Ivd.Ka.B31ls | R13: 3 | S13: 0 | T13: 30 | U13: yellow | V13: Ivd.Na.B31ls | W13: 3 | X13: -10 | Y13: 0 | Z13: yellow
A16: stimulation (.trt) | L16: output variables
B17: Current injection | G17: Voltage clamp | L17: all | M17: type "all" in first cell to output all graphed variables or type individual channels
B18: neuron | C18: start | D18: stop | E18: magnitude | G18: neuron | H18: start | I18: stop | J18: potential
B19: B63rs | C19: 0.5 | D19: 1.5 | E19: 1.2
B20: B63rs | C20: 2.5 | D20: 3.5 | E20: 1.2
B21: B63rs | C21: 4.5 | D21: 5.5 | E21: 1.2
B22: B63rs | C22: 6.5 | D22: 7.5 | E22: 1.2

Sheet BMP_TONIC_l.smu
F1: syntax | L1: example variables | M1: IVDxREG | N1: currrent by conductance and regulation | T1: example synapses
A2: smu | B2: name | C2: BMP_TONIC_l | D2: graph | E2: 1 | F2: conductance | G2: variable.conductance.neuron | M2: V | N2: voltage | Q2: Ics | R2: chem syn current | T2: f_exc | U2: fast excitatory
B3: duration | C3: 60 | D3: store | E3: 1 | F3: example | G3: Ivd.Na.N1 | I3: fBR | J3: fBR.ion.ch.neuron | M3: Ivd | N3: current by voltage gated conductance | Q3: Cion | R3: amount of ion | T3: s_exc | U3: slow excitatory
B4: stepsize | C4: 5e-05 | D4: method | E4: 1 | F4: neuron | G4: variable.neuron | I4: synapse | J4: variable.pre.post.type | M4: A | N4: activation of conductance | Q4: Ies | R4: elec syn current | T4: f_inh | U4: fast inhibitory
B5: red indicates simlation longer than graph duration | F5: example | G5: V.N1 | I5: example | J5: Ics.N1.N4.f_exc | M5: B | N5: Inactivation of conductance | Q5: slex | R5: trt current | T5: s_inh | U5: slow inhibitory
A6: graph (ous) | J6: Ies.N1.N4 | M6: SIVD_reg | N6: for total current
B7: time | G7: variable 1 | L7: variable 2 | Q7: variable 3 | V7: variable 4
A8: Size | B8: variable | C8: # ticks | D8: start | E8: stop | F8: color | G8: variable | H8: # ticks | I8: min | J8: max | K8: color | L8: variable | M8: # ticks | N8: min | O8: max | P8: color | Q8: variable | R8: # ticks | S8: min | T8: max | U8: color | V8: variable | W8: # ticks | X8: min | Y8: max | Z8: color
A9: 1 | B9: time | C9: 6 | D9: 0 | E9: 60 | F9: blue | G9: V.B31rs | H9: 5 | I9: -70 | J9: -20 | K9: red
A10: 1 | B10: time | C10: 6 | D10: 0 | E10: 60 | F10: blue | G10: V.B63ls | H10: 7 | I10: -70 | J10: 0 | K10: magenta | L10: V.B64la | M10: 7 | N10: -70 | O10: 0 | P10: yellow
A11: 1 | B11: time | C11: 6 | D11: 0 | E11: 60 | F11: blue | G11: V.B64ls | H11: 5 | I11: -70 | J11: -20 | K11: pink
A12: 1 | B12: time | C12: 6 | D12: 0 | E12: 60 | F12: blue | G12: Ics.B63la.B31rs.s_exc | H12: 5 | I12: -200 | J12: 0 | K12: magenta | L12: Ics.B63la.B64ls.s_exc | M12: 5 | N12: -2 | O12: 0 | P12: blue
A13: 1 | B13: time | C13: 6 | D13: 0 | E13: 60 | F13: blue | G13: Ivd.Napp.B64ls | H13: 4 | I13: -20 | J13: 0 | K13: red | L13: Ivd.Ka.B64ls | M13: 4 | N13: 0 | O13: 40 | P13: orange | Q13: Ivd.Kv.B64ls | R13: 4 | S13: 0 | T13: 12 | U13: green
A16: stimulation (.trt) | L16: output variables
B17: Current injection | G17: Voltage clamp | L17: all | M17: type "all" in first cell to output all graphed variables or type individual channels
B18: neuron | C18: start | D18: stop | E18: magnitude | G18: neuron | H18: start | I18: stop | J18: potential
B19: B63ls | C19: 1 | D19: 60 | E19: 1.2

Sheet BMP_TONIC_r.smu
F1: syntax | L1: example variables | M1: IVDxREG | N1: currrent by conductance and regulation | T1: example synapses
A2: smu | B2: name | C2: BMP_TONIC_r | D2: graph | E2: 1 | F2: conductance | G2: variable.conductance.neuron | M2: V | N2: voltage | Q2: Ics | R2: chem syn current | T2: f_exc | U2: fast excitatory
B3: duration | C3: 100 | D3: store | E3: 1 | F3: example | G3: Ivd.Na.N1 | I3: fBR | J3: fBR.ion.ch.neuron | M3: Ivd | N3: current by voltage gated conductance | Q3: Cion | R3: amount of ion | T3: s_exc | U3: slow excitatory
B4: stepsize | C4: 5e-05 | D4: method | E4: 1 | F4: neuron | G4: variable.neuron | I4: synapse | J4: variable.pre.post.type | M4: A | N4: activation of conductance | Q4: Ies | R4: elec syn current | T4: f_inh | U4: fast inhibitory
B5: red indicates simlation longer than graph duration | F5: example | G5: V.N1 | I5: example | J5: Ics.N1.N4.f_exc | M5: B | N5: Inactivation of conductance | Q5: slex | R5: trt current | T5: s_inh | U5: slow inhibitory
A6: graph (ous) | J6: Ies.N1.N4 | M6: SIVD_reg | N6: for total current
B7: time | G7: variable 1 | L7: variable 2 | Q7: variable 3 | V7: variable 4
A8: Size | B8: variable | C8: # ticks | D8: start | E8: stop | F8: color | G8: variable | H8: # ticks | I8: min | J8: max | K8: color | L8: variable | M8: # ticks | N8: min | O8: max | P8: color | Q8: variable | R8: # ticks | S8: min | T8: max | U8: color | V8: variable | W8: # ticks | X8: min | Y8: max | Z8: color
A9: 1 | B9: time | C9: 20 | D9: 0 | E9: 100 | F9: blue | G9: V.B31ls | H9: 7 | I9: -70 | J9: 0 | K9: red
A10: 1 | B10: time | C10: 20 | D10: 0 | E10: 100 | F10: blue | G10: V.B63rs | H10: 7 | I10: -70 | J10: 0 | K10: magenta
A16: stimulation (.trt) | L16: output variables
B17: Current injection | G17: Voltage clamp | L17: all | M17: type "all" in first cell to output all graphed variables or type individual channels
B18: neuron | C18: start | D18: stop | E18: magnitude | G18: neuron | H18: start | I18: stop | J18: potential
B19: B63rs | C19: 1 | D19: 99 | E19: 1
B20: B31ls | C20: 1 | D20: 99 | E20: 1

Sheet BMP1_l.smu
F1: syntax | L1: example variables | M1: IVDxREG | N1: currrent by conductance and regulation | T1: example synapses
A2: smu | B2: name | C2: BMP1_l | D2: graph | E2: 1 | F2: conductance | G2: variable.conductance.neuron | M2: V | N2: voltage | Q2: Ics | R2: chem syn current | T2: f_exc | U2: fast excitatory
B3: duration | C3: 14 | D3: store | E3: 1 | F3: example | G3: Ivd.Na.N1 | I3: fBR | J3: fBR.ion.ch.neuron | M3: Ivd | N3: current by voltage gated conductance | Q3: Cion | R3: amount of ion | T3: s_exc | U3: slow excitatory
B4: stepsize | C4: 5e-05 | D4: method | E4: 1 | F4: neuron | G4: variable.neuron | I4: synapse | J4: variable.pre.post.type | M4: A | N4: activation of conductance | Q4: Ies | R4: elec syn current | T4: f_inh | U4: fast inhibitory
B5: red indicates simlation longer than graph duration | F5: example | G5: V.N1 | I5: example | J5: Ics.N1.N4.f_exc | M5: B | N5: Inactivation of conductance | Q5: slex | R5: trt current | T5: s_inh | U5: slow inhibitory
A6: graph (ous) | J6: Ies.N1.N4 | M6: sIVD_reg | N6: for total current
B7: time | G7: variable 1 | L7: variable 2 | Q7: variable 3 | V7: variable 4
A8: Size | B8: variable | C8: # ticks | D8: start | E8: stop | F8: color | G8: variable | H8: # ticks | I8: min | J8: max | K8: color | L8: variable | M8: # ticks | N8: min | O8: max | P8: color | Q8: variable | R8: # ticks | S8: min | T8: max | U8: color | V8: variable | W8: # ticks | X8: min | Y8: max | Z8: color
A9: 1 | B9: time | C9: 7 | D9: 0 | E9: 14 | F9: red | G9: V.B31rs | H9: 6 | I9: -70 | J9: -10 | K9: red
A10: 1 | B10: time | C10: 7 | D10: 0 | E10: 14 | F10: blue | G10: V.B63ls | H10: 7 | I10: -70 | J10: 0 | K10: green | L10: V.B63la | M10: 7 | N10: -70 | O10: 0 | P10: yellow
A11: 1 | B11: time | C11: 7 | D11: 0 | E11: 14 | F11: cyan | G11: Ics.B63la.B31rs.s_exc | H11: 5 | I11: -2.001 | J11: 0.001 | K11: magenta | L11: Ics.B63la.B31rs.f_exc | M11: 5 | N11: -2.001 | O11: 0.001 | P11: blue
A12: 1 | B12: time | C12: 7 | D12: 0 | E12: 2.1 | F12: cyan | G12: V.B63la | H12: 5 | I12: -70 | J12: 30 | K12: yellow
A18: stimulation (.trt) | L18: output variables
B19: Current injection | G19: Voltage clamp | L19: all | M19: type "all" in first cell to output all graphed variables or type individual channels
B20: neuron | C20: start | D20: stop | E20: magnitude | G20: neuron | H20: start | I20: stop | J20: potential
B21: B31rs | C21: 0.5 | D21: 1.5 | E21: 40
B22: B31rs | C22: 2.5 | D22: 3.5 | E22: 40
B23: B31rs | C23: 4.5 | D23: 5.5 | E23: 40
B24: B31rs | C24: 6.5 | D24: 7.5 | E24: 40

Sheet BMP1_r.smu
F1: syntax | L1: example variables | M1: IVDxREG | N1: currrent by conductance and regulation | T1: example synapses
A2: smu | B2: name | C2: BMP1_r | D2: graph | E2: 1 | F2: conductance | G2: variable.conductance.neuron | M2: V | N2: voltage | Q2: Ics | R2: chem syn current | T2: f_exc | U2: fast excitatory
B3: duration | C3: 14 | D3: store | E3: 1 | F3: example | G3: Ivd.Na.N1 | I3: fBR | J3: fBR.ion.ch.neuron | M3: Ivd | N3: current by voltage gated conductance | Q3: Cion | R3: amount of ion | T3: s_exc | U3: slow excitatory
B4: stepsize | C4: 5e-05 | D4: method | E4: 1 | F4: neuron | G4: variable.neuron | I4: synapse | J4: variable.pre.post.type | M4: A | N4: activation of conductance | Q4: Ies | R4: elec syn current | T4: f_inh | U4: fast inhibitory
B5: red indicates simlation longer than graph duration | F5: example | G5: V.N1 | I5: example | J5: Ics.N1.N4.f_exc | M5: B | N5: Inactivation of conductance | Q5: slex | R5: trt current | T5: s_inh | U5: slow inhibitory
A6: graph (ous) | J6: Ies.N1.N4 | M6: sIVD_reg | N6: for total current
B7: time | G7: variable 1 | L7: variable 2 | Q7: variable 3 | V7: variable 4
A8: Size | B8: variable | C8: # ticks | D8: start | E8: stop | F8: color | G8: variable | H8: # ticks | I8: min | J8: max | K8: color | L8: variable | M8: # ticks | N8: min | O8: max | P8: color | Q8: variable | R8: # ticks | S8: min | T8: max | U8: color | V8: variable | W8: # ticks | X8: min | Y8: max | Z8: color
A9: 1 | B9: time | C9: 7 | D9: 0 | E9: 14 | F9: red | G9: V.B31ls | H9: 6 | I9: -70 | J9: -10 | K9: red
A10: 1 | B10: time | C10: 7 | D10: 0 | E10: 14 | F10: blue | G10: V.B63rs | H10: 7 | I10: -70 | J10: 0 | K10: green | L10: V.B63ra | M10: 7 | N10: -70 | O10: 0 | P10: yellow
A11: 1 | B11: time | C11: 7 | D11: 0 | E11: 14 | F11: cyan | G11: Ics.B63ra.B31ls.s_exc | H11: 5 | I11: -2.001 | J11: 0.001 | K11: magenta | L11: Ics.B63ra.B31ls.f_exc | M11: 5 | N11: -2.001 | O11: 0.001 | P11: blue
A12: 1 | B12: time | C12: 7 | D12: 0 | E12: 2.1 | F12: cyan | G12: V.B63ra | H12: 5 | I12: -70 | J12: 30 | K12: yellow
A18: stimulation (.trt) | L18: output variables
B19: Current injection | G19: Voltage clamp | L19: all | M19: type "all" in first cell to output all graphed variables or type individual channels
B20: neuron | C20: start | D20: stop | E20: magnitude | G20: neuron | H20: start | I20: stop | J20: potential
B21: B31ls | C21: 0.5 | D21: 1.5 | E21: 40
B22: B31ls | C22: 2.5 | D22: 3.5 | E22: 40
B23: B31ls | C23: 4.5 | D23: 5.5 | E23: 40
B24: B31ls | C24: 6.5 | D24: 7.5 | E24: 40

Sheet VC_l.smu
F1: syntax | L1: example variables | M1: IVDxREG | N1: currrent by conductance and regulation | T1: example synapses
A2: smu | B2: name | C2: VC_l | D2: graph | E2: 1 | F2: conductance | G2: variable.conductance.neuron | M2: V | N2: voltage | Q2: Ics | R2: chem syn current | T2: f_exc | U2: fast excitatory
B3: duration | C3: 1.16 | D3: store | E3: 1 | F3: example | G3: Ivd.Na.N1 | I3: fBR | J3: fBR.ion.ch.neuron | M3: Ivd | N3: current by voltage gated conductance | Q3: Cion | R3: amount of ion | T3: s_exc | U3: slow excitatory
B4: stepsize | C4: 5e-05 | D4: method | E4: 1 | F4: neuron | G4: variable.neuron | I4: synapse | J4: variable.pre.post.type | M4: A | N4: activation of conductance | Q4: Ies | R4: elec syn current | T4: f_inh | U4: fast inhibitory
B5: red indicates simlation longer than graph duration | F5: example | G5: V.N1 | I5: example | J5: Ics.N1.N4.f_exc | M5: B | N5: Inactivation of conductance | Q5: slex | R5: trt current | T5: s_inh | U5: slow inhibitory
A6: graph (ous) | J6: Ies.N1.N4 | M6: sIVD_reg | N6: for total current
B7: time | G7: variable 1 | L7: variable 2 | Q7: variable 3 | V7: variable 4
A8: Size | B8: variable | C8: # ticks | D8: start | E8: stop | F8: color | G8: variable | H8: # ticks | I8: min | J8: max | K8: color | L8: variable | M8: # ticks | N8: min | O8: max | P8: color | Q8: variable | R8: # ticks | S8: min | T8: max | U8: color | V8: variable | W8: # ticks | X8: min | Y8: max | Z8: color
A9: 1 | B9: time | C9: 5 | D9: 0.96 | E9: 1.16 | F9: blue | G9: V.B31rs | H9: 8 | I9: -70 | J9: 10 | K9: green
A10: 1 | B10: time | C10: 5 | D10: 0.96 | E10: 1.16 | F10: blue | G10: Ivd.Kv.B31rs | H10: 5 | I10: 0 | J10: 500 | K10: orange | L10: Ivd.K_main.B31rs | M10: 5 | N10: 0 | O10: 50 | P10: pink | Q10: Ivd.Ka.B31rs | R10: 5 | S10: 0 | T10: 500 | U10: yellow
A18: stimulation (.trt) | L18: output variables
B19: Current injection | G19: Voltage clamp | L19: all | M19: type "all" in first cell to output all graphed variables or type individual channels
B20: neuron | C20: start | D20: stop | E20: magnitude | G20: neuron | H20: start | I20: stop | J20: potential
G21: B31rs | H21: 0 | I21: 1 | J21: -80
G22: B31rs | H22: 1 | I22: 4 | J22: 0
G23: B31rs | H23: 4 | I23: 5 | J23: -80

Sheet VC_r.smu
F1: syntax | L1: example variables | M1: IVDxREG | N1: currrent by conductance and regulation | T1: example synapses
A2: smu | B2: name | C2: VC_r | D2: graph | E2: 1 | F2: conductance | G2: variable.conductance.neuron | M2: V | N2: voltage | Q2: Ics | R2: chem syn current | T2: f_exc | U2: fast excitatory
B3: duration | C3: 5 | D3: store | E3: 1 | F3: example | G3: Ivd.Na.N1 | I3: fBR | J3: fBR.ion.ch.neuron | M3: Ivd | N3: current by voltage gated conductance | Q3: Cion | R3: amount of ion | T3: s_exc | U3: slow excitatory
B4: stepsize | C4: 5e-05 | D4: method | E4: 1 | F4: neuron | G4: variable.neuron | I4: synapse | J4: variable.pre.post.type | M4: A | N4: activation of conductance | Q4: Ies | R4: elec syn current | T4: f_inh | U4: fast inhibitory
B5: red indicates simlation longer than graph duration | F5: example | G5: V.N1 | I5: example | J5: Ics.N1.N4.f_exc | M5: B | N5: Inactivation of conductance | Q5: slex | R5: trt current | T5: s_inh | U5: slow inhibitory
A6: graph (ous) | J6: Ies.N1.N4 | M6: sIVD_reg | N6: for total current
B7: time | G7: variable 1 | L7: variable 2 | Q7: variable 3 | V7: variable 4
A8: Size | B8: variable | C8: # ticks | D8: start | E8: stop | F8: color | G8: variable | H8: # ticks | I8: min | J8: max | K8: color | L8: variable | M8: # ticks | N8: min | O8: max | P8: color | Q8: variable | R8: # ticks | S8: min | T8: max | U8: color | V8: variable | W8: # ticks | X8: min | Y8: max | Z8: color
A9: 1 | B9: time | C9: 5 | D9: 0 | E9: 5 | F9: blue | G9: V.B31ls | H9: 8 | I9: -70 | J9: 10 | K9: green
A10: 1 | B10: time | C10: 5 | D10: 0 | E10: 5 | F10: blue | G10: Ivd.Kv.B31ls | H10: 5 | I10: 0 | J10: 500 | K10: orange | L10: Ivd.K_main.B31ls | M10: 5 | N10: 0 | O10: 50 | P10: pink | Q10: Ivd.Ka.B31ls | R10: 5 | S10: 0 | T10: 500 | U10: yellow
A11: 1 | B11: time | C11: 5 | D11: 0 | E11: 5 | F11: blue | G11: Ivd.Na.B31ls | H11: 5 | I11: -500 | J11: 0 | K11: cyan
A18: stimulation (.trt) | L18: output variables
B19: Current injection | G19: Voltage clamp | L19: all | M19: type "all" in first cell to output all graphed variables or type individual channels
B20: neuron | C20: start | D20: stop | E20: magnitude | G20: neuron | H20: start | I20: stop | J20: potential
G21: B31ls | H21: 0 | I21: 1 | J21: -80
G22: B31ls | H22: 1 | I22: 4 | J22: 0
G23: B31ls | H23: 4 | I23: 5 | J23: -80

Sheet BMP3SIMPLE.smu
F1: syntax | L1: example variables | M1: IVDxREG | N1: currrent by conductance and regulation | T1: example synapses
A2: smu | B2: name | C2: BMP3SIMPLE | D2: graph | E2: 1 | F2: conductance | G2: variable.conductance.neuron | M2: V | N2: voltage | Q2: Ics | R2: chem syn current | T2: f_exc | U2: fast excitatory
B3: duration | C3: 60 | D3: store | E3: 1 | F3: example | G3: Ivd.Na.N1 | I3: fBR | J3: fBR.ion.ch.neuron | M3: Ivd | N3: current by voltage gated conductance | Q3: Cion | R3: amount of ion | T3: s_exc | U3: slow excitatory
B4: stepsize | C4: 5e-05 | D4: method | E4: 1 | F4: neuron | G4: variable.neuron | I4: synapse | J4: variable.pre.post.type | M4: A | N4: activation of conductance | Q4: Ies | R4: elec syn current | T4: f_inh | U4: fast inhibitory
B5: red indicates simlation longer than graph duration | F5: example | G5: V.N1 | I5: example | J5: Ics.N1.N4.f_exc | M5: B | N5: Inactivation of conductance | Q5: slex | R5: trt current | T5: s_inh | U5: slow inhibitory
A6: graph (ous) | J6: Ies.N1.N4 | M6: SIVD_reg | N6: for total current
B7: time | G7: variable 1 | L7: variable 2 | Q7: variable 3 | V7: variable 4
A8: Size | B8: variable | C8: # ticks | D8: start | E8: stop | F8: color | G8: variable | H8: # ticks | I8: min | J8: max | K8: color | L8: variable | M8: # ticks | N8: min | O8: max | P8: color | Q8: variable | R8: # ticks | S8: min | T8: max | U8: color | V8: variable | W8: # ticks | X8: min | Y8: max | Z8: color
A9: 1 | B9: time | C9: 6 | D9: 0 | E9: 60 | F9: blue | G9: V.B31rs | H9: 7 | I9: -70 | J9: 0 | K9: red
A10: 1 | B10: time | C10: 6 | D10: 10 | E10: 22 | F10: blue | G10: V.B63ls | H10: 7 | I10: -70 | J10: -35 | K10: blue
A11: 1 | B11: time | C11: 6 | D11: 0 | E11: 60 | F11: blue | G11: Ics.B63la.B31rs.s_exc | H11: 5 | I11: -2.001 | J11: 0.001 | K11: magenta | L11: Ics.B63la.B31rs.f_exc | M11: 5 | N11: -2.001 | O11: 0.001 | P11: blue
A12: 1 | B12: time | C12: 6 | D12: 0 | E12: 60 | F12: blue | G12: Ivd.Kv.B31rs | H12: 3 | I12: 0 | J12: 30 | K12: orange | L12: Ivd.K_main.B31rs | M12: 3 | N12: 0 | O12: 30 | P12: pink | Q12: Ivd.Ka.B31rs | R12: 3 | S12: 0 | T12: 30 | U12: yellow
A18: stimulation (.trt) | L18: output variables
B19: Current injection | G19: Voltage clamp | L19: all | M19: type "all" in first cell to output all graphed variables or type individual channels
B20: neuron | C20: start | D20: stop | E20: magnitude | G20: neuron | H20: start | I20: stop | J20: potential
B21: B63ls | C21: 1 | D21: 6 | E21: 0.63

Sheet cs_g
C1: Postsynaptic
C2: =Neu!$B4 -> B63ls | D2: =Neu!$B5 -> B63la | E2: =Neu!$B6 -> B31rs | F2: =Neu!$B7 -> B64ls | G2: =Neu!$B8 -> B64la | H2: =Neu!$B9 -> B63rs | I2: =Neu!$B10 -> B63ra | J2: =Neu!$B11 -> B31ls | K2: =Neu!$B12 -> B64rs | L2: =Neu!$B13 -> B64ra | M2: =Neu!$B14 -> 0 | N2: =Neu!$B15 -> 0 | T2: =Neu!$B16 -> 0 | U2: =Neu!$B17 -> 0 | W2: =Neu!$B24 -> 0
A3: Presynaptic | B3: =Neu!B4 -> B63ls | X3: fast | Y3: Colorbar
X4: slow | Y4: =MAX($C$3:$W$44)-(ROW(Y4)-4)*0.5 -> 18
B5: =Neu!B5 -> B63la | E5: 0.4 | Y5: =MAX($C$3:$W$44)-(ROW(Y5)-4)*0.5 -> 17.5
E6: 18 | F6: 0 | G6: 0 | Y6: =MAX($C$3:$W$44)-(ROW(Y6)-4)*0.5 -> 17
B7: =Neu!B6 -> B31rs | Y7: =MAX($C$3:$W$44)-(ROW(Y7)-4)*0.5 -> 16.5
Y8: =MAX($C$3:$W$44)-(ROW(Y8)-4)*0.5 -> 16
B9: =Neu!B7 -> B64ls | Y9: =MAX($C$3:$W$44)-(ROW(Y9)-4)*0.5 -> 15.5
Y10: =MAX($C$3:$W$44)-(ROW(Y10)-4)*0.5 -> 15
B11: =Neu!B8 -> B64la | Y11: =MAX($C$3:$W$44)-(ROW(Y11)-4)*0.5 -> 14.5
C12: 0 | D12: 0 | E12: 0 | Y12: =MAX($C$3:$W$44)-(ROW(Y12)-4)*0.5 -> 14
B13: =Neu!B9 -> B63rs | Y13: =MAX($C$3:$W$44)-(ROW(Y13)-4)*0.5 -> 13.5
Y14: =MAX($C$3:$W$44)-(ROW(Y14)-4)*0.5 -> 13
B15: =Neu!B10 -> B63ra | J15: 0.4 | Y15: =MAX($C$3:$W$44)-(ROW(Y15)-4)*0.5 -> 12.5
J16: 0 | K16: 0 | L16: 0 | Y16: =MAX($C$3:$W$44)-(ROW(Y16)-4)*0.5 -> 12
B17: =Neu!B11 -> B31ls | Y17: =MAX($C$3:$W$44)-(ROW(Y17)-4)*0.5 -> 11.5
Y18: =MAX($C$3:$W$44)-(ROW(Y18)-4)*0.5 -> 11
B19: =Neu!B12 -> B64rs | Y19: =MAX($C$3:$W$44)-(ROW(Y19)-4)*0.5 -> 10.5
Y20: =MAX($C$3:$W$44)-(ROW(Y20)-4)*0.5 -> 10
B21: =Neu!B13 -> B64ra | Y21: =MAX($C$3:$W$44)-(ROW(Y21)-4)*0.5 -> 9.5
H22: 0 | I22: 0 | J22: 0 | Y22: =MAX($C$3:$W$44)-(ROW(Y22)-4)*0.5 -> 9
B23: =Neu!B14 -> 0 | Y23: =MAX($C$3:$W$44)-(ROW(Y23)-4)*0.5 -> 8.5
Y24: =MAX($C$3:$W$44)-(ROW(Y24)-4)*0.5 -> 8
B25: =Neu!B15 -> 0 | Y25: =MAX($C$3:$W$44)-(ROW(Y25)-4)*0.5 -> 7.5
Y26: =MAX($C$3:$W$44)-(ROW(Y26)-4)*0.5 -> 7
B37: =Neu!B16 -> 0
B39: =Neu!B17 -> 0
B43: =Neu!B24 -> 0

Sheet cs_E
C1: Postsynaptic
C2: =Neu!$B4 -> B63ls | D2: =Neu!$B5 -> B63la | E2: =Neu!$B6 -> B31rs | F2: =Neu!$B7 -> B64ls | G2: =Neu!$B8 -> B64la | H2: =Neu!$B9 -> B63rs | I2: =Neu!$B10 -> B63ra | J2: =Neu!$B11 -> B31ls | K2: =Neu!$B12 -> B64rs | L2: =Neu!$B13 -> B64ra | M2: =Neu!$B14 -> 0 | N2: =Neu!$B15 -> 0 | T2: =Neu!$B16 -> 0 | U2: =Neu!$B17 -> 0 | W2: =Neu!$B24 -> 0
A3: Presynaptic | B3: =Neu!B4 -> B63ls | X3: fast | Y3: Colorbar
X4: slow | Y4: =MAX($C$3:$W$44)-(ROW(Y4)-4)*10 -> 0
B5: =Neu!B5 -> B63la | E5: 0 | Y5: =MAX($C$3:$W$44)-(ROW(Y5)-4)*10 -> -10
E6: -2 | F6: -2 | G6: -2 | Y6: =MAX($C$3:$W$44)-(ROW(Y6)-4)*10 -> -20
B7: =Neu!B6 -> B31rs | Y7: =MAX($C$3:$W$44)-(ROW(Y7)-4)*10 -> -30
Y8: =MAX($C$3:$W$44)-(ROW(Y8)-4)*10 -> -40
B9: =Neu!B7 -> B64ls | Y9: =MAX($C$3:$W$44)-(ROW(Y9)-4)*10 -> -50
Y10: =MAX($C$3:$W$44)-(ROW(Y10)-4)*10 -> -60
B11: =Neu!B8 -> B64la | Y11: =MAX($C$3:$W$44)-(ROW(Y11)-4)*10 -> -70
C12: -75 | D12: -75 | E12: -75 | Y12: =MAX($C$3:$W$44)-(ROW(Y12)-4)*10 -> -80
B13: =Neu!B9 -> B63rs | Y13: =MAX($C$3:$W$44)-(ROW(Y13)-4)*10 -> -90
Y14: =MAX($C$3:$W$44)-(ROW(Y14)-4)*10 -> -100
B15: =Neu!B10 -> B63ra | J15: 0 | Y15: =MAX($C$3:$W$44)-(ROW(Y15)-4)*10 -> -110
J16: -2 | K16: -2 | L16: -2 | Y16: =MAX($C$3:$W$44)-(ROW(Y16)-4)*10 -> -120
B17: =Neu!B11 -> B31ls | Y17: =MAX($C$3:$W$44)-(ROW(Y17)-4)*10 -> -130
Y18: =MAX($C$3:$W$44)-(ROW(Y18)-4)*10 -> -140
B19: =Neu!B12 -> B64rs | Y19: =MAX($C$3:$W$44)-(ROW(Y19)-4)*10 -> -150
Y20: =MAX($C$3:$W$44)-(ROW(Y20)-4)*10 -> -160
B21: =Neu!B13 -> B64ra | Y21: =MAX($C$3:$W$44)-(ROW(Y21)-4)*10 -> -170
H22: -75 | I22: -75 | J22: -75 | Y22: =MAX($C$3:$W$44)-(ROW(Y22)-4)*10 -> -180
B23: =Neu!B14 -> 0 | Y23: =MAX($C$3:$W$44)-(ROW(Y23)-4)*10 -> -190
Y24: =MAX($C$3:$W$44)-(ROW(Y24)-4)*10 -> -200
B25: =Neu!B15 -> 0 | Y25: =MAX($C$3:$W$44)-(ROW(Y25)-4)*10 -> -210
Y26: =MAX($C$3:$W$44)-(ROW(Y26)-4)*10 -> -220
Y27: =MAX($C$3:$W$44)-(ROW(Y27)-4)*10 -> -230
Y28: =MAX($C$3:$W$44)-(ROW(Y28)-4)*10 -> -240
Y29: =MAX($C$3:$W$44)-(ROW(Y29)-4)*10 -> -250
Y30: =MAX($C$3:$W$44)-(ROW(Y30)-4)*10 -> -260
Y31: =MAX($C$3:$W$44)-(ROW(Y31)-4)*10 -> -270
Y32: =MAX($C$3:$W$44)-(ROW(Y32)-4)*10 -> -280
B37: =Neu!B16 -> 0
B39: =Neu!B17 -> 0
B43: =Neu!B24 -> 0

Sheet cs_FAT
C1: Postsynaptic | AA1: taus | AC1: depression | AE1: Voltage dependence | AI1: facilitation
C2: =Neu!$B4 -> B63ls | D2: =Neu!$B5 -> B63la | E2: =Neu!$B6 -> B31rs | F2: =Neu!$B7 -> B64ls | G2: =Neu!$B8 -> B64la | H2: =Neu!$B9 -> B63rs | I2: =Neu!$B10 -> B63ra | J2: =Neu!$B11 -> B31ls | K2: =Neu!$B12 -> B64rs | L2: =Neu!$B13 -> B64ra | M2: =Neu!$B14 -> 0 | N2: =Neu!$B15 -> 0 | T2: =Neu!$B16 -> 0 | U2: =Neu!$B17 -> 0 | W2: =Neu!$B24 -> 0 | AA2: u1 | AB2: u2 | AC2: ud | AD2: ur | AE2: h | AF2: s | AG2: p | AH2: tx | AI2: ion | AJ2: u
A3: Presynaptic | B3: =Neu!B4 -> B63ls | X3: fast | Y3: 1 | Z3: 1 | AA3: 0.001 | AB3: 0.01 | AC3: -0.09 | AD3: 3.3
X4: slow | Y4: 2 | Z4: 2 | AA4: 1.4 | AB4: 2.8 | AC4: -0.09 | AD4: 3.3 | AE4: -50 | AF4: 4 | AG4: 1 | AH4: 0.3
B5: =Neu!B5 -> B63la | E5: 1 | Y5: =COUNTIF($C$3:$W$44,ROW(Z5)-2) -> 0 | Z5: 3 | AA5: 1.4 | AB5: 2.8 | AC5: -1 | AD5: 1 | AE5: -50 | AF5: 4 | AG5: 1 | AH5: 0.3
E6: 2 | F6: 2 | G6: 2 | Y6: =COUNTIF($C$3:$W$44,ROW(Z6)-2) -> 6 | Z6: =IF(ROW(AA6)-2<=MAX($C$3:$W$44),ROW(AA6)-2,"") -> 4 | AA6: 0.015 | AB6: 1.5 | AC6: -1 | AD6: 1
B7: =Neu!B6 -> B31rs | Y7: =COUNTIF($C$3:$W$44,ROW(Z7)-2) -> 0 | Z7: =IF(ROW(AA7)-2<=MAX($C$3:$W$44),ROW(AA7)-2,"") | AA7: 0.004 | AB7: 0.0015 | AI7: Na | AJ7: 0.5
Y8: =COUNTIF($C$3:$W$44,ROW(Z8)-2) -> 0 | Z8: =IF(ROW(AA8)-2<=MAX($C$3:$W$44),ROW(AA8)-2,"") | AA8: 1 | AE8: -31 | AF8: 3 | AG8: 1 | AH8: 0.5 | AI8: Na | AJ8: 0.5
B9: =Neu!B7 -> B64ls | Y9: =COUNTIF($C$3:$W$44,ROW(Z9)-2) -> 0 | Z9: =IF(ROW(AA9)-2<=MAX($C$3:$W$44),ROW(AA9)-2,"") | AA9: 0.2 | AB9: 0.001 | AK9: if u2 is empty it is assumed equal to u1
Y10: =COUNTIF($C$3:$W$44,ROW(Z10)-2) -> 0 | Z10: =IF(ROW(AA10)-2<=MAX($C$3:$W$44),ROW(AA10)-2,"") | AA10: 0.005 | AI10: Na | AJ10: 0.5
B11: =Neu!B8 -> B64la | Y11: =COUNTIF($C$3:$W$44,ROW(Z11)-2) -> 0 | Z11: =IF(ROW(AA11)-2<=MAX($C$3:$W$44),ROW(AA11)-2,"") | AA11: 0.01 | AI11: Na | AJ11: 0.5
C12: 4 | D12: 4 | E12: 4 | Y12: =COUNTIF($C$3:$W$44,ROW(Z12)-2) -> 0 | Z12: =IF(ROW(AA12)-2<=MAX($C$3:$W$44),ROW(AA12)-2,"") | AA12: 0.02
B13: =Neu!B9 -> B63rs | Y13: =COUNTIF($C$3:$W$44,ROW(Z13)-2) -> 0 | Z13: =IF(ROW(AA13)-2<=MAX($C$3:$W$44),ROW(AA13)-2,"") | AA13: 0.5 | AB13: 5 | AE13: -30 | AF13: 15 | AG13: 1 | AH13: 0.5 | AK13: Ach
Y14: =COUNTIF($C$3:$W$44,ROW(Z14)-2) -> 0 | Z14: =IF(ROW(AA14)-2<=MAX($C$3:$W$44),ROW(AA14)-2,"") | AA14: 0.2 | AE14: -48 | AF14: 4 | AG14: 3 | AH14: 0.1 | AI14: Na | AJ14: 0.5
B15: =Neu!B10 -> B63ra | J15: 1 | Y15: =COUNTIF($C$3:$W$44,ROW(Z15)-2) -> 0 | Z15: =IF(ROW(AA15)-2<=MAX($C$3:$W$44),ROW(AA15)-2,"") | AA15: 1.5
J16: 2 | K16: 2 | L16: 2 | Y16: =COUNTIF($C$3:$W$44,ROW(Z16)-2) -> 0 | Z16: =IF(ROW(AA16)-2<=MAX($C$3:$W$44),ROW(AA16)-2,"") | AA16: 0.025 | AC16: 0.5 | AD16: 1
B17: =Neu!B11 -> B31ls | Y17: =COUNTIF($C$3:$W$44,ROW(Z17)-2) -> 0 | Z17: =IF(ROW(AA17)-2<=MAX($C$3:$W$44),ROW(AA17)-2,"") | AA17: 0.02 | AC17: 0.042 | AD17: 15
Y18: =COUNTIF($C$3:$W$44,ROW(Z18)-2) -> 0 | Z18: =IF(ROW(AA18)-2<=MAX($C$3:$W$44),ROW(AA18)-2,"") | AA18: 1.3
B19: =Neu!B12 -> B64rs | Y19: =COUNTIF($C$3:$W$44,ROW(Z19)-2) -> 0 | Z19: =IF(ROW(AA19)-2<=MAX($C$3:$W$44),ROW(AA19)-2,"") | AA19: 0.002
Y20: =COUNTIF($C$3:$W$44,ROW(Z20)-2) -> 0 | Z20: =IF(ROW(AA20)-2<=MAX($C$3:$W$44),ROW(AA20)-2,"") | AA20: 4
B21: =Neu!B13 -> B64ra | Y21: =COUNTIF($C$3:$W$44,ROW(Z21)-2) -> 0 | Z21: =IF(ROW(AA21)-2<=MAX($C$3:$W$44),ROW(AA21)-2,"") | AA21: 5 | AB21: 0.001 | AE21: -31 | AF21: 3 | AG21: 1
H22: 4 | I22: 4 | J22: 4 | Y22: =COUNTIF($C$3:$W$44,ROW(Z22)-2) -> 0 | Z22: =IF(ROW(AA22)-2<=MAX($C$3:$W$44),ROW(AA22)-2,"") | AA22: 0.005
B23: =Neu!B14 -> 0 | Y23: =COUNTIF($C$3:$W$44,ROW(Z23)-2) -> 0 | Z23: =IF(ROW(AA23)-2<=MAX($C$3:$W$44),ROW(AA23)-2,"") | AA23: 0.03
Y24: =COUNTIF($C$3:$W$44,ROW(Z24)-2) -> 0 | Z24: =IF(ROW(AA24)-2<=MAX($C$3:$W$44),ROW(AA24)-2,"") | AA24: 0.5 | AI24: Na | AJ24: 0.5
B25: =Neu!B15 -> 0 | Y25: =COUNTIF($C$3:$W$44,ROW(Z25)-2) -> 0 | Z25: =IF(ROW(AA25)-2<=MAX($C$3:$W$44),ROW(AA25)-2,"") | AA25: 0.015 | AI25: Na | AJ25: 0.5
Y26: =COUNTIF($C$3:$W$44,ROW(Z26)-2) -> 0 | Z26: =IF(ROW(AA26)-2<=MAX($C$3:$W$44),ROW(AA26)-2,"") | AA26: 0.01
B37: =Neu!B16 -> 0
B39: =Neu!B17 -> 0
B43: =Neu!B24 -> 0
V45: midrange | W45: =(MAX(Z:Z)+MIN(Z:Z))/2 -> 2.5 | Z45: =IF(ROW(AA45)-2<=MAX($C$3:$W$44),ROW(AA45)-2,"")
Z46: =IF(ROW(AA46)-2<=MAX($C$3:$W$44),ROW(AA46)-2,"")
Z47: =IF(ROW(AA47)-2<=MAX($C$3:$W$44),ROW(AA47)-2,"")
Z48: =IF(ROW(AA48)-2<=MAX($C$3:$W$44),ROW(AA48)-2,"")
Z49: =IF(ROW(AA49)-2<=MAX($C$3:$W$44),ROW(AA49)-2,"")
Z50: =IF(ROW(AA50)-2<=MAX($C$3:$W$44),ROW(AA50)-2,"")
Z51: =IF(ROW(AA51)-2<=MAX($C$3:$W$44),ROW(AA51)-2,"")
Z52: =IF(ROW(AA52)-2<=MAX($C$3:$W$44),ROW(AA52)-2,"")
Z53: =IF(ROW(AA53)-2<=MAX($C$3:$W$44),ROW(AA53)-2,"")
Z54: =IF(ROW(AA54)-2<=MAX($C$3:$W$44),ROW(AA54)-2,"")
Z55: =IF(ROW(AA55)-2<=MAX($C$3:$W$44),ROW(AA55)-2,"")
...

Sheet es
C1: Postsynaptic
C2: =Neu!$B4 -> B63ls | D2: =Neu!$B5 -> B63la | E2: =Neu!$B6 -> B31rs | F2: =Neu!$B7 -> B64ls | G2: =Neu!$B8 -> B64la | H2: =Neu!$B9 -> B63rs | I2: =Neu!$B10 -> B63ra | J2: =Neu!$B11 -> B31ls | K2: =Neu!$B12 -> B64rs | L2: =Neu!$B13 -> B64ra | M2: =Neu!B14 -> 0 | N2: =Neu!B15 -> 0 | T2: =Neu!$B16 -> 0 | U2: =Neu!$B17 -> 0 | W2: =Neu!$B24 -> 0
A3: Presynaptic | B3: =Neu!B4 -> B63ls | D3: =C4 -> 0.13 | E3: =C5 -> 0 | F3: =C6 -> 0 | G3: =C7 -> 0 | H3: =C8 -> 0 | I3: =C9 -> 0 | J3: =C10 -> 0 | K3: =C11 -> 0 | L3: =C12 -> 0 | M3: =C13 -> 0 | N3: =C14 -> 0 | S3: =C19 -> 0 | T3: =C20 -> 0 | U3: =C21 -> 0 | V3: =C22 -> 0 | W3: =C23 -> 0
B4: =Neu!B5 -> B63la | C4: 0.13 | E4: 0.045 | G4: =D7 -> 0 | H4: =D8 -> 0 | I4: =D9 -> 0 | J4: =D10 -> 0 | K4: =D11 -> 0 | L4: =D12 -> 0 | M4: =D13 -> 0 | N4: =D14 -> 0 | S4: =D19 -> 0 | T4: =D20 -> 0 | U4: =D21 -> 0 | V4: =D22 -> 0 | W4: =D23 -> 0
B5: =Neu!B6 -> B31rs | D5: 0.045 | G5: =E7 -> 0 | H5: =E8 -> 0 | I5: =E9 -> 0 | J5: =E10 -> 0 | K5: =E11 -> 0 | L5: =E12 -> 0 | M5: =E13 -> 0 | N5: =E14 -> 0 | S5: =E19 -> 0 | T5: =E20 -> 0 | U5: =E21 -> 0 | V5: =E22 -> 0 | W5: =E23 -> 0
B6: =Neu!B7 -> B64ls | G6: 0.025 | H6: =F8 -> 0 | I6: =F9 -> 0 | J6: =F10 -> 0 | K6: =F11 -> 0 | L6: =F12 -> 0 | M6: =F13 -> 0 | N6: =F14 -> 0 | S6: =F19 -> 0 | T6: =F20 -> 0 | U6: =F21 -> 0 | V6: =F22 -> 0 | W6: =F23 -> 0
