Workbook

Sheet Neu
D1: File | E1: leak | G1: Na | AH1: Ka | BI1: Kv | CJ1: K_main | DK1: Napp
E2: vdg | G2: vdg | J2: A | V2: B | AH2: vdg | AK2: A | AW2: B | BI2: vdg | BL2: A | BX2: B | CJ2: vdg | CM2: A | CY2: B | DK2: vdg | DN2: A | DZ2: B
B3: Name | C3: Template | D3: cm | E3: g | F3: E | G3: g | H3: p | I3: E | J3: An | K3: h | L3: s | M3: p | N3: tmx | O3: tmin | P3: th1 | Q3: ts1 | R3: tp1 | S3: th2 | T3: ts2 | U3: tp2 | V3: Bn | W3: h | X3: s | Y3: p | Z3: tmx | AA3: tmin | AB3: th1 | AC3: ts1 | AD3: tp1 | AE3: th2 | AF3: ts2 | AG3: tp2 | AH3: g | AI3: p | AJ3: E | AK3: An | AL3: h | AM3: s | AN3: p | AO3: tmx | AP3: tmin | AQ3: th1 | AR3: ts1 | AS3: tp1 | AT3: th2 | AU3: ts2 | AV3: tp2 | AW3: Bn | AX3: h | AY3: s | AZ3: p | BA3: tmx | BB3: tmin | BC3: th1 | BD3: ts1 | BE3: tp1 | BF3: th2 | BG3: ts2 | BH3: tp2 | BI3: g | BJ3: p | BK3: E | BL3: An | BM3: h | BN3: s | BO3: p | BP3: tmx | BQ3: tmin | BR3: th1 | BS3: ts1 | BT3: tp1 | BU3: th2 | BV3: ts2 | BW3: tp2 | BX3: Bn | BY3: h | BZ3: s | CA3: p | CB3: tmx | CC3: tmin | CD3: th1 | CE3: ts1 | CF3: tp1 | CG3: th2 | CH3: ts2 | CI3: tp2 | CJ3: g | CK3: p | CL3: E | CM3: An | CN3: h | CO3: s | CP3: p | CQ3: tmx | CR3: tmin | CS3: th1 | CT3: ts1 | CU3: tp1 | CV3: th2 | CW3: ts2 | CX3: tp2 | CY3: Bn | CZ3: h | DA3: s | DB3: p | DC3: tmx | DD3: tmin | DE3: th1 | DF3: ts1 | DG3: tp1 | DH3: th2 | DI3: ts2 | DJ3: tp2 | DK3: g | DL3: p | DM3: E | DN3: An | DO3: h | DP3: s | DQ3: p | DR3: tmx | DS3: tmin | DT3: th1 | DU3: ts1 | DV3: tp1 | DW3: th2 | DX3: ts2 | DY3: tp2 | DZ3: Bn | EA3: h | EB3: s | EC3: p | ED3: tmx | EE3: tmin | EF3: th1 | EG3: ts1 | EH3: tp1 | EI3: th2 | EJ3: ts2 | EK3: tp2
A4: B63s | B4: B63s | D4: 0.003 | E4: 0.025 | F4: -60 | G4: 7.5 | H4: 1 | I4: 50 | J4: 0 | K4: -42.1 | L4: 4.8 | M4: 3 | N4: 0.0015 | O4: 0.00045 | P4: -32.7 | Q4: 1.85 | R4: 1 | V4: 0 | W4: -51.5 | X4: 9.2 | Y4: 1 | Z4: 0.01 | AA4: 0.0024 | AB4: -39.2 | AC4: 3.5 | AD4: 1 | AH4: 50 | AI4: 4 | AJ4: -70 | AK4: 0 | AL4: -26.4 | AM4: 8.8 | AN4: 1 | AO4: 0.027 | AP4: 0.00216 | AQ4: -24 | AR4: 11.7 | AS4: 1 | AW4: 0.15 | AX4: -16.4 | AY4: 1.5 | AZ4: 2 | BA4: 0.2 | BB4: 0.02 | BC4: -24 | BD4: 8.3 | BE4: 1
A5: B63a | B5: B63a | D5: 0.003 | E5: 0.0012 | F5: -60 | G5: 7.5 | H5: 1 | I5: 50 | J5: 0 | K5: -42.1 | L5: 4.8 | M5: 3 | N5: 0.0015 | O5: 0.00045 | P5: -32.7 | Q5: 1.85 | R5: 1 | V5: 0 | W5: -51.5 | X5: 9.2 | Y5: 1 | Z5: 0.01 | AA5: 0.0024 | AB5: -39.2 | AC5: 3.5 | AD5: 1 | AH5: 60 | AI5: 4 | AJ5: -70 | AK5: 0 | AL5: -26.4 | AM5: 8.8 | AN5: 1 | AO5: 0.027 | AP5: 0.00216 | AQ5: -24 | AR5: 11.7 | AS5: 1 | AW5: 0.15 | AX5: -16.4 | AY5: 1.5 | AZ5: 2 | BA5: 0.2 | BB5: 0.02 | BC5: -24 | BD5: 8.3 | BE5: 1
A6: B31s | B6: B31s | D6: 0.011 | E6: 0.37 | F6: -60 | AH6: 9.5 | AI6: 1 | AJ6: -85 | AK6: 0 | AL6: -14 | AM6: 20 | AN6: 3 | AO6: 0.02 | AP6: 0.000275 | AQ6: -88 | AR6: 30 | AS6: 1 | AT6: -50 | AU6: -5 | AV6: 1 | AW6: 0 | AX6: -30 | AY6: 11 | AZ6: 1 | BA6: 0.33 | BB6: 0.008 | BC6: -80 | BD6: 70 | BE6: 1 | BF6: -73 | BG6: -9 | BH6: 1 | BI6: 15 | BJ6: 1 | BK6: -70 | BL6: 0 | BM6: 6 | BN6: 14 | BO6: 1 | BP6: 0.014 | BQ6: 0.003 | BR6: 20 | BS6: 7 | BT6: 1 | BU6: -15 | BV6: -6 | BW6: 1 | BX6: 0 | BY6: -31 | BZ6: 7 | CA6: 1 | CB6: 0.875 | CC6: 0.11 | CD6: -15 | CE6: 6 | CF6: 1 | CG6: -73 | CH6: -9 | CI6: 1 | CJ6: 5 | CK6: 1 | CL6: -35 | CM6: 0 | CN6: 19 | CO6: 11 | CP6: 1 | CQ6: 0.014 | CR6: 0.003 | CS6: 20 | CT6: 7 | CU6: 1 | CV6: -15 | CW6: -6 | CX6: 1 | CY6: 0 | CZ6: 1000 | DA6: 7 | DB6: 1
A7: B64s | B7: B64s | D7: 0.003 | E7: 0.05 | F7: -60 | G7: 0.9 | H7: 1 | I7: 50 | J7: 0 | K7: -42.1 | L7: 4.8 | M7: 3 | N7: 0.0015 | O7: 0.00045 | P7: -32.7 | Q7: 1.85 | R7: 1 | V7: 0 | W7: -51.5 | X7: 9.2 | Y7: 1 | Z7: 0.01 | AA7: 0.0024 | AB7: -39.2 | AC7: 3.5 | AD7: 1 | AH7: 3 | AI7: 4 | AJ7: -70 | AK7: 0 | AL7: -33 | AM7: 8.8 | AN7: 1 | AO7: 0.027 | AP7: 0.003 | AQ7: -24 | AR7: 11.7 | AS7: 1 | AW7: 0.15 | AX7: -16.4 | AY7: 1.5 | AZ7: 2 | BA7: 0.2 | BB7: 0.02 | BC7: -24 | BD7: 8.3 | BE7: 1 | BI7: 70 | BJ7: 4 | BK7: -70 | BL7: 0 | BM7: -19 | BN7: 8.8 | BO7: 1 | BP7: 0.27 | BQ7: 0.0216 | BR7: -24 | BS7: 11.7 | BT7: 1 | BX7: 0.15 | BY7: -16.4 | BZ7: 1.5 | CA7: 2 | CB7: 2 | CC7: 0.2 | CD7: -24 | CE7: 8.3 | CF7: 1 | DK7: 4.6 | DL7: 3 | DM7: 50 | DN7: 0 | DO7: -48 | DP7: 4 | DQ7: 2 | DR7: 0.16 | DS7: 0.00015 | DT7: -30 | DU7: 4 | DV7: 4 | DW7: -50 | DX7: -4 | DY7: 4 | DZ7: 0 | EA7: -57 | EB7: 5 | EC7: 2 | ED7: 2 | EE7: 0.2 | EF7: -44 | EG7: -3 | EH7: 4
A8: B64a | B8: B64a | D8: 0.003 | E8: 0.03 | F8: -60 | G8: 4 | H8: 1 | I8: 50 | J8: 0 | K8: -42.1 | L8: 4.8 | M8: 3 | N8: 0.0015 | O8: 0.00045 | P8: -32.7 | Q8: 1.85 | R8: 1 | V8: 0 | W8: -51.5 | X8: 9.2 | Y8: 1 | Z8: 0.01 | AA8: 0.0024 | AB8: -39.2 | AC8: 3.5 | AD8: 1 | AH8: 19 | AI8: 4 | AJ8: -70 | AK8: 0 | AL8: -33 | AM8: 8.8 | AN8: 1 | AO8: 0.027 | AP8: 0.003 | AQ8: -24 | AR8: 11.7 | AS8: 1 | AW8: 0.15 | AX8: -16.4 | AY8: 1.5 | AZ8: 2 | BA8: 0.2 | BB8: 0.02 | BC8: -24 | BD8: 8.3 | BE8: 1 | DK8: 0.01 | DL8: 3 | DM8: 50 | DN8: 0 | DO8: -48 | DP8: 4 | DQ8: 2 | DR8: 0.005 | DS8: 0.04 | DT8: -56 | DU8: -3 | DV8: 4 | DW8: -30 | DX8: -3 | DY8: 4 | DZ8: 0 | EA8: -56 | EB8: 5 | EC8: 2 | ED8: 3 | EE8: 0.05 | EF8: -40 | EG8: -2 | EH8: 4
A9: =Neu!B9 -> 0
A10: =Neu!B10 -> 0
A11: =Neu!B11 -> 0
A12: =Neu!B12 -> 0
A13: =Neu!B13 -> 0
A14: =Neu!B14 -> 0
A15: =Neu!B15 -> 0
A16: =Neu!B16 -> 0
A17: =Neu!B17 -> 0
A18: =Neu!B18 -> 0
A19: =Neu!B19 -> 0
A20: =Neu!B20 -> 0
... A24: =Neu!B24 -> 0
D29: Ion pools | O29: Conductance to ion | Z29: Ion to conductance | BD29: Initial voltage
D30: Name | E30: ion | F30: K1 | G30: K2 | H30: ion | I30: K1 | J30: K2 | K30: ion | L30: K1 | M30: K2 | O30: Name | P30: ch | Q30: ion | R30: ch | S30: ion | T30: ch | U30: ion | V30: ch | W30: ion | Z30: Name | AA30: ion | AB30: ch | AC30: opt1 | AD30: opt2 | AE30: p1 | AF30: p2 | AG30: b | AH30: ion | AI30: ch | AJ30: opt1 | AK30: opt2 | AL30: p1 | AM30: p2 | AN30: b | AO30: ion | AP30: ch | AQ30: opt1 | AR30: opt2 | AS30: p1 | AT30: p2 | AU30: b | AV30: ion | AW30: ch | AX30: opt1 | AY30: opt2 | AZ30: p1 | BA30: p2 | BB30: b | BD30: Name | BE30: mV
D31: =Neu!$B4 -> B63s | O31: =Neu!$B4 -> B63s | Z31: =Neu!$B4 -> B63s | BD31: =Neu!$B4 -> B63s | BE31: -62
D32: =Neu!$B5 -> B63a | O32: =Neu!$B5 -> B63a | Z32: =Neu!$B5 -> B63a | BD32: =Neu!$B5 -> B63a | BE32: -62
D33: =Neu!$B6 -> B31s | O33: =Neu!$B6 -> B31s | Z33: =Neu!$B6 -> B31s | BD33: =Neu!$B6 -> B31s | BE33: -62
D34: =Neu!$B7 -> B64s | O34: =Neu!$B7 -> B64s | Z34: =Neu!$B7 -> B64s | BD34: =Neu!$B7 -> B64s | BE34: -62
D35: =Neu!$B8 -> B64a | O35: =Neu!$B8 -> B64a | Z35: =Neu!$B8 -> B64a | BD35: =Neu!$B8 -> B64a | BE35: -62
D36: =Neu!$B9 -> 0 | O36: =Neu!$B9 -> 0 | Z36: =Neu!$B9 -> 0
D37: =Neu!$B10 -> 0 | O37: =Neu!$B10 -> 0 | Z37: =Neu!$B10 -> 0
D38: =Neu!$B11 -> 0 | O38: =Neu!$B11 -> 0 | Z38: =Neu!$B11 -> 0
D39: =Neu!$B12 -> 0 | O39: =Neu!$B12 -> 0 | Z39: =Neu!$B12 -> 0
D40: =Neu!$B13 -> 0 | O40: =Neu!$B13 -> 0 | Z40: =Neu!$B13 -> 0
D41: =Neu!$B14 -> 0 | O41: =Neu!$B14 -> 0 | Z41: =Neu!$B14 -> 0
D42: =Neu!$B15 -> 0 | O42: =Neu!$B15 -> 0 | Z42: =Neu!$B15 -> 0
D43: =Neu!$B16 -> 0 | O43: =Neu!$B16 -> 0 | Z43: =Neu!$B16 -> 0
D44: =Neu!$B17 -> 0 | O44: =Neu!$B17 -> 0 | Z44: =Neu!$B17 -> 0
D45: =Neu!$B18 -> 0 | O45: =Neu!$B18 -> 0 | Z45: =Neu!$B18 -> 0
D46: =Neu!$B19 -> 0 | O46: =Neu!$B19 -> 0 | Z46: =Neu!$B19 -> 0
D47: =Neu!$B20 -> 0 | O47: =Neu!$B20 -> 0 | Z47: =Neu!$B20 -> 0
...

Sheet cs_g
C1: Postsynaptic
C2: =Neu!$B4 -> B63s | D2: =Neu!$B5 -> B63a | E2: =Neu!$B6 -> B31s | F2: =Neu!$B7 -> B64s | G2: =Neu!$B8 -> B64a | H2: =Neu!$B9 -> 0 | I2: =Neu!$B10 -> 0 | J2: =Neu!$B11 -> 0 | K2: =Neu!$B12 -> 0 | L2: =Neu!$B13 -> 0 | M2: =Neu!$B14 -> 0 | N2: =Neu!$B15 -> 0 | O2: =Neu!$B16 -> 0 | P2: =Neu!$B17 -> 0 | Q2: =Neu!$B18 -> 0 | R2: =Neu!$B19 -> 0 | S2: =Neu!$B20 -> 0 | T2: =Neu!$B21 -> 0 | U2: =Neu!$B22 -> 0 | V2: =Neu!$B23 -> 0 | W2: =Neu!$B24 -> 0
A3: Presynaptic | B3: =Neu!B4 -> B63s | X3: fast | Y3: Colorbar
X4: slow | Y4: =MAX($C$3:$W$44)-(ROW(Y4)-4)*0.5 -> 18
B5: =Neu!B5 -> B63a | E5: 0.4 | Y5: =MAX($C$3:$W$44)-(ROW(Y5)-4)*0.5 -> 17.5
E6: 18 | Y6: =MAX($C$3:$W$44)-(ROW(Y6)-4)*0.5 -> 17
B7: =Neu!B6 -> B31s | Y7: =MAX($C$3:$W$44)-(ROW(Y7)-4)*0.5 -> 16.5
Y8: =MAX($C$3:$W$44)-(ROW(Y8)-4)*0.5 -> 16
B9: =Neu!B7 -> B64s | Y9: =MAX($C$3:$W$44)-(ROW(Y9)-4)*0.5 -> 15.5
Y10: =MAX($C$3:$W$44)-(ROW(Y10)-4)*0.5 -> 15
B11: =Neu!B8 -> B64a | Y11: =MAX($C$3:$W$44)-(ROW(Y11)-4)*0.5 -> 14.5
Y12: =MAX($C$3:$W$44)-(ROW(Y12)-4)*0.5 -> 14
B13: =Neu!B9 -> 0 | Y13: =MAX($C$3:$W$44)-(ROW(Y13)-4)*0.5 -> 13.5
Y14: =MAX($C$3:$W$44)-(ROW(Y14)-4)*0.5 -> 13
B15: =Neu!B10 -> 0 | Y15: =MAX($C$3:$W$44)-(ROW(Y15)-4)*0.5 -> 12.5
Y16: =MAX($C$3:$W$44)-(ROW(Y16)-4)*0.5 -> 12
B17: =Neu!B11 -> 0 | Y17: =MAX($C$3:$W$44)-(ROW(Y17)-4)*0.5 -> 11.5
Y18: =MAX($C$3:$W$44)-(ROW(Y18)-4)*0.5 -> 11
B19: =Neu!B12 -> 0 | Y19: =MAX($C$3:$W$44)-(ROW(Y19)-4)*0.5 -> 10.5
Y20: =MAX($C$3:$W$44)-(ROW(Y20)-4)*0.5 -> 10
B21: =Neu!B13 -> 0 | Y21: =MAX($C$3:$W$44)-(ROW(Y21)-4)*0.5 -> 9.5
Y22: =MAX($C$3:$W$44)-(ROW(Y22)-4)*0.5 -> 9
B23: =Neu!B14 -> 0 | Y23: =MAX($C$3:$W$44)-(ROW(Y23)-4)*0.5 -> 8.5
Y24: =MAX($C$3:$W$44)-(ROW(Y24)-4)*0.5 -> 8
B25: =Neu!B15 -> 0 | Y25: =MAX($C$3:$W$44)-(ROW(Y25)-4)*0.5 -> 7.5
Y26: =MAX($C$3:$W$44)-(ROW(Y26)-4)*0.5 -> 7
B27: =Neu!B16 -> 0
B29: =Neu!B17 -> 0
B31: =Neu!B18 -> 0
B33: =Neu!B19 -> 0
B35: =Neu!B20 -> 0
B37: =Neu!B21 -> 0
B39: =Neu!B22 -> 0
B41: =Neu!B23 -> 0
B43: =Neu!B24 -> 0

Sheet cs_E
C1: Postsynaptic
C2: =Neu!$B4 -> B63s | D2: =Neu!$B5 -> B63a | E2: =Neu!$B6 -> B31s | F2: =Neu!$B7 -> B64s | G2: =Neu!$B8 -> B64a | H2: =Neu!$B9 -> 0 | I2: =Neu!$B10 -> 0 | J2: =Neu!$B11 -> 0 | K2: =Neu!$B12 -> 0 | L2: =Neu!$B13 -> 0 | M2: =Neu!$B14 -> 0 | N2: =Neu!$B15 -> 0 | O2: =Neu!$B16 -> 0 | P2: =Neu!$B17 -> 0 | Q2: =Neu!$B18 -> 0 | R2: =Neu!$B19 -> 0 | S2: =Neu!$B20 -> 0 | T2: =Neu!$B21 -> 0 | U2: =Neu!$B22 -> 0 | V2: =Neu!$B23 -> 0 | W2: =Neu!$B24 -> 0
A3: Presynaptic | B3: =Neu!B4 -> B63s | X3: fast | Y3: Colorbar
X4: slow | Y4: =MAX($C$3:$W$44)-(ROW(Y4)-4)*10 -> 0
B5: =Neu!B5 -> B63a | E5: 0 | Y5: =MAX($C$3:$W$44)-(ROW(Y5)-4)*10 -> -10
E6: -2 | Y6: =MAX($C$3:$W$44)-(ROW(Y6)-4)*10 -> -20
B7: =Neu!B6 -> B31s | Y7: =MAX($C$3:$W$44)-(ROW(Y7)-4)*10 -> -30
Y8: =MAX($C$3:$W$44)-(ROW(Y8)-4)*10 -> -40
B9: =Neu!B7 -> B64s | Y9: =MAX($C$3:$W$44)-(ROW(Y9)-4)*10 -> -50
Y10: =MAX($C$3:$W$44)-(ROW(Y10)-4)*10 -> -60
B11: =Neu!B8 -> B64a | Y11: =MAX($C$3:$W$44)-(ROW(Y11)-4)*10 -> -70
Y12: =MAX($C$3:$W$44)-(ROW(Y12)-4)*10 -> -80
B13: =Neu!B9 -> 0 | Y13: =MAX($C$3:$W$44)-(ROW(Y13)-4)*10 -> -90
Y14: =MAX($C$3:$W$44)-(ROW(Y14)-4)*10 -> -100
B15: =Neu!B10 -> 0 | Y15: =MAX($C$3:$W$44)-(ROW(Y15)-4)*10 -> -110
Y16: =MAX($C$3:$W$44)-(ROW(Y16)-4)*10 -> -120
B17: =Neu!B11 -> 0 | Y17: =MAX($C$3:$W$44)-(ROW(Y17)-4)*10 -> -130
Y18: =MAX($C$3:$W$44)-(ROW(Y18)-4)*10 -> -140
B19: =Neu!B12 -> 0 | Y19: =MAX($C$3:$W$44)-(ROW(Y19)-4)*10 -> -150
Y20: =MAX($C$3:$W$44)-(ROW(Y20)-4)*10 -> -160
B21: =Neu!B13 -> 0 | Y21: =MAX($C$3:$W$44)-(ROW(Y21)-4)*10 -> -170
Y22: =MAX($C$3:$W$44)-(ROW(Y22)-4)*10 -> -180
B23: =Neu!B14 -> 0 | Y23: =MAX($C$3:$W$44)-(ROW(Y23)-4)*10 -> -190
Y24: =MAX($C$3:$W$44)-(ROW(Y24)-4)*10 -> -200
B25: =Neu!B15 -> 0 | Y25: =MAX($C$3:$W$44)-(ROW(Y25)-4)*10 -> -210
Y26: =MAX($C$3:$W$44)-(ROW(Y26)-4)*10 -> -220
B27: =Neu!B16 -> 0 | Y27: =MAX($C$3:$W$44)-(ROW(Y27)-4)*10 -> -230
Y28: =MAX($C$3:$W$44)-(ROW(Y28)-4)*10 -> -240
B29: =Neu!B17 -> 0 | Y29: =MAX($C$3:$W$44)-(ROW(Y29)-4)*10 -> -250
Y30: =MAX($C$3:$W$44)-(ROW(Y30)-4)*10 -> -260
B31: =Neu!B18 -> 0 | Y31: =MAX($C$3:$W$44)-(ROW(Y31)-4)*10 -> -270
Y32: =MAX($C$3:$W$44)-(ROW(Y32)-4)*10 -> -280
B33: =Neu!B19 -> 0
B35: =Neu!B20 -> 0
B37: =Neu!B21 -> 0
B39: =Neu!B22 -> 0
B41: =Neu!B23 -> 0
B43: =Neu!B24 -> 0

Sheet cs_FAT
C1: Postsynaptic | AA1: taus | AC1: depression | AE1: Voltage dependence | AI1: facilitation
C2: =Neu!$B4 -> B63s | D2: =Neu!$B5 -> B63a | E2: =Neu!$B6 -> B31s | F2: =Neu!$B7 -> B64s | G2: =Neu!$B8 -> B64a | H2: =Neu!$B9 -> 0 | I2: =Neu!$B10 -> 0 | J2: =Neu!$B11 -> 0 | K2: =Neu!$B12 -> 0 | L2: =Neu!$B13 -> 0 | M2: =Neu!$B14 -> 0 | N2: =Neu!$B15 -> 0 | O2: =Neu!$B16 -> 0 | P2: =Neu!$B17 -> 0 | Q2: =Neu!$B18 -> 0 | R2: =Neu!$B19 -> 0 | S2: =Neu!$B20 -> 0 | T2: =Neu!$B21 -> 0 | U2: =Neu!$B22 -> 0 | V2: =Neu!$B23 -> 0 | W2: =Neu!$B24 -> 0 | AA2: u1 | AB2: u2 | AC2: ud | AD2: ur | AE2: h | AF2: s | AG2: p | AH2: tx | AI2: ion | AJ2: u
A3: Presynaptic | B3: =Neu!B4 -> B63s | X3: fast | Y3: =COUNTIF($C$3:$W$44,ROW(Z3)-2) -> 1 | Z3: =IF(ROW(AA3)-2<=MAX($C$3:$W$44),ROW(AA3)-2,"") -> 1 | AA3: 0.001 | AB3: 0.01 | AC3: -0.09 | AD3: 3.3
X4: slow | Y4: =COUNTIF($C$3:$W$44,ROW(Z4)-2) -> 1 | Z4: =IF(ROW(AA4)-2<=MAX($C$3:$W$44),ROW(AA4)-2,"") -> 2 | AA4: 1.4 | AB4: 2.8 | AC4: -0.09 | AD4: 3.3 | AE4: -50 | AF4: 4 | AG4: 1 | AH4: 0.3
B5: =Neu!B5 -> B63a | E5: 1 | Y5: =COUNTIF($C$3:$W$44,ROW(Z5)-2) -> 0 | Z5: =IF(ROW(AA5)-2<=MAX($C$3:$W$44),ROW(AA5)-2,"")
E6: 2 | Y6: =COUNTIF($C$3:$W$44,ROW(Z6)-2) -> 0 | Z6: =IF(ROW(AA6)-2<=MAX($C$3:$W$44),ROW(AA6)-2,"")
B7: =Neu!B6 -> B31s | Y7: =COUNTIF($C$3:$W$44,ROW(Z7)-2) -> 0 | Z7: =IF(ROW(AA7)-2<=MAX($C$3:$W$44),ROW(AA7)-2,"")
Y8: =COUNTIF($C$3:$W$44,ROW(Z8)-2) -> 0 | Z8: =IF(ROW(AA8)-2<=MAX($C$3:$W$44),ROW(AA8)-2,"")
B9: =Neu!B7 -> B64s | Y9: =COUNTIF($C$3:$W$44,ROW(Z9)-2) -> 0 | Z9: =IF(ROW(AA9)-2<=MAX($C$3:$W$44),ROW(AA9)-2,"") | AK9: if u2 is empty it is assumed equal to u1
Y10: =COUNTIF($C$3:$W$44,ROW(Z10)-2) -> 0 | Z10: =IF(ROW(AA10)-2<=MAX($C$3:$W$44),ROW(AA10)-2,"")
B11: =Neu!B8 -> B64a | Y11: =COUNTIF($C$3:$W$44,ROW(Z11)-2) -> 0 | Z11: =IF(ROW(AA11)-2<=MAX($C$3:$W$44),ROW(AA11)-2,"")
Y12: =COUNTIF($C$3:$W$44,ROW(Z12)-2) -> 0 | Z12: =IF(ROW(AA12)-2<=MAX($C$3:$W$44),ROW(AA12)-2,"")
B13: =Neu!B9 -> 0 | Y13: =COUNTIF($C$3:$W$44,ROW(Z13)-2) -> 0 | Z13: =IF(ROW(AA13)-2<=MAX($C$3:$W$44),ROW(AA13)-2,"") | AK13: Ach
Y14: =COUNTIF($C$3:$W$44,ROW(Z14)-2) -> 0 | Z14: =IF(ROW(AA14)-2<=MAX($C$3:$W$44),ROW(AA14)-2,"")
B15: =Neu!B10 -> 0 | Y15: =COUNTIF($C$3:$W$44,ROW(Z15)-2) -> 0 | Z15: =IF(ROW(AA15)-2<=MAX($C$3:$W$44),ROW(AA15)-2,"")
Y16: =COUNTIF($C$3:$W$44,ROW(Z16)-2) -> 0 | Z16: =IF(ROW(AA16)-2<=MAX($C$3:$W$44),ROW(AA16)-2,"")
B17: =Neu!B11 -> 0 | Y17: =COUNTIF($C$3:$W$44,ROW(Z17)-2) -> 0 | Z17: =IF(ROW(AA17)-2<=MAX($C$3:$W$44),ROW(AA17)-2,"")
Y18: =COUNTIF($C$3:$W$44,ROW(Z18)-2) -> 0 | Z18: =IF(ROW(AA18)-2<=MAX($C$3:$W$44),ROW(AA18)-2,"")
B19: =Neu!B12 -> 0 | Y19: =COUNTIF($C$3:$W$44,ROW(Z19)-2) -> 0 | Z19: =IF(ROW(AA19)-2<=MAX($C$3:$W$44),ROW(AA19)-2,"")
Y20: =COUNTIF($C$3:$W$44,ROW(Z20)-2) -> 0 | Z20: =IF(ROW(AA20)-2<=MAX($C$3:$W$44),ROW(AA20)-2,"")
B21: =Neu!B13 -> 0 | Y21: =COUNTIF($C$3:$W$44,ROW(Z21)-2) -> 0 | Z21: =IF(ROW(AA21)-2<=MAX($C$3:$W$44),ROW(AA21)-2,"")
Y22: =COUNTIF($C$3:$W$44,ROW(Z22)-2) -> 0 | Z22: =IF(ROW(AA22)-2<=MAX($C$3:$W$44),ROW(AA22)-2,"")
B23: =Neu!B14 -> 0 | Y23: =COUNTIF($C$3:$W$44,ROW(Z23)-2) -> 0 | Z23: =IF(ROW(AA23)-2<=MAX($C$3:$W$44),ROW(AA23)-2,"")
Y24: =COUNTIF($C$3:$W$44,ROW(Z24)-2) -> 0 | Z24: =IF(ROW(AA24)-2<=MAX($C$3:$W$44),ROW(AA24)-2,"")
B25: =Neu!B15 -> 0 | Y25: =COUNTIF($C$3:$W$44,ROW(Z25)-2) -> 0 | Z25: =IF(ROW(AA25)-2<=MAX($C$3:$W$44),ROW(AA25)-2,"")
Y26: =COUNTIF($C$3:$W$44,ROW(Z26)-2) -> 0 | Z26: =IF(ROW(AA26)-2<=MAX($C$3:$W$44),ROW(AA26)-2,"")
B27: =Neu!B16 -> 0 | Y27: =COUNTIF($C$3:$W$44,ROW(Z27)-2) -> 0 | Z27: =IF(ROW(AA27)-2<=MAX($C$3:$W$44),ROW(AA27)-2,"")
Y28: =COUNTIF($C$3:$W$44,ROW(Z28)-2) -> 0 | Z28: =IF(ROW(AA28)-2<=MAX($C$3:$W$44),ROW(AA28)-2,"")
B29: =Neu!B17 -> 0 | Y29: =COUNTIF($C$3:$W$44,ROW(Z29)-2) -> 0 | Z29: =IF(ROW(AA29)-2<=MAX($C$3:$W$44),ROW(AA29)-2,"")
Y30: =COUNTIF($C$3:$W$44,ROW(Z30)-2) -> 0 | Z30: =IF(ROW(AA30)-2<=MAX($C$3:$W$44),ROW(AA30)-2,"")
B31: =Neu!B18 -> 0 | Y31: =COUNTIF($C$3:$W$44,ROW(Z31)-2) -> 0 | Z31: =IF(ROW(AA31)-2<=MAX($C$3:$W$44),ROW(AA31)-2,"")
Y32: =COUNTIF($C$3:$W$44,ROW(Z32)-2) -> 0 | Z32: =IF(ROW(AA32)-2<=MAX($C$3:$W$44),ROW(AA32)-2,"")
B33: =Neu!B19 -> 0 | Y33: =COUNTIF($C$3:$W$44,ROW(Z33)-2) -> 0 | Z33: =IF(ROW(AA33)-2<=MAX($C$3:$W$44),ROW(AA33)-2,"")
Y34: =COUNTIF($C$3:$W$44,ROW(Z34)-2) -> 0 | Z34: =IF(ROW(AA34)-2<=MAX($C$3:$W$44),ROW(AA34)-2,"")
B35: =Neu!B20 -> 0 | Y35: =COUNTIF($C$3:$W$44,ROW(Z35)-2) -> 0 | Z35: =IF(ROW(AA35)-2<=MAX($C$3:$W$44),ROW(AA35)-2,"")
Y36: =COUNTIF($C$3:$W$44,ROW(Z36)-2) -> 0 | Z36: =IF(ROW(AA36)-2<=MAX($C$3:$W$44),ROW(AA36)-2,"")
B37: =Neu!B21 -> 0 | Y37: =COUNTIF($C$3:$W$44,ROW(Z37)-2) -> 0 | Z37: =IF(ROW(AA37)-2<=MAX($C$3:$W$44),ROW(AA37)-2,"")
Y38: =COUNTIF($C$3:$W$44,ROW(Z38)-2) -> 0 | Z38: =IF(ROW(AA38)-2<=MAX($C$3:$W$44),ROW(AA38)-2,"")
B39: =Neu!B22 -> 0 | Y39: =COUNTIF($C$3:$W$44,ROW(Z39)-2) -> 0 | Z39: =IF(ROW(AA39)-2<=MAX($C$3:$W$44),ROW(AA39)-2,"")
Y40: =COUNTIF($C$3:$W$44,ROW(Z40)-2) -> 0 | Z40: =IF(ROW(AA40)-2<=MAX($C$3:$W$44),ROW(AA40)-2,"")
...

Sheet es
C1: Postsynaptic
C2: =Neu!B4 -> B63s | D2: =Neu!B5 -> B63a | E2: =Neu!B6 -> B31s | F2: =Neu!B7 -> B64s | G2: =Neu!B8 -> B64a | H2: =Neu!B9 -> 0 | I2: =Neu!B10 -> 0 | J2: =Neu!B11 -> 0 | K2: =Neu!B12 -> 0 | L2: =Neu!B13 -> 0 | M2: =Neu!B14 -> 0 | N2: =Neu!B15 -> 0 | O2: =Neu!B16 -> 0 | P2: =Neu!B17 -> 0 | Q2: =Neu!$B18 -> 0 | R2: =Neu!$B19 -> 0 | S2: =Neu!$B20 -> 0 | T2: =Neu!$B21 -> 0 | U2: =Neu!$B22 -> 0 | V2: =Neu!$B23 -> 0 | W2: =Neu!$B24 -> 0
A3: Presynaptic | B3: =Neu!B4 -> B63s | D3: 0.13 | E3: 0 | F3: 0 | G3: 0 | H3: =C8 -> 0 | I3: =C9 -> 0 | J3: =C10 -> 0 | K3: =C11 -> 0 | L3: =C12 -> 0 | M3: =C13 -> 0 | N3: =C14 -> 0 | O3: =C14 -> 0 | P3: =C16 -> 0 | Q3: =C17 -> 0 | R3: =C18 -> 0 | S3: =C19 -> 0 | T3: =C20 -> 0 | U3: =C21 -> 0 | V3: =C22 -> 0 | W3: =C23 -> 0
B4: =Neu!B5 -> B63a | C4: 0.13 | E4: 0.045 | G4: 0 | H4: =D8 -> 0 | I4: =D9 -> 0 | J4: =D10 -> 0 | K4: =D11 -> 0 | L4: =D12 -> 0 | M4: =D13 -> 0 | N4: =D14 -> 0 | O4: =D15 -> 0 | P4: =D16 -> 0 | Q4: =D17 -> 0 | R4: =D18 -> 0 | S4: =D19 -> 0 | T4: =D20 -> 0 | U4: =D21 -> 0 | V4: =D22 -> 0 | W4: =D23 -> 0
B5: =Neu!B6 -> B31s | D5: 0.045 | G5: 0 | H5: =E8 -> 0 | I5: =E9 -> 0 | J5: =E10 -> 0 | K5: =E11 -> 0 | L5: =E12 -> 0 | M5: =E13 -> 0 | N5: =E14 -> 0 | O5: =E15 -> 0 | P5: =E16 -> 0 | Q5: =E17 -> 0 | R5: =E18 -> 0 | S5: =E19 -> 0 | T5: =E20 -> 0 | U5: =E21 -> 0 | V5: =E22 -> 0 | W5: =E23 -> 0
B6: =Neu!B7 -> B64s | G6: 0.025 | H6: =F8 -> 0 | I6: =F9 -> 0 | J6: =F10 -> 0 | K6: =F11 -> 0 | L6: =F12 -> 0 | M6: =F13 -> 0 | N6: =F14 -> 0 | O6: =F15 -> 0 | P6: =F16 -> 0 | Q6: =F17 -> 0 | R6: =F18 -> 0 | S6: =F19 -> 0 | T6: =F20 -> 0 | U6: =F21 -> 0 | V6: =F22 -> 0 | W6: =F23 -> 0
B7: =Neu!B8 -> B64a | F7: 0.1 | H7: =G8 -> 0 | I7: =G9 -> 0 | J7: =G10 -> 0 | K7: =G11 -> 0 | L7: =G12 -> 0 | M7: =G13 -> 0 | N7: =G14 -> 0 | O7: =G15 -> 0 | P7: =G16 -> 0 | Q7: =G17 -> 0 | R7: =G18 -> 0 | S7: =G19 -> 0 | T7: =G20 -> 0 | U7: =G21 -> 0 | V7: =G22 -> 0 | W7: =G23 -> 0
B8: =Neu!B9 -> 0 | I8: =H9 -> 0 | J8: =H10 -> 0 | K8: =H11 -> 0 | L8: =H12 -> 0 | M8: =H13 -> 0 | N8: =H14 -> 0 | O8: =H15 -> 0 | P8: =H16 -> 0 | Q8: =H17 -> 0 | R8: =H18 -> 0 | S8: =H19 -> 0 | T8: =H20 -> 0 | U8: =H21 -> 0 | V8: =H22 -> 0 | W8: =H23 -> 0
B9: =Neu!B10 -> 0 | J9: =I10 -> 0 | K9: =I11 -> 0 | L9: =I12 -> 0 | M9: =I13 -> 0 | N9: =I14 -> 0 | O9: =I15 -> 0 | P9: =I16 -> 0 | Q9: =I17 -> 0 | R9: =I18 -> 0 | S9: =I19 -> 0 | T9: =I20 -> 0 | U9: =I21 -> 0 | V9: =I22 -> 0 | W9: =I23 -> 0
B10: =Neu!B11 -> 0 | K10: =J11 -> 0 | L10: =J12 -> 0 | M10: =J13 -> 0 | N10: =J14 -> 0 | O10: =J15 -> 0 | P10: =J16 -> 0 | Q10: =J17 -> 0 | R10: =J18 -> 0 | S10: =J19 -> 0 | T10: =J20 -> 0 | U10: =J21 -> 0 | V10: =J22 -> 0 | W10: =J23 -> 0
B11: =Neu!B12 -> 0 | L11: =K12 -> 0 | M11: =K13 -> 0 | N11: =K14 -> 0 | O11: =K15 -> 0 | P11: =K16 -> 0 | Q11: =K17 -> 0 | R11: =K18 -> 0 | S11: =K19 -> 0 | T11: =K20 -> 0 | U11: =K21 -> 0 | V11: =K22 -> 0 | W11: =K23 -> 0
B12: =Neu!B13 -> 0 | M12: =L13 -> 0 | N12: =L14 -> 0 | O12: =L15 -> 0 | P12: =L16 -> 0 | Q12: =L17 -> 0 | R12: =L18 -> 0 | S12: =L19 -> 0 | T12: =L20 -> 0 | U12: =L21 -> 0 | V12: =L22 -> 0 | W12: =L23 -> 0
B13: =Neu!B14 -> 0 | N13: =M14 -> 0 | O13: =M15 -> 0 | P13: =M16 -> 0 | Q13: =M17 -> 0 | R13: =M18 -> 0 | S13: =M19 -> 0 | T13: =M20 -> 0 | U13: =M21 -> 0 | V13: =M22 -> 0 | W13: =M23 -> 0
B14: =Neu!B15 -> 0 | O14: =N15 -> 0 | P14: =N16 -> 0 | Q14: =N17 -> 0 | R14: =N18 -> 0 | S14: =N19 -> 0 | T14: =N20 -> 0 | U14: =N21 -> 0 | V14: =N22 -> 0 | W14: =N23 -> 0
B15: =Neu!B16 -> 0 | P15: =O16 -> 0 | Q15: =O17 -> 0 | R15: =O18 -> 0 | S15: =O19 -> 0 | T15: =O20 -> 0 | U15: =O21 -> 0 | V15: =O22 -> 0 | W15: =O23 -> 0
B16: =Neu!B17 -> 0 | Q16: =P17 -> 0 | R16: =P18 -> 0 | S16: =P19 -> 0 | T16: =P20 -> 0 | U16: =P21 -> 0 | V16: =P22 -> 0 | W16: =P23 -> 0
B17: =Neu!B18 -> 0 | R17: =Q18 -> 0 | S17: =Q19 -> 0 | T17: =Q20 -> 0 | U17: =Q21 -> 0 | V17: =Q22 -> 0 | W17: =Q23 -> 0
B18: =Neu!B19 -> 0 | S18: =R19 -> 0 | T18: =R20 -> 0 | U18: =R21 -> 0 | V18: =R22 -> 0 | W18: =R23 -> 0
B19: =Neu!B20 -> 0 | T19: =S20 -> 0 | U19: =S21 -> 0 | V19: =S22 -> 0 | W19: =S23 -> 0
B20: =Neu!B21 -> 0 | U20: =T21 -> 0 | V20: =T22 -> 0 | W20: =T23 -> 0
B21: =Neu!B22 -> 0 | V21: =U22 -> 0 | W21: =U23 -> 0
B22: =Neu!B23 -> 0 | W22: =V23 -> 0
B23: =Neu!B24 -> 0

Sheet noise
B1: Amplitude | C1: step size | D1: jitter in step size
A2: votage-dependent conductance (.vdg) | B2: 0 | C2: 50 | D2: 10
A3: chemical synapse (.cs) | B3: 0 | C3: 200 | D3: 10
A4: electrical synapse (.es) | B4: 0 | C4: 200 | D4: 10

Sheet BMP_test.smu
F1: syntax | L1: example variables | M1: IVDxREG | N1: currrent by conductance and regulation | T1: example synapses
A2: smu | B2: name | C2: BMP_TONIC | D2: graph | E2: 1 | F2: conductance | G2: variable.conductance.neuron | M2: V | N2: voltage | Q2: Ics | R2: chem syn current | T2: f_exc | U2: fast excitatory
B3: duration | C3: 60 | D3: store | E3: 1 | F3: example | G3: Ivd.Na.N1 | I3: fBR | J3: fBR.ion.ch.neuron | M3: Ivd | N3: current by voltage gated conductance | Q3: Cion | R3: amount of ion | T3: s_exc | U3: slow excitatory
B4: stepsize | C4: 5e-05 | D4: method | E4: 1 | F4: neuron | G4: variable.neuron | I4: synapse | J4: variable.pre.post.type | M4: A | N4: activation of conductance | Q4: Ies | R4: elec syn current | T4: f_inh | U4: fast inhibitory
B5: red indicates simlation longer than graph duration | F5: example | G5: V.N1 | I5: example | J5: Ics.N1.N4.f_exc | M5: B | N5: Inactivation of conductance | Q5: slex | R5: trt current | T5: s_inh | U5: slow inhibitory
A6: graph (ous) | J6: Ies.N1.N4 | M6: sIVD_reg | N6: for total current
B7: time | G7: variable 1 | L7: variable 2 | Q7: variable 3 | V7: variable 4
A8: Size | B8: variable | C8: # ticks | D8: start | E8: stop | F8: color | G8: variable | H8: # ticks | I8: min | J8: max | K8: color | L8: variable | M8: # ticks | N8: min | O8: max | P8: color | Q8: variable | R8: # ticks | S8: min | T8: max | U8: color | V8: variable | W8: # ticks | X8: min | Y8: max | Z8: color
A25: stimulation (.trt) | L25: output variables
B26: Current injection | G26: Voltage clamp | L26: all | M26: type "all" in first cell to output all graphed variables or type individual channels
B27: neuron | C27: start | D27: stop | E27: magnitude | G27: neuron | H27: start | I27: stop | J27: potential
B28: B63s | C28: 1 | D28: 60 | E28: 1
B29: B31s | C29: 1 | D29: 60 | E29: 1

Sheet BMP_TONIC.smu
F1: syntax | L1: example variables | M1: IVDxREG | N1: currrent by conductance and regulation | T1: example synapses
A2: smu | B2: name | C2: BMP_TONIC | D2: graph | E2: 1 | F2: conductance | G2: variable.conductance.neuron | M2: V | N2: voltage | Q2: Ics | R2: chem syn current | T2: f_exc | U2: fast excitatory
B3: duration | C3: 60 | D3: store | E3: 1 | F3: example | G3: Ivd.Na.N1 | I3: fBR | J3: fBR.ion.ch.neuron | M3: Ivd | N3: current by voltage gated conductance | Q3: Cion | R3: amount of ion | T3: s_exc | U3: slow excitatory
B4: stepsize | C4: 5e-05 | D4: method | E4: 1 | F4: neuron | G4: variable.neuron | I4: synapse | J4: variable.pre.post.type | M4: A | N4: activation of conductance | Q4: Ies | R4: elec syn current | T4: f_inh | U4: fast inhibitory
B5: red indicates simlation longer than graph duration | F5: example | G5: V.N1 | I5: example | J5: Ics.N1.N4.f_exc | M5: B | N5: Inactivation of conductance | Q5: slex | R5: trt current | T5: s_inh | U5: slow inhibitory
A6: graph (ous) | J6: Ies.N1.N4 | M6: sIVD_reg | N6: for total current
B7: time | G7: variable 1 | L7: variable 2 | Q7: variable 3 | V7: variable 4
A8: Size | B8: variable | C8: # ticks | D8: start | E8: stop | F8: color | G8: variable | H8: # ticks | I8: min | J8: max | K8: color | L8: variable | M8: # ticks | N8: min | O8: max | P8: color | Q8: variable | R8: # ticks | S8: min | T8: max | U8: color | V8: variable | W8: # ticks | X8: min | Y8: max | Z8: color
A25: stimulation (.trt) | L25: output variables
B26: Current injection | G26: Voltage clamp | L26: all | M26: type "all" in first cell to output all graphed variables or type individual channels
B27: neuron | C27: start | D27: stop | E27: magnitude | G27: neuron | H27: start | I27: stop | J27: potential
B28: B63s | C28: 1 | D28: 60 | E28: 1.2

Sheet BMP2SIMPLE.smu
F1: syntax | L1: example variables | M1: IVDxREG | N1: currrent by conductance and regulation | T1: example synapses
A2: smu | B2: name | C2: BMP2SIMPLE | D2: graph | E2: 1 | F2: conductance | G2: variable.conductance.neuron | M2: V | N2: voltage | Q2: Ics | R2: chem syn current | T2: f_exc | U2: fast excitatory
B3: duration | C3: 24 | D3: store | E3: 1 | F3: example | G3: Ivd.Na.N1 | I3: fBR | J3: fBR.ion.ch.neuron | M3: Ivd | N3: current by voltage gated conductance | Q3: Cion | R3: amount of ion | T3: s_exc | U3: slow excitatory
B4: stepsize | C4: 5e-05 | D4: method | E4: 1 | F4: neuron | G4: variable.neuron | I4: synapse | J4: variable.pre.post.type | M4: A | N4: activation of conductance | Q4: Ies | R4: elec syn current | T4: f_inh | U4: fast inhibitory
B5: red indicates simlation longer than graph duration | F5: example | G5: V.N1 | I5: example | J5: Ics.N1.N4.f_exc | M5: B | N5: Inactivation of conductance | Q5: slex | R5: trt current | T5: s_inh | U5: slow inhibitory
A6: graph (ous) | J6: Ies.N1.N4 | M6: sIVD_reg | N6: for total current
B7: time | G7: variable 1 | L7: variable 2 | Q7: variable 3 | V7: variable 4
A8: Size | B8: variable | C8: # ticks | D8: start | E8: stop | F8: color | G8: variable | H8: # ticks | I8: min | J8: max | K8: color | L8: variable | M8: # ticks | N8: min | O8: max | P8: color | Q8: variable | R8: # ticks | S8: min | T8: max | U8: color | V8: variable | W8: # ticks | X8: min | Y8: max | Z8: color
A25: stimulation (.trt) | L25: output variables
B26: Current injection | G26: Voltage clamp | L26: all | M26: type "all" in first cell to output all graphed variables or type individual channels
B27: neuron | C27: start | D27: stop | E27: magnitude | G27: neuron | H27: start | I27: stop | J27: potential
B28: B63s | C28: 0.5 | D28: 1.5 | E28: 1.2
B29: B63s | C29: 2.5 | D29: 3.5 | E29: 1.2
B30: B63s | C30: 4.5 | D30: 5.5 | E30: 1.2
B31: B63s | C31: 6.5 | D31: 7.5 | E31: 1.2
