Workbook

Sheet Neu
D1: File | E1: leak | G1: Na | AH1: Ka | BI1: Kv | CJ1: K_main | DK1: Napp
E2: vdg | G2: vdg | J2: A | V2: B | AH2: vdg | AK2: A | AW2: B | BI2: vdg | BL2: A | BX2: B | CJ2: vdg | CM2: A | CY2: B | DK2: vdg | DN2: A | DZ2: B
B3: Name | C3: Template | D3: cm | E3: g | F3: E | G3: g | H3: p | I3: E | J3: An | K3: h | L3: s | M3: p | N3: tmx | O3: tmin | P3: th1 | Q3: ts1 | R3: tp1 | S3: th2 | T3: ts2 | U3: tp2 | V3: Bn | W3: h | X3: s | Y3: p | Z3: tmx | AA3: tmin | AB3: th1 | AC3: ts1 | AD3: tp1 | AE3: th2 | AF3: ts2 | AG3: tp2 | AH3: g | AI3: p | AJ3: E | AK3: An | AL3: h | AM3: s | AN3: p | AO3: tmx | AP3: tmin | AQ3: th1 | AR3: ts1 | AS3: tp1 | AT3: th2 | AU3: ts2 | AV3: tp2 | AW3: Bn | AX3: h | AY3: s | AZ3: p | BA3: tmx | BB3: tmin | BC3: th1 | BD3: ts1 | BE3: tp1 | BF3: th2 | BG3: ts2 | BH3: tp2 | BI3: g | BJ3: p | BK3: E | BL3: An | BM3: h | BN3: s | BO3: p | BP3: tmx | BQ3: tmin | BR3: th1 | BS3: ts1 | BT3: tp1 | BU3: th2 | BV3: ts2 | BW3: tp2 | BX3: Bn | BY3: h | BZ3: s | CA3: p | CB3: tmx | CC3: tmin | CD3: th1 | CE3: ts1 | CF3: tp1 | CG3: th2 | CH3: ts2 | CI3: tp2 | CJ3: g | CK3: p | CL3: E | CM3: An | CN3: h | CO3: s | CP3: p | CQ3: tmx | CR3: tmin | CS3: th1 | CT3: ts1 | CU3: tp1 | CV3: th2 | CW3: ts2 | CX3: tp2 | CY3: Bn | CZ3: h | DA3: s | DB3: p | DC3: tmx | DD3: tmin | DE3: th1 | DF3: ts1 | DG3: tp1 | DH3: th2 | DI3: ts2 | DJ3: tp2 | DK3: g | DL3: p | DM3: E | DN3: An | DO3: h | DP3: s | DQ3: p | DR3: tmx | DS3: tmin | DT3: th1 | DU3: ts1 | DV3: tp1 | DW3: th2 | DX3: ts2 | DY3: tp2 | DZ3: Bn | EA3: h | EB3: s | EC3: p | ED3: tmx | EE3: tmin | EF3: th1 | EG3: ts1 | EH3: tp1 | EI3: th2 | EJ3: ts2 | EK3: tp2
A4: B63ls | B4: B63ls | D4: 0.003 | E4: 0.025 | F4: -60 | G4: 7.5 | H4: 1 | I4: 50 | J4: 0 | K4: -42.1 | L4: 4.8 | M4: 3 | N4: 0.0015 | O4: 0.00045 | P4: -32.7 | Q4: 1.85 | R4: 1 | V4: 0 | W4: -51.5 | X4: 9.2 | Y4: 1 | Z4: 0.01 | AA4: 0.0024 | AB4: -39.2 | AC4: 3.5 | AD4: 1 | AH4: 50 | AI4: 4 | AJ4: -70 | AK4: 0 | AL4: -26.4 | AM4: 8.8 | AN4: 1 | AO4: 0.027 | AP4: 0.00216 | AQ4: -24 | AR4: 11.7 | AS4: 1 | AW4: 0.15 | AX4: -16.4 | AY4: 1.5 | AZ4: 2 | BA4: 0.2 | BB4: 0.02 | BC4: -24 | BD4: 8.3 | BE4: 1
A5: B63la | B5: B63la | D5: 0.003 | E5: 0.0012 | F5: -60 | G5: 7.5 | H5: 1 | I5: 50 | J5: 0 | K5: -42.1 | L5: 4.8 | M5: 3 | N5: 0.0015 | O5: 0.00045 | P5: -32.7 | Q5: 1.85 | R5: 1 | V5: 0 | W5: -51.5 | X5: 9.2 | Y5: 1 | Z5: 0.01 | AA5: 0.0024 | AB5: -39.2 | AC5: 3.5 | AD5: 1 | AH5: 60 | AI5: 4 | AJ5: -70 | AK5: 0 | AL5: -26.4 | AM5: 8.8 | AN5: 1 | AO5: 0.027 | AP5: 0.00216 | AQ5: -24 | AR5: 11.7 | AS5: 1 | AW5: 0.15 | AX5: -16.4 | AY5: 1.5 | AZ5: 2 | BA5: 0.2 | BB5: 0.02 | BC5: -24 | BD5: 8.3 | BE5: 1
A6: B31rs | B6: B31rs | D6: 0.011 | E6: 0.37 | F6: -60 | AH6: 9.5 | AI6: 1 | AJ6: -85 | AK6: 0 | AL6: -14 | AM6: 20 | AN6: 3 | AO6: 0.02 | AP6: 0.000275 | AQ6: -88 | AR6: 30 | AS6: 1 | AT6: -50 | AU6: -5 | AV6: 1 | AW6: 0 | AX6: -30 | AY6: 11 | AZ6: 1 | BA6: 0.33 | BB6: 0.008 | BC6: -80 | BD6: 70 | BE6: 1 | BF6: -73 | BG6: -9 | BH6: 1 | BI6: 15 | BJ6: 1 | BK6: -70 | BL6: 0 | BM6: 6 | BN6: 14 | BO6: 1 | BP6: 0.014 | BQ6: 0.003 | BR6: 20 | BS6: 7 | BT6: 1 | BU6: -15 | BV6: -6 | BW6: 1 | BX6: 0 | BY6: -31 | BZ6: 7 | CA6: 1 | CB6: 0.875 | CC6: 0.11 | CD6: -15 | CE6: 6 | CF6: 1 | CG6: -73 | CH6: -9 | CI6: 1 | CJ6: 5 | CK6: 1 | CL6: -35 | CM6: 0 | CN6: 19 | CO6: 11 | CP6: 1 | CQ6: 0.014 | CR6: 0.003 | CS6: 20 | CT6: 7 | CU6: 1 | CV6: -15 | CW6: -6 | CX6: 1 | CY6: 0 | CZ6: 1000 | DA6: 7 | DB6: 1
A7: B64ls | B7: B64ls | D7: 0.003 | E7: 0.05 | F7: -60 | G7: 0.9 | H7: 1 | I7: 50 | J7: 0 | K7: -42.1 | L7: 4.8 | M7: 3 | N7: 0.0015 | O7: 0.00045 | P7: -32.7 | Q7: 1.85 | R7: 1 | V7: 0 | W7: -51.5 | X7: 9.2 | Y7: 1 | Z7: 0.01 | AA7: 0.0024 | AB7: -39.2 | AC7: 3.5 | AD7: 1 | AH7: 3 | AI7: 4 | AJ7: -70 | AK7: 0 | AL7: -33 | AM7: 8.8 | AN7: 1 | AO7: 0.027 | AP7: 0.003 | AQ7: -24 | AR7: 11.7 | AS7: 1 | AW7: 0.15 | AX7: -16.4 | AY7: 1.5 | AZ7: 2 | BA7: 0.2 | BB7: 0.02 | BC7: -24 | BD7: 8.3 | BE7: 1 | BI7: 70 | BJ7: 4 | BK7: -70 | BL7: 0 | BM7: -19 | BN7: 8.8 | BO7: 1 | BP7: 0.27 | BQ7: 0.0216 | BR7: -24 | BS7: 11.7 | BT7: 1 | BX7: 0.15 | BY7: -16.4 | BZ7: 1.5 | CA7: 2 | CB7: 2 | CC7: 0.2 | CD7: -24 | CE7: 8.3 | CF7: 1 | DK7: 4.6 | DL7: 3 | DM7: 50 | DN7: 0 | DO7: -48 | DP7: 4 | DQ7: 2 | DR7: 0.16 | DS7: 0.00015 | DT7: -30 | DU7: 4 | DV7: 4 | DW7: -50 | DX7: -4 | DY7: 4 | DZ7: 0 | EA7: -57 | EB7: 5 | EC7: 2 | ED7: 2 | EE7: 0.2 | EF7: -44 | EG7: -3 | EH7: 4
A8: B64la | B8: B64la | D8: 0.003 | E8: 0.03 | F8: -60 | G8: 4 | H8: 1 | I8: 50 | J8: 0 | K8: -42.1 | L8: 4.8 | M8: 3 | N8: 0.0015 | O8: 0.00045 | P8: -32.7 | Q8: 1.85 | R8: 1 | V8: 0 | W8: -51.5 | X8: 9.2 | Y8: 1 | Z8: 0.01 | AA8: 0.0024 | AB8: -39.2 | AC8: 3.5 | AD8: 1 | AH8: 19 | AI8: 4 | AJ8: -70 | AK8: 0 | AL8: -33 | AM8: 8.8 | AN8: 1 | AO8: 0.027 | AP8: 0.003 | AQ8: -24 | AR8: 11.7 | AS8: 1 | AW8: 0.15 | AX8: -16.4 | AY8: 1.5 | AZ8: 2 | BA8: 0.2 | BB8: 0.02 | BC8: -24 | BD8: 8.3 | BE8: 1 | DK8: 0.01 | DL8: 3 | DM8: 50 | DN8: 0 | DO8: -48 | DP8: 4 | DQ8: 2 | DR8: 0.005 | DS8: 0.04 | DT8: -56 | DU8: -3 | DV8: 4 | DW8: -30 | DX8: -3 | DY8: 4 | DZ8: 0 | EA8: -56 | EB8: 5 | EC8: 2 | ED8: 3 | EE8: 0.05 | EF8: -40 | EG8: -2 | EH8: 4
A9: B63rs | B9: B63rs | D9: 0.003 | E9: 0.025 | F9: -60 | G9: 7.5 | H9: 1 | I9: 50 | J9: 0 | K9: -42.1 | L9: 4.8 | M9: 3 | N9: 0.0015 | O9: 0.00045 | P9: -32.7 | Q9: 1.85 | R9: 1 | V9: 0 | W9: -51.5 | X9: 9.2 | Y9: 1 | Z9: 0.01 | AA9: 0.0024 | AB9: -39.2 | AC9: 3.5 | AD9: 1 | AH9: 50 | AI9: 4 | AJ9: -70 | AK9: 0 | AL9: -26.4 | AM9: 8.8 | AN9: 1 | AO9: 0.027 | AP9: 0.00216 | AQ9: -24 | AR9: 11.7 | AS9: 1 | AW9: 0.15 | AX9: -16.4 | AY9: 1.5 | AZ9: 2 | BA9: 0.2 | BB9: 0.02 | BC9: -24 | BD9: 8.3 | BE9: 1
A10: B63ra | B10: B63ra | D10: 0.003 | E10: 0.0012 | F10: -60 | G10: 7.5 | H10: 1 | I10: 50 | J10: 0 | K10: -42.1 | L10: 4.8 | M10: 3 | N10: 0.0015 | O10: 0.00045 | P10: -32.7 | Q10: 1.85 | R10: 1 | V10: 0 | W10: -51.5 | X10: 9.2 | Y10: 1 | Z10: 0.01 | AA10: 0.0024 | AB10: -39.2 | AC10: 3.5 | AD10: 1 | AH10: 60 | AI10: 4 | AJ10: -70 | AK10: 0 | AL10: -26.4 | AM10: 8.8 | AN10: 1 | AO10: 0.027 | AP10: 0.00216 | AQ10: -24 | AR10: 11.7 | AS10: 1 | AW10: 0.15 | AX10: -16.4 | AY10: 1.5 | AZ10: 2 | BA10: 0.2 | BB10: 0.02 | BC10: -24 | BD10: 8.3 | BE10: 1
A11: B31ls | B11: B31ls | D11: 0.011 | E11: 0.37 | F11: -60 | G11: 0.8 | H11: 3 | I11: -2 | J11: 0 | K11: -50 | L11: 4 | M11: 1 | N11: 1.6 | AH11: 9.5 | AI11: 1 | AJ11: -85 | AK11: 0 | AL11: -14 | AM11: 20 | AN11: 3 | AO11: 0.02 | AP11: 0.000275 | AQ11: -88 | AR11: 30 | AS11: 1 | AT11: -50 | AU11: -5 | AV11: 1 | AW11: 0 | AX11: -30 | AY11: 11 | AZ11: 1 | BA11: 0.33 | BB11: 0.008 | BC11: -80 | BD11: 70 | BE11: 1 | BF11: -73 | BG11: -9 | BH11: 1 | BI11: 15 | BJ11: 1 | BK11: -70 | BL11: 0 | BM11: 6 | BN11: 14 | BO11: 1 | BP11: 0.014 | BQ11: 0.003 | BR11: 20 | BS11: 7 | BT11: 1 | BU11: -15 | BV11: -6 | BW11: 1 | BX11: 0 | BY11: -31 | BZ11: 7 | CA11: 1 | CB11: 0.875 | CC11: 0.11 | CD11: -15 | CE11: 6 | CF11: 1 | CG11: -73 | CH11: -9 | CI11: 1 | CJ11: 5 | CK11: 1 | CL11: -35 | CM11: 0 | CN11: 19 | CO11: 11 | CP11: 1 | CQ11: 0.014 | CR11: 0.003 | CS11: 20 | CT11: 7 | CU11: 1 | CV11: -15 | CW11: -6 | CX11: 1 | CY11: 0 | CZ11: 1000 | DA11: 7 | DB11: 1
A12: B64rs | B12: B64rs | D12: 0.003 | E12: 0.05 | F12: -60 | G12: 0.9 | H12: 1 | I12: 50 | J12: 0 | K12: -42.1 | L12: 4.8 | M12: 3 | N12: 0.0015 | O12: 0.00045 | P12: -32.7 | Q12: 1.85 | R12: 1 | V12: 0 | W12: -51.5 | X12: 9.2 | Y12: 1 | Z12: 0.01 | AA12: 0.0024 | AB12: -39.2 | AC12: 3.5 | AD12: 1 | AH12: 3 | AI12: 4 | AJ12: -70 | AK12: 0 | AL12: -33 | AM12: 8.8 | AN12: 1 | AO12: 0.027 | AP12: 0.003 | AQ12: -24 | AR12: 11.7 | AS12: 1 | AW12: 0.15 | AX12: -16.4 | AY12: 1.5 | AZ12: 2 | BA12: 0.2 | BB12: 0.02 | BC12: -24 | BD12: 8.3 | BE12: 1 | BI12: 70 | BJ12: 4 | BK12: -70 | BL12: 0 | BM12: -19 | BN12: 8.8 | BO12: 1 | BP12: 0.27 | BQ12: 0.0216 | BR12: -24 | BS12: 11.7 | BT12: 1 | BX12: 0.15 | BY12: -16.4 | BZ12: 1.5 | CA12: 2 | CB12: 2 | CC12: 0.2 | CD12: -24 | CE12: 8.3 | CF12: 1 | DK12: 4.6 | DL12: 3 | DM12: 50 | DN12: 0 | DO12: -48 | DP12: 4 | DQ12: 2 | DR12: 0.16 | DS12: 0.00015 | DT12: -30 | DU12: 4 | DV12: 4 | DW12: -50 | DX12: -4 | DY12: 4 | DZ12: 0 | EA12: -57 | EB12: 5 | EC12: 2 | ED12: 2 | EE12: 0.2 | EF12: -44 | EG12: -3 | EH12: 4
A13: B64ra | B13: B64ra | D13: 0.003 | E13: 0.01 | F13: -60 | G13: 4 | H13: 1 | I13: 50 | J13: 0 | K13: -42.1 | L13: 4.8 | M13: 3 | N13: 0.0015 | O13: 0.00045 | P13: -32.7 | Q13: 1.85 | R13: 1 | V13: 0 | W13: -51.5 | X13: 9.2 | Y13: 1 | Z13: 0.01 | AA13: 0.0024 | AB13: -39.2 | AC13: 3.5 | AD13: 1 | AH13: 19 | AI13: 4 | AJ13: -70 | AK13: 0 | AL13: -33 | AM13: 8.8 | AN13: 1 | AO13: 0.027 | AP13: 0.003 | AQ13: -24 | AR13: 11.7 | AS13: 1 | AW13: 0.15 | AX13: -16.4 | AY13: 1.5 | AZ13: 2 | BA13: 0.2 | BB13: 0.02 | BC13: -24 | BD13: 8.3 | BE13: 1 | DK13: 0.01 | DL13: 3 | DM13: 50 | DN13: 0 | DO13: -48 | DP13: 4 | DQ13: 2 | DR13: 0.005 | DS13: 0.04 | DT13: -56 | DU13: -3 | DV13: 4 | DW13: -30 | DX13: -3 | DY13: 4 | DZ13: 0 | EA13: -56 | EB13: 5 | EC13: 2 | ED13: 3 | EE13: 0.05 | EF13: -40 | EG13: -2 | EH13: 4
A14: =Neu!B14 -> 0
A15: =Neu!B15 -> 0
A16: =Neu!B16 -> 0
A17: =Neu!B17 -> 0
A18: =Neu!B18 -> 0
A19: =Neu!B19 -> 0
A20: =Neu!B20 -> 0
A21: =Neu!B21 -> 0
A22: =Neu!B22 -> 0
A23: =Neu!B23 -> 0
A24: =Neu!B24 -> 0
D29: Ion pools | O29: Conductance to ion | Z29: Ion to conductance | BD29: Initial voltage
D30: Name | E30: ion | F30: K1 | G30: K2 | H30: ion | I30: K1 | J30: K2 | K30: ion | L30: K1 | M30: K2 | O30: Name | P30: ch | Q30: ion | R30: ch | S30: ion | T30: ch | U30: ion | V30: ch | W30: ion | Z30: Name | AA30: ion | AB30: ch | AC30: opt1 | AD30: opt2 | AE30: p1 | AF30: p2 | AG30: b | AH30: ion | AI30: ch | AJ30: opt1 | AK30: opt2 | AL30: p1 | AM30: p2 | AN30: b | AO30: ion | AP30: ch | AQ30: opt1 | AR30: opt2 | AS30: p1 | AT30: p2 | AU30: b | AV30: ion | AW30: ch | AX30: opt1 | AY30: opt2 | AZ30: p1 | BA30: p2 | BB30: b | BD30: Name | BE30: mV
D31: =Neu!$B4 -> B63ls | O31: =Neu!$B4 -> B63ls | Z31: =Neu!$B4 -> B63ls | BD31: =Neu!$B4 -> B63ls | BE31: -62
D32: =Neu!$B5 -> B63la | E32: Na | F32: 14 | G32: 0.4 | O32: =Neu!$B5 -> B63la | P32: Na | Q32: Na | Z32: =Neu!$B5 -> B63la | BD32: =Neu!$B5 -> B63la | BE32: -62
D33: =Neu!$B6 -> B31rs | O33: =Neu!$B6 -> B31rs | Z33: =Neu!$B6 -> B31rs | BD33: =Neu!$B6 -> B31rs | BE33: -62
D34: =Neu!$B7 -> B64ls | O34: =Neu!$B7 -> B64ls | Z34: =Neu!$B7 -> B64ls | BD34: =Neu!$B7 -> B64ls | BE34: -62
D35: =Neu!$B8 -> B64la | O35: =Neu!$B8 -> B64la | Z35: =Neu!$B8 -> B64la | BD35: =Neu!$B8 -> B64la | BE35: -62
D36: =Neu!$B9 -> B63rs | O36: =Neu!$B9 -> B63rs | Z36: =Neu!$B9 -> B63rs | BD36: =Neu!$B9 -> B63rs | BE36: -62
D37: =Neu!$B10 -> B63ra | O37: =Neu!$B10 -> B63ra | Z37: =Neu!$B10 -> B63ra | BD37: =Neu!$B10 -> B63ra | BE37: -62
D38: =Neu!$B11 -> B31ls | O38: =Neu!$B11 -> B31ls | Z38: =Neu!$B11 -> B31ls | BD38: =Neu!$B11 -> B31ls | BE38: -62
D39: =Neu!$B12 -> B64rs | O39: =Neu!$B12 -> B64rs | Z39: =Neu!$B12 -> B64rs | BD39: =Neu!$B12 -> B64rs | BE39: -62
D40: =Neu!$B13 -> B64ra | O40: =Neu!$B13 -> B64ra | Z40: =Neu!$B13 -> B64ra | BD40: =Neu!$B13 -> B64ra | BE40: -62
D41: =Neu!$B14 -> 0 | O41: =Neu!$B14 -> 0 | Z41: =Neu!$B14 -> 0
D42: =Neu!$B15 -> 0 | O42: =Neu!$B15 -> 0 | Z42: =Neu!$B15 -> 0
D43: =Neu!$B16 -> 0 | O43: =Neu!$B16 -> 0 | Z43: =Neu!$B16 -> 0
D44: =Neu!$B17 -> 0 | O44: =Neu!$B17 -> 0 | Z44: =Neu!$B17 -> 0
...

Sheet cs_g
C1: Postsynaptic
C2: =Neu!$B4 -> B63ls | D2: =Neu!$B5 -> B63la | E2: =Neu!$B6 -> B31rs | F2: =Neu!$B7 -> B64ls | G2: =Neu!$B8 -> B64la | H2: =Neu!$B9 -> B63rs | I2: =Neu!$B10 -> B63ra | J2: =Neu!$B11 -> B31ls | K2: =Neu!$B12 -> B64rs | L2: =Neu!$B13 -> B64ra | M2: =Neu!$B14 -> 0 | N2: =Neu!$B15 -> 0 | O2: =Neu!$B16 -> 0 | P2: =Neu!$B17 -> 0 | Q2: =Neu!$B18 -> 0 | R2: =Neu!$B19 -> 0 | S2: =Neu!$B20 -> 0 | T2: =Neu!$B21 -> 0 | U2: =Neu!$B22 -> 0 | V2: =Neu!$B23 -> 0 | W2: =Neu!$B24 -> 0
A3: Presynaptic | B3: =Neu!B4 -> B63ls | X3: fast | Y3: Colorbar
X4: slow | Y4: =MAX($C$3:$W$44)-(ROW(Y4)-4)*0.5 -> 1000
B5: =Neu!B5 -> B63la | E5: 0.4 | Y5: =MAX($C$3:$W$44)-(ROW(Y5)-4)*0.5 -> 999.5
E6: 18 | F6: 0.16 | G6: 0.01 | Y6: =MAX($C$3:$W$44)-(ROW(Y6)-4)*0.5 -> 999
B7: =Neu!B6 -> B31rs | Y7: =MAX($C$3:$W$44)-(ROW(Y7)-4)*0.5 -> 998.5
Y8: =MAX($C$3:$W$44)-(ROW(Y8)-4)*0.5 -> 998
B9: =Neu!B7 -> B64ls | Y9: =MAX($C$3:$W$44)-(ROW(Y9)-4)*0.5 -> 997.5
Y10: =MAX($C$3:$W$44)-(ROW(Y10)-4)*0.5 -> 997
B11: =Neu!B8 -> B64la | Y11: =MAX($C$3:$W$44)-(ROW(Y11)-4)*0.5 -> 996.5
C12: 200 | D12: 200 | E12: 1000 | Y12: =MAX($C$3:$W$44)-(ROW(Y12)-4)*0.5 -> 996
B13: =Neu!B9 -> B63rs | Y13: =MAX($C$3:$W$44)-(ROW(Y13)-4)*0.5 -> 995.5
Y14: =MAX($C$3:$W$44)-(ROW(Y14)-4)*0.5 -> 995
B15: =Neu!B10 -> B63ra | J15: 0.4 | Y15: =MAX($C$3:$W$44)-(ROW(Y15)-4)*0.5 -> 994.5
J16: 1e-06 | K16: 0.16 | L16: 0.01 | Y16: =MAX($C$3:$W$44)-(ROW(Y16)-4)*0.5 -> 994
B17: =Neu!B11 -> B31ls | Y17: =MAX($C$3:$W$44)-(ROW(Y17)-4)*0.5 -> 993.5
Y18: =MAX($C$3:$W$44)-(ROW(Y18)-4)*0.5 -> 993
B19: =Neu!B12 -> B64rs | Y19: =MAX($C$3:$W$44)-(ROW(Y19)-4)*0.5 -> 992.5
Y20: =MAX($C$3:$W$44)-(ROW(Y20)-4)*0.5 -> 992
B21: =Neu!B13 -> B64ra | Y21: =MAX($C$3:$W$44)-(ROW(Y21)-4)*0.5 -> 991.5
H22: 200 | I22: 200 | J22: 1000 | Y22: =MAX($C$3:$W$44)-(ROW(Y22)-4)*0.5 -> 991
B23: =Neu!B14 -> 0 | Y23: =MAX($C$3:$W$44)-(ROW(Y23)-4)*0.5 -> 990.5
Y24: =MAX($C$3:$W$44)-(ROW(Y24)-4)*0.5 -> 990
B25: =Neu!B15 -> 0 | Y25: =MAX($C$3:$W$44)-(ROW(Y25)-4)*0.5 -> 989.5
Y26: =MAX($C$3:$W$44)-(ROW(Y26)-4)*0.5 -> 989
B27: =Neu!B16 -> 0
B29: =Neu!B17 -> 0
B31: =Neu!B18 -> 0
B33: =Neu!B19 -> 0
B35: =Neu!B20 -> 0
B37: =Neu!B21 -> 0
B39: =Neu!B22 -> 0
B41: =Neu!B23 -> 0
B43: =Neu!B24 -> 0

Sheet cs_E
C1: Postsynaptic
C2: =Neu!$B4 -> B63ls | D2: =Neu!$B5 -> B63la | E2: =Neu!$B6 -> B31rs | F2: =Neu!$B7 -> B64ls | G2: =Neu!$B8 -> B64la | H2: =Neu!$B9 -> B63rs | I2: =Neu!$B10 -> B63ra | J2: =Neu!$B11 -> B31ls | K2: =Neu!$B12 -> B64rs | L2: =Neu!$B13 -> B64ra | M2: =Neu!$B14 -> 0 | N2: =Neu!$B15 -> 0 | O2: =Neu!$B16 -> 0 | P2: =Neu!$B17 -> 0 | Q2: =Neu!$B18 -> 0 | R2: =Neu!$B19 -> 0 | S2: =Neu!$B20 -> 0 | T2: =Neu!$B21 -> 0 | U2: =Neu!$B22 -> 0 | V2: =Neu!$B23 -> 0 | W2: =Neu!$B24 -> 0
A3: Presynaptic | B3: =Neu!B4 -> B63ls | X3: fast | Y3: Colorbar
X4: slow | Y4: =MAX($C$3:$W$44)-(ROW(Y4)-4)*10 -> 0
B5: =Neu!B5 -> B63la | E5: 0 | Y5: =MAX($C$3:$W$44)-(ROW(Y5)-4)*10 -> -10
E6: -2 | F6: -2 | G6: -2 | Y6: =MAX($C$3:$W$44)-(ROW(Y6)-4)*10 -> -20
B7: =Neu!B6 -> B31rs | Y7: =MAX($C$3:$W$44)-(ROW(Y7)-4)*10 -> -30
Y8: =MAX($C$3:$W$44)-(ROW(Y8)-4)*10 -> -40
B9: =Neu!B7 -> B64ls | Y9: =MAX($C$3:$W$44)-(ROW(Y9)-4)*10 -> -50
Y10: =MAX($C$3:$W$44)-(ROW(Y10)-4)*10 -> -60
B11: =Neu!B8 -> B64la | Y11: =MAX($C$3:$W$44)-(ROW(Y11)-4)*10 -> -70
C12: -75 | D12: -75 | E12: -75 | Y12: =MAX($C$3:$W$44)-(ROW(Y12)-4)*10 -> -80
B13: =Neu!B9 -> B63rs | Y13: =MAX($C$3:$W$44)-(ROW(Y13)-4)*10 -> -90
Y14: =MAX($C$3:$W$44)-(ROW(Y14)-4)*10 -> -100
B15: =Neu!B10 -> B63ra | J15: 0 | Y15: =MAX($C$3:$W$44)-(ROW(Y15)-4)*10 -> -110
J16: -2 | K16: -2 | L16: -2 | Y16: =MAX($C$3:$W$44)-(ROW(Y16)-4)*10 -> -120
B17: =Neu!B11 -> B31ls | Y17: =MAX($C$3:$W$44)-(ROW(Y17)-4)*10 -> -130
Y18: =MAX($C$3:$W$44)-(ROW(Y18)-4)*10 -> -140
B19: =Neu!B12 -> B64rs | Y19: =MAX($C$3:$W$44)-(ROW(Y19)-4)*10 -> -150
Y20: =MAX($C$3:$W$44)-(ROW(Y20)-4)*10 -> -160
B21: =Neu!B13 -> B64ra | Y21: =MAX($C$3:$W$44)-(ROW(Y21)-4)*10 -> -170
H22: -75 | I22: -75 | J22: -75 | Y22: =MAX($C$3:$W$44)-(ROW(Y22)-4)*10 -> -180
B23: =Neu!B14 -> 0 | Y23: =MAX($C$3:$W$44)-(ROW(Y23)-4)*10 -> -190
Y24: =MAX($C$3:$W$44)-(ROW(Y24)-4)*10 -> -200
B25: =Neu!B15 -> 0 | Y25: =MAX($C$3:$W$44)-(ROW(Y25)-4)*10 -> -210
Y26: =MAX($C$3:$W$44)-(ROW(Y26)-4)*10 -> -220
B27: =Neu!B16 -> 0 | Y27: =MAX($C$3:$W$44)-(ROW(Y27)-4)*10 -> -230
Y28: =MAX($C$3:$W$44)-(ROW(Y28)-4)*10 -> -240
B29: =Neu!B17 -> 0 | Y29: =MAX($C$3:$W$44)-(ROW(Y29)-4)*10 -> -250
Y30: =MAX($C$3:$W$44)-(ROW(Y30)-4)*10 -> -260
B31: =Neu!B18 -> 0 | Y31: =MAX($C$3:$W$44)-(ROW(Y31)-4)*10 -> -270
Y32: =MAX($C$3:$W$44)-(ROW(Y32)-4)*10 -> -280
B33: =Neu!B19 -> 0
B35: =Neu!B20 -> 0
B37: =Neu!B21 -> 0
B39: =Neu!B22 -> 0
B41: =Neu!B23 -> 0
B43: =Neu!B24 -> 0

Sheet cs_FAT
C1: Postsynaptic | AA1: taus | AC1: depression | AE1: Voltage dependence | AI1: facilitation
C2: =Neu!$B4 -> B63ls | D2: =Neu!$B5 -> B63la | E2: =Neu!$B6 -> B31rs | F2: =Neu!$B7 -> B64ls | G2: =Neu!$B8 -> B64la | H2: =Neu!$B9 -> B63rs | I2: =Neu!$B10 -> B63ra | J2: =Neu!$B11 -> B31ls | K2: =Neu!$B12 -> B64rs | L2: =Neu!$B13 -> B64ra | M2: =Neu!$B14 -> 0 | N2: =Neu!$B15 -> 0 | O2: =Neu!$B16 -> 0 | P2: =Neu!$B17 -> 0 | Q2: =Neu!$B18 -> 0 | R2: =Neu!$B19 -> 0 | S2: =Neu!$B20 -> 0 | T2: =Neu!$B21 -> 0 | U2: =Neu!$B22 -> 0 | V2: =Neu!$B23 -> 0 | W2: =Neu!$B24 -> 0 | AA2: u1 | AB2: u2 | AC2: ud | AD2: ur | AE2: h | AF2: s | AG2: p | AH2: tx | AI2: ion | AJ2: u
A3: Presynaptic | B3: =Neu!B4 -> B63ls | X3: fast | Y3: =COUNTIF($C$3:$W$44,ROW(Z3)-2) -> 2 | Z3: =IF(ROW(AA3)-2<=MAX($C$3:$W$44),ROW(AA3)-2,"") -> 1 | AA3: 0.001 | AB3: 0.01 | AC3: -0.09 | AD3: 3.3
X4: slow | Y4: =COUNTIF($C$3:$W$44,ROW(Z4)-2) -> 6 | Z4: =IF(ROW(AA4)-2<=MAX($C$3:$W$44),ROW(AA4)-2,"") -> 2 | AA4: 1.4 | AB4: 2.8 | AC4: -0.09 | AD4: 3.3 | AE4: -50 | AF4: 4 | AG4: 1 | AH4: 0.3
B5: =Neu!B5 -> B63la | E5: 1 | Y5: =COUNTIF($C$3:$W$44,ROW(Z5)-2) -> 0 | Z5: =IF(ROW(AA5)-2<=MAX($C$3:$W$44),ROW(AA5)-2,"") -> 3 | AA5: 1.4 | AB5: 2.8 | AC5: -1 | AD5: 1 | AE5: -50 | AF5: 4 | AG5: 1 | AH5: 0.3
E6: 2 | F6: 2 | G6: 2 | Y6: =COUNTIF($C$3:$W$44,ROW(Z6)-2) -> 6 | Z6: =IF(ROW(AA6)-2<=MAX($C$3:$W$44),ROW(AA6)-2,"") -> 4 | AA6: 0.015 | AB6: 1.5 | AC6: -1 | AD6: 1
B7: =Neu!B6 -> B31rs | Y7: =COUNTIF($C$3:$W$44,ROW(Z7)-2) -> 0 | Z7: =IF(ROW(AA7)-2<=MAX($C$3:$W$44),ROW(AA7)-2,"")
Y8: =COUNTIF($C$3:$W$44,ROW(Z8)-2) -> 0 | Z8: =IF(ROW(AA8)-2<=MAX($C$3:$W$44),ROW(AA8)-2,"")
B9: =Neu!B7 -> B64ls | Y9: =COUNTIF($C$3:$W$44,ROW(Z9)-2) -> 0 | Z9: =IF(ROW(AA9)-2<=MAX($C$3:$W$44),ROW(AA9)-2,"") | AK9: if u2 is empty it is assumed equal to u1
Y10: =COUNTIF($C$3:$W$44,ROW(Z10)-2) -> 0 | Z10: =IF(ROW(AA10)-2<=MAX($C$3:$W$44),ROW(AA10)-2,"")
B11: =Neu!B8 -> B64la | Y11: =COUNTIF($C$3:$W$44,ROW(Z11)-2) -> 0 | Z11: =IF(ROW(AA11)-2<=MAX($C$3:$W$44),ROW(AA11)-2,"")
C12: 4 | D12: 4 | E12: 4 | Y12: =COUNTIF($C$3:$W$44,ROW(Z12)-2) -> 0 | Z12: =IF(ROW(AA12)-2<=MAX($C$3:$W$44),ROW(AA12)-2,"")
B13: =Neu!B9 -> B63rs | Y13: =COUNTIF($C$3:$W$44,ROW(Z13)-2) -> 0 | Z13: =IF(ROW(AA13)-2<=MAX($C$3:$W$44),ROW(AA13)-2,"") | AK13: Ach
Y14: =COUNTIF($C$3:$W$44,ROW(Z14)-2) -> 0 | Z14: =IF(ROW(AA14)-2<=MAX($C$3:$W$44),ROW(AA14)-2,"")
B15: =Neu!B10 -> B63ra | J15: 1 | Y15: =COUNTIF($C$3:$W$44,ROW(Z15)-2) -> 0 | Z15: =IF(ROW(AA15)-2<=MAX($C$3:$W$44),ROW(AA15)-2,"")
J16: 2 | K16: 2 | L16: 2 | Y16: =COUNTIF($C$3:$W$44,ROW(Z16)-2) -> 0 | Z16: =IF(ROW(AA16)-2<=MAX($C$3:$W$44),ROW(AA16)-2,"")
B17: =Neu!B11 -> B31ls | Y17: =COUNTIF($C$3:$W$44,ROW(Z17)-2) -> 0 | Z17: =IF(ROW(AA17)-2<=MAX($C$3:$W$44),ROW(AA17)-2,"")
Y18: =COUNTIF($C$3:$W$44,ROW(Z18)-2) -> 0 | Z18: =IF(ROW(AA18)-2<=MAX($C$3:$W$44),ROW(AA18)-2,"")
B19: =Neu!B12 -> B64rs | Y19: =COUNTIF($C$3:$W$44,ROW(Z19)-2) -> 0 | Z19: =IF(ROW(AA19)-2<=MAX($C$3:$W$44),ROW(AA19)-2,"")
Y20: =COUNTIF($C$3:$W$44,ROW(Z20)-2) -> 0 | Z20: =IF(ROW(AA20)-2<=MAX($C$3:$W$44),ROW(AA20)-2,"")
B21: =Neu!B13 -> B64ra | Y21: =COUNTIF($C$3:$W$44,ROW(Z21)-2) -> 0 | Z21: =IF(ROW(AA21)-2<=MAX($C$3:$W$44),ROW(AA21)-2,"")
H22: 4 | I22: 4 | J22: 4 | Y22: =COUNTIF($C$3:$W$44,ROW(Z22)-2) -> 0 | Z22: =IF(ROW(AA22)-2<=MAX($C$3:$W$44),ROW(AA22)-2,"")
B23: =Neu!B14 -> 0 | Y23: =COUNTIF($C$3:$W$44,ROW(Z23)-2) -> 0 | Z23: =IF(ROW(AA23)-2<=MAX($C$3:$W$44),ROW(AA23)-2,"")
Y24: =COUNTIF($C$3:$W$44,ROW(Z24)-2) -> 0 | Z24: =IF(ROW(AA24)-2<=MAX($C$3:$W$44),ROW(AA24)-2,"")
B25: =Neu!B15 -> 0 | Y25: =COUNTIF($C$3:$W$44,ROW(Z25)-2) -> 0 | Z25: =IF(ROW(AA25)-2<=MAX($C$3:$W$44),ROW(AA25)-2,"")
Y26: =COUNTIF($C$3:$W$44,ROW(Z26)-2) -> 0 | Z26: =IF(ROW(AA26)-2<=MAX($C$3:$W$44),ROW(AA26)-2,"")
B27: =Neu!B16 -> 0 | Y27: =COUNTIF($C$3:$W$44,ROW(Z27)-2) -> 0 | Z27: =IF(ROW(AA27)-2<=MAX($C$3:$W$44),ROW(AA27)-2,"")
Y28: =COUNTIF($C$3:$W$44,ROW(Z28)-2) -> 0 | Z28: =IF(ROW(AA28)-2<=MAX($C$3:$W$44),ROW(AA28)-2,"")
B29: =Neu!B17 -> 0 | Y29: =COUNTIF($C$3:$W$44,ROW(Z29)-2) -> 0 | Z29: =IF(ROW(AA29)-2<=MAX($C$3:$W$44),ROW(AA29)-2,"")
Y30: =COUNTIF($C$3:$W$44,ROW(Z30)-2) -> 0 | Z30: =IF(ROW(AA30)-2<=MAX($C$3:$W$44),ROW(AA30)-2,"")
B31: =Neu!B18 -> 0 | Y31: =COUNTIF($C$3:$W$44,ROW(Z31)-2) -> 0 | Z31: =IF(ROW(AA31)-2<=MAX($C$3:$W$44),ROW(AA31)-2,"")
Y32: =COUNTIF($C$3:$W$44,ROW(Z32)-2) -> 0 | Z32: =IF(ROW(AA32)-2<=MAX($C$3:$W$44),ROW(AA32)-2,"")
B33: =Neu!B19 -> 0 | Y33: =COUNTIF($C$3:$W$44,ROW(Z33)-2) -> 0 | Z33: =IF(ROW(AA33)-2<=MAX($C$3:$W$44),ROW(AA33)-2,"")
Y34: =COUNTIF($C$3:$W$44,ROW(Z34)-2) -> 0 | Z34: =IF(ROW(AA34)-2<=MAX($C$3:$W$44),ROW(AA34)-2,"")
B35: =Neu!B20 -> 0 | Y35: =COUNTIF($C$3:$W$44,ROW(Z35)-2) -> 0 | Z35: =IF(ROW(AA35)-2<=MAX($C$3:$W$44),ROW(AA35)-2,"")
Y36: =COUNTIF($C$3:$W$44,ROW(Z36)-2) -> 0 | Z36: =IF(ROW(AA36)-2<=MAX($C$3:$W$44),ROW(AA36)-2,"")
B37: =Neu!B21 -> 0 | Y37: =COUNTIF($C$3:$W$44,ROW(Z37)-2) -> 0 | Z37: =IF(ROW(AA37)-2<=MAX($C$3:$W$44),ROW(AA37)-2,"")
Y38: =COUNTIF($C$3:$W$44,ROW(Z38)-2) -> 0 | Z38: =IF(ROW(AA38)-2<=MAX($C$3:$W$44),ROW(AA38)-2,"")
B39: =Neu!B22 -> 0 | Y39: =COUNTIF($C$3:$W$44,ROW(Z39)-2) -> 0 | Z39: =IF(ROW(AA39)-2<=MAX($C$3:$W$44),ROW(AA39)-2,"")
Y40: =COUNTIF($C$3:$W$44,ROW(Z40)-2) -> 0 | Z40: =IF(ROW(AA40)-2<=MAX($C$3:$W$44),ROW(AA40)-2,"")
...

Sheet es
C1: Postsynaptic
C2: =Neu!B4 -> B63ls | D2: =Neu!B5 -> B63la | E2: =Neu!B6 -> B31rs | F2: =Neu!B7 -> B64ls | G2: =Neu!B8 -> B64la | H2: =Neu!B9 -> B63rs | I2: =Neu!B10 -> B63ra | J2: =Neu!B11 -> B31ls | K2: =Neu!B12 -> B64rs | L2: =Neu!B13 -> B64ra | M2: =Neu!B14 -> 0 | N2: =Neu!B15 -> 0 | O2: =Neu!B16 -> 0 | P2: =Neu!B17 -> 0 | Q2: =Neu!$B18 -> 0 | R2: =Neu!$B19 -> 0 | S2: =Neu!$B20 -> 0 | T2: =Neu!$B21 -> 0 | U2: =Neu!$B22 -> 0 | V2: =Neu!$B23 -> 0 | W2: =Neu!$B24 -> 0
A3: Presynaptic | B3: =Neu!B4 -> B63ls | D3: =C4 -> 0.13 | E3: =C5 -> 0 | F3: =C6 -> 0 | G3: =C7 -> 0 | H3: =C8 -> 0 | I3: =C9 -> 0 | J3: =C10 -> 0 | K3: =C11 -> 0 | L3: =C12 -> 0
B4: =Neu!B5 -> B63la | C4: 0.13 | E4: 0.045 | G4: =D7 -> 0 | H4: =D8 -> 0 | I4: =D9 -> 0 | J4: =D10 -> 0 | K4: =D11 -> 0 | L4: =D12 -> 0
B5: =Neu!B6 -> B31rs | D5: 0.045 | G5: =E7 -> 0 | H5: =E8 -> 0 | I5: =E9 -> 0 | J5: =E10 -> 0 | K5: =E11 -> 0 | L5: =E12 -> 0
B6: =Neu!B7 -> B64ls | G6: 0.025 | H6: =F8 -> 0 | I6: =F9 -> 0 | J6: =F10 -> 0 | K6: =F11 -> 0 | L6: =F12 -> 0
B7: =Neu!B8 -> B64la | F7: 0.1 | H7: =G8 -> 0 | I7: =G9 -> 0 | J7: =G10 -> 0 | K7: =G11 -> 0 | L7: =G12 -> 0
B8: =Neu!B9 -> B63rs | I8: =H9 -> 0.13 | J8: =H10 -> 0 | K8: =H11 -> 0 | L8: =H12 -> 0
B9: =Neu!B10 -> B63ra | H9: 0.13 | J9: =I10 -> 0.05 | K9: =I11 -> 0 | L9: =I12 -> 0
B10: =Neu!B11 -> B31ls | I10: 0.05 | K10: =J11 -> 0 | L10: =J12 -> 0
B11: =Neu!B12 -> B64rs | L11: 0.025
B12: =Neu!B13 -> B64ra | K12: 0.1
B13: =Neu!B14 -> 0
B14: =Neu!B15 -> 0
B15: =Neu!B16 -> 0
B16: =Neu!B17 -> 0
B17: =Neu!B18 -> 0
B18: =Neu!B19 -> 0
B19: =Neu!B20 -> 0
B20: =Neu!B21 -> 0
B21: =Neu!B22 -> 0
B22: =Neu!B23 -> 0
B23: =Neu!B24 -> 0

Sheet noise
B1: Amplitude | C1: step size | D1: jitter in step size
A2: votage-dependent conductance (.vdg) | B2: 0 | C2: 50 | D2: 10
A3: chemical synapse (.cs) | B3: 0 | C3: 200 | D3: 10
A4: electrical synapse (.es) | B4: 0 | C4: 200 | D4: 10

Sheet BMP2SIMPLE_l.smu
F1: syntax | L1: example variables | M1: IVDxREG | N1: currrent by conductance and regulation | T1: example synapses
A2: smu | B2: name | C2: BMP2SIMPLE_l | D2: graph | E2: 1 | F2: conductance | G2: variable.conductance.neuron | M2: V | N2: voltage | Q2: Ics | R2: chem syn current | T2: f_exc | U2: fast excitatory
B3: duration | C3: 24 | D3: store | E3: 1 | F3: example | G3: Ivd.Na.N1 | I3: fBR | J3: fBR.ion.ch.neuron | M3: Ivd | N3: current by voltage gated conductance | Q3: Cion | R3: amount of ion | T3: s_exc | U3: slow excitatory
B4: stepsize | C4: 5e-05 | D4: method | E4: 1 | F4: neuron | G4: variable.neuron | I4: synapse | J4: variable.pre.post.type | M4: A | N4: activation of conductance | Q4: Ies | R4: elec syn current | T4: f_inh | U4: fast inhibitory
B5: red indicates simlation longer than graph duration | F5: example | G5: V.N1 | I5: example | J5: Ics.N1.N4.f_exc | M5: B | N5: Inactivation of conductance | Q5: slex | R5: trt current | T5: s_inh | U5: slow inhibitory
A6: graph (ous) | J6: Ies.N1.N4 | M6: SIVD_reg | N6: for total current
B7: time | G7: variable 1 | L7: variable 2 | Q7: variable 3 | V7: variable 4
A8: Size | B8: variable | C8: # ticks | D8: start | E8: stop | F8: color | G8: variable | H8: # ticks | I8: min | J8: max | K8: color | L8: variable | M8: # ticks | N8: min | O8: max | P8: color | Q8: variable | R8: # ticks | S8: min | T8: max | U8: color | V8: variable | W8: # ticks | X8: min | Y8: max | Z8: color
A9: 1 | B9: time | C9: 6 | D9: 0 | E9: 24 | F9: blue | G9: V.B31rs | H9: 7 | I9: -70 | J9: 0 | K9: red
A10: 1 | B10: time | C10: 6 | D10: 0 | E10: 24 | F10: blue | G10: V.B63ls | H10: 7 | I10: -70 | J10: 0 | K10: magenta
A11: 1 | B11: time | C11: 6 | D11: 0 | E11: 24 | F11: blue | G11: V.B64ls | H11: 7 | I11: -70 | J11: 0 | K11: pink | L11: V.B64la | M11: 7 | N11: -70 | O11: 0 | P11: yellow
A12: 1 | B12: time | C12: 6 | D12: 0 | E12: 24 | F12: blue | G12: Ics.B63la.B31rs.s_exc | H12: 5 | I12: -60 | J12: 0 | K12: magenta | L12: Ics.B63la.B64ls.s_exc | M12: 5 | N12: -2 | O12: 0 | P12: blue
A13: 1 | B13: time | C13: 6 | D13: 0 | E13: 24 | F13: blue | G13: Ivd.Napp.B64ls | H13: 6 | I13: -5 | J13: 1 | K13: red | L13: Ivd.Ka.B64ls | M13: 6 | N13: -2 | O13: 34 | P13: orange | Q13: Ivd.Kv.B64ls | R13: 6 | S13: -2 | T13: 34 | U13: green
A16: stimulation (.trt) | L16: output variables
B17: Current injection | G17: Voltage clamp | L17: all | M17: type "all" in first cell to output all graphed variables or type individual channels
B18: neuron | C18: start | D18: stop | E18: magnitude | G18: neuron | H18: start | I18: stop | J18: potential
B19: B63ls | C19: 0.5 | D19: 1.5 | E19: 1.2
B20: B63ls | C20: 2.5 | D20: 3.5 | E20: 1.2
B21: B63ls | C21: 4.5 | D21: 5.5 | E21: 1.2
B22: B63ls | C22: 6.5 | D22: 7.5 | E22: 1.2

Sheet BMP_TONIC_l.smu
F1: syntax | L1: example variables | M1: IVDxREG | N1: currrent by conductance and regulation | T1: example synapses
A2: smu | B2: name | C2: BMP_TONIC_l | D2: graph | E2: 1 | F2: conductance | G2: variable.conductance.neuron | M2: V | N2: voltage | Q2: Ics | R2: chem syn current | T2: f_exc | U2: fast excitatory
B3: duration | C3: 60 | D3: store | E3: 1 | F3: example | G3: Ivd.Na.N1 | I3: fBR | J3: fBR.ion.ch.neuron | M3: Ivd | N3: current by voltage gated conductance | Q3: Cion | R3: amount of ion | T3: s_exc | U3: slow excitatory
B4: stepsize | C4: 5e-05 | D4: method | E4: 1 | F4: neuron | G4: variable.neuron | I4: synapse | J4: variable.pre.post.type | M4: A | N4: activation of conductance | Q4: Ies | R4: elec syn current | T4: f_inh | U4: fast inhibitory
B5: red indicates simlation longer than graph duration | F5: example | G5: V.N1 | I5: example | J5: Ics.N1.N4.f_exc | M5: B | N5: Inactivation of conductance | Q5: slex | R5: trt current | T5: s_inh | U5: slow inhibitory
A6: graph (ous) | J6: Ies.N1.N4 | M6: SIVD_reg | N6: for total current
B7: time | G7: variable 1 | L7: variable 2 | Q7: variable 3
A8: Size | B8: variable | C8: # ticks | D8: start | E8: stop | F8: color | G8: variable | H8: # ticks | I8: min | J8: max | K8: color | L8: variable | M8: # ticks | N8: min | O8: max | P8: color | Q8: variable | R8: # ticks | S8: min | T8: max | U8: color
A9: 1 | B9: time | C9: 6 | D9: 0 | E9: 60 | F9: blue | G9: V.B31rs | H9: 5 | I9: -70 | J9: -20 | K9: red
A10: 1 | B10: time | C10: 6 | D10: 0 | E10: 60 | F10: blue | G10: V.B63ls | H10: 7 | I10: -70 | J10: 0 | K10: magenta | L10: V.B64la | M10: 7 | N10: -70 | O10: 0 | P10: yellow
A11: 1 | B11: time | C11: 6 | D11: 0 | E11: 60 | F11: blue | G11: V.B64ls | H11: 5 | I11: -70 | J11: -20 | K11: pink
A12: 1 | B12: time | C12: 6 | D12: 0 | E12: 60 | F12: blue | G12: Ics.B63la.B31rs.s_exc | H12: 5 | I12: -200 | J12: 0 | K12: magenta | L12: Ics.B63la.B64ls.s_exc | M12: 5 | N12: -2 | O12: 0 | P12: blue
A13: 1 | B13: time | C13: 6 | D13: 0 | E13: 60 | F13: blue | G13: Ivd.Napp.B64ls | H13: 4 | I13: -20 | J13: 0 | K13: red | L13: Ivd.Ka.B64ls | M13: 4 | N13: 0 | O13: 40 | P13: orange | Q13: Ivd.Kv.B64ls | R13: 4 | S13: 0 | T13: 12 | U13: green
A16: stimulation (.trt) | L16: output variables
B17: Current injection | G17: Voltage clamp | L17: all | M17: type "all" in first cell to output all graphed variables or type individual channels
B18: neuron | C18: start | D18: stop | E18: magnitude | G18: neuron | H18: start | I18: stop | J18: potential
B19: B63ls | C19: 1 | D19: 60 | E19: 1.2
